Workbook

Sheet Highway
B1: Sales by Sections | H1: Sales by Order Type | N1: Sales by Category | W1: Daily and Hourly Sales (TBD)
B2: Total Bill Count | C2: Net Sales | D2: Remaining | E2: Skip | F2: DD | G2: Uber | H2: Take Out | I2: Delivery | J2: Bar Tab | K2: Dine-In | L2: Online Order | M2: Net Sales | N2: Chickentarian | O2: Drinks | P2: Food (Pizza K) | Q2: Food Court | R2: Food Highway | S2: Kabab Wala | T2: Smash Ox Burger | U2: Uncategorized | V2: Net Sales | W2: 8AM - 11AM | X2: 11AM - 3PM | Y2: 3PM - 6PM | Z2: 6PM - 11PM | AA2: 11PM-7AM
A3: Dec 30 - Jan 05 2025
A4: Jan 06 - Jan 12 2025
A5: Jan 13 - Jan 19 2025
A6: Jan 20 - Jan 26 2025
A7: Jan 27 - Feb 02 2025
A8: Feb 03 - Feb 09 2025 | C8: 11861.51 | D8: 9636.07 | E8: 155.86 | F8: 19.17 | G8: 2050.41 | H8: 2953.18 | I8: 0 | J8: 132.96 | K8: 6549.93 | L8: 2225.44 | M8: 11861.51 | N8: 27.98 | O8: 77.45 | P8: 4161.14 | Q8: 0 | R8: 7594.94 | S8: 0 | U8: 0 | V8: 11861.51
A9: Feb 10 - Feb 16 2025 | C9: 13261.22 | D9: 10552.83 | E9: 103.06 | F9: 34.5 | G9: 2570.83 | H9: 3565.24 | I9: 0 | J9: 22 | K9: 6965.61 | L9: 2708.39 | M9: 13261.24 | N9: 41.97 | O9: 39.95 | P9: 3813.5 | Q9: 0 | R9: 9365.82 | S9: 0 | U9: 0 | V9: 13261.24 | W9: 0 | X9: 2199.32 | Y9: 1984.54 | Z9: 7733.3 | AA9: 1344.06
A10: Feb 17 - Feb 23 2025 | C10: 13844.9 | D10: 11974.8 | E10: 157.5 | F10: 41.68 | G10: 1670.92 | H10: 3836.29 | I10: 0 | J10: 123.65 | K10: 8014.86 | L10: 1870.1 | M10: 13844.9 | N10: 83.94 | O10: 69.75 | P10: 4216.31 | Q10: 0 | R10: 9474.9 | S10: 0 | U10: 0 | V10: 13844.9 | W10: 0 | X10: 1769.57 | Y10: 2832.43 | Z10: 7231 | AA10: 2011.9
A11: Feb 24 - Mar 02 2025 | C11: 12020.47 | D11: 10244.94 | E11: 185.6 | F11: 0 | G11: 1589.93 | H11: 3308.11 | I11: 0 | J11: 120.96 | K11: 6789.47 | L11: 1801.93 | M11: 12020.47 | N11: 27.98 | O11: 56.35 | P11: 3759.38 | Q11: 0 | R11: 8176.76 | S11: 0 | U11: 0 | V11: 12020.47 | W11: 0 | X11: 1231.12 | Y11: 2495.84 | Z11: 5553.74 | AA11: 2739.77
A12: Mar 03 - Mar 09 2025 | C12: 14922.09 | D12: 13909.7 | E12: 69.4 | F12: 0 | G12: 942.99 | H12: 3436.43 | I12: 0 | J12: 80.9 | K12: 10179.04 | L12: 1225.72 | M12: 14922.09 | N12: 0 | O12: 18.45 | P12: 2986.44 | Q12: 0 | R12: 11917.2 | S12: 0 | U12: 0 | V12: 14922.09 | W12: 0 | X12: 200.08 | Y12: 2720.72 | Z12: 6277.32 | AA12: 5723.97
A13: Mar 10 - Mar 16 2025 | C13: 13617.54 | D13: 12075.21 | E13: 112.79 | F13: 0 | G13: 1429.54 | H13: 2801.76 | I13: 0 | J13: 176.69 | K13: 8984.7 | L13: 1654.39 | M13: 13617.54 | N13: 27.98 | O13: 55.8 | P13: 3346.17 | Q13: 0 | R13: 10187.59 | S13: 0 | U13: 0 | V13: 13617.54 | W13: 0 | X13: 334.64 | Y13: 1714.4 | Z13: 7152.15 | AA13: 4416.35
A14: Mar 17 - Mar 23 2025 | C14: 15855.89 | D14: 13916.46 | E14: 32.4 | F14: 0 | G14: 1907.03 | H14: 2812.34 | I14: 0 | J14: 104.36 | K14: 10885.01 | L14: 2054.18 | M14: 15855.89 | N14: 27.98 | O14: 67.95 | P14: 3694.94 | Q14: 0 | R14: 12065.02 | S14: 0 | U14: 0 | V14: 15855.89 | W14: 0 | X14: 409.54 | Y14: 2584.09 | Z14: 9092.84 | AA14: 3769.42
A15: Mar 24 - Mar 30 2025 | C15: =G15+D15 | D15: =3675.92+2746+14430.35 | E15: 38.4 | F15: 0 | G15: 1816.28 | H15: 4920.34 | I15: 0 | J15: 390.73 | K15: 15088.82 | L15: 2307.07 | M15: 22706.96 | N15: 83.94 | O15: 43.75 | P15: 4700.82 | Q15: 0 | R15: 17878.45 | S15: 0 | U15: 0 | V15: 22706.96 | W15: 0 | X15: 2395.02 | Y15: 2213.4 | Z15: 13198.8 | AA15: 4899.74
A16: March 31 - April 6 | C16: 15129.21 | D16: =8263.32+3606.63+1198.69 | E16: 142.59 | F16: 88.2 | G16: 1829.78 | H16: 3126.25 | I16: 0 | J16: 0 | K16: 9557.01 | L16: 2445.95 | M16: 15129.21 | N16: 27.98 | O16: 48.75 | P16: 4050.56 | Q16: 0 | R16: 11001.92 | S16: 0 | U16: 0 | V16: 15129.21 | W16: 1915.8 | X16: 9598.38 | Y16: =923.09+2692.56 | Z16: OLD HOURS
A17: April 7 - April 13 | C17: 12415.08 | D17: =6964.46+1984.48+2516.88 | E17: 80.4 | F17: 0 | G17: 868.86 | H17: 3475.96 | I17: 0 | J17: 187.96 | K17: 7743.95 | L17: 1007.21 | M17: 12415.08 | N17: 13.99 | O17: 38.95 | P17: 4096.54 | Q17: 0 | R17: 8265.6 | S17: 0 | U17: 0 | V17: 12415.08 | W17: 0 | X17: 1486.56 | Y17: 1892.75 | Z17: 8113.16 | AA17: =195.33+727.28
A18: April 14 - April 20 | C18: 16190.69 | D18: 14342.29 | E18: 67.2 | F18: 0 | G18: 1781.2 | H18: 3426.85 | I18: 0 | J18: 334.21 | K18: 10310.6 | L18: 2119.03 | M18: 16190.69 | N18: 0 | O18: 88.03 | P18: 4493.69 | Q18: 0 | R18: 11608.97 | S18: 0 | U18: 0 | V18: 16190.69 | W18: 0 | X18: 2512.99 | Y18: 2138.3 | Z18: 9477.36 | AA18: =625.26+1436.78
A19: Apr 21 - Apr 27 | C19: 12906.22 | D19: 11142.93 | E19: 217.48 | F19: 0 | G19: 1545.81 | H19: 2696.95 | I19: 0 | J19: 245.26 | K19: 8151.67 | L19: 1812.34 | M19: 12906.22 | N19: 0 | O19: 50.5 | P19: 4039.93 | Q19: 0 | R19: 8815.79 | S19: 0 | U19: 0 | V19: =SUM(O19,P19,R19) | W19: 0 | X19: 2039.34 | Y19: 1767.52 | Z19: 7952.37 | AA19: 1146.99
A20: Apr 28 - May 4 | C20: 13772.08 | D20: 12387.89 | E20: 58.8 | F20: 0 | G20: 1325.39 | H20: 3320.75 | I20: 0 | J20: 193.37 | K20: 8617.61 | L20: 1640.35 | M20: 13772.08 | N20: 0 | O20: 79 | P20: 4515.9 | Q20: 0 | R20: 9177.18 | S20: 0 | U20: 0 | V20: 13772.08 | W20: 0 | X20: 2015.54 | Y20: 1614.67 | Z20: 8889.63 | AA20: 1252.24
A21: May 5 - May 11 | C21: 13748.61 | D21: 12562.75 | E21: 143.69 | F21: 0 | G21: 1042.17 | H21: 4251.11 | I21: 0 | J21: 61.35 | K21: 8207.09 | L21: 1229.06 | M21: 13748.61 | N21: 27.98 | O21: 45.45 | P21: 4337 | Q21: 0 | R21: 9338.18 | S21: 0 | U21: 0 | V21: 13748.61 | W21: 0 | X21: 1959.21 | Y21: 2110.99 | Z21: 8337.77 | AA21: 1340.64
A22: May 12 - May 18 | C22: 12290.66 | D22: 10739.46 | E22: 173.79 | F22: 0 | G22: 1377.41 | H22: 2481.46 | I22: 0 | J22: 103.64 | K22: 7955.27 | L22: 1750.29 | M22: 12290.66 | N22: 41.97 | O22: 74.8 | P22: 4474.7 | Q22: 0 | R22: 7699.19 | S22: 0 | U22: 0 | V22: 12290.66 | W22: 0 | X22: 1451.63 | Y22: 1778.95 | Z22: 7446.58 | AA22: 1613.5
A23: May 19 - May 25 | C23: 13981.9 | D23: 12784.11 | E23: 168.4 | F23: 0 | G23: 1029.39 | H23: 2929.15 | I23: 0 | J23: 119.45 | K23: 9620.54 | L23: 1312.76 | M23: 13981.9 | N23: 0 | O23: 33.55 | P23: 3960.45 | Q23: 0 | R23: 9987.9 | S23: 0 | U23: 0 | V23: 13981.9 | W23: 0 | X23: 1701.81 | Y23: 1595.58 | Z23: 9187.6 | AA23: 1496.91
A24: May 26 - Jun 01 | C24: 11574.64 | D24: 10118.56 | E24: 32.4 | F24: 0 | G24: 1423.68 | H24: 2701.74 | I24: 0 | J24: 128.73 | K24: 7237.72 | L24: 1506.45 | M24: 11574.64 | N24: 0 | O24: 72.95 | P24: 3957.53 | Q24: 0 | R24: 7544.16 | S24: 0 | U24: 0 | V24: 11574.64 | W24: 0 | X24: 1687.81 | Y24: 1664.01 | Z24: 6685.98 | AA24: 1536.84
A25: Jun 02 - Jun 08 | C25: 18206.2 | D25: 16664.27 | E25: 287.09 | F25: 0 | G25: 1254.84 | H25: 4400.74 | I25: 0 | J25: 89.22 | K25: 12174.31 | L25: 1541.93 | M25: 18206.2 | N25: 55.96 | O25: 105.05 | P25: 4590.87 | Q25: 0 | R25: 13454.32 | S25: 0 | U25: 0 | V25: 18206.2 | W25: 0 | X25: 3016.41 | Y25: 2613.18 | Z25: 11270.48 | AA25: 1306.13
A26: Jun 09 - Jun 15 | C26: 16528.92 | D26: 15152.84 | E26: 168.77 | F26: 27 | G26: 1180.31 | H26: 3926.92 | I26: 0 | J26: 42.89 | K26: 11156.63 | L26: 1402.48 | M26: 16528.92 | N26: 0 | O26: 103.34 | P26: 4003.24 | Q26: 0 | R26: 12422.34 | S26: 0 | U26: 0 | V26: 16528.92 | W26: 0 | X26: 2132.37 | Y26: 2058.91 | Z26: 10056.62 | AA26: 2281.02
A27: Jun 16 - Jun 22 | C27: 12195.73 | D27: 11186.54 | E27: 126.6 | F27: 0 | G27: 882.59 | H27: 3304.14 | I27: 0 | J27: 312.32 | K27: 7430.62 | L27: 1148.69 | M27: 12195.77 | N27: 0 | O27: 37.7 | P27: 3331.89 | Q27: 0 | R27: 8826.18 | S27: 0 | U27: 0 | V27: 12195.77 | W27: 0 | X27: 1563.01 | Y27: 1426.28 | Z27: 7266.42 | AA27: 1940.02
A28: Jun 23 - Jun 29 | C28: 12515.82 | D28: 11168.75 | E28: 166.8 | F28: 0 | G28: 1180.27 | H28: 2597.63 | I28: 0 | J28: 367.32 | K28: 8203.8 | L28: 1347.07 | M28: 12515.82 | N28: 0 | O28: 47.45 | P28: 3107.1 | Q28: 0 | R28: 9361.27 | S28: 0 | U28: 0 | V28: 12515.82 | W28: 0 | X28: 1398.39 | Y28: 1285.6 | Z28: 8054.27 | AA28: 1777.56
A29: Jun 30 - Jul 06 | C29: 13715.1 | D29: 12214.28 | E29: 159.9 | F29: 0 | G29: 1340.92 | H29: 3459.07 | I29: 0 | J29: 19.99 | K29: 8712.42 | L29: 1523.62 | M29: 13715.1 | N29: 0 | O29: 115.03 | P29: 3851.94 | Q29: 38 | R29: 9697.88 | S29: 12.25 | U29: 0 | V29: 13715.1 | W29: 0 | X29: 1606.08 | Y29: 1299.05 | Z29: 8671.71 | AA29: 2138.26
A30: Jul 07 - Jul 13 | C30: 10417.25 | D30: 8805.33 | E30: 191.32 | F30: 330.67 | G30: 1089.93 | H30: 1805.3 | I30: 0 | J30: 41.89 | K30: 6872.35 | L30: 1697.71 | M30: 10417.25 | N30: 0 | O30: 91.23 | P30: 3355.68 | Q30: 0 | R30: 6970.34 | S30: 0 | U30: 0 | V30: 10417.25 | W30: 0 | X30: 1286.69 | Y30: 950.58 | Z30: 6943.97 | AA30: 1236.01
A31: Jul 14 - Jul 20 | C31: 13688.31 | D31: 11860.5 | E31: 26.7 | F31: 341.74 | G31: 1459.37 | H31: 3418.86 | I31: 0 | J31: 26.48 | K31: 8415.16 | L31: 1827.81 | M31: 13688.31 | N31: 0 | O31: 169.24 | P31: 4664.19 | Q31: 0 | R31: 8836.89 | S31: 0 | U31: 17.99 | V31: 13688.31 | W31: 0 | X31: 1271.15 | Y31: 2862.91 | Z31: 8174.94 | AA31: 1379.31
... A44: Oct 13 - Oct 19 | C44: 10020.64 | D44: 8901.79 | E44: 26.4 | F44: 218.37 | G44: 874.08 | H44: 2887.67 | I44: 0 | J44: 22 | K44: 5895.79 | L44: 1215.14 | M44: 10020.6 | N44: 0 | O44: 65.8 | P44: 3467.28 | Q44: 0 | R44: 6487.52 | S44: 0 | U44: 0 | V44: 10020.6 | W44: 0 | X44: 1584.54 | Y44: 1189.87 | Z44: 6545.74 | AA44: 700.49
A45: Oct 20 - Oct 26 | B45: 196 | C45: 9135.37 | D45: 8370.62 | E45: 18 | F45: 128.7 | G45: 618.05 | H45: 618.05 | I45: 0 | J45: 97.17 | K45: 5721.76 | L45: 845.15 | M45: 9135.38 | N45: 0 | O45: 83.5 | P45: 3322.13 | Q45: 0 | R45: 5729.75 | S45: 0 | U45: 0 | V45: 9135.38 | W45: 0 | X45: 1143.14 | Y45: 1495.46 | Z45: 5394.95 | AA45: 1101.82
A46: Oct 27 - Nov 02 | B46: 232 | C46: 11249.53 | D46: 10368.78 | E46: 0 | F46: 356.86 | G46: 523.89 | H46: 3605.42 | I46: 0 | J46: 142.35 | K46: 6051.88 | L46: 1449.87 | M46: 11249.52 | N46: 0 | O46: 65.85 | P46: 4676.31 | Q46: 0 | R46: 6507.36 | S46: 0 | U46: 0 | V46: 11249.52 | W46: 0 | X46: 1726.97 | Y46: 2431.93 | Z46: 5864.14 | AA46: 1226.49
A47: Nov 03 - Nov 09 | B47: 213 | C47: 9503.78 | D47: 8134.81 | E47: 0 | F47: 473.43 | G47: 895.54 | H47: 3344.3 | I47: 0 | J47: 0 | K47: 4638.81 | L47: 1520.66 | M47: 9503.77 | N47: 13.99 | O47: 82.1 | P47: 3780.4 | Q47: 0 | R47: 5627.28 | S47: 0 | U47: 0 | V47: 9503.77 | W47: 0 | X47: 1636.25 | Y47: 1912 | Z47: 5261.71 | AA47: 693.82
A48: Nov 10 - Nov 16 | B48: 231 | C48: 11177.8 | D48: 9729.76 | E48: 18 | F48: 298.58 | G48: 1131.46 | H48: 2535.16 | I48: 0 | J48: 0 | K48: 7012.29 | L48: 1630.34 | M48: 11177.79 | N48: 13.99 | O48: 69.45 | P48: 3867.16 | Q48: 0 | R48: 7227.19 | S48: 0 | U48: 0 | V48: 11177.79 | W48: 0 | X48: 988.52 | Y48: 2101.73 | Z48: 7184.26 | AA48: 903.29
A49: Nov 17 - Nov 23 | B49: 247 | C49: 10660.61 | D49: 8845.04 | E49: 0 | F49: 386.88 | G49: 1428.69 | H49: 3763.53 | I49: 0 | J49: 35.98 | K49: 5029.54 | L49: 1831.57 | M49: 10660.62 | N49: 0 | O49: 78.43 | P49: 4567.44 | Q49: 14 | R49: 6000.75 | S49: 0 | U49: 0 | V49: 10660.62 | W49: 0 | X49: 1954.13 | Y49: 1835.6 | Z49: 5570.8 | AA49: 1300.08
A50: Nov 24 - Nov 30 | B50: 213 | C50: 9596.81 | D50: 7700.59 | E50: 32.86 | F50: 378.37 | G50: 1484.99 | H50: 2294.12 | I50: 0 | J50: 93.31 | K50: 5295.14 | L50: 1914.22 | M50: 9596.79 | N50: 0 | O50: 68.85 | P50: 3586.31 | Q50: 0 | R50: 5941.63 | S50: 0 | U50: 0 | V50: 9596.79 | W50: 0 | X50: 1632.15 | Y50: 1723.22 | Z50: 5313.96 | AA50: 927.48
A51: Dec 01 - Dec 07 | B51: 231 | C51: 10964.28 | D51: 9373.59 | E51: 0 | F51: 373.48 | G51: 1217.21 | H51: 2788.97 | I51: 0 | J51: 0 | K51: 6584.61 | L51: 1590.69 | M51: 10964.27 | N51: 0 | O51: 62.05 | P51: 4331.05 | Q51: 0 | R51: 6571.17 | S51: 0 | U51: 0 | V51: 10964.27 | W51: 0 | X51: 1474.6 | Y51: 2233.88 | Z51: 6000.94 | AA51: 1254.86
A52: Dec 08 - Dec 14 | B52: 232 | C52: 10104.58 | D52: 8819.74 | E52: 0 | F52: 325.78 | G52: 959.06 | H52: 3485.19 | I52: 0 | J52: 39.99 | K52: 5094.53 | L52: 1484.87 | M52: 10104.58 | N52: 13.99 | O52: 71.75 | P52: 3900.86 | Q52: 0 | R52: 6117.98 | S52: 0 | U52: 0 | V52: 10104.58 | W52: 0 | X52: 1630.43 | Y52: 1948.64 | Z52: 5362.39 | AA52: 1163.12
...

Sheet Kababwala
B1: Sales by Sections | H1: Sales by Order Type | N1: Sales by Category | U1: Daily and Hourly Sales (TBD)
B2: Total Bill Count | C2: Net Sales | D2: Remaining | E2: Skip | F2: DD | G2: Uber | H2: Take Out | I2: Delivery | J2: Bar Tab | K2: Dine-In | L2: Online Order | M2: Net Sales | N2: Drinks | O2: Food (Pizza K) | P2: Food Court | Q2: Smash Ox Burger | R2: Food Highway | S2: Kabab Wala | T2: Net Sales | U2: 8AM - 11AM | V2: 11AM - 3PM | W2: 3PM - 6PM | X2: 6PM - 11PM | Y2: 11PM-7AM
A3: Dec 30 - Jan 05 2025
A4: Jan 06 - Jan 12 2025
A5: Jan 13 - Jan 19 2025
A6: Jan 20 - Jan 26 2025
A7: Jan 27 - Feb 02 2025
A8: Feb 03 - Feb 09 2025 | C8: 14273.41 | D8: 10274.77 | E8: 195.67 | F8: 599.59 | G8: 3203.38 | H8: 8519.58 | I8: 0 | J8: 0 | K8: 1755.19 | L8: 3998.64 | M8: 14273.41 | N8: 0 | O8: 0 | P8: 2219.14 | Q8: 0 | S8: 12054.27 | T8: 14273.41
A9: Feb 10 - Feb 16 2025 | C9: 13043.35 | D9: 10539.78 | E9: 234.24 | F9: 187.04 | G9: 2082.29 | H9: 9115.1 | I9: 0 | J9: 0 | K9: 1384.54 | L9: 2543.71 | M9: 13043.35 | N9: 0 | O9: 2.4 | P9: 2087.58 | Q9: 0 | S9: 10953.37 | T9: 13043.35 | U9: 0 | V9: 1672.51 | W9: 2887.81 | X9: 7453.09 | Y9: 1029.94
A10: Feb 17 - Feb 23 2025 | C10: 18319.37 | D10: 15612.65 | E10: 126.49 | F10: 204.9 | G10: 2375.33 | H10: 12926.14 | I10: 0 | J10: 0 | K10: 2686.51 | L10: 2706.72 | M10: 18319.37 | N10: 0 | O10: 0 | P10: 3777.53 | Q10: 0 | S10: 14541.84 | T10: 18319.37 | U10: 0 | V10: 3200.98 | W10: 3873.53 | X10: 10380.7 | Y10: 864.16
A11: Feb 24 - Mar 02 2025 | C11: 11915.13 | D11: 9357.28 | E11: 156.53 | F11: 255.33 | G11: 2145.99 | H11: 8138.07 | I11: 0 | J11: 0 | K11: 1219.21 | L11: 2557.85 | M11: 11915.13 | N11: 0 | O11: 2.4 | P11: 2156.83 | Q11: 0 | S11: 9755.9 | T11: 11915.13 | U11: 0 | V11: 1553.43 | W11: 3528.14 | X11: 5852.23 | Y11: 981.33
A12: Mar 03 - Mar 09 2025 | C12: 13558.97 | D12: 11083.03 | E12: 92.94 | F12: 242.7 | G12: 2140.3 | H12: 9837.08 | I12: 0 | J12: 0 | K12: 1245.95 | L12: 2475.94 | M12: 13558.97 | N12: 0 | O12: 0 | P12: 2536.48 | Q12: 0 | S12: 11022.49 | T12: 13558.97 | U12: 0 | V12: 1362.2 | W12: 5872.5 | X12: 4382.68 | Y12: 1941.59
A13: Mar 10 - Mar 16 2025 | C13: 14906.28 | D13: 12203.82 | E13: 403.24 | F13: 572.37 | G13: 1726.85 | H13: 10758.4 | I13: 0 | J13: 0 | K13: 1445.42 | L13: 2702.46 | M13: 14906.28 | N13: 0 | O13: 2.4 | P13: 2134.1 | Q13: 0 | S13: 12769.78 | T13: 14906.28 | U13: 0 | V13: 725.83 | W13: 5560.16 | X13: 6547.33 | Y13: 2072.96
A14: Mar 17 - Mar 23 2025 | C14: 15353.13 | D14: 11772.36 | E14: 307.37 | F14: 229.5 | G14: 3043.9 | H14: 9329.15 | I14: 0 | J14: 0 | K14: 2443.25 | L14: 3580.77 | M14: 15353.17 | N14: 0 | O14: 7.2 | P14: 2087.73 | Q14: 0 | S14: 13258.24 | T14: 15353.17 | U14: 0 | V14: 968.87 | W14: 4960.77 | X14: 7230.18 | Y14: 2193.31
A15: Mar 24 - Mar 30 2025 | C15: =G15+F15+E15+D15 | D15: 17239.64 | E15: 75.97 | F15: 329.42 | G15: 3407.34 | H15: 15556.96 | I15: 0 | J15: 0 | K15: 1682.72 | L15: 3812.73 | M15: 21052.41 | N15: 0 | O15: 9 | P15: 2728.15 | Q15: 0 | S15: 18315.26 | T15: 21052.41 | U15: 34 | V15: 3781.8 | W15: 5640.75 | X15: 9502.39 | Y15: 2093.4
A16: March 31 - April 6 | C16: 18572.98 | D16: 15982.93 | E16: 99.57 | F16: 325.63 | G16: 2164.85 | H16: 13233 | I16: 0 | J16: 0 | K16: 2749.93 | L16: 2590.05 | M16: 18572.98 | N16: 0 | O16: 7.2 | P16: 2555.78 | Q16: 0 | S16: 16010 | T16: 18572.98 | U16: 3748.2 | V16: 13359.65 | W16: =439.92+1025.21
A17: April 7 - April 13 | C17: 15322.98 | D17: 12364.38 | E17: 49.86 | F17: 327.77 | G17: 2583.97 | H17: 9275.02 | I17: 0 | J17: 0 | K17: 3089.36 | L17: 2958.6 | M17: 15322.98 | N17: 0 | O17: 7.2 | P17: 1980.89 | Q17: 0 | S17: 13334.89 | T17: 15322.98 | U17: 112.5 | V17: 2110.87 | W17: 2420.79 | X17: 9451.96 | Y17: =536.93+689.93
A18: April 14 - April 20 | C18: 18823.82 | D18: 16212.3 | E18: 0 | F18: 49.86 | G18: 2561.66 | H18: 11294.92 | I18: 0 | J18: 0 | K18: 4917.42 | L18: 2611.52 | M18: 18823.86 | N18: 0 | O18: 14.4 | P18: 2237.26 | Q18: 0 | S18: 16572.2 | T18: 18823.86 | U18: 0 | V18: 3318.56 | W18: 4385.44 | X18: 9514.13 | Y18: =432.92+1172.77
A19: Apr 21 - Apr 27 | C19: 15758.11 | D19: 13051.45 | E19: 16.8 | F19: 223.46 | G19: 2466.4 | H19: 9833.62 | I19: 0 | J19: 0 | K19: 3217.85 | L19: 2706.66 | M19: 15758.13 | N19: 0 | O19: 10.8 | P19: 2042.7 | Q19: 0 | S19: 13704.63 | T19: 15758.13 | U19: 53.13 | V19: 2496.1 | W19: 3597.8 | X19: 8432.37 | Y19: 1178.61
A20: Apr 28 - May 4 | C20: 17377.64 | D20: 15402.32 | E20: 63.37 | F20: 188.26 | G20: 1723.69 | H20: 11631.52 | I20: 0 | J20: 0 | K20: 3770.8 | L20: 1975.32 | M20: 17377.64 | N20: 0 | O20: 1.2 | P20: 2560.14 | Q20: 83.41 | S20: 14732.89 | T20: 17377.64 | U20: 195.45 | V20: 2383.19 | W20: 4278.88 | X20: 8562.21 | Y20: 1957.91
A21: May 5 - May 11 | C21: 16181.36 | D21: 14028.63 | E21: 91.55 | F21: 91.14 | G21: 1970.04 | H21: 10275.73 | I21: 0 | J21: 42.99 | K21: 3709.91 | L21: 2152.73 | M21: 16181.36 | N21: 0 | O21: 28.2 | P21: 2362.12 | Q21: 130.36 | S21: 13660.68 | T21: 16181.36 | U21: 53.47 | V21: 3131.7 | W21: 3001.98 | X21: 8827.77 | Y21: 1166.44
A22: May 12 - May 18 | C22: 17390.45 | D22: 15192.66 | E22: 30.08 | F22: 136.91 | G22: 2030.8 | H22: 11096.7 | I22: 0 | J22: 0 | K22: 4095.98 | L22: 2197.79 | M22: 17390.47 | N22: 0 | O22: 35.4 | P22: 2317.87 | Q22: 228.17 | S22: 14809.03 | T22: 17390.47 | U22: 0 | V22: 3280.15 | W22: 3621.44 | X22: 9241.05 | Y22: 1247.81
A23: May 19 - May 25 | C23: 16865.13 | D23: 14131.51 | E23: 98.46 | F23: 148.87 | G23: 2486.29 | H23: 10457.17 | I23: 0 | J23: 0 | K23: 3674.4 | L23: 2733.62 | M23: 16865.19 | N23: 0 | O23: 2.4 | P23: 2247.08 | Q23: 277.22 | S23: 14338.49 | T23: 16865.19 | U23: 21 | V23: 2589.59 | W23: 4126.88 | X23: 8563.44 | Y23: 1564.22
A24: May 26 - Jun 01 | C24: 19146.4 | D24: 16228.53 | E24: 21.8 | F24: 251.15 | G24: 2644.92 | H24: 12914.29 | I24: 0 | J24: 15.47 | K24: 3298.82 | L24: 2917.87 | M24: 19146.45 | N24: 0 | O24: 34.8 | P24: 1820.53 | Q24: 343.66 | S24: 16947.46 | T24: 19146.45 | U24: 0 | V24: 2844 | W24: 4066.64 | X24: 9888.83 | Y24: 2346.93
A25: Jun 02 - Jun 08 | C25: 21760.9 | D25: 18673.66 | E25: 58.35 | F25: 67.93 | G25: 2960.96 | H25: 14550.68 | I25: 0 | J25: 0 | K25: 4122.98 | L25: 3087.24 | M25: 21760.9 | N25: 0 | O25: 9.6 | P25: 2486.78 | Q25: 397.61 | S25: 18866.91 | T25: 21760.9 | U25: 158.71 | V25: 5119.2 | W25: 4155.94 | X25: 10587.95 | Y25: 1739.1
A26: Jun 09 - Jun 15 | C26: 17684.01 | D26: 14687.63 | E26: 19.62 | F26: 358.51 | G26: 2618.25 | H26: 11547.42 | I26: 0 | J26: 0 | K26: 3140.21 | L26: 2996.38 | M26: 17684.01 | N26: 0 | O26: 15.6 | P26: 2101.12 | Q26: 282.21 | S26: 15285.08 | T26: 17684.01 | U26: 36.98 | V26: 3571.38 | W26: 2990.02 | X26: 9302.44 | Y26: 1783.19
A27: Jun 16 - Jun 22 | C27: 17394.72 | D27: 14622.01 | E27: 18.66 | F27: 268.59 | G27: 2485.46 | H27: 11607.65 | I27: 0 | J27: 0 | K27: 3014.36 | L27: 2772.71 | M27: 17394.72 | N27: 0 | O27: 14.4 | P27: 1629.05 | Q27: 205.62 | S27: 15545.65 | T27: 17394.72 | U27: 97.9 | V27: 3017.98 | W27: 3261.12 | X27: 9595.88 | Y27: 1421.84
A28: Jun 23 - Jun 29 | C28: 17356.78 | D28: 14263.59 | E28: 190.74 | F28: 109.76 | G28: 2792.69 | H28: 11140.9 | I28: 0 | J28: 0 | K28: 3122.69 | L28: 3093.19 | M28: 17356.78 | N28: 0 | O28: 12 | P28: 1554.24 | Q28: 180.84 | S28: 15609.7 | T28: 17356.78 | U28: 27 | V28: 2842.64 | W28: 2110.54 | X28: 10660.47 | Y28: 1716.13
A29: Jun 30 - Jul 06 | C29: 18326.25 | D29: 15286 | E29: 251.99 | F29: 238.03 | G29: 2550.23 | H29: 11770.93 | I29: 0 | J29: 0 | K29: 3515.07 | L29: 3040.25 | M29: 18326.25 | N29: 0 | O29: 28.2 | P29: 2098.82 | Q29: 192.32 | S29: 16006.91 | T29: 18326.25 | U29: 49.91 | V29: 3592.65 | W29: 3380.72 | X29: 9850.24 | Y29: 1452.73
A30: Jul 07 - Jul 13 | C30: 17307.89 | D30: 15576.3 | E30: 74.21 | F30: 159.33 | G30: 1498.05 | H30: 11418.4 | I30: 0 | J30: 0 | K30: 4157.9 | L30: 1731.59 | M30: 17307.89 | N30: 0 | O30: 27.6 | P30: 3082.06 | Q30: 246.79 | S30: 13951.44 | T30: 17307.89 | U30: 50.91 | V30: 2520.23 | W30: 3687.71 | X30: 9262.34 | Y30: 1786.7
... A32: Jul 21 - Jul 27 | C32: 19250.84 | D32: 16442.69 | E32: 52.11 | F32: 504.12 | G32: 2251.92 | H32: 11413.76 | I32: 0 | J32: 0 | K32: 5028.92 | L32: 2808.15 | M32: 19250.83 | N32: 0 | O32: 11.4 | P32: 2591.74 | Q32: 308.23 | S32: 16339.46 | T32: 19250.83 | U32: 17.99 | V32: 2436.06 | W32: 4033.15 | X32: 11091.84 | Y32: 1671.8
A33: Jul 28 - Aug 03 | C33: 17443.35 | D33: 15595.52 | E33: 96.27 | F33: 18.59 | G33: 1732.97 | H33: 11432.81 | I33: 0 | J33: 0 | K33: 4162.68 | L33: 1847.83 | M33: 17443.32 | N33: 0 | O33: 30 | P33: 2330.72 | Q33: 208.32 | R33: 0 | S33: 14874.28 | T33: 17443.32 | U33: 51.86 | V33: 2850.02 | W33: 2864.14 | X33: 10142.12 | Y33: 1535.21
A34: Aug 04 - Aug 10 | C34: 19115.15 | D34: 17187.14 | E34: 48.28 | F34: 149.36 | G34: 1730.37 | H34: 12915.17 | I34: 0 | J34: 0 | K34: 4271.97 | L34: 1928.01 | M34: 19115.15 | N34: 0 | O34: 6.6 | P34: 2615.25 | Q34: 375.17 | R34: 0 | S34: 16118.13 | T34: 19115.15 | U34: 13.99 | V34: 3401.75 | W34: 4234.65 | X34: 10097.33 | Y34: 1367.43
A35: Aug 11 - Aug 17 | C35: 17474.33 | D35: 16262.77 | E35: 73.77 | F35: 301.37 | G35: 836.42 | H35: 11453.34 | I35: 0 | J35: 0 | K35: 4809.4 | L35: 1211.56 | M35: 17474.3 | N35: 0 | O35: 10.2 | P35: 2298.51 | Q35: 402.62 | R35: 0 | S35: 14762.97 | T35: 17474.3 | U35: 123.9 | V35: 2057.17 | W35: 2773.66 | X35: 10130.05 | Y35: 2389.55
A36: Aug 18 - Aug 24 | C36: 16199.2 | D36: 14382.84 | E36: 16.79 | F36: 176.02 | G36: 1623.55 | H36: 10565.84 | I36: 0 | J36: 0 | K36: 3817 | L36: 1816.36 | M36: 16199.2 | N36: 0 | O36: 6 | P36: 2617.14 | Q36: 276.74 | R36: 0 | S36: 13299.32 | T36: 16199.2 | U36: 34.22 | V36: 2206.94 | W36: 3461.63 | X36: 8974.44 | Y36: 1521.97
A37: Aug 25 - Aug 31 | C37: 19083.93 | D37: 17664.64 | E37: 40.2 | F37: 284.79 | G37: 1094.3 | H37: 13314.26 | I37: 0 | J37: 0 | K37: 4350.38 | L37: 1419.29 | M37: 19083.93 | N37: 0 | O37: 2.4 | P37: 2969.24 | Q37: 308.04 | R37: 0 | S37: 15804.25 | T37: 19083.93 | U37: 56.96 | V37: 2128.24 | W37: 3652.91 | X37: 11735.85 | Y37: 1509.97
A38: Sep 01 - Sep 07 | C38: 15524.34 | D38: 13926.86 | E38: 0 | F38: 101.18 | G38: 1496.3 | H38: 9862.39 | I38: 0 | J38: 0 | K38: 4064.47 | L38: 1597.48 | M38: 15524.34 | N38: 0 | O38: 22.8 | P38: 1865.23 | Q38: 389.26 | R38: 0 | S38: 13247.05 | T38: 15524.34 | U38: 38.97 | V38: 3040.11 | W38: 2766.05 | X38: 8582.04 | Y38: 1097.17
A39: Sep 08 - Sep 14 | C39: 15558.56 | D39: 14364.77 | E39: 89.96 | F39: 90.51 | G39: 1013.32 | H39: 10301.67 | I39: 0 | J39: 0 | K39: 4063.1 | L39: 1193.79 | M39: 15558.56 | N39: 0 | O39: 13.6 | P39: 2151.14 | Q39: 347.3 | R39: 0 | S39: 13046.52 | T39: 15558.56 | U39: 0 | V39: 2653.8 | W39: 2606.64 | X39: 9220.46 | Y39: 1077.66
A40: Sep 15 - Sep 21 | C40: 16173.27 | D40: 15074.13 | E40: 300.69 | F40: 50.8 | G40: 747.65 | H40: 10523.38 | I40: 0 | J40: 0 | K40: 4550.73 | L40: 1099.14 | M40: 16173.25 | N40: 0 | O40: 12.8 | P40: 2451.33 | Q40: 320.01 | R40: 0 | S40: 13389.11 | T40: 16173.25 | U40: 39.46 | V40: 2557.24 | W40: 3380.71 | X40: 9193.64 | Y40: 1002.22
A41: Sep 22 - Sep 28 | C41: 14572.18 | D41: 12695.29 | E41: 206.01 | F41: 384.94 | G41: 1285.94 | H41: 8699.21 | I41: 0 | J41: 0 | K41: 3926.58 | L41: 1876.89 | M41: 14502.68 | N41: 0 | O41: 13.99 | P41: 2200.04 | Q41: 290.17 | R41: 0 | S41: 11998.48 | T41: 14502.68 | U41: 0 | V41: 2291.72 | W41: 3906.61 | X41: 7673.56 | Y41: 700.29
...

Sheet Pizza K Heartland
B1: Sales by Sections | H1: Sales by Order Type | N1: Sales by Category (Net Sales) | V1: Daily and Hourly Sales (TBD)
B2: Total Bill Count | C2: Net Sales | D2: Remaining | E2: Skip | F2: DD | G2: Uber | H2: Take Out | I2: Delivery | J2: Bar Tab | K2: Dine-In | L2: Online Order | M2: Net Sales | N2: Chickentarian | O2: KT Icecream | P2: Food (Pizza K) | Q2: Food Court | R2: Drinks | S2: Smash Ox Burger | T2: Uncategorized | U2: Net Sales | V2: 8AM - 11AM | W2: 11AM - 3PM | X2: 3PM - 6PM | Y2: 6PM - 11PM | Z2: 11PM-7AM
A3: Dec 30 - Jan 05 2025
A4: Jan 06 - Jan 12 2025
A5: Jan 13 - Jan 19 2025
A6: Jan 20 - Jan 26 2025
A7: Jan 27 - Feb 02 2025
A8: Feb 03 - Feb 09 2025 | C8: 15602.64 | D8: 15602.64 | E8: 0 | F8: 0 | G8: 0 | H8: 14639.32 | I8: 0 | J8: 0 | K8: 963.32 | L8: 0 | M8: 15602.64 | N8: 0 | O8: 0 | P8: 15197.89 | Q8: 92 | R8: 312.75 | T8: 0 | U8: 15602.64
A9: Feb 10 - Feb 16 2025 | C9: 15478.89 | D9: 15478.89 | E9: 0 | F9: 0 | G9: 0 | H9: 13853.08 | I9: 0 | J9: 0 | K9: 1625.86 | L9: 0 | M9: 15478.94 | N9: 0 | O9: 0 | P9: 15101.67 | Q9: 20 | R9: 357.27 | T9: 0 | U9: 15478.94 | V9: 0 | W9: 1957.29 | X9: 3065.81 | Y9: 8883.44 | Z9: 1572.35
A10: Feb 17 - Feb 23 2025 | C10: 14771.2 | D10: 14771.2 | E10: 0 | F10: 0 | G10: 0 | H10: 13402.78 | I10: 0 | J10: 0 | K10: 1368.5 | L10: 0 | M10: 14771.28 | N10: 0 | O10: 0 | P10: 14507.47 | Q10: 20 | R10: 243.81 | T10: 0 | U10: 14771.28 | V10: 0 | W10: 2077.79 | X10: 3263.9 | Y10: 8377.84 | Z10: 1051.67
A11: Feb 24 - Mar 02 2025 | C11: 15585.11 | D11: 8797.31 | E11: 0 | F11: 592.94 | G11: 6194.86 | H11: 7952.68 | I11: 0 | J11: 0 | K11: 844.65 | L11: 6787.8 | M11: 15585.13 | N11: 0 | O11: 0 | P11: 15255.36 | Q11: 16 | R11: 313.77 | T11: 0 | U11: 15585.13 | V11: 0 | W11: 2155.73 | X11: 4491.48 | Y11: 7779.59 | Z11: 1158.31
A12: Mar 03 - Mar 09 2025 | C12: 14788.75 | D12: 8498.44 | E12: 18 | F12: 618.26 | G12: 5654.05 | H12: 7034.55 | I12: 0 | J12: 0 | K12: 1463.92 | L12: 6290.31 | M12: 14788.78 | N12: 0 | O12: 598.03 | P12: 13894.14 | Q12: 12 | R12: 284.61 | T12: 0 | U12: 14788.78 | V12: 0 | W12: 861.91 | X12: 6751.97 | Y12: 5302.35 | Z12: 1872.52
A13: Mar 10 - Mar 16 2025 | C13: 18698.97 | D13: 11737.05 | E13: 18 | F13: 836.45 | G13: 6107.47 | H13: 8795.32 | I13: 0 | J13: 0 | K13: 2941.73 | L13: 6961.92 | M13: 18698.97 | N13: 0 | O13: 826.13 | P13: 17495.24 | Q13: 76.5 | R13: 301.1 | T13: 0 | U13: 18698.97 | V13: 0 | W13: 1435.78 | X13: 3762.6 | Y13: 10941.81 | Z13: 2558.78
A14: Mar 17 - Mar 23 2025 | C14: 17650.04 | D14: 10632.6 | E14: 0 | F14: 752.41 | G14: 6265.03 | H14: 8981.17 | I14: 0 | J14: 0 | K14: 1651.43 | L14: 7017.44 | M14: 17650.04 | N14: 0 | O14: 566.37 | P14: 16632.37 | Q14: 62.5 | R14: 388.8 | T14: 0 | U14: 17650.04 | V14: 0 | W14: 1542.19 | X14: 4134.29 | Y14: 10004.14 | Z14: 1969.42
A15: Mar 24 - Mar 30 2025 | C15: 23667.17 | D15: 13752.97 | E15: 33.6 | F15: 766.22 | G15: 9114.38 | H15: 11512.29 | I15: 0 | J15: 0 | K15: 2240.68 | L15: 9914.2 | M15: 23667.17 | N15: 0 | O15: 703.46 | P15: 22324.47 | Q15: 157.5 | R15: 481.74 | T15: 0 | U15: 23667.17 | V15: 0 | W15: 2069.54 | X15: 4436.84 | Y15: 13812.24 | Z15: 3348.55
A16: March 31 - April 6 | C16: 18566.53 | D16: =2538.67+9075.32 | E16: 16.8 | F16: 618.55 | G16: 6317.19 | H16: 9051.07 | I16: 0 | J16: 24.25 | K16: 2538.67 | L16: 6952.54 | M16: 18566.53 | N16: 0 | O16: 1028.1 | P16: 16976.3 | Q16: 90.5 | R16: 471.63 | T16: 0 | U16: 18566.53 | V16: 3434.27 | W16: 13042.69 | X16: =827.06+1262.51
A17: April 7 - April 13 | C17: 18741.13 | D17: =2072.02+9258.01 | E17: 0 | F17: 795.99 | G17: 6615.11 | H17: 9258.01 | I17: 0 | J17: 0 | K17: 2072.02 | L17: 7411.1 | M17: 18741.13 | N17: 0 | O17: 980.55 | P17: 17228.04 | Q17: 88.99 | R17: 443.55 | T17: 0 | U17: 18741.13 | V17: 0 | W17: 2762.95 | X17: 4027.9 | Y17: 10473.7 | Z17: =598.63+877.95
A18: April 14 - April 20 | C18: 22357.34 | D18: 15405.08 | E18: 0 | F18: 766.89 | G18: 6185.37 | H18: 12186.02 | I18: 0 | J18: 489.2 | K18: 2729.86 | L18: 6952.26 | M18: 22357.34 | N18: 154.4 | O18: 1160.48 | P18: 20441.97 | Q18: 70.49 | R18: 530 | T18: 0 | U18: 22357.34 | V18: 0 | W18: 3427.54 | X18: 3889.66 | Y18: 12602.2 | Z18: =702.04+1735.9
A19: Apr 21 - Apr 27 | C19: 20006.97 | D19: 13208.43 | E19: 0 | F19: 760.95 | G19: 6037.59 | H19: 11009.32 | I19: 0 | J19: 482.6 | K19: 1716.51 | L19: 6798.54 | M19: 20006.97 | N19: 148.2 | O19: 995.09 | P19: 18383.04 | Q19: 73.47 | R19: 407.17 | T19: 0 | U19: =R19+Q19+P19+O19+N19 | V19: 285.44 | W19: 3815.02 | X19: 3265.44 | Y19: 11015.07 | Z19: 1626
A20: Apr 28 - May 4 | C20: 18912.04 | D20: 12668.7 | E20: 0 | F20: 761.11 | G20: 5482.23 | H20: 10413.89 | I20: 0 | J20: 513.25 | K20: 1741.56 | L20: 6243.34 | M20: 18912.04 | N20: 118.93 | O20: 693.08 | P20: 17547.31 | Q20: 43.99 | R20: 508.73 | T20: 0 | U20: 18912.04 | V20: 61.49 | W20: 2575.21 | X20: 3402.81 | Y20: 11020.22 | Z20: 1852.31
A21: May 5 - May 11 | C21: 19737.83 | D21: 12744.63 | E21: 0 | F21: 654.27 | G21: 6338.93 | H21: 11191.11 | I21: 0 | J21: 331.92 | K21: 1221.6 | L21: 6993.2 | M21: 19737.83 | N21: 66.95 | O21: 700.08 | P21: 18431.63 | Q21: 52.5 | R21: 486.67 | T21: 0 | U21: 19737.83 | V21: 271.79 | W21: 2615.85 | X21: 3500.08 | Y21: 11478.17 | Z21: 1871.94
A22: May 12 - May 18 | C22: 20649.48 | D22: 14025.42 | E22: 0 | F22: 592.17 | G22: 6031.89 | H22: 12371.58 | I22: 0 | J22: 379.43 | K22: 1274.41 | L22: 6624.06 | M22: 20649.48 | N22: 102.42 | O22: 828.63 | P22: 19209.06 | Q22: 27.5 | R22: 481.87 | T22: 0 | U22: 20649.48 | V22: 425.22 | W22: 2891.94 | X22: 3324.53 | Y22: 11964.67 | Z22: 2043.12
A23: May 19 - May 25 | C23: 21289.71 | D23: 14091.25 | E23: 0 | F23: 788.06 | G23: 6410.4 | H23: 11722.2 | I23: 0 | J23: 586.27 | K23: 1782.8 | L23: 7198.46 | M23: 21289.73 | N23: 55.46 | O23: 670.84 | P23: 19987.28 | Q23: 71.5 | R23: 504.65 | T23: 0 | U23: 21289.73 | V23: 312.03 | W23: 3238.18 | X23: 4200.58 | Y23: 11924.99 | Z23: 1613.93
A24: May 26 - Jun 01 | C24: 17476.95 | D24: 12195.79 | E24: 0 | F24: 191.68 | G24: 5089.48 | H24: 10091.96 | I24: 0 | J24: 271.51 | K24: 1832.32 | L24: 5281.16 | M24: 17476.95 | N24: 212.36 | O24: 904.99 | P24: 15832.65 | Q24: 65 | R24: 461.95 | T24: 0 | U24: 17476.95 | V24: 17.09 | W24: 2349.85 | X24: 3191.36 | Y24: 10096.86 | Z24: 1821.79
A25: Jun 02 - Jun 08 | C25: 20551.17 | D25: 14724.33 | E25: 0 | F25: 0 | G25: 5826.84 | H25: 11772.66 | I25: 0 | J25: 314.74 | K25: 2636.9 | L25: 5826.84 | M25: 20551.14 | N25: 223.83 | O25: 1264.98 | P25: 18505.9 | Q25: 90.96 | R25: 465.47 | T25: 0 | U25: 20551.14 | V25: 134.8 | W25: 2948.79 | X25: 3032.97 | Y25: 11920.37 | Z25: 2514.24
A26: Jun 09 - Jun 15 | C26: 19206.44 | D26: 13152.36 | E26: 0 | F26: 0 | G26: 6054.08 | H26: 10775.95 | I26: 0 | J26: 95.17 | K26: 2281.24 | L26: 6054.08 | M26: 19206.44 | N26: 132.41 | O26: 980.07 | P26: 17451.44 | Q26: 100.5 | R26: 542.02 | T26: 0 | U26: 19206.44 | V26: 226 | W26: 2713.95 | X26: 3725.52 | Y26: 10581.56 | Z26: 1959.41
A27: Jun 16 - Jun 22 | C27: 19963.09 | D27: 13642.9 | E27: 0 | F27: 0 | G27: 6320.19 | H27: 11052.54 | I27: 0 | J27: 267.19 | K27: 2323.19 | L27: 6320.19 | M27: 19963.11 | N27: 167.38 | O27: 1274.96 | P27: 17858.8 | Q27: 33.24 | R27: 628.73 | T27: 0 | U27: 19963.11 | V27: 461.09 | W27: 2829.03 | X27: 3802.48 | Y27: 10907 | Z27: 1963.49
A28: Jun 23 - Jun 29 | C28: 20181.46 | D28: 13603.1 | E28: 0 | F28: 0 | G28: 6578.36 | H28: 11553.37 | I28: 0 | J28: 245.99 | K28: 1803.78 | L28: 6578.36 | M28: 20181.5 | N28: 275.09 | O28: 896.08 | P28: 18369 | Q28: 57.7 | R28: 583.63 | T28: 0 | U28: 20181.5 | V28: 138.58 | W28: 3212.86 | X28: 3131.36 | Y28: 11521.81 | Z28: 2176.85
A29: Jun 30 - Jul 06 | C29: 20244.38 | D29: 15069.42 | E29: 0 | F29: 0 | G29: 5174.96 | H29: 13354.01 | I29: 0 | J29: 173.47 | K29: 1541.94 | L29: 5174.96 | M29: 20244.38 | N29: 109.43 | O29: 971.39 | P29: 18384.24 | Q29: 161.6 | R29: 617.72 | T29: 0 | U29: 20244.38 | V29: 44 | W29: 2595.24 | X29: 3121 | Y29: 11827.82 | Z29: 2656.32
A30: Jul 07 - Jul 13 | C30: 21199.52 | D30: 15061.68 | E30: 0 | F30: 0 | G30: 6137.84 | H30: 12959.4 | I30: 0 | J30: 108.99 | K30: 1993.3 | L30: 6137.84 | M30: 21199.53 | N30: 266.81 | O30: 1133.59 | P30: 19138.56 | Q30: 53 | R30: 607.57 | T30: 0 | U30: 21199.53 | V30: 351.46 | W30: 3360.14 | X30: 3833.98 | Y30: 11503.94 | Z30: 2150
A31: Jul 14 - Jul 20 | C31: 20083.65 | D31: 14254.69 | E31: 0 | F31: 0 | G31: 5828.96 | H31: 12144.69 | I31: 0 | J31: 31.25 | K31: 2078.75 | L31: 5828.96 | M31: 20083.65 | N31: 185.89 | O31: 1033.8 | P31: 18123.87 | Q31: 141.49 | R31: 568.61 | T31: 29.99 | U31: 20083.65 | V31: 32.39 | W31: 2496.41 | X31: 4484.49 | Y31: 11042.95 | Z31: 2027.41
... A44: Oct 13 - Oct 19 | C44: 17252.3 | D44: 13234.44 | E44: 200.1 | F44: 0 | G44: 3817.76 | H44: 11583.47 | I44: 0 | J44: 68.99 | K44: 1581.98 | L44: 4017.86 | M44: 17252.3 | N44: 73.46 | O44: 454.9 | P44: 16123.9 | Q44: 62 | R44: 496.05 | T44: 41.99 | U44: 17252.3 | V44: 88 | W44: 2891.59 | X44: 3809.79 | Y44: 9227.17 | Z44: 1235.75
A45: Oct 20 - Oct 26 | B45: 575 | C45: 18506.6 | D45: 13467.13 | E45: 255.15 | F45: 0 | G45: 4784.32 | H45: 4784.32 | I45: 0 | J45: 765.96 | K45: 1537.69 | L45: 5039.47 | M45: 18506.61 | N45: 165.51 | O45: 317.07 | P45: 17529.14 | Q45: 17.5 | R45: 405.41 | T45: 71.98 | U45: 18506.61 | V45: 0 | W45: 2812.28 | X45: 3814.43 | Y45: 10552.43 | Z45: 1327.46
A46: Oct 27 - Nov 02 | B46: 535 | C46: 17425.06 | D46: 12637.58 | E46: 367.19 | F46: 0 | G46: 4420.29 | H46: 10830.51 | I46: 0 | J46: 372.99 | K46: 1434.09 | L46: 4787.48 | M46: 17425.07 | N46: 157.29 | O46: 203.52 | P46: 16508.06 | Q46: 38 | R46: 500.21 | T46: 17.99 | U46: 17425.07 | V46: 287.98 | W46: 2102.13 | X46: 4211.55 | Y46: 9915.96 | Z46: 907.44
A47: Nov 03 - Nov 09 | B47: 539 | C47: 16264.56 | D47: 11402.71 | E47: 192.68 | F47: 0 | G47: 4669.17 | H47: 9987.75 | I47: 0 | J47: 197.8 | K47: 1217.15 | L47: 4861.85 | M47: 16264.55 | N47: 976.69 | O47: 167.3 | P47: 14626.97 | Q47: 30 | R47: 373.6 | T47: 89.99 | U47: 16264.55 | V47: 174.48 | W47: 2144.43 | X47: 4246.61 | Y47: 8894.17 | Z47: 804.87
A48: Nov 10 - Nov 16 | B48: 566 | C48: 17748.23 | D48: 12929.35 | E48: 337.96 | F48: 0 | G48: 4480.92 | H48: 11231.75 | I48: 0 | J48: 107.19 | K48: 1590.4 | L48: 4818.88 | M48: 17748.22 | N48: 758.43 | O48: 153.85 | P48: 16353.27 | Q48: 28 | R48: 448.68 | T48: 5.99 | U48: 17748.22 | V48: 123.87 | W48: 2831.11 | X48: 4206.03 | Y48: 9001.57 | Z48: 1585.65
A49: Nov 17 - Nov 23 | B49: 589 | C49: 19214.09 | D49: 12834.55 | E49: 171.69 | F49: 0 | G49: 6207.85 | H49: 10200.88 | I49: 0 | J49: 510.34 | K49: 2123.33 | L49: 6379.54 | M49: 19214.09 | N49: 344.6 | O49: 197.38 | P49: 18165.12 | Q49: 17.49 | R49: 453.52 | T49: 35.98 | U49: 19214.09 | V49: 131.78 | W49: 3118.92 | X49: 4236.62 | Y49: 10453.51 | Z49: 1273.26
A50: Nov 24 - Nov 30 | B50: 584 | C50: 19246.06 | D50: 12768.97 | E50: 102.93 | F50: 0 | G50: 6374.16 | H50: 11026.68 | I50: 0 | J50: 27 | K50: 1715.28 | L50: 6477.09 | M50: 19246.05 | N50: 197.97 | O50: 385.61 | P50: 18015.48 | Q50: 35 | R50: 576.01 | T50: 35.98 | U50: 19246.05 | V50: 191.19 | W50: 3026 | X50: 5126.61 | Y50: 9853.09 | Z50: 1049.17
A51: Dec 01 - Dec 07 | B51: 617 | C51: 19778.6 | D51: 11560.99 | E51: 137.74 | F51: 0 | G51: 8079.87 | H51: 9767.92 | I51: 0 | J51: 313.24 | K51: 1479.83 | L51: 8217.61 | M51: 19778.6 | N51: 321.4 | O51: 358.11 | P51: 18502 | Q51: 27.99 | R51: 515.11 | T51: 53.99 | U51: 19778.6 | V51: 15.89 | W51: 3444.35 | X51: 4867.35 | Y51: 10045.82 | Z51: 1405.19
A52: Dec 08 - Dec 14 | B52: 598 | C52: 18690.72 | D52: 12819.93 | E52: 140.78 | F52: 0 | G52: 5730.01 | H52: 11175.47 | I52: 0 | J52: 297.26 | K52: 1347.18 | L52: 5870.79 | M52: 18690.7 | N52: 280.43 | O52: 215.48 | P52: 17617.04 | Q52: 21 | R52: 502.78 | T52: 53.97 | U52: 18690.7 | V52: 22 | W52: 3122.5 | X52: 4171.36 | Y52: 9442.76 | Z52: 1932.1
...

Sheet Pizza K Eglinton
B1: Sales by Sections | H1: Sales by Order Type | N1: Sales by Category (Net Sales) | T1: Daily and Hourly Sales (TBD)
B2: Total Bill Count | C2: Net Sales | D2: Remaining | E2: Skip | F2: DD | G2: Uber | H2: Take Out | I2: Delivery | J2: Bar Tab | K2: Dine-In | L2: Online Order | M2: Net Sales | N2: Drinks | O2: Food (Pizza K) | P2: Food Court | Q2: Smash Ox Burger | R2: Uncategorized | S2: Net Sales | T2: 8AM - 11AM | U2: 11AM - 3PM | V2: 3PM - 6PM | W2: 6PM - 11PM | X2: 11PM-7AM
A3: Dec 30 - Jan 05 2025
A4: Jan 06 - Jan 12 2025
A5: Jan 13 - Jan 19 2025
A6: Jan 20 - Jan 26 2025
A7: Jan 27 - Feb 02 2025
A8: Feb 03 - Feb 09 2025 | C8: 25785.18 | D8: 25785.18 | E8: 0 | F8: 0 | G8: 0 | H8: 18727.75 | I8: 0 | J8: 0 | K8: 7057.47 | L8: 0 | M8: 25785.22 | N8: 843.76 | O8: 24813.46 | P8: 128 | R8: 0 | S8: 25785.22
A9: Feb 10 - Feb 16 2025 | C9: 26342.05 | D9: 26342.05 | E9: 0 | F9: 0 | G9: 0 | H9: 19985.95 | I9: 0 | J9: 0 | K9: 6356.12 | L9: 0 | M9: 26342.07 | N9: 865.01 | O9: 25417.06 | P9: 60 | R9: 0 | S9: 26342.07 | T9: 0 | U9: 2517.02 | V9: 4644.48 | W9: 14645.41 | X9: 4535.14
A10: Feb 17 - Feb 23 2025 | C10: 29300.91 | D10: 29300.91 | E10: 0 | F10: 0 | G10: 0 | H10: 20433.86 | I10: 0 | J10: 0 | K10: 8867.05 | L10: 0 | M10: 29300.91 | N10: 1073.15 | O10: 28026.76 | P10: 201 | R10: 0 | S10: 29300.91
A11: Feb 24 - Mar 02 2025 | C11: 23559.79 | D11: 17339.25 | E11: 0 | F11: 499.96 | G11: 5720.58 | H11: 11683.63 | I11: 0 | J11: 0 | K11: 5655.64 | L11: 6220.54 | M11: 23559.81 | N11: 735.72 | O11: 22667.09 | P11: 157 | R11: 0 | S11: 23559.81 | T11: 0 | U11: 2352.18 | V11: 6702.39 | W11: 11027.15 | X11: 3478.08
A12: Mar 03 - Mar 09 2025 | C12: 26360.52 | D12: 19061.44 | E12: 898.78 | F12: 169.2 | G12: 6231.1 | H12: 12933.83 | I12: 0 | J12: 0 | K12: 6127.6 | L12: 7299.08 | M12: 26360.51 | N12: 865.17 | O12: 25347.84 | P12: 147.5 | R12: 0 | S12: 26360.51 | T12: 0 | U12: 1509.86 | V12: 8825.1 | W12: 9791.61 | X12: 6233.95
A13: Mar 10 - Mar 16 2025 | C13: 30492.57 | D13: 21596.66 | E13: 1187.71 | F13: 198.6 | G13: 7509.6 | H13: 14340.23 | I13: 0 | J13: 0 | K13: 7256.45 | L13: 8895.91 | M13: 30492.59 | N13: 949.96 | O13: 29405.63 | P13: 137 | R13: 0 | S13: 30492.59 | T13: 0 | U13: 1292.66 | V13: 5453.6 | W13: 16453.57 | X13: 7292.74
A14: Mar 17 - Mar 23 2025 | C14: 31662.34 | D14: 22681.9 | E14: 613.34 | F14: 299.19 | G14: 8067.91 | H14: 15298.91 | I14: 0 | J14: 0 | K14: 7383.05 | L14: 8980.44 | M14: 31662.4 | N14: 917.64 | O14: 30564.76 | P14: 180 | R14: 0 | S14: 31662.4 | T14: 0 | U14: 1338.71 | V14: 6114.97 | W14: 17245.8 | X14: 6962.86
A15: Mar 24 - Mar 30 2025 | C15: =G15+F15+E15+D15 | D15: 26202.62 | E15: 850.61 | F15: 604.78 | G15: 10894.53 | H15: 17616.63 | I15: 0 | J15: 0 | K15: 8586.08 | L15: 12349.92 | M15: 38552.63 | N15: 1270.42 | O15: 37103.21 | P15: 179 | R15: 0 | S15: 38552.63 | T15: 14 | U15: 3440.41 | V15: 5664.33 | W15: 20092.84 | X15: 9340.96
A16: March 31 - April 6 | C16: 34829.62 | D16: 24641.64 | E16: 999.37 | F16: 205.2 | G16: 8983.4 | H16: 14743.68 | I16: 0 | J16: 0 | K16: 9897.95 | L16: 10406.96 | M16: 35048.59 | N16: 1433.88 | O16: 33445.71 | P16: 169 | R16: 0 | S16: 35048.59 | T16: 4644.15 | U16: 23334.35 | V16: =4271.06+2580.16
A17: April 7 - April 13 | C17: 33358.89 | D17: 25093.37 | E17: 527.6 | F17: 306.57 | G17: 7431.35 | H17: 15644.25 | I17: 0 | J17: 0 | K17: 9449.14 | L17: 8265.52 | M17: 33358.91 | N17: 1210.39 | O17: 32041.02 | P17: 107.5 | R17: 0 | S17: 33358.91 | T17: 0 | U17: 3775.43 | V17: 5788.33 | W17: 18093.91 | X17: =3106.5+2594.72
A18: April 14 - April 20 | C18: 37719.85 | D18: 29230.44 | E18: 771.35 | F18: 597.72 | G18: 7120.34 | H18: 17877.46 | I18: 0 | J18: 0 | K18: 11401.84 | L18: 8489.41 | M18: 37768.71 | N18: 1415 | O18: 36160.71 | P18: 193 | R18: 0 | S18: 37768.71 | T18: 0 | U18: 4407.8 | V18: 7314.37 | W18: 20004.08 | X18: =3319.27+2674.33
A19: Apr 21 - Apr 27 | C19: 32696.87 | D19: 24557.66 | E19: 762.23 | F19: 358.83 | G19: 7018.15 | H19: 14157.07 | I19: 0 | J19: 0 | K19: 10400.69 | L19: 8139.21 | M19: 32696.97 | N19: 1577.3 | O19: 31010.67 | P19: 109 | R19: 0 | S19: =P19+O19+N19 | T19: 0 | U19: 3919.7 | V19: 5597.34 | W19: 17680.07 | X19: 5499.76
A20: Apr 28 - May 4 | C20: 32178.58 | D20: 25692.62 | E20: 766.37 | F20: 371.6 | G20: 5347.99 | H20: 15690.31 | I20: 0 | J20: 0 | K20: 10002.39 | L20: 6485.96 | M20: 32178.66 | N20: 1296.06 | O20: 30727.6 | P20: 155 | R20: 0 | S20: 32178.66 | T20: 0 | U20: 3589.45 | V20: 5424.85 | W20: 17639.67 | X20: 5524.61
A21: May 5 - May 11 | C21: 35456.79 | D21: 27199.04 | E21: 936.81 | F21: 212.99 | G21: 7107.95 | H21: 16807.53 | I21: 0 | J21: 0 | K21: 10391.61 | L21: 8257.75 | M21: 35456.89 | N21: 1317.02 | O21: 34009.37 | P21: 130.5 | R21: 0 | S21: 35456.89 | T21: 0 | U21: 3851.59 | V21: 5812.38 | W21: 20316.61 | X21: 5476.21
A22: May 12 - May 18 | C22: 33561.9 | D22: 26057.63 | E22: 547.72 | F22: 446.95 | G22: 6509.6 | H22: 15439.95 | I22: 0 | J22: 1.78 | K22: 10615.92 | L22: 7504.27 | M22: 33561.92 | N22: 1207.89 | O22: 32226.53 | P22: 127.5 | R22: 0 | S22: 33561.92 | T22: 0 | U22: 2795.98 | V22: 5632.7 | W22: 18169.07 | X22: 6964.15
A23: May 19 - May 25 | C23: 34569.42 | D23: 27029.09 | E23: 827.39 | F23: 362.08 | G23: 6350.86 | H23: 16647.39 | I23: 0 | J23: 0 | K23: 10381.72 | L23: 7540.33 | M23: 34569.44 | N23: 1222.42 | O23: 33148.02 | P23: 199 | R23: 0 | S23: 34569.44 | T23: 28.89 | U23: 3013.96 | V23: 7039.16 | W23: 18601.26 | X23: 5886.15
A24: May 26 - Jun 01 | C24: 33583.35 | D24: 26050.21 | E24: 508.94 | F24: 158.38 | G24: 6865.82 | H24: 15566.11 | I24: 0 | J24: 0 | K24: 10484.12 | L24: 7533.14 | M24: 33583.37 | N24: 1264.82 | O24: 32152.05 | P24: 166.5 | R24: 0 | S24: 33583.37 | T24: 0 | U24: 2901.14 | V24: 5979.98 | W24: 19224.18 | X24: 5478.05
A25: Jun 02 - Jun 08 | C25: 39076.66 | D25: 30285.8 | E25: 584.15 | F25: 555.57 | G25: 7651.14 | H25: 17430.66 | I25: 0 | J25: 0 | K25: 12855.17 | L25: 8790.86 | M25: 39076.7 | N25: 1725.77 | O25: 37161.43 | P25: 189.5 | R25: 0 | S25: 39076.7 | T25: 0 | U25: 4337.2 | V25: 5638.61 | W25: 20706.01 | X25: 8394.84
A26: Jun 09 - Jun 15 | C26: 35369.66 | D26: 27482.76 | E26: 1139 | F26: 266.87 | G26: 6481.03 | H26: 17344.87 | I26: 0 | J26: 0 | K26: 10137.95 | L26: 7886.9 | M26: 35369.72 | N26: 1496.47 | O26: 33605.25 | P26: 268 | R26: 0 | S26: 35369.72 | T26: 12 | U26: 4161.98 | V26: 4939.09 | W26: 19404.22 | X26: 6852.37
A27: Jun 16 - Jun 22 | C27: 36493.44 | D27: 27702.72 | E27: 1131.29 | F27: 424.56 | G27: 7234.87 | H27: 16855.36 | I27: 0 | J27: 0 | K27: 10847.42 | L27: 8790.72 | M27: 36493.5 | N27: 1597.62 | O27: 34788.38 | P27: 107.5 | R27: 0 | S27: 36493.5 | T27: 24.78 | U27: 3848.23 | V27: 5453.03 | W27: 20876.46 | X27: 6290.94
A28: Jun 23 - Jun 29 | C28: 43298.28 | D28: 33615.84 | E28: 872.82 | F28: 587.17 | G28: 8222.45 | H28: 20704.17 | I28: 0 | J28: 0 | K28: 12911.69 | L28: 9682.44 | M28: 43298.3 | N28: 1770.27 | O28: 41411.03 | P28: 117 | R28: 0 | S28: 43298.3 | T28: 0 | U28: 5910.23 | V28: 6559.96 | W28: 23314.59 | X28: 7513.5
A29: Jun 30 - Jul 06 | C29: 43696.36 | D29: 35061.14 | E29: 599.72 | F29: 601.62 | G29: 7433.88 | H29: 21516.06 | I29: 0 | J29: 0 | K29: 13545.02 | L29: 8635.22 | M29: 43696.3 | N29: 1792.55 | O29: 41787.75 | P29: 116 | R29: 0 | S29: 43696.3 | T29: 0 | U29: 4456.59 | V29: 5527.16 | W29: 23498.84 | X29: 10213.77
A30: Jul 07 - Jul 13 | C30: 39228.65 | D30: 31189.46 | E30: 549.67 | F30: 705.86 | G30: 6783.66 | H30: 20503.62 | I30: 0 | J30: 0 | K30: 10685.84 | L30: 8039.19 | M30: 39228.65 | N30: 1537.11 | O30: 37606.54 | P30: 85 | R30: 0 | S30: 39228.65 | T30: 0 | U30: 4188.12 | V30: 5417.42 | W30: 21908.91 | X30: 7714.2
A31: Jul 14 - Jul 20 | C31: 38732.85 | D31: 30147.56 | E31: 602.82 | F31: 386.79 | G31: 7595.68 | H31: 19139.71 | I31: 0 | J31: 0 | K31: 11007.84 | L31: 8585.29 | M31: 38732.84 | N31: 1643.25 | O31: 36774.6 | P31: 117 | R31: 197.99 | S31: 38732.84 | T31: 0 | U31: 4060.28 | V31: 5470.16 | W31: 21091.78 | X31: 8110.63
... A45: Oct 20 - Oct 26 | C45: 33616.29 | D45: 25602.63 | E45: 834.67 | F45: 337.75 | G45: 6841.24 | H45: 6841.24 | I45: 0 | J45: 0 | K45: 9453.35 | L45: 8013.66 | M45: 33616.24 | N45: 1294.92 | O45: 32201.33 | P45: 102 | R45: 17.99 | S45: 33616.24 | T45: 0 | U45: 3872.67 | V45: 6105.04 | W45: 18571.05 | X45: 5067.53
A46: Oct 27 - Nov 02 | B46: 979 | C46: 33277.95 | D46: 23552.91 | E46: 775.33 | F46: 557.08 | G46: 8392.63 | H46: 15876.43 | I46: 0 | J46: 0 | K46: 7676.41 | L46: 9725.04 | M46: 33277.88 | N46: 1065.64 | O46: 32095.24 | P46: 81 | R46: 36 | S46: 33277.88 | T46: 0 | U46: 3084.66 | V46: 7203.61 | W46: 19014.75 | X46: 3974.93
A47: Nov 03 - Nov 09 | B47: 879 | C47: 28533.75 | D47: 21086.37 | E47: 642.82 | F47: 391.03 | G47: 6413.53 | H47: 14202.48 | I47: 0 | J47: 0 | K47: 6883.85 | L47: 7447.38 | M47: 28533.71 | N47: 1084.24 | O47: 27294.49 | P47: 95 | R47: 59.98 | S47: 28533.71 | T47: 0 | U47: 3481.37 | V47: 6312.91 | W47: 14446.54 | X47: 4292.93
A48: Nov 10 - Nov 16 | B48: 937 | C48: 29074.81 | D48: 22138.82 | E48: 728.93 | F48: 267.66 | G48: 5939.4 | H48: 15201.28 | I48: 0 | J48: 0 | K48: 6937.53 | L48: 6935.99 | M48: 29074.8 | N48: 878.93 | O48: 28047.88 | P48: 82 | R48: 65.99 | S48: 29074.8 | T48: 0 | U48: 3795.11 | V48: 5610.22 | W48: 15358.02 | X48: 4311.46
A49: Nov 17 - Nov 23 | B49: 989 | C49: 33988.91 | D49: 24701.18 | E49: 449.73 | F49: 468.51 | G49: 8369.49 | H49: 16509.08 | I49: 0 | J49: 0 | K49: 8192.11 | L49: 9287.73 | M49: 33988.92 | N49: 972.24 | O49: 32743.18 | P49: 153.5 | R49: 120 | S49: 33988.92 | T49: 0 | U49: 3624.62 | V49: 6740.52 | W49: 18544.7 | X49: 5079.07
A50: Nov 24 - Nov 30 | B50: 1063 | C50: 35264.52 | D50: 24221.36 | E50: 844.61 | F50: 565.92 | G50: 9632.63 | H50: 15877.62 | I50: 0 | J50: 0 | K50: 8343.73 | L50: 11043.16 | M50: 35264.51 | N50: 948.89 | O50: 34071.62 | P50: 160 | R50: 84 | S50: 35264.51 | T50: 0 | U50: 3847.14 | V50: 7807.85 | W50: 18100.21 | X50: 5509.32
A51: Dec 01 - Dec 07 | B51: 966 | C51: 33345.07 | D51: 20425.93 | E51: 578.79 | F51: 551.85 | G51: 11788.5 | H51: 15164.54 | I51: 0 | J51: 0 | K51: 5236.01 | L51: 12944.51 | M51: 33345.06 | N51: 772.22 | O51: 32479.84 | P51: 57 | R51: 36 | S51: 33345.06 | T51: 0 | U51: 3552.14 | V51: 7203.05 | W51: 17856.59 | X51: 4733.29
A52: Dec 08 - Dec 14 | B52: 1,018 | C52: 34683.6 | D52: 22103.09 | E52: 620.99 | F52: 504.76 | G52: 11454.76 | H52: 15812.56 | I52: 0 | J52: 0 | K52: 6290.49 | L52: 12580.51 | M52: 34683.56 | N52: 920.13 | O52: 33638.93 | P52: 124.5 | R52: 0 | S52: 34683.56 | T52: 0 | U52: 4292.47 | V52: 8279.75 | W52: 17116.21 | X52: 4995.17
A53: Dec 15 - Dec 21 | B53: 1,078 | C53: 36575.23 | D53: 24496.68 | E53: 960.82 | F53: 680.74 | G53: 10436.99 | H53: 15722.21 | I53: 0 | J53: 0 | K53: 8774.4 | L53: 12078.55 | M53: 36575.16 | N53: 1106.38 | O53: 35351.78 | P53: 81 | R53: 36 | S53: 36575.16 | T53: 0 | U53: 4747.48 | V53: 8034.44 | W53: 18209.03 | X53: 5584.28
...

Sheet Karachi Food Court
B1: Sales by Sections | H1: Sales by Order Type | N1: Sales by Category (Net Sales) | W1: Daily and Hourly Sales (TBD)
B2: Total Bill Count | C2: Net Sales | D2: Remaining | E2: Skip | F2: DD | G2: Uber | H2: Take Out | I2: Delivery | J2: Bar Tab | K2: Dine-In | L2: Online Order | M2: Net Sales | N2: Chickentarian | O2: Drinks | P2: Food | Q2: Food Court | R2: Food Highway | S2: KT Icecream | T2: Kabab Wala | U2: Smash Ox Burger | V2: Net Sales | W2: 8AM - 11AM | X2: 11AM - 3PM | Y2: 3PM - 6PM | Z2: 6PM - 11PM | AA2: 11PM-7AM | AB2: 7 AM- 8 AM
A3: Dec 30 - Jan 05 2025
A4: Jan 06 - Jan 12 2025
A5: Jan 13 - Jan 19 2025
A6: Jan 20 - Jan 26 2025
A7: Jan 27 - Feb 02 2025
A8: Feb 03 - Feb 09 2025 | C8: 42408.88 | D8: 39376.72 | E8: 240.13 | F8: 186.2 | G8: 2605.83 | H8: 37169.48 | I8: 0 | J8: 0 | K8: 2207.32 | L8: 3032.16 | M8: 42408.96 | N8: 3904.75 | O8: 813.93 | P8: 0 | Q8: 10608.13 | S8: 1310.45 | T8: 23036.91 | U8: 2734.79 | V8: 42408.96
A9: Feb 10 - Feb 16 2025 | C9: 38328.99 | D9: 36670.19 | E9: 169.34 | F9: 37.47 | G9: 1451.99 | H9: 34406.82 | I9: 0 | J9: 344.97 | K9: 1902.29 | L9: 1674.99 | M9: 38329.07 | N9: 3666.03 | O9: 642 | Q9: 9799.47 | S9: 1217.65 | T9: 20346.5 | U9: 2657.42 | V9: 38329.07
A10: Feb 17 - Feb 23 2025 | C10: 55100.66 | D10: 51373.3 | E10: 344.81 | F10: 76.09 | G10: 3306.46 | H10: 48073.17 | I10: 0 | J10: 620.18 | K10: 2680.08 | L10: 3727.36 | M10: 55100.79 | N10: 6124.26 | O10: 756 | P10: 1.8 | Q10: 15538.76 | R10: 27 | S10: 1677.85 | T10: 27589.81 | U10: 3385.31 | V10: 55100.79 | W10: 2214.63 | X10: 10139.25 | Y10: 8869.89 | Z10: 27333.97 | AA10: 6542.92
A11: Feb 24 - Mar 02 2025 | C11: 38257.93 | D11: 35952.52 | E11: 274.03 | F11: 23.38 | G11: 2008 | H11: 33558.36 | I11: 0 | J11: 0 | K11: 2394.27 | L11: 2305.41 | M11: 38258.04 | N11: 3756.45 | O11: 162 | P11: 0 | Q11: 11090.41 | R11: 0 | S11: 887.34 | T11: 19934.14 | U11: 2427.7 | V11: 38258.04 | W11: 7 | X11: 2946.65 | Y11: 5321.06 | Z11: 18826.1 | AA11: 11157.12
A12: Mar 03 - Mar 09 2025 | C12: 43531.99 | D12: 39887.7 | E12: 219.35 | F12: 234.34 | G12: 3190.6 | H12: 37620.97 | I12: 0 | J12: 0 | K12: 2266.92 | L12: 3644.29 | M12: 43532.18 | N12: 4038.38 | O12: 15 | P12: 0 | Q12: 15692.48 | R12: 18 | S12: 1107.96 | T12: 20869.96 | U12: 1790.4 | V12: 43532.18 | W12: 0 | X12: 0 | Y12: 8117.57 | Z12: 15601.66 | AA12: 19805.77 | AB12: 6.99
A13: Mar 10 - Mar 16 2025 | C13: 59233.97 | D13: 56306.62 | E13: 306.77 | F13: 110.65 | G13: 2509.93 | H13: 53561.58 | I13: 0 | J13: 0 | K13: 2744.95 | L13: 2927.35 | M13: 59233.88 | N13: 4875.31 | O13: 3 | P13: 0 | Q13: 22489.72 | R13: 9 | S13: 1992.52 | T13: 26278.27 | U13: 3586.06 | V13: 59233.88 | W13: 0 | X13: 0 | Y13: 3737.65 | Z13: 24697.63 | AA13: 30798.69
A14: Mar 17 - Mar 23 2025 | C14: 57026.08 | D14: 52209.01 | E14: 254.79 | F14: 80.97 | G14: 4481.31 | H14: 49866.97 | I14: 0 | J14: 0 | K14: 2342.25 | L14: 4817.07 | M14: 57026.29 | N14: 5786.59 | O14: 24 | P14: 6.99 | Q14: 21171.3 | R14: 9 | S14: 1343.12 | T14: 25762.66 | U14: 2922.63 | V14: 57026.29 | W14: 0 | X14: 0 | Y14: 5243.19 | Z14: 24339.62 | AA14: 27443.98
A15: Mar 24 - Mar 30 2025 | C15: =G15+F15+E15+D15 | D15: 65804.91 | E15: 260.59 | F15: 116.93 | G15: 3929.61 | H15: 62815.92 | I15: 0 | J15: 0 | K15: 2989.09 | L15: 4307.13 | M15: 70112.14 | N15: 6242.04 | O15: 12 | P15: 0 | Q15: 27125.21 | R15: 9 | S15: 1876.94 | T15: 30974.63 | U15: 3872.32 | V15: 70112.14 | W15: 4384.89 | X15: 4569.99 | Y15: 6697.76 | Z15: 24134.76 | AA15: 30324.64
A16: March 31 - April 6 | C16: 65484.62 | D16: 61646.29 | E16: 89.75 | F16: 283.22 | G16: 3465.36 | H16: 58018.85 | I16: 0 | J16: 0 | K16: 3763.16 | L16: 3838.33 | M16: 65620.34 | N16: 6892.34 | O16: 58.95 | P16: 0 | Q16: 19123.61 | R16: 32.99 | S16: 2334.1 | T16: 33137.02 | U16: 4041.33 | V16: 65620.34 | W16: 11449.94 | X16: 38877.45 | Y16: =11107.76+4049.47
A17: April 7 - April 13 | C17: 56769.38 | D17: 52694.01 | E17: 329.73 | F17: 251.06 | G17: 3494.58 | H17: 50424.58 | I17: 0 | J17: 0 | K17: 2269.56 | L17: 4075.37 | M17: 56769.51 | N17: 6139.99 | O17: 21 | P17: 0 | Q17: 16512.75 | R17: 6 | S17: 1421.08 | T17: 28844.69 | U17: 3824 | V17: 56769.51 | W17: 1807.42 | X17: 10000.7 | Y17: 7280.51 | Z17: 29548.61 | AA17: =4918.12+3214.02
A18: April 14 - April 20 | C18: 72232.17 | D18: 67953.78 | E18: 287.06 | F18: 521.5 | G18: 3469.83 | H18: 64544.72 | I18: 0 | J18: 0 | K18: 3409.1 | L18: 4278.39 | M18: 72232.21 | N18: 6784.18 | O18: 102 | P18: 0 | Q18: 20325.03 | R18: 62.93 | S18: 2216.71 | T18: 37686.67 | U18: 5054.69 | V18: 72232.21 | W18: 2071.58 | X18: 10951.14 | Y18: 10021.95 | Z18: 36425.49 | AA18: 12761.91
A19: Apr 21 - Apr 27 | C19: 55009.4 | D19: 51573.96 | E19: 189.97 | F19: 277.59 | G19: 2967.88 | H19: 48707.28 | I19: 0 | J19: 0 | K19: 2866.91 | L19: 3435.44 | M19: 55009.63 | N19: 5135.94 | O19: 105 | P19: 0 | Q19: 16635.29 | R19: 15.48 | S19: 1718.86 | T19: 27737.11 | U19: 3661.95 | V19: 55009.63 | W19: 1315.42 | X19: 9825.05 | Y19: 7229.33 | Z19: 26603.52 | AA19: 10036.08
A20: Apr 28 - May 4 | C20: 54909.43 | D20: 51416.75 | E20: 107.43 | F20: 341.33 | G20: 3043.92 | H20: 48799.71 | I20: 45.13 | J20: 0 | K20: 2572.05 | L20: 3492.68 | M20: 54909.57 | N20: 5376.13 | O20: 57 | P20: 0 | Q20: 15194.02 | R20: 139.86 | S20: 1821.08 | T20: 29006.63 | U20: 3314.85 | V20: 54909.57 | W20: 1333.13 | X20: 7182.09 | Y20: 6747.34 | Z20: 28372.96 | AA20: 11273.91
A21: May 5 - May 11 | C21: 58655.27 | D21: 55827.69 | E21: 317.86 | F21: 130.13 | G21: 2379.59 | H21: 53256.95 | I21: 0 | J21: 0 | K21: 2570.86 | L21: 2827.58 | M21: 58655.39 | N21: 5816.72 | O21: 12 | P21: 0 | Q21: 17027.99 | R21: 75.93 | S21: 1914.01 | T21: 30172.21 | U21: 3636.53 | V21: 58655.39 | W21: 2141.01 | X21: 10792.9 | Y21: 7726.89 | Z21: 28049.06 | AA21: 9945.41
A22: May 12 - May 18 | C22: 64319.69 | D22: 61079.04 | E22: 296.9 | F22: 15.7 | G22: 2928.05 | H22: 57901.49 | I22: 0 | J22: 69.97 | K22: 3107.68 | L22: 3240.65 | M22: 64319.79 | N22: 6352.93 | O22: 9 | P22: 0 | Q22: 17789.44 | R22: 44.95 | S22: 2179.54 | T22: 33709.87 | U22: 4234.06 | V22: 64319.79 | W22: 2204.28 | X22: 11364.08 | Y22: 6979.08 | Z22: 31727.75 | AA22: 12044.5
A23: May 19 - May 25 | C23: 66620.85 | D23: 63351.22 | E23: 509.1 | F23: 149.31 | G23: 2611.22 | H23: 60685.56 | I23: 0 | J23: 0 | K23: 2665.8 | L23: 3269.63 | M23: 66620.99 | N23: 5831.26 | O23: 6 | P23: 0 | Q23: 21287.08 | R23: 71.92 | S23: 2584.74 | T23: 32951.05 | U23: 3888.94 | V23: 66620.99 | W23: 3348.28 | X23: 13053.1 | Y23: 8439.75 | Z23: 30187.15 | AA23: 11592.57
A24: May 26 - Jun 01 | C24: 63478.08 | D24: 60452.9 | E24: 279.82 | F24: 252.03 | G24: 2493.33 | H24: 58126.81 | I24: 40.15 | J24: 0 | K24: 2286.15 | L24: 3025.18 | M24: 63478.29 | N24: 6260.95 | O24: 6 | P24: 0 | Q24: 18643.11 | R24: 26.97 | S24: 1804.12 | T24: 32013.33 | U24: 4723.81 | V24: 63478.29 | W24: 1889.79 | X24: 11311.88 | Y24: 7300.08 | Z24: 31336.71 | AA24: 11639.62
A25: Jun 02 - Jun 08 | C25: 74512.66 | D25: 70969.24 | E25: 655.6 | F25: 0 | G25: 2887.82 | H25: 68144.7 | I25: 0 | J25: 0 | K25: 2824.76 | L25: 3543.42 | M25: 74512.88 | N25: 6663.08 | O25: 15 | P25: 0 | Q25: 22639.67 | R25: 0 | S25: 2567.07 | T25: 37626.91 | U25: 5001.15 | V25: 74512.88 | W25: 3826.43 | X25: 14081.8 | Y25: 7625.59 | Z25: 34064.5 | AA25: 14914.34
A26: Jun 09 - Jun 15 | C26: 68484.61 | D26: 64870.47 | E26: 295.88 | F26: 0 | G26: 3318.26 | H26: 62901.5 | I26: 14.99 | J26: 0 | K26: 1954.18 | L26: 3614.14 | M26: 68484.81 | N26: 6353.61 | O26: 6 | P26: 0 | Q26: 18250.06 | R26: 0 | S26: 2259.93 | T26: 37055.69 | U26: 4559.52 | V26: 68484.81 | W26: 2414.55 | X26: 13409.93 | Y26: 7462.37 | Z26: 34085.95 | AA26: 11111.81
A27: Jun 16 - Jun 22 | C27: 64628.14 | D27: 62071.43 | E27: 308.12 | F27: 0 | G27: 2248.59 | H27: 59487.85 | I27: 3.5 | J27: 0 | K27: 2580.33 | L27: 2556.71 | M27: 64628.39 | N27: 6877.31 | O27: 27 | P27: 0 | Q27: 18259.75 | R27: 14.99 | S27: 3219.96 | T27: 32672.52 | U27: 3556.86 | V27: 64628.39 | W27: 12320.78 | X27: 1289.27 | Y27: 11828.61 | Z27: 7197.45 | AA27: 31992.03
A28: Jun 23 - Jun 29 | C28: 64145.69 | D28: 61398.03 | E28: 206.83 | F28: 0 | G28: 2540.83 | H28: 58168.2 | I28: 0 | J28: 0 | K28: 3230.08 | L28: 2747.66 | M28: 64145.94 | N28: 6726.82 | O28: 51 | P28: 0 | Q28: 18254.25 | R28: 0 | S28: 3078.8 | T28: 31900.01 | U28: 4135.06 | V28: 64145.94 | W28: 2065.41 | X28: 10173.83 | Y28: 5936.83 | Z28: 32583.17 | AA28: 13386.45
A29: Jun 30 - Jul 06 | C29: 85140.47 | D29: 81944.22 | E29: 486.19 | F29: 33.58 | G29: 2676.48 | H29: 78767.71 | I29: 42.96 | J29: 0 | K29: 3133.51 | L29: 3196.25 | M29: 85140.43 | N29: 8760.63 | O29: 51 | P29: 0 | Q29: 23261.72 | R29: 0 | S29: 3709.85 | T29: 44262.86 | U29: 5094.37 | V29: 85140.43 | W29: 2599.72 | X29: 15609.56 | Y29: 8108.38 | Z29: 37021.87 | AA29: 21800.94
... A46: Oct 27 - Nov 02 | C46: 54239.89 | D46: 50919.68 | E46: 46.77 | F46: 283.04 | G46: 2990.4 | H46: 49124.95 | I46: 0 | J46: 0 | K46: 1794.68 | L46: 3320.21 | M46: 54239.84 | N46: 3594.35 | O46: 6.99 | P46: 6.99 | Q46: 17627.79 | R46: 0 | S46: 1269.54 | T46: 29153.4 | U46: 2580.78 | V46: 54239.84 | W46: 2766.93 | X46: 9248.31 | Y46: 7786.61 | Z46: 25138.89 | AA46: 9299.15
A47: Nov 03 - Nov 09 | B47: 1,519 | C47: 49748.58 | D47: 46128.03 | E47: 102.36 | F47: 289.88 | G47: 3228.31 | H47: 44221.01 | I47: 0 | J47: 0 | K47: 1906.93 | L47: 3620.55 | M47: 49748.49 | N47: 3387.87 | O47: 0 | P47: 0 | Q47: 16812.98 | R47: 0 | S47: 1127.5 | T47: 25993.65 | U47: 2426.49 | V47: 49748.49 | W47: 2690.75 | X47: 9300.45 | Y47: 6331.77 | Z47: 24440.63 | AA47: 6984.98
A48: Nov 10 - Nov 16 | B48: 1,488 | C48: 50407.18 | D48: 47850.75 | E48: 25.18 | F48: 188.22 | G48: 2343.03 | H48: 46100.4 | I48: 0 | J48: 0 | K48: 1750.27 | L48: 2556.43 | M48: 50407.1 | N48: 3543.35 | O48: 8.1 | P48: 0 | Q48: 16705.85 | R48: 0 | S48: 1315.89 | T48: 26192.07 | U48: 2641.84 | V48: 50407.1 | W48: 2304.77 | X48: 10083.42 | Y48: 6775.18 | Z48: 24322.56 | AA48: 6921.25
A49: Nov 17 - Nov 23 | B49: 1,448 | C49: 46870.52 | D49: 44573.78 | E49: 64.16 | F49: 87.67 | G49: 2144.91 | H49: 43094.13 | I49: 0 | J49: 0 | K49: 1479.51 | L49: 2296.74 | M49: 46870.38 | N49: 3796.76 | O49: 0 | P49: 0 | Q49: 16207.52 | R49: 0 | S49: 1213.7 | T49: 23201.22 | U49: 2451.18 | V49: 46870.38 | W49: 1670.21 | X49: 9778.51 | Y49: 6427.66 | Z49: 22029.55 | AA49: 6964.59
A50: Nov 24 - Nov 30 | B50: 1407 | C50: 49452.29 | D50: 45726.39 | E50: 32.38 | F50: 46.17 | G50: 3647.35 | H50: 44191.09 | I50: 0 | J50: 0 | K50: 1512.39 | L50: 3748.81 | M50: 49452.29 | N50: 3696.74 | O50: 0 | P50: 0 | Q50: 17846.58 | R50: 0 | S50: 1321.54 | T50: 24013.92 | U50: 2573.51 | V50: 49452.29 | W50: 2571.07 | X50: 9556.12 | Y50: 7199.69 | Z50: 24207.02 | AA50: 5918.39
A51: Dec 01 - Dec 07 | B51: 1281 | C51: 42457.23 | D51: 38758.09 | E51: 0 | F51: 144.72 | G51: 3554.42 | H51: 37591.8 | I51: 0 | J51: 0 | K51: 1166.2 | L51: 3699.14 | M51: 42457.14 | N51: 2690.15 | O51: 2.7 | P51: 0 | Q51: 13497.11 | R51: 0 | S51: 860.29 | T51: 22450.68 | U51: 2956.21 | V51: 42457.14 | W51: 1807.74 | X51: 7916.29 | Y51: 7000.62 | Z51: 20125.45 | AA51: 5607.13
A52: Dec 08 - Dec 14 | B52: 1,138 | C52: 37599.25 | D52: 34426.32 | E52: 16.79 | F52: 163.09 | G52: 2993.05 | H52: 33247.3 | I52: 0 | J52: 0 | K52: 1075.24 | L52: 3276.62 | M52: 37599.16 | N52: 3280.15 | O52: 14.98 | P52: 0 | Q52: 11870.24 | R52: 0 | S52: 660.57 | T52: 19679.12 | U52: 2094.1 | V52: 37599.16 | W52: 1669.91 | X52: 7512.86 | Y52: 6612.93 | Z52: 16714.06 | AA52: 5089.49
A53: Dec 15 - Dec 21 | B53: 1,603 | C53: 47606.93 | D53: 43702.94 | E53: 125.92 | F53: 64.35 | G53: 3713.72 | H53: 42224.68 | I53: 0 | J53: 18.47 | K53: 1421.4 | L53: 3942.35 | M53: 47606.9 | N53: 3571.77 | O53: 1.5 | P53: 0 | Q53: 15196.49 | R53: 0 | S53: 1195.27 | T53: 24375.63 | U53: 3266.24 | V53: 47606.9 | W53: 1698.25 | X53: 9982.25 | Y53: 6614.32 | Z53: 20294.06 | AA53: 9018.05
A54: Dec 22 - Dec 28 | B54: 1806 | C54: 66529.91 | D54: 35.39 | E54: 383.46 | F54: 3677.53 | G54: 62433.53 | H54: 60827.42 | I54: 0 | J54: 0 | K54: 1606 | L54: 4096.38 | M54: 66529.8 | N54: 5175.86 | O54: 5.4 | P54: 0 | Q54: 22174.81 | R54: 38 | S54: 1356.22 | T54: 33227.65 | U54: 4551.86 | V54: 66529.8 | W54: 3406.8 | X54: 15562.03 | Y54: 9578.2 | Z54: 28521.17 | AA54: 9461.71
A55: Dec 29 - Jan 04 | B55: 2,080 | C55: 75867.23 | D55: 72085.37 | E55: 137.95 | F55: 0 | G55: 3643.91 | H55: 69578.53 | I55: 0 | J55: 0 | K55: 2506.66 | L55: 3781.86 | M55: 75867.05 | N55: 6103.19 | O55: 5.4 | P55: 0 | Q55: 24500.36 | R55: 0 | S55: 2033.45 | T55: 38257.53 | U55: 4967.12 | V55: 75867.05 | W55: 2496.08 | X55: 16055.82 | Y55: 10231.19 | Z55: 32897.02 | AA55: 14187.12
A56: Jan 05 - Jan 11 | B56: 1,228 | C56: 41725.22 | D56: 39246.19 | E56: 93.46 | F56: 58.44 | G56: 2327.13 | H56: 37869.66 | I56: 0 | J56: 0 | K56: 1376.44 | L56: 2479.03 | M56: 41725.13 | N56: 2662.89 | O56: 0 | P56: 0 | Q56: 13691.02 | R56: 0 | S56: 1229.66 | T56: 22147.54 | U56: 1994.02 | V56: 41725.13 | W56: 1581.36 | X56: 8121.41 | Y56: 5703.24 | Z56: 20350.67 | AA56: 5968.54
...

Sheet Markham
B1: Sales by Sections | H1: Sales by Order Type | N1: Sales by Category (Net Sales) | T1: Daily and Hourly Sales (TBD)
B2: Total Bill Count | C2: Net Sales | D2: Remaining | E2: Skip | F2: DD | G2: Uber | H2: Take Out | I2: Delivery | J2: Bar Tab | K2: Dine-In | L2: Online Order | M2: Net Sales | N2: Drinks | O2: Food (Pizza K) | P2: UNCATEGORIZED | Q2: Food Court | R2: Smash Ox Burger | S2: Net Sales | T2: 8AM - 11AM | U2: 11AM - 3PM | V2: 3PM - 6PM | W2: 6PM - 11PM | X2: 11PM-7AM
A3: Dec 30 - Jan 05 2025
A4: Jan 06 - Jan 12 2025
A5: Jan 13 - Jan 19 2025
A6: Jan 20 - Jan 26 2025
A7: Jan 27 - Feb 02 2025
A8: Feb 03 - Feb 09 2025 | C8: 10469.7 | D8: 7217.26 | E8: 33.6 | F8: 135.6 | G8: 3083.24 | H8: 4926.66 | I8: 0 | J8: 0 | K8: 2290.6 | L8: 3252.44 | M8: 10469.7 | N8: 398.7 | O8: 10031.5 | Q8: 39.5 | S8: 10469.7
