Workbook

Sheet Highway
A1: Statement For Selected Period | C1: Total Revenue | G1: 2021 | I1: 2022 | K1: 2023
A2: August 28 2023 - September 3 2023 | C2: 19246.99 | G2: January | I2: January | J2: 18130.06 | K2: January | L2: 63461.24
A3: September 4 2023 - September 10 2023 | C3: 14356.63 | G3: February | I3: February | J3: 39412.26 | K3: February | L3: 56826.84
A4: September 11 2023 - September 17 2023 | C4: 13870.89 | G4: March | I4: March | J4: 66452.65 | K4: March | L4: 54406.31
A5: September 18 2023 - September 24 2023 | C5: 14354.51 | G5: April | I5: April | J5: 63986.87 | K5: April | L5: 87441.54
A6: September 25 2023 - October 1 2023 | C6: 11876.87 | G6: May | I6: May | J6: 80342.74 | K6: May | L6: 71540.19
A7: October 2 2023 - October 8 2023 | C7: 15468 | G7: June | I7: June | J7: 69278.77 | K7: June | L7: 80490.19
A8: October 9 2023 - October 15 2023 | C8: 14791.27 | G8: July | H8: 29200.29 | I8: July | J8: 93630.05 | K8: July | L8: 80901.93
A9: October 16 2023 - October 22 2023 | C9: 13591.26 | G9: August | H9: 29200.29 | I9: August | J9: 89897.43 | K9: August | L9: 78025.38
A10: October 23 2023 - October 29 2023 | C10: 13390.93 | G10: September | H10: 38093.04 | I10: September | J10: 81288.88 | K10: September | L10: 65349.57
A11: October 30 2023 - November 5 2023 | C11: 14787.15 | G11: October | H11: 43748.26 | I11: October | J11: 80599.73 | K11: October | L11: 62182.59
A12: November 6 2023 - November 12 2023 | C12: 11788.3 | G12: November | H12: 57688.09 | I12: November | J12: 47414.18 | K12: November
A13: November 13 2023 - November 19 2023 | C13: 12920.71 | G13: December | H13: 49551.8 | I13: December | J13: 70946.08 | K13: December
A14: November 20 2023 - November 26 2023 | C14: 15064.65
A15: November 27 2023 - December 03 2024 | C15: 14390.04
A16: December 04 2023 - December 10 2024 | C16: 13466.62
A17: December 11 2023 - December 17 2024 | C17: 14152.59
A18: December 18 2023 - December 24 2024 | C18: 16836.46
A19: December 25 2023 - December 31 2024 | C19: 24926.22
A20: Jan 1 - Jan 07 2024 | C20: 17046.54
A21: Jan 8 - Jan 14 2024 | C21: 11512.96
A22: Jan 15 - Jan 21 2024 | C22: 11871.2
A23: Jan 22 - Jan 28 2025 | C23: 12831.63
A24: Jan 29 - Feb 04 2026 | C24: 12981.55
A25: Feb 05 - Feb 11 2026 | C25: 11512.96
... A66: Nov 18 - Nov 24 2024 | C66: 11890.27
A67: Nov 25 - Dec 01 2024 | C67: 14674.88 | F67: In-Store | G67: Skip | H67: DD | I67: Uber (TB) | J67: Uber Website
A68: Dec 02 - Dec 08 2024 | C68: 13074.02
A69: Dec 09 - Dec 15 2024 | C69: 13673.26 | M69: =SUM(M70:M71) -> 2641.62
A70: Dec 16 - Dec 22 2024 | C70: 14020.88 | K70: 3682.96 | L70: 1516.54 | M70: =K70-L70 -> 2166.42
A71: Dec 23 - Dec 29 2024 | C71: 22334.02 | F71: =SUM(C71-(I71+G71+H71)) -> 17858.33 | G71: 167.98 | H71: 72.54 | I71: 4235.17 | K71: 756.52 | L71: 281.32 | M71: =K71-L71 -> 475.2
A72: Dec 30 - Jan 05 2025 | C72: 18755.59 | F72: =SUM(C72-(I72+G72+H72)) -> 14841.51 | G72: 64.78 | H72: 7.2 | I72: 3842.1
A73: Jan 06 - Jan 12 2025 | C73: 13898.98 | F73: In-Store | G73: Skip | H73: DD | I73: Uber (TB) | J73: Uber Website | L73: Highway Uber | M73: Pizza Highway Uber
A74: Jan 13 - Jan 19 2025 | C74: 14787.59 | F74: 12005.1 | G74: 79.13 | H74: 61.74 | I74: 4393.88 | J74: 2641.62 | K74: =SUM(F74,G74,H74,J74) -> 14787.59
A75: Jan 20 - Jan 26 2025 | C75: 13933.15 | F75: 10361.99 | G75: 184.76 | H75: 137.97 | I75: 4864.51 | J75: =SUM(L75:M75) -> 3248.43 | K75: =SUM(F75,G75,H75,J75) -> 13933.15 | L75: 805.91 | M75: 2442.52
A76: Jan 27 - Feb 02 2025 | C76: 13637.18 | F76: 10759.87 | G76: 0 | H76: 84 | I76: 2793.31 | J76: =SUM(L76:M76) -> 3293.25 | K76: =SUM(F76,G76,H76,J76) -> 14137.12 | L76: 787.96 | M76: 2505.29
A77: Feb 03 - Feb 09 2025 | C77: 11683.72 | F77: 9636.07 | G77: 155.86 | H77: 19.17 | I77: 2050.41 | J77: =SUM(L77:M77) -> 1872.62 | K77: =SUM(F77,G77,H77,J77) -> 11683.72 | L77: 196.93 | M77: 1675.69
A78: Feb 10 - Feb 16 2025 | C78: 12823.09 | F78: 10552.83 | G78: 103.06 | H78: 34.5 | I78: 2570.83 | J78: =SUM(L78:M78) -> 2132.7 | K78: =SUM(F78,G78,H78,J78) -> 12823.09 | L78: 932.29 | M78: 1200.41
A79: Feb 17 - Feb 23 2025 | C79: 13647.35 | F79: 11974.8 | G79: 157.5 | H79: 41.68 | I79: 1670.92 | J79: =SUM(L79:M79) -> 1473.37 | K79: =SUM(F79,G79,H79,J79) -> 13647.35 | L79: 483.5 | M79: 989.87
A80: Feb 24 - Mar 02 2025 | C80: 11761.23 | F80: 10244.94 | G80: 185.6 | H80: 0 | I80: 1589.93 | J80: =SUM(L80:M80) -> 1330.69 | K80: =SUM(F80,G80,H80,J80) -> 11761.23 | L80: 247.92 | M80: 1082.77
...

Sheet Kababwala
A1: Statement For Selected Period | C1: Total Revenue | H1: 2021 | K1: 2023
A2: August 28 2023 - September 3 2023 | C2: 18907.64 | H2: January | I2: 74079.49 | J2: 87281.23 | K2: January | N2: 69403.69
A3: September 4 2023 - September 10 2023 | C3: 16117.29 | H3: February | I3: 68100.95 | J3: 63034.51 | K3: February | N3: 62943.14 | O3: 384
A4: September 11 2023 - September 17 2023 | C4: 13973.31 | H4: March | I4: 77326.19 | J4: 64569.19 | K4: March | N4: 69917.17 | O4: 6412.27
A5: September 18 2023 - September 24 2023 | C5: 15058.21 | H5: April | I5: 74335 | J5: 66704.55 | K5: April | N5: 85521.5 | O5: 3821.88
A6: September 25 2023 - October 1 2023 | C6: 14752.34 | H6: May | I6: 101590.8 | J6: 86171.39 | K6: May | N6: 78013.1 | O6: 4152
A7: October 2 2023 - October 8 2023 | C7: 16461.74 | H7: June | I7: 77714.7 | J7: 78073.55 | K7: June | N7: 88939.31 | O7: 2856
A8: October 9 2023 - October 15 2023 | C8: 15751.3 | H8: July | I8: 91085.51 | J8: 98373.87 | K8: July | N8: 95569.19 | O8: 2237.6
A9: October 16 2023 - October 22 2023 | C9: 14944.6 | H9: August | I9: 80633.19 | J9: 77958.51 | K9: August | N9: 83798.18 | O9: 4480
A10: October 23 2023 - October 29 2023 | C10: 15238.49 | H10: September | I10: 75143.44 | J10: 76305.52 | K10: September | N10: 68745.39 | O10: 3384
A11: October 30 2023 - November 5 2023 | C11: 16537.96 | H11: October | I11: 83713.46 | J11: 82557.77 | K11: October | N11: 67822.85 | O11: 3832
A12: November 6 2023 - November 12 2023 | C12: 16254.22 | H12: November | I12: 70757.44 | J12: 76685.89 | K12: November
A13: November 13 2023 - November 19 2023 | C13: 16419.73 | H13: December | I13: 92026.07 | J13: 84136.76 | K13: December
A14: November 20 2023 - November 26 2023 | C14: 16688.44
A15: November 27 2023 - December 03 2024 | C15: 14806.91
A17: December 04 2023 - December 10 2024 | C17: 14923.3
A18: December 11 2023 - December 17 2024 | C18: 14084.19
A19: December 18 2023 - December 24 2024 | C19: 17814.62
A20: December 25 2023 - December 31 2024 | C20: 19192.27
A21: Jan 1 - Jan 07 2024 | C21: 14988.73
A22: Jan 8 - Jan 14 2024 | C22: 10837.15
A23: Jan 15 - Jan 21 2024 | C23: 13313.4
A24: Jan 22 - Jan 28 2025 | C24: 12023.55
A25: Jan 29 - Feb 04 2026 | C25: 11182.05
A26: Feb 05 - Feb 11 2026 | C26: 10837.15
... A40: May 13 - May 19 2024 | C40: 14598.85
A41: May 20 - May 26 2024 | C41: $13,235.24 + $2,003.04 = 15,238.28
A42: May 27 - Jun 02 2024 | C42: 15801.56
A43: Jun 03 - Jun 09 2024 | C43: 13718.57
A44: Jun 10 - Jun 16 2024 | C44: 16076.79
A45: Jun 17 - Jun 23 2024 | C45: 16021.38
A46: Jun 24 - Jun 30 2024 | C46: 16792.57
A47: Jul 1 - Jul 7 2024 | C47: 17314.17
A48: Jul 8 - Jul 14 2024 | C48: 15062.86
A49: Jul 15 - Jul 21 2024 | C49: =14363.75+1000 -> 15363.75
A50: Jul 22 - Jul 28 2024 | C50: 15367.46
A51: Jul 29 - Aug 04 2024 | C51: 16876.78
A52: Aug 05 - Aug 11 2024 | C52: 16542.52
A53: Aug 12 - Aug 18 2024 | C53: 15998.15
A54: Aug 19 - Aug 25 2024 | C54: 14843.19
...

Sheet Pizza K Heartland
A1: Statement For Selected Period | C1: Total Revenue | I1: 2021 | K1: 2022 | O1: 2023
A2: August 28 2023 - September 3 2023 | C2: 26049.7 | I2: January | K2: January | O2: January
A3: September 4 2023 - September 10 2023 | C3: 22729.95 | I3: February | K3: February | O3: February
A4: September 11 2023 - September 17 2023 | C4: 19150.68 | I4: March | K4: March | O4: March
A5: September 18 2023 - September 24 2023 | C5: 20976.15 | I5: April | K5: April | O5: April
A6: September 25 2023 - October 1 2023 | C6: 19281.47 | I6: May | K6: May | O6: May
A7: October 2 2023 - October 8 2023 | C7: 21980.84 | I7: June | K7: June | O7: June
A8: October 9 2023 - October 15 2023 | C8: 22217.19 | I8: July | K8: July | O8: July
A9: October 16 2023 - October 22 2023 | C9: 20227.23 | I9: August | K9: August | O9: August
A10: October 23 2023 - October 29 2023 | C10: 21580.85 | I10: September | K10: September | O10: September
A11: October 30 2023 - November 5 2023 | C11: 21160.1 | I11: October | K11: October | O11: October
A12: November 6 2023 - November 12 2023 | C12: 21675.23 | I12: November | K12: November | O12: November
A13: November 13 2023 - November 19 2023 | C13: 21532.99 | I13: December | K13: December | O13: December
A14: November 20 2023 - November 26 2023 | C14: 21351.69
A15: November 27 2023 - December 03 2024 | C15: 18942.47
A16: December 04 2023 - December 10 2024 | C16: 18663.72
A17: December 11 2023 - December 17 2024 | C17: 17784.97
A18: December 18 2023 - December 24 2024 | C18: 20137.82
A19: December 25 2023 - December 31 2024 | C19: 29483.6
A20: Jan 1 - Jan 07 2024 | C20: 19057.18
A21: Jan 8 - Jan 14 2024 | C21: 16748.41
A22: Jan 15 - Jan 21 2024 | C22: 17827.58
A23: Jan 22 - Jan 28 2025 | C23: 15105.89
A24: Jan 29 - Feb 04 2026 | C24: 15592.57
A25: Feb 05 - Feb 11 2026 | C25: 15907.12
... A33: Apr 1 - Apr 07 2024 | C33: 16391.15
A34: Apr 8 - Apr 14 2024 | C34: 21,423.57
A35: Apr 15 - Apr 21 2024 | C35: 16814.71
A36: Apr 22 - Apr 28 2024 | C36: 14692.87
A37: Apr 29 - May 5 2024 | C37: 16252.68
A38: May 6 - May 12 2024 | C38: 14728.67
A39: May 13 - May 19 2024 | C39: 16675.46
A40: May 20 - May 26 2024 | C40: 15420.47
A41: May 27 - Jun 02 2024 | C41: 15964.98
A42: Jun 03 - Jun 09 2024 | C42: 16516.16
A43: Jun 10 - Jun 16 2024 | C43: 17167.97
A44: Jun 17 - Jun 23 2024 | C44: 17725.56
A45: Jun 24 - Jun 30 2024 | C45: 19207.7
A46: Jul 1 - Jul 7 2024 | C46: 18274.48
... A64: Nov 4 - Nov 10 2024 | C64: 15474.42
...

Sheet Pizza K Eglinton
A1: Statement For Selected Period | C1: Total Revenue | G1: 2021 | I1: 2022 | K1: 2023
A6: July 3 2023 - Jul 9 2023
A7: July 10 2023 - Jul 16 2023
A8: July 17 2023 - Jul 23 2023
A9: July 24 2023 - Jul 30 2023
A10: July 31 2023 - Aug 6 2023
A11: Aug 7 2023 - Aug 13 2023
A12: Aug 14 2023 - Aug 20 2023
A13: Aug 21 2023 - Aug 27 2023
A14: August 28 2023 - September 3 2023 | G14: January | I14: January | K14: January
A15: September 4 2023 - September 10 2023 | C15: 35828.04 | G15: February | I15: February | K15: February
A16: September 11 2023 - September 17 2023 | C16: 32800.14 | G16: March | I16: March | K16: March
A17: September 18 2023 - September 24 2023 | C17: 32570.58 | G17: April | I17: April | K17: April
A18: September 25 2023 - October 1 2023 | C18: 31003.05 | G18: May | I18: May | K18: May
A19: October 2 2023 - October 8 2023 | C19: 33502.67 | G19: June | I19: June | K19: June
A20: October 9 2023 - October 15 2023 | C20: 33884.25 | G20: July | I20: July | K20: July
A21: October 16 2023 - October 22 2023 | C21: 32268.41 | G21: August | I21: August | K21: August
A22: October 23 2023 - October 29 2023 | C22: 30896.17 | G22: September | I22: September | K22: September
A23: October 30 2023 - November 5 2023 | C23: 32576.91 | G23: October | I23: October | K23: October
A24: November 6 2023 - November 12 2023 | C24: 33068.93 | G24: November | I24: November | K24: November
A25: November 13 2023 - November 19 2023 | C25: 31608.72 | G25: December | I25: December | K25: December
A26: November 20 2023 - November 26 2023 | C26: 33190.03
A27: November 27 2023 - December 03 2024 | C27: 28202.06
A28: December 04 2023 - December 10 2024 | C28: 27415.28
A29: December 11 2023 - December 17 2024 | C29: 27243.43
A30: December 18 2023 - December 24 2024 | C30: 32192.08
A31: December 25 2023 - December 31 2024 | C31: 49259.55
A32: Jan 1 - Jan 07 2024 | C32: 34128.44
A33: Jan 8 - Jan 14 2024 | C33: 24621.42
A34: Jan 15 - Jan 21 2024 | C34: 26885.29
A35: Jan 8 - Jan 14 2024 | C35: 24621.42
A36: Jan 15 - Jan 21 2024 | C36: 26885.29
A37: Jan 22 - Jan 28 2025 | C37: 26012.71
A38: Jan 29 - Feb 04 2026 | C38: 28448.32 | J38: Food ordering review
A39: Feb 05 - Feb 11 2026 | C39: 27376.4 | J39: scheduling
A40: Feb 12 - Feb 18 2024 | C40: 29073.36 | J40: store 1 hr both stores
A41: Feb 19 - Feb 25 2024 | C41: 30876.28
A42: Feb 26 - Mar 03, 2024 | C42: 26034.34
A43: Mar 04 - Mar 10, 2024 | C43: 28154.72
A44: Mar 11 - Mar 17, 2024 | C44: 22169.44
...

Sheet Karachi Food Court
A1: Statement For Selected Period | C1: Total Revenue | H1: 2023
A2: August 28 2023 - September 3 2023 | H2: January
A3: September 4 2023 - September 10 2023 | H3: February
A4: September 11 2023 - September 17 2023 | C4: 19936.98 | H4: March
A5: September 18 2023 - September 24 2023 | C5: 26303.86 | H5: April
A6: September 25 2023 - October 1 2023 | C6: 26748.71 | H6: May
A7: October 2 2023 - October 8 2023 | C7: 27040.61 | H7: June
A8: October 9 2023 - October 15 2023 | C8: 23879.31 | H8: July
A9: October 16 2023 - October 22 2023 | C9: 22117.11 | H9: August
A10: October 23 2023 - October 29 2023 | C10: 23843.55 | H10: September
A11: October 30 2023 - November 5 2023 | C11: 21104.57 | H11: October
A12: November 6 2023 - November 12 2023 | C12: 24501.77 | H12: November
A13: November 13 2023 - November 19 2023 | C13: 24352.37 | H13: December
A14: November 20 2023 - November 26 2023 | C14: 26183.71
A15: November 27 2023 - December 03 2024 | C15: 22082.62
A16: December 04 2023 - December 10 2024 | C16: 25238.83
A17: December 11 2023 - December 17 2024 | C17: 20086.32
A18: December 18 2023 - December 24 2024 | C18: 23791.89
A19: December 25 2023 - December 31 2024 | C19: 44516.8
A20: Jan 1 - Jan 07 2024 | C20: 21563.55
A21: Jan 8 - Jan 14 2024 | C21: 17092.53
A22: Jan 15 - Jan 21 2024 | C22: 9587.8
A23: Jan 22 - Jan 28 2025 | C23: 20279.16
A24: Jan 29 - Feb 04 2026 | C24: 19566.21
A25: Feb 05 - Feb 11 2026 | C25: 19072.64
... A69: Dec 09 - Dec 15 2024 | C69: 37559.1
A70: Dec 16 - Dec 22 2024 | C70: 43475.56 | D70: Bill Count | E70: TB Total | F70: In Store | G70: Skip | H70: DD | I70: Uber TB | J70: FC Rev | K70: FC Marketing | L70: Chickentarian Rev | M70: Chickentarian Marketing | N70: Smash Rev | O70: Smash Marketing | P70: Uber (After Discount) | Q70: Total Revenue
A71: Dec 23 - Dec 29 2024 | C71: 89842.47 | F71: =C71-(I71+G71+H71) -> 85670.25 | G71: 174.68 | H71: 971.89 | I71: 3025.65
A72: Dec 30 - Jan 05 2025 | C72: 77438.75 | F72: =C72-(I72+G72+H72) -> 74012.65 | G72: 421.45 | H72: 171.72 | I72: 2832.93
A73: Jan 06 - Jan 12 2025 | C73: 39667.86
A74: Jan 13 - Jan 19 2025 | C74: 44859.21 | F74: 41435.41 | G74: 210.42 | H74: 346.95 | I74: 2866.43 | J74: 2750.28
A75: Jan 20 - Jan 26 2025 | C75: 44159.58 | F75: 41486.14 | G75: 380.65 | H75: 43.38 | I75: 2249.41
A76: Jan 27 - Feb 02 2025 | C76: 41432.64 | F76: 38186.99 | G76: 362.55 | H76: 433.19 | I76: 2449.91
A77: Feb 03 - Feb 09 2025 | C77: 42408.88 | F77: 39376.72 | G77: 240.13 | H77: 186.2 | I77: 2605.83
A78: Feb 10 - Feb 16 2025 | C78: 38328.99 | F78: 36670.19 | G78: 169.34 | H78: 37.47 | I78: 1451.99
A79: Feb 17 - Feb 23 2025 | C79: 55100.66 | F79: 51373.3 | G79: 344.81 | H79: 76.09 | I79: 3306.46
A80: Feb 24 - Mar 02 2025 | C80: 38257.93 | F80: 35952.52 | G80: 274.03 | H80: 23.38 | I80: 2008
A81: Mar 03 - Mar 09 2025 | C81: 43531.99 | F81: 39887.7 | G81: 219.35 | H81: 234.34 | I81: 3190.6
A82: Mar 10 - Mar 16 2025 | C82: 59192.5 | F82: 56306.62 | G82: 306.77 | H82: 110.65 | I82: 2509.93 | J82: 2617.51 | K82: 149.05 | P82: =(J82-K82) -> 2468.46 | Q82: =SUM(F82,G82,H82,P82) -> 59192.5
A83: Mar 17 - Mar 23 2025 | C83: 56656.53 | F83: 52209.01 | G83: 254.79 | H83: 80.97 | I83: 4481.31 | J83: 4427.92 | K83: 316.16 | P83: =(J83-K83) -> 4111.76 | Q83: =SUM(F83,G83,H83,P83) -> 56656.53
...

Sheet Markham
A1: Markham
A2: Statement For Selected Period | B2: Total Revenue (Net Sales) | C2: Royalties (6%) | D2: Marketing (2%)
A3: December 18 2023 - December 24 2024 | B3: 4640.56 | C3: =B3*0.06 -> 278.4336 | D3: =B3*0.02 -> 92.8112
A4: December 25 2023 - December 31 2024 | B4: 12060.9 | C4: =B4*0.06 -> 723.654 | D4: =B4*0.02 -> 241.218
A5: Jan 1 - Jan 07 2024 | B5: 11251.81 | C5: =B5*0.06 -> 675.1086 | D5: =B5*0.02 -> 225.0362
A6: Jan 8 - Jan 14 2024 | B6: 8547.71 | C6: =B6*0.06 -> 512.8626 | D6: =B6*0.02 -> 170.9542
A7: Jan 15 - Jan 21 2024 | B7: 10272.1 | C7: =B7*0.06 -> 616.326 | D7: =B7*0.02 -> 205.442
A8: Jan 22 - Jan 28 2024 | B8: 11991.64 | C8: =B8*0.06 -> 719.4984 | D8: =B8*0.02 -> 239.8328
A9: Jan 29 - Feb 04 2024 | B9: 10169.08 | C9: =B9*0.06 -> 610.1448 | D9: =B9*0.02 -> 203.3816
A10: Feb 05 - Feb 11 2024 | B10: 10185.83 | C10: =B10*0.06 -> 611.1498 | D10: =B10*0.02 -> 203.7166
A11: Feb 12 - Feb 18 2024 | B11: 9415.22 | C11: =B11*0.06 -> 564.9132 | D11: =B11*0.02 -> 188.3044
A12: Feb 19 - Feb 25 2024 | B12: 10664.05 | C12: =B12*0.06 -> 639.843 | D12: =B12*0.02 -> 213.281
A13: Feb 26 - Mar 03, 2024 | B13: 10643.55 | C13: =B13*0.06 -> 638.613 | D13: =B13*0.02 -> 212.871
A14: Mar 04 - Mar 10, 2024 | B14: 8627.64 | C14: =B14*0.06 -> 517.6584 | D14: =B14*0.02 -> 172.5528
... A20: Apr 15 - Apr 21 2024 | B20: 9134.63 | C20: =B20*0.06 -> 548.0778 | D20: =B20*0.02 -> 182.6926
A21: Apr 22 - Apr 28 2024 | B21: 9378.85 | C21: =(B21*0.06)*1.13 -> 635.88603 | D21: =(B21*0.02)*1.13 -> 211.96201
A22: Apr 29 - May 5 2024 | B22: 8840.32 | C22: =(B22*0.06)*1.13 -> 599.3737 | D22: =(B22*0.02)*1.13 -> 199.79123
A23: May 6 - May 12 2024 | B23: 9831.2 | C23: =(B23*0.06)*1.13 -> 666.55536 | D23: =(B23*0.02)*1.13 -> 222.18512
A24: May 13 - May 19 2024 | B24: 10206.77 | C24: =(B24*0.06)*1.13 -> 692.01901 | D24: =(B24*0.02)*1.13 -> 230.673
A25: May 20 - May 26 2024 | B25: 12184.27 | C25: =(B25*0.06)*1.13 -> 826.09351 | D25: =(B25*0.02)*1.13 -> 275.3645
A26: May 27 - Jun 02 2024 | B26: 11920.02 | C26: =(B26*0.06)*1.13 -> 808.17736 | D26: =(B26*0.02)*1.13 -> 269.39245
A27: Jun 03 - Jun 09 2024 | B27: 13116.63 | C27: =(B27*0.06)*1.13 -> 889.30751 | D27: =(B27*0.02)*1.13 -> 296.43584
A28: Jun 10 - Jun 16 2024 | B28: 12257.18 | C28: =(B28*0.06)*1.13 -> 831.0368 | D28: =(B28*0.02)*1.13 -> 277.01227
A29: Jun 17 - Jun 23 2024 | B29: 13754.28 | C29: =(B29*0.06)*1.13 -> 932.54018 | D29: =(B29*0.02)*1.13 -> 310.84673
A30: Jun 24 - Jun 30 2024 | B30: 12247.99 | C30: =(B30*0.06)*1.13 -> 830.41372 | D30: =(B30*0.02)*1.13 -> 276.80457
A31: Jul 1 - Jul 7 2024 | B31: =13152.46-1164.26 -> 11988.2 | C31: =(B31*0.06)*1.13 -> 812.79996 | D31: =(B31*0.02)*1.13 -> 270.93332
A32: Jul 8 - Jul 14 2024 | B32: 11665.99 | C32: =(B32*0.06)*1.13 -> 790.95412 | D32: =(B32*0.02)*1.13 -> 263.65137
A33: Jul 15 - Jul 21 2024 | B33: 11814.15 | C33: =(B33*0.06)*1.13 -> 800.99937 | D33: =(B33*0.02)*1.13 -> 266.99979
A34: Jul 22 - Jul 28 2024 | B34: 11963.75 | C34: =(B34*0.06)*1.13 -> 811.14225 | D34: =(B34*0.02)*1.13 -> 270.38075
A35: Jul 29 - Aug 04 2024 | B35: 12977.57 | C35: =(B35*0.06)*1.13 -> 879.87925 | D35: =(B35*0.02)*1.13 -> 293.29308
A36: Aug 05 - Aug 11 2024 | B36: 13094.69 | C36: =(B36*0.06)*1.13 -> 887.81998 | D36: =(B36*0.02)*1.13 -> 295.93999
A37: Aug 12 - Aug 18 2024 | B37: 13216.82 | C37: =(B37*0.06)*1.13 -> 896.1004 | D37: =(B37*0.02)*1.13 -> 298.70013
A38: Aug 19 - Aug 25 2024 | B38: 12088.66 | C38: =(B38*0.06)*1.13 -> 819.61115 | D38: =(B38*0.02)*1.13 -> 273.20372
A39: Aug 26 - Sep 01 2024 | B39: 13164.76 | C39: =(B39*0.06)*1.13 -> 892.57073 | D39: =(B39*0.02)*1.13 -> 297.52358
A40: Sep 02 - Sep 08 2024 | B40: 13465.82 | C40: =(B40*0.06)*1.13 -> 912.9826 | D40: =(B40*0.02)*1.13 -> 304.32753
A41: Sep 09 - Sep 15 2024 | B41: 12064.43 | C41: =(B41*0.06)*1.13 -> 817.96835 | D41: =(B41*0.02)*1.13 -> 272.65612
A42: Sep 16 - Sep 22 2024 | B42: 13132.43 | C42: =(B42*0.06)*1.13 -> 890.37875 | D42: =(B42*0.02)*1.13 -> 296.79292
A43: Sep 23 - Sep 29 2024 | B43: 12136.79 | C43: =(B43*0.06)*1.13 -> 822.87436 | D43: =(B43*0.02)*1.13 -> 274.29145
... A53: Dec 02 - Dec 08 2024 | B53: 10374.78 | C53: =(B53*0.06)*1.13 -> 703.41008 | D53: =(B53*0.02)*1.13 -> 234.47003
A54: Dec 09 - Dec 15 2024 | B54: 10277.44 | C54: =(B54*0.06)*1.13 -> 696.81043 | D54: =(B54*0.02)*1.13 -> 232.27014 | E54: Bill Count | F54: TB Total | G54: In Store | H54: Skip | I54: DD | J54: Uber TB | K54: Uber Website | L54: Marketing | M54: Uber Total | N54: Total
...

Sheet Jane
A1: Wonderland
A2: Statement For Selected Period | B2: Total Revenue (Net Sales) | C2: Royalties (6%) | D2: Marketing (2%)
A3: Aug 12 - Aug 18 2024 | B3: 2155.81 | C3: =(B3*0.06)*1.13 -> 146.16392 | D3: =(B3*0.02)*1.13 -> 48.721306
A4: Aug 19 - Aug 25 2024 | B4: 8077.84 | C4: =(B4*0.06)*1.13 -> 547.67755 | D4: =(B4*0.02)*1.13 -> 182.55918
A5: Aug 26 - Sep 01 2024 | B5: 11929.59 | C5: =(B5*0.06)*1.13 -> 808.8262 | D5: =(B5*0.02)*1.13 -> 269.60873
A6: Sep 02 - Sep 08 2024 | B6: 8374.32 | C6: =(B6*0.06)*1.13 -> 567.7789 | D6: =(B6*0.02)*1.13 -> 189.25963
A7: Sep 09 - Sep 15 2024 | B7: 8953.43 | C7: =(B7*0.06)*1.13 -> 607.04255 | D7: =(B7*0.02)*1.13 -> 202.34752
A8: Sep 16 - Sep 22 2024 | B8: 9370.37 | C8: =(B8*0.06)*1.13 -> 635.31109 | D8: =(B8*0.02)*1.13 -> 211.77036
A9: Sep 23 - Sep 29 2024 | B9: 11456.84 | C9: =(B9*0.06)*1.13 -> 776.77375 | D9: =(B9*0.02)*1.13 -> 258.92458
A10: Sep 30 - Oct 06 2024 | B10: 11124.69 | C10: =(B10*0.06)*1.13 -> 754.25398 | D10: =(B10*0.02)*1.13 -> 251.41799
A11: Oct 07 - Oct 13 2024 | B11: 9620.03 | C11: =(B11*0.06)*1.13 -> 652.23803 | D11: =(B11*0.02)*1.13 -> 217.41268
A12: Oct 14 - Oct 20 2024 | B12: 11409.59 | C12: =(B12*0.06)*1.13 -> 773.5702 | D12: =(B12*0.02)*1.13 -> 257.85673
A13: Oct 21 - Oct 27 2024 | B13: 11377.48 | C13: =(B13*0.06)*1.13 -> 771.39314 | D13: =(B13*0.02)*1.13 -> 257.13105
A14: Oct 28 - Nov 03 2024 | B14: 9556.77 | C14: =(B14*0.06)*1.13 -> 647.94901 | D14: =(B14*0.02)*1.13 -> 215.983
... A19: Dec 02 - Dec 08 2024 | B19: 6573.21 | C19: =(B19*0.06)*1.13 -> 445.66364 | D19: =(B19*0.02)*1.13 -> 148.55455
A20: Dec 09 - Dec 15 2024 | B20: 7432.33 | C20: =(B20*0.06)*1.13 -> 503.91197 | D20: =(B20*0.02)*1.13 -> 167.97066 | E20: Bill Count | F20: TB Total | G20: In Store | H20: Skip | I20: DD | J20: Uber TB | K20: Uber Website | L20: Marketing/Discount | M20: Smash Ox Rev | N20: Smash Ox Marketing | O20: Uber (After Discount) | P20: Total Revenue
A21: Dec 16 - Dec 22 2024 | B21: 7909.19 | C21: =(B21*0.06)*1.13 -> 536.24308 | D21: =(B21*0.02)*1.13 -> 178.74769 | G21: 5772.68 | H21: 98.74 | I21: 163.2 | J21: 2815.1 | K21: 2815.1 | L21: 940.53 | O21: =K21-L21 -> 1874.57 | P21: =SUM(O21,I21,H21,G21) -> 7909.19
C22: =(B22*0.06)*1.13 -> 0 | D22: =(B22*0.02)*1.13 -> 0 | J22: 65 orders | K22: 65 orders
A23: Dec 23 - Dec 29 2024 | B23: 11818.28 | C23: =(B23*0.06)*1.13 -> 801.27938 | D23: =(B23*0.02)*1.13 -> 267.09313 | G23: 8559.6 | H23: 22.8 | I23: 111.89 | J23: 4752.48 | K23: 4752.48 | L23: =1625.79+2.7 -> 1628.49 | O23: =K23-L23 -> 3123.99 | P23: =SUM(O23,I23,H23,G23) -> 11818.28
C24: =(B24*0.06)*1.13 -> 0 | D24: =(B24*0.02)*1.13 -> 0 | J24: 98 orders | K24: 98 orders
A25: Dec 30 - Jan 05 2025 | B25: 11433.7 | C25: =(B25*0.06)*1.13 -> 775.20486 | D25: =(B25*0.02)*1.13 -> 258.40162 | G25: 8336.8 | H25: 133.19 | I25: 185.69 | J25: 4093.06 | K25: 4131.06 | L25: =1323.94+29.1 -> 1353.04 | O25: =K25-L25 -> 2778.02 | P25: =SUM(G25,H25,I25,O25) -> 11433.7
C26: =(B26*0.06)*1.13 -> 0 | D26: =(B26*0.02)*1.13 -> 0 | J26: 91 orders | K26: 92 orders
A27: Jan 06 - Jan 12 2025 | B27: 7060.74 | C27: =(B27*0.06)*1.13 -> 478.71817 | D27: =(B27*0.02)*1.13 -> 159.57272 | G27: 4933.67 | H27: 22.8 | I27: 125.37 | J27: 2770.9 | K27: 2770.9 | L27: 792 | O27: =K27-L27 -> 1978.9 | P27: =SUM(G27,H27,I27,O27) -> 7060.74
C28: =(B28*0.06)*1.13 -> 0 | D28: =(B28*0.02)*1.13 -> 0 | J28: 58 | K28: 58
A29: Jan 13 - Jan 19 2025 | B29: 9149.74 | C29: =(B29*0.06)*1.13 -> 620.35237 | D29: =(B29*0.02)*1.13 -> 206.78412 | G29: 6642.75 | H29: 78.4 | I29: 31.59 | J29: 2887.05 | K29: 3459 | L29: 1062 | O29: =K29-L29 -> 2397 | P29: =SUM(G29,H29,I29,O29) -> 9149.74
C30: =(B30*0.06)*1.13 -> 0 | D30: =(B30*0.02)*1.13 -> 0
A31: Jan 20 - Jan 26 2025 | B31: 7637.81 | C31: =(B31*0.06)*1.13 -> 517.84352 | D31: =(B31*0.02)*1.13 -> 172.61451 | G31: 5102.85 | H31: 76.67 | I31: 40.8 | J31: 3425.49 | K31: 3461.49 | L31: 1044 | O31: =K31-L31 -> 2417.49 | P31: =SUM(G31,H31,I31,O31) -> 7637.81
C32: =(B32*0.06)*1.13 -> 0 | D32: =(B32*0.02)*1.13 -> 0 | P32: =SUM(G32,H32,I32,O32) -> 0
A33: Jan 27 - Feb 02 2025 | B33: 8956.04 | C33: =(B33*0.06)*1.13 -> 607.21951 | D33: =(B33*0.02)*1.13 -> 202.4065 | G33: 6202.67 | H33: 70.92 | I33: 80.4 | J33: 3824.05 | K33: 3826.05 | L33: 1224 | O33: =K33-L33 -> 2602.05 | P33: =SUM(G33,H33,I33,O33) -> 8956.04
C34: =(B34*0.06)*1.13 -> 0 | D34: =(B34*0.02)*1.13 -> 0
A35: Feb 03 - Feb 09 2025 | B35: 8608.3 | C35: =(B35*0.06)*1.13 -> 583.64274 | D35: =(B35*0.02)*1.13 -> 194.54758 | G35: 6327.3 | H35: 39.87 | I35: 366.28 | J35: 2016.85 | K35: 2018.85 | L35: 144 | O35: =K35-L35 -> 1874.85 | P35: =SUM(G35,H35,I35,O35) -> 8608.3
C36: =(B36*0.06)*1.13 -> 0 | D36: =(B36*0.02)*1.13 -> 0
A37: Feb 10 - Feb 16 2025 | B37: 8833.99 | C37: =(B37*0.06)*1.13 -> 598.94452 | D37: =(B37*0.02)*1.13 -> 199.64817 | G37: 6502.12 | H37: 47.13 | I37: 332.33 | J37: 2035.3 | K37: 2008.9 | L37: 56.49 | O37: =K37-L37 -> 1952.41 | P37: =SUM(G37,H37,I37,O37) -> 8833.99
C38: =(B38*0.06)*1.13 -> 0 | D38: =(B38*0.02)*1.13 -> 0
A39: Feb 17 - Feb 23 2025 | B39: 8500.48 | C39: =(B39*0.06)*1.13 -> 576.33254 | D39: =(B39*0.02)*1.13 -> 192.11085 | G39: 5630.35 | H39: 50.39 | I39: 354.55 | J39: 2530.36 | K39: 2601.02 | L39: 135.83 | O39: =K39-L39 -> 2465.19 | P39: =SUM(G39,H39,I39,O39) -> 8500.48
C40: =(B40*0.06)*1.13 -> 0 | D40: =(B40*0.02)*1.13 -> 0
A41: Feb 24 - Mar 02 2025 | B41: 7690.28 | C41: =(B41*0.06)*1.13 -> 521.40098 | D41: =(B41*0.02)*1.13 -> 173.80033 | G41: 5726.56 | H41: 77.05 | I41: 202.77 | J41: 1745.82 | K41: 1759.01 | L41: 75.11 | O41: =K41-L41 -> 1683.9 | P41: =SUM(G41,H41,I41,O41) -> 7690.28
C42: =(B42*0.06)*1.13 -> 0 | D42: =(B42*0.02)*1.13 -> 0
A43: Mar 03 - Mar 09 2025 | B43: 6502.39 | C43: =(B43*0.06)*1.13 -> 440.86204 | D43: =(B43*0.02)*1.13 -> 146.95401 | G43: 4634.61 | H43: 131.39 | I43: 94.8 | J43: 1659.44 | K43: 1659.44 | L43: 17.85 | O43: =K43-L43 -> 1641.59 | P43: =SUM(G43,H43,I43,O43) -> 6502.39
C44: =(B44*0.06)*1.13 -> 0 | D44: =(B44*0.02)*1.13 -> 0
...

Sheet Ajax
A1: Ajax
A2: Statement For Selected Period | B2: Total Revenue (Net Sales) | C2: Royalties (6%) | D2: Marketing (2%)
A3: Sep 23 - Sep 29 2024 | B3: 4033.49 | C3: =(B3*0.06)*1.13 -> 273.47062 | D3: =(B3*0.02)*1.13 -> 91.156874
A4: Sep 30 - Oct 06 2024 | B4: 9597.76 | C4: =(B4*0.06)*1.13 -> 650.72813 | D4: =(B4*0.02)*1.13 -> 216.90938
A5: Oct 07 - Oct 13 2024 | B5: 11281.14 | C5: =(B5*0.06)*1.13 -> 764.86129 | D5: =(B5*0.02)*1.13 -> 254.95376
A6: Oct 14 - Oct 20 2024 | B6: 11483.19 | C6: =(B6*0.06)*1.13 -> 778.56028 | D6: =(B6*0.02)*1.13 -> 259.52009
A7: Oct 21 - Oct 27 2024 | B7: 11478.83 | C7: =(B7*0.06)*1.13 -> 778.26467 | D7: =(B7*0.02)*1.13 -> 259.42156
A8: Oct 28 - Nov 03 2024 | B8: 9937.88 | C8: =(B8*0.06)*1.13 -> 673.78826 | D8: =(B8*0.02)*1.13 -> 224.59609
A9: Nov 4 - Nov 10 2024 | B9: 10406.88 | C9: =(B9*0.06)*1.13 -> 705.58646 | D9: =(B9*0.02)*1.13 -> 235.19549
A10: Nov 11 - Nov 17 2024 | B10: 9061.93 | C10: =(B10*0.06)*1.13 -> 614.39885 | D10: =(B10*0.02)*1.13 -> 204.79962
A11: Nov 18 - Nov 24 2024 | B11: 9513.59 | C11: =(B11*0.06)*1.13 -> 645.0214 | D11: =(B11*0.02)*1.13 -> 215.00713
A12: Nov 25 - Dec 01 2024 | B12: 9365.94 | C12: =(B12*0.06)*1.13 -> 635.01073 | D12: =(B12*0.02)*1.13 -> 211.67024
A13: Dec 02 - Dec 08 2024 | B13: 9682.96 | C13: =(B13*0.06)*1.13 -> 656.50469 | D13: =(B13*0.02)*1.13 -> 218.8349
A14: Dec 09 - Dec 15 2024 | B14: 11096.12 | C14: =(B14*0.06)*1.13 -> 752.31694 | D14: =(B14*0.02)*1.13 -> 250.77231
A15: Dec 16 - Dec 22 2024 | B15: 10054.79 | C15: =(B15*0.06)*1.13 -> 681.71476 | D15: =(B15*0.02)*1.13 -> 227.23825 | E15: Bill Count | F15: TB Revenue | G15: In-Store | H15: Skip | I15: DD | J15: Uber | K15: Uber Earnings | L15: Uber Marketing | O15: Uber (Total) | P15: Total
A16: Dec 23 - Dec 29 2024 | B16: 15668 | C16: =(B16*0.06)*1.13 -> 1062.2904 | D16: =(B16*0.02)*1.13 -> 354.0968 | G16: 11263.41 | H16: 268.17 | I16: 521.25 | J16: 3615.17
A17: Dec 30 - Jan 05 2025 | B17: 13399.51 | C17: =(B17*0.06)*1.13 -> 908.48678 | D17: =(B17*0.02)*1.13 -> 302.82893 | G17: 9069.76 | H17: 330.15 | I17: 532.78 | J17: 3466.82
A18: Jan 06 - Jan 12 2025 | B18: 9836.76 | C18: =(B18*0.06)*1.13 -> 666.93233 | D18: =(B18*0.02)*1.13 -> 222.31078
A19: Jan 13 - Jan 19 2025 | B19: 9635.01 | C19: =(B19*0.06)*1.13 -> 653.25368 | D19: =(B19*0.02)*1.13 -> 217.75123 | G19: 6684.79 | H19: 284.67 | I19: 358.98 | J19: 2306.57 | O19: 2262 | P19: =SUM(G19:J19) -> 9635.01
A20: Jan 20 - Jan 26 2025 | B20: 10717.23 | C20: =(B20*0.06)*1.13 -> 726.62819 | D20: =(B20*0.02)*1.13 -> 242.2094 | G20: 7891.66 | H20: 394.28 | I20: 355.14 | J20: 2076.15 | O20: 2116.95 | P20: =SUM(G20:J20) -> 10717.23
A21: Jan 27 - Feb 02 2025 | B21: 10695.63 | C21: =(B21*0.06)*1.13 -> 725.16371 | D21: =(B21*0.02)*1.13 -> 241.72124
A22: Feb 03 - Feb 09 2025 | B22: 10607.6 | C22: =(B22*0.06)*1.13 -> 719.19528 | D22: =(B22*0.02)*1.13 -> 239.73176 | F22: 10609.82 | G22: 7389.99 | H22: 278.97 | I22: 407.38 | J22: 2533.48 | K22: 2535.48 | L22: 4.22 | O22: =(K22-L22) -> 2531.26 | P22: =SUM(G22,H22,I22,O22) -> 10607.6
A23: Feb 10 - Feb 16 2025 | B23: 9317.92 | C23: =(B23*0.06)*1.13 -> 631.75498 | D23: =(B23*0.02)*1.13 -> 210.58499 | F23: 9317.92 | G23: 7103.86 | H23: 226.8 | I23: 546.81 | J23: 1440.45 | K23: 1440.45 | L23: 0 | O23: =(K23-L23) -> 1440.45 | P23: =SUM(G23,H23,I23,O23) -> 9317.92
A24: Feb 17 - Feb 23 2025 | B24: 12389.36 | C24: =(B24*0.06)*1.13 -> 839.99861 | D24: =(B24*0.02)*1.13 -> 279.99954 | F24: 12885.05 | G24: 9549.8 | H24: 105.6 | I24: 590.81 | J24: 2638.84 | K24: 2638.84 | L24: 495.69 | O24: =(K24-L24) -> 2143.15 | P24: =SUM(G24,H24,I24,O24) -> 12389.36
A25: Feb 24 - Mar 02 2025 | B25: 9107.42 | C25: =(B25*0.06)*1.13 -> 617.48308 | D25: =(B25*0.02)*1.13 -> 205.82769 | F25: 9312.86 | G25: 6193.36 | H25: 184.66 | I25: 278.48 | J25: 2656.36 | K25: 2745.46 | L25: 294.54 | O25: =(K25-L25) -> 2450.92 | P25: =SUM(G25,H25,I25,O25) -> 9107.42
A26: Mar 03 - Mar 09 2025 | B26: 9346.16 | C26: =(B26*0.06)*1.13 -> 633.66965 | D26: =(B26*0.02)*1.13 -> 211.22322 | F26: 9676.14 | G26: 6082.76 | H26: 128.39 | I26: 259.05 | J26: 3205.94 | K26: 3205.94 | L26: 329.98 | O26: =(K26-L26) -> 2875.96 | P26: =SUM(G26,H26,I26,O26) -> 9346.16
A27: Mar 10 - Mar 16 2025 | B27: 9881.08 | C27: =(B27*0.06)*1.13 -> 669.93722 | D27: =(B27*0.02)*1.13 -> 223.31241 | F27: 10463.53 | G27: 6271.89 | H27: 187.23 | I27: 162.27 | J27: 3842.14 | K27: 3788.14 | L27: 528.45 | O27: =(K27-L27) -> 3259.69 | P27: =SUM(G27,H27,I27,O27) -> 9881.08
A28: Mar 17 - Mar 23 2025 | B28: 9422.94 | C28: =(B28*0.06)*1.13 -> 638.87533 | D28: =(B28*0.02)*1.13 -> 212.95844 | F28: 10033 | G28: 5689.23 | H28: 227.57 | I28: 240.99 | J28: 3875.21 | K28: 3875.21 | L28: 610.06 | O28: =(K28-L28) -> 3265.15 | P28: =SUM(G28,H28,I28,O28) -> 9422.94
A29: Mar 24 - Mar 30 2025 | B29: 12856.63 | C29: =(B29*0.06)*1.13 -> 871.67951 | D29: =(B29*0.02)*1.13 -> 290.55984 | F29: 13331.58 | G29: 8429.27 | H29: 233.38 | I29: 200.17 | J29: 4468.76 | K29: 4496.36 | L29: 502.55 | O29: =(K29-L29) -> 3993.81 | P29: =SUM(G29,H29,I29,O29) -> 12856.63
A30: Mar 31 - Apr 6 2025 | B30: 13777.58 | C30: =(B30*0.06)*1.13 -> 934.11992 | D30: =(B30*0.02)*1.13 -> 311.37331 | F30: 13817.12 | G30: 10277.94 | H30: 176.09 | I30: 345.17 | J30: 3017.92 | K30: 3047.92 | L30: 69.54 | O30: =(K30-L30) -> 2978.38 | P30: =SUM(G30,H30,I30,O30) -> 13777.58
A31: Apr 7 - Apr 13 2025 | B31: 11168.82 | C31: =(B31*0.06)*1.13 -> 757.246 | D31: =(B31*0.02)*1.13 -> 252.41533 | F31: 11390.74 | G31: 7525.76 | H31: 115.58 | I31: 402.91 | K31: 3346.49 | L31: 221.92 | O31: =(K31-L31) -> 3124.57 | P31: =SUM(G31,H31,I31,O31) -> 11168.82
A32: Apr 14 - Apr 20 2025 | B32: 15131.23 | C32: =(B32*0.06)*1.13 -> 1025.8974 | D32: =(B32*0.02)*1.13 -> 341.9658 | G32: 10454.27 | H32: 413.06 | I32: 446.92 | J32: 4077.93 | K32: 4041.93 | L32: 224.95 | O32: =(K32-L32) -> 3816.98 | P32: =SUM(G32,H32,I32,O32) -> 15131.23
A33: Apr 21 - Apr 27 2025 | B33: 12922.11 | C33: =(B33*0.06)*1.13 -> 876.11906 | D33: =(B33*0.02)*1.13 -> 292.03969 | F33: 13129.61 | G33: 8421.13 | H33: 399.99 | I33: 285.49 | J33: 4023 | K33: 4059 | L33: 243.5 | O33: =(K33-L33) -> 3815.5 | P33: =SUM(G33,H33,I33,O33) -> 12922.11
A34: Apr 28 - May 04 2025 | B34: 12067.53 | C34: =(B34*0.06)*1.13 -> 818.17853 | D34: =(B34*0.02)*1.13 -> 272.72618 | G34: 7781.83 | H34: 238.34 | I34: 235.35 | J34: 4046.66 | K34: 4046.66 | L34: 234.65 | O34: =(K34-L34) -> 3812.01 | P34: =SUM(G34,H34,I34,O34) -> 12067.53
A35: May 05 - May 11 2025 | B35: 11958.73 | C35: =(B35*0.06)*1.13 -> 810.80189 | D35: =(B35*0.02)*1.13 -> 270.2673 | F35: 12101.05 | G35: 7982.31 | H35: 198.57 | I35: 318.96 | J35: 3601.21 | K35: 3686.41 | L35: 227.52 | O35: =(K35-L35) -> 3458.89 | P35: =SUM(G35,H35,I35,O35) -> 11958.73
A36: May 12 - May 18 2025 | B36: 11178.71 | C36: =(B36*0.06)*1.13 -> 757.91654 | D36: =(B36*0.02)*1.13 -> 252.63885 | F36: 11438.46 | G36: 8405.86 | H36: 78.4 | I36: 136.06 | J36: 2818.14 | K36: 2746.14 | L36: 187.75 | O36: =(K36-L36) -> 2558.39 | P36: =SUM(G36,H36,I36,O36) -> 11178.71
A37: May 19 - May 25 2025 | B37: 12467.05 | C37: =(B37*0.06)*1.13 -> 845.26599 | D37: =(B37*0.02)*1.13 -> 281.75533 | F37: 12590.84 | G37: 8994.09 | H37: 184.39 | I37: 327.44 | J37: 3084.92 | K37: 3110.13 | L37: 149 | O37: =(K37-L37) -> 2961.13 | P37: =SUM(G37,H37,I37,O37) -> 12467.05
A38: May 26 - June 01 2025 | B38: 11331.89 | C38: =(B38*0.06)*1.13 -> 768.30214 | D38: =(B38*0.02)*1.13 -> 256.10071 | F38: 11570.02 | G38: 7507.73 | H38: 226.8 | I38: 244.58 | J38: 3590.91 | K38: 3592.91 | L38: 240.13 | O38: =(K38-L38) -> 3352.78 | P38: =SUM(G38,H38,I38,O38) -> 11331.89
A39: June 02 - June 08 2025 | B39: 13019.08 | C39: =(B39*0.06)*1.13 -> 882.69362 | D39: =(B39*0.02)*1.13 -> 294.23121 | F39: 13101.38 | G39: 9587.9 | H39: 96.4 | I39: 373.06 | J39: 3044.02 | K39: 3101.91 | L39: 140.19 | O39: =(K39-L39) -> 2961.72 | P39: =SUM(G39,H39,I39,O39) -> 13019.08
A40: June 09 - June 15 2025 | B40: 10681.11 | C40: =(B40*0.06)*1.13 -> 724.17926 | D40: =(B40*0.02)*1.13 -> 241.39309 | F40: 10858.39 | G40: 7482.18 | H40: 146.78 | I40: 419.77 | J40: 2809.66 | K40: 2809.66 | L40: 177.28 | O40: =(K40-L40) -> 2632.38 | P40: =SUM(G40,H40,I40,O40) -> 10681.11
...

Sheet PKQueen
A1: PK Queen St.
A2: Statement For Selected Period | B2: Total Revenue (Net Sales) | C2: Royalties (6%) | D2: Marketing (2%)
A3: Oct 21 - Oct 27 2024 | C3: =(B3*0.06)*1.13 -> 0 | D3: =(B3*0.02)*1.13 -> 0
A4: Oct 28 - Nov 03 2024 | B4: 2261.82 | C4: =(B4*0.06)*1.13 -> 153.3514 | D4: =(B4*0.02)*1.13 -> 51.117132
A5: Nov 4 - Nov 10 2024 | B5: 5128.36 | C5: =(B5*0.06)*1.13 -> 347.70281 | D5: =(B5*0.02)*1.13 -> 115.90094
A6: Nov 11 - Nov 17 2024 | B6: 6350.06 | C6: =(B6*0.06)*1.13 -> 430.53407 | D6: =(B6*0.02)*1.13 -> 143.51136
A7: Nov 18 - Nov 24 2024 | B7: 7297.6 | C7: =(B7*0.06)*1.13 -> 494.77728 | D7: =(B7*0.02)*1.13 -> 164.92576
A8: Nov 25 - Dec 01 2024 | B8: 6278.52 | C8: =(B8*0.06)*1.13 -> 425.68366 | D8: =(B8*0.02)*1.13 -> 141.89455
A9: Dec 02 - Dec 08 2024 | B9: 7318.83 | C9: =(B9*0.06)*1.13 -> 496.21667 | D9: =(B9*0.02)*1.13 -> 165.40556
A10: Dec 09 - Dec 15 2024 | B10: 8909.29 | C10: =(B10*0.06)*1.13 -> 604.04986 | D10: =(B10*0.02)*1.13 -> 201.34995
A11: Dec 16 - Dec 22 2024 | B11: 9881.16 | C11: =(B11*0.06)*1.13 -> 669.94265 | D11: =(B11*0.02)*1.13 -> 223.31422
A12: Dec 23 - Dec 29 2024 | B12: 10740.81 | C12: =(B12*0.06)*1.13 -> 728.22692 | D12: =(B12*0.02)*1.13 -> 242.74231 | G12: 3794.73 | H12: 5063.33 | I12: 172.65 | J12: 1710.1
A13: Dec 30 - Jan 05 2025 | B13: 11526.52 | C13: =(B13*0.06)*1.13 -> 781.49806 | D13: =(B13*0.02)*1.13 -> 260.49935 | G13: 5010.36 | H13: 5289.89 | I13: 137.1 | J13: 1089.17
A14: Jan 06 - Jan 12 2025 | B14: 7725.15 | C14: =(B14*0.06)*1.13 -> 523.76517 | D14: =(B14*0.02)*1.13 -> 174.58839 | G14: In-Store | H14: Skip | I14: DD | J14: Uber (TB) | K14: Uber (Website) | L14: Subtract | M14: Final uber | N14: Total
A15: Jan 13 - Jan 19 2025 | B15: 10708.9 | C15: =(B15*0.06)*1.13 -> 726.06342 | D15: =(B15*0.02)*1.13 -> 242.02114 | G15: 4115.66 | H15: 141.98 | I15: 618.91 | J15: 6167.33 | K15: 6498 | L15: 665.65 | M15: =K15-L15 -> 5832.35 | N15: =SUM(G15,H15,I15,M15) -> 10708.9
A16: Jan 20 - Jan 26 2025 | B16: 9536.83 | C16: =(B16*0.06)*1.13 -> 646.59707 | D16: =(B16*0.02)*1.13 -> 215.53236 | G16: 3288.21 | H16: 360.78 | I16: 922.87 | J16: 5886.81 | K16: 5487.98 | L16: 523.01 | M16: =K16-L16 -> 4964.97 | N16: =SUM(G16,H16,I16,M16) -> 9536.83
A17: Jan 27 - Feb 02 2025 | B17: 10031.3 | C17: =(B17*0.06)*1.13 -> 680.12214 | D17: =(B17*0.02)*1.13 -> 226.70738 | G17: 3134.86 | H17: 116.27 | I17: 892.31 | J17: 6608.49 | K17: 6546.71 | L17: 658.85 | M17: =K17-L17 -> 5887.86 | N17: =SUM(G17,H17,I17,M17) -> 10031.3
C18: =(B18*0.06)*1.13 -> 0 | D18: =(B18*0.02)*1.13 -> 0 | E18: Bill Count | F18: TB Total | G18: In-Store | H18: Skip | I18: DD | J18: Uber (TB) | K18: PK Uber (Rev) | L18: PK Uber (Marketing) | M18: Ox Uber (Rev) | N18: Ox Uber (Marketing) | O18: Chickentarian Uber (Rev) | P18: Chickentarian Uber (Marketing) | Q18: Final Uber | R18: Total
A19: Feb 03 - Feb 09 2025 | B19: 9989.9 | C19: =(B19*0.06)*1.13 -> 677.31522 | D19: =(B19*0.02)*1.13 -> 225.77174 | G19: 3046.85 | H19: 191.24 | I19: 1554.46 | J19: 6048.37 | K19: 5985.12 | L19: 764.08 | M19: 0 | N19: 23.69 | Q19: =((K19-L19)+(M19-N19)) -> 5197.35 | R19: =SUM(G19,H19,I19,Q19) -> 9989.9
A20: Feb 10 - Feb 16 2025 | B20: 10366.24 | C20: =(B20*0.06)*1.13 -> 702.83107 | D20: =(B20*0.02)*1.13 -> 234.27702 | G20: 3813.2 | H20: 258.86 | I20: 1318.63 | J20: 5465.37 | K20: 5711.49 | L20: 726.31 | M20: 0 | N20: 9.63 | Q20: =((K20-L20)+(M20-N20)) -> 4975.55 | R20: =SUM(G20,H20,I20,Q20) -> 10366.24
A21: Feb 17 - Feb 23 2025 | B21: 11016.59 | C21: =(B21*0.06)*1.13 -> 746.9248 | D21: =(B21*0.02)*1.13 -> 248.97493 | G21: 3713.38 | H21: 144.94 | I21: 1470.88 | J21: 6566.33 | K21: 6441.86 | L21: 749.27 | M21: 0 | N21: 5.2 | Q21: =((K21-L21)+(M21-N21)) -> 5687.39 | R21: =SUM(G21,H21,I21,Q21) -> 11016.59
A22: Feb 24 - Mar 02 2025 | B22: 10510.49 | C22: =(B22*0.06)*1.13 -> 712.61122 | D22: =(B22*0.02)*1.13 -> 237.53707 | G22: 3365.12 | H22: 325.87 | I22: 1385.13 | J22: 6210.1 | K22: 6477.34 | L22: 1033.6 | M22: 0 | N22: 9.37 | Q22: =((K22-L22)+(M22-N22)) -> 5434.37 | R22: =SUM(G22,H22,I22,Q22) -> 10510.49
A23: Mar 03 - Mar 09 2025 | B23: 9931.58 | C23: =(B23*0.06)*1.13 -> 673.36112 | D23: =(B23*0.02)*1.13 -> 224.45371 | G23: 2763.72 | H23: 141.2 | I23: 1103.87 | J23: 6882.12 | K23: 6856.92 | L23: 919.06 | M23: 0 | N23: 15.07 | Q23: =((K23-L23)+(M23-N23)) -> 5922.79 | R23: =SUM(G23,H23,I23,Q23) -> 9931.58
A24: Mar 10 - Mar 16 2025 | B24: 10702.22 | C24: =(B24*0.06)*1.13 -> 725.61052 | D24: =(B24*0.02)*1.13 -> 241.87017 | G24: 3579.99 | H24: 241.88 | I24: 1197.78 | J24: 6516.21 | K24: 6558.71 | L24: 857.84 | M24: 0 | N24: 18.3 | Q24: =((K24-L24)+(M24-N24)) -> 5682.57 | R24: =SUM(G24,H24,I24,Q24) -> 10702.22
A25: Mar 17 - Mar 23 2025 | B25: 12097.52 | C25: =(B25*0.06)*1.13 -> 820.21186 | D25: =(B25*0.02)*1.13 -> 273.40395 | G25: 4509.91 | H25: 419.45 | I25: 1168.6 | J25: 7059.11 | K25: 7134.45 | L25: 1110.23 | M25: 0 | N25: 24.66 | Q25: =((K25-L25)+(M25-N25)) -> 5999.56 | R25: =SUM(G25,H25,I25,Q25) -> 12097.52
A26: Mar 24 - Mar 30 2025 | B26: 12606.67 | C26: =(B26*0.06)*1.13 -> 854.73223 | D26: =(B26*0.02)*1.13 -> 284.91074 | G26: 3955.85 | H26: 247.58 | I26: 1820.72 | J26: 7729.27 | K26: 7752.39 | L26: 1004.83 | M26: 194.23 | N26: 359.27 | Q26: =((K26-L26)+(M26-N26)) -> 6582.52 | R26: =SUM(G26,H26,I26,Q26) -> 12606.67
A27: Mar 31 - Apr 6 2025 | B27: =(10523.76 - 620.37) -> 9903.39 | C27: =(B27*0.06)*1.13 -> 671.44984 | D27: =(B27*0.02)*1.13 -> 223.81661 | G27: 3779.47 | H27: 149.6 | I27: 1433.27 | J27: 5337.88 | K27: 5351.37 | L27: 153.5 | M27: 0 | N27: 36.45 | Q27: =((K27-L27)+(M27-N27)) -> 5161.42 | R27: =SUM(G27,H27,I27,Q27) -> 10523.76
A28: Apr 7 - Apr 13 2025 | B28: 11452.13 | C28: =(B28*0.06)*1.13 -> 776.45441 | D28: =(B28*0.02)*1.13 -> 258.81814 | G28: 3535.88 | H28: 330.28 | I28: 1380.22 | J28: 6641.72 | K28: 6639.96 | L28: 437.83 | M28: 29.37 | N28: 25.75 | Q28: =((K28-L28)+(M28-N28)) -> 6205.75 | R28: =SUM(G28,H28,I28,Q28) -> 11452.13
A29: Apr 14 - Apr 20 2025 | B29: 11997.78 | C29: =(B29*0.06)*1.13 -> 813.44948 | D29: =(B29*0.02)*1.13 -> 271.14983 | G29: 3757.69 | H29: 151.2 | I29: 1978.17 | J29: 6624.85 | K29: 6589.1 | L29: 455.9 | M29: 0 | N29: 22.48 | Q29: =((K29-L29)+(M29-N29)) -> 6110.72 | R29: =SUM(G29,H29,I29,Q29) -> 11997.78
A30: Apr 21 - Apr 27 2025 | B30: 12128 | C30: =(B30*0.06)*1.13 -> 822.2784 | D30: =(B30*0.02)*1.13 -> 274.0928 | G30: 4046.75 | H30: 338.98 | I30: 1511.3 | J30: 6616 | K30: 6678.47 | L30: 451.43 | M30: 23.98 | N30: 20.05 | Q30: =((K30-L30)+(M30-N30)) -> 6230.97 | R30: =SUM(G30,H30,I30,Q30) -> 12128
A31: Apr 28 - May 04 2025 | B31: 13751.65 | C31: =(B31*0.06)*1.13 -> 932.36187 | D31: =(B31*0.02)*1.13 -> 310.78729 | F31: 14143.37 | G31: 5084.33 | H31: 264.78 | I31: 1538.62 | J31: 7255.64 | K31: 7340.46 | L31: 446.72 | M31: 0 | N31: 29.82 | Q31: =((K31-L31)+(M31-N31)) -> 6863.92 | R31: =SUM(G31,H31,I31,Q31) -> 13751.65
A32: May 05 - May 11 2025 | B32: 13226.86 | C32: =(B32*0.06)*1.13 -> 896.78111 | D32: =(B32*0.02)*1.13 -> 298.92704 | F32: 13618.49 | G32: 4056.91 | H32: 375.69 | I32: 2037.02 | J32: 7148.87 | K32: 7294.01 | L32: 517.46 | M32: 0 | N32: 19.31 | Q32: =((K32-L32)+(M32-N32)) -> 6757.24 | R32: =SUM(G32,H32,I32,Q32) -> 13226.86
A33: May 12 - May 18 2025 | B33: 12254.64 | C33: =(B33*0.06)*1.13 -> 830.86459 | D33: =(B33*0.02)*1.13 -> 276.95486 | F33: 12877.68 | G33: 4131.83 | H33: 369.6 | I33: 1855.22 | J33: 6521.03 | K33: 6362.97 | L33: 441.1 | M33: 0 | N33: 23.88 | Q33: =((K33-L33)+(M33-N33)) -> 5897.99 | R33: =SUM(G33,H33,I33,Q33) -> 12254.64
A34: May 19 - May 25 2025 | B34: 13263.23 | C34: =(B34*0.06)*1.13 -> 899.24699 | D34: =(B34*0.02)*1.13 -> 299.749 | F34: 13643.37 | G34: 3511.71 | H34: 186.97 | I34: 2082.91 | J34: 7861.78 | K34: 8006.63 | L34: 517.01 | M34: 0 | N34: 7.98 | Q34: =((K34-L34)+(M34-N34)) -> 7481.64 | R34: =SUM(G34,H34,I34,Q34) -> 13263.23
A35: May 26 - June 01 2025 | B35: 12676.84 | C35: =(B35*0.06)*1.13 -> 859.48975 | D35: =(B35*0.02)*1.13 -> 286.49658 | F35: 12886.76 | G35: 4188.9 | H35: 311.05 | I35: 1659.35 | J35: 6727.46 | K35: 6929.81 | L35: 411.48 | M35: 15.58 | N35: 16.37 | Q35: =((K35-L35)+(M35-N35)) -> 6517.54 | R35: =SUM(G35,H35,I35,Q35) -> 12676.84
A36: June 02 - June 08 2025 | B36: 12445.2 | C36: =(B36*0.06)*1.13 -> 843.78456 | D36: =(B36*0.02)*1.13 -> 281.26152 | F36: 12956.18 | G36: 3756.92 | H36: 162.3 | I36: 1535.15 | J36: 7501.81 | K36: 7508.04 | L36: 485.05 | M36: 0 | N36: 32.16 | Q36: =((K36-L36)+(M36-N36)) -> 6990.83 | R36: =SUM(G36,H36,I36,Q36) -> 12445.2
A37: June 09 - June 15 2025 | B37: 13944 | C37: =(B37*0.06)*1.13 -> 945.4032 | D37: =(B37*0.02)*1.13 -> 315.1344 | F37: 14232.26 | G37: 4461.48 | H37: 424.48 | I37: 1637.19 | J37: 7709.11 | K37: 7863.61 | L37: 460.53 | M37: 32.77 | N37: 15 | Q37: =((K37-L37)+(M37-N37)) -> 7420.85 | R37: =SUM(G37,H37,I37,Q37) -> 13944
A38: June 16 - June 22 2025 | B38: 14173.26 | C38: =(B38*0.06)*1.13 -> 960.94703 | D38: =(B38*0.02)*1.13 -> 320.31568 | F38: 14632.14 | G38: 4942.68 | H38: 177.18 | I38: 1703.43 | J38: 7808.85 | K38: 7803.71 | L38: 448.28 | M38: 21.98 | N38: 27.44 | Q38: =((K38-L38)+(M38-N38)) -> 7349.97 | R38: =SUM(G38,H38,I38,Q38) -> 14173.26
A39: June 23 - June 29 2025 | B39: 13029.85 | C39: =(B39*0.06)*1.13 -> 883.42383 | D39: =(B39*0.02)*1.13 -> 294.47461 | F39: 13312.48 | G39: 4305.79 | H39: 137.19 | I39: 2011.49 | J39: 6858.01 | K39: 6806.83 | L39: 210.74 | M39: 0 | N39: 20.71 | Q39: =((K39-L39)+(M39-N39)) -> 6575.38 | R39: =SUM(G39,H39,I39,Q39) -> 13029.85
A40: June 30 - July 06 2025 | B40: 15688.35 | C40: =(B40*0.06)*1.13 -> 1063.6701 | D40: =(B40*0.02)*1.13 -> 354.55671 | F40: 15865.18 | G40: 5143.43 | H40: 235.46 | I40: 2363.68 | J40: 8122.61 | K40: 8164.91 | L40: 200.01 | M40: 0 | N40: 19.12 | Q40: =((K40-L40)+(M40-N40)) -> 7945.78 | R40: =SUM(G40,H40,I40,Q40) -> 15688.35
...

Sheet KKWQueen
A1: Queen KKW
A2: Statement For Selected Period | B2: Total Revenue (Net Sales) | C2: Royalties (6%) +HST | D2: Marketing (2%) +HST | E2: Bill Count | F2: POS Total | G2: In-Store | H2: Skip | I2: DD | J2: Uber (TB) | K2: Uber (Rev) | L2: Uber (Marketing) | M2: Final Uber | N2: Total
A3: May 12 - May 18 2025 | B3: 664.16 | C3: =(B3*0.06)*1.13 -> 45.030048 | D3: =(B3*0.02)*1.13 -> 15.010016 | F3: 664.16 | G3: 664.16 | N3: =SUM(G3,H3,I3,M3) -> 664.16
A4: May 19 - May 25 2025 | B4: 1547.11 | C4: =(B4*0.06)*1.13 -> 104.89406 | D4: =(B4*0.02)*1.13 -> 34.964686
A5: May 26 - June 01 2025 | B5: 2799.9 | C5: =(B5*0.06)*1.13 -> 189.83322 | D5: =(B5*0.02)*1.13 -> 63.27774 | F5: 2799.9 | G5: 2799.9 | K5: 291.93 | L5: 0 | M5: =K5-L5 -> 291.93
A6: June 02 - June 08 2025 | B6: 4365.58 | C6: =(B6*0.06)*1.13 -> 295.98632 | D6: =(B6*0.02)*1.13 -> 98.662108 | F6: 4365.58 | G6: 4365.58 | K6: 1235.52 | L6: 105.1 | M6: =K6-L6 -> 1130.42
A7: June 09 - June 15 2025 | B7: 4947.29 | C7: =(B7*0.06)*1.13 -> 335.42626 | D7: =(B7*0.02)*1.13 -> 111.80875 | G7: 4947.29 | K7: 1186.64 | L7: 86.8 | M7: =K7-L7 -> 1099.84
A8: June 16 - June 22 2025 | B8: 4793.11 | C8: =(B8*0.06)*1.13 -> 324.97286 | D8: =(B8*0.02)*1.13 -> 108.32429 | G8: 4793.11 | K8: 1830.45 | L8: 70.2 | M8: =K8-L8 -> 1760.25
A9: June 23 - June 29 2025 | B9: 5624.88 | C9: =(B9*0.06)*1.13 -> 381.36686 | D9: =(B9*0.02)*1.13 -> 127.12229 | G9: 5624.88 | K9: 1263.81 | L9: 99.44 | M9: =K9-L9 -> 1164.37
A10: June 30 - July 06 2025 | B10: 6403.23 | C10: =(B10*0.06)*1.13 -> 434.13899 | D10: =(B10*0.02)*1.13 -> 144.713 | F10: 6403.23 | G10: 6403.23 | K10: 1556.64 | L10: 79.56 | M10: =K10-L10 -> 1477.08
A11: July 07 - July 13 2025 | B11: 6338.56 | C11: =(B11*0.06)*1.13 -> 429.75437 | D11: =(B11*0.02)*1.13 -> 143.25146 | F11: 6338.56 | G11: 6338.56 | K11: 1515.09 | L11: 105.05 | M11: =K11-L11 -> 1410.04
A12: July 14 - July 20 2025 | B12: 6910.99 | C12: =(B12*0.06)*1.13 -> 468.56512 | D12: =(B12*0.02)*1.13 -> 156.18837 | E12: 292 | F12: 6910.99 | G12: 6910.99 | K12: 972.39 | L12: 132.79 | M12: =K12-L12 -> 839.6
A13: July 21 - July 27 2025 | B13: 7603.96 | C13: =(B13*0.06)*1.13 -> 515.54849 | D13: =(B13*0.02)*1.13 -> 171.8495 | E13: 272 | F13: 7016.72 | G13: 5957.03 | J13: 1059.69 | K13: 1791.65 | L13: 144.72 | M13: =K13-L13 -> 1646.93 | N13: =SUM(G13,H13,I13,M13) -> 7603.96
A14: July 28 - Aug 03 2025 | B14: 7021.72 | C14: =(B14*0.06)*1.13 -> 476.07262 | D14: =(B14*0.02)*1.13 -> 158.69087 | E14: 295 | F14: 7104.35 | G14: 5850.61 | J14: 1253.74 | K14: 1310.71 | L14: 139.6 | M14: =K14-L14 -> 1171.11 | N14: =SUM(G14,H14,I14,M14) -> 7021.72
A15: Aug 04 - Aug 10 2025 | B15: 9389.62 | C15: =(B15*0.06)*1.13 -> 636.61624 | D15: =(B15*0.02)*1.13 -> 212.20541 | E15: 362 | F15: 9626.57 | G15: 7180.12 | I15: 513.74 | J15: 1932.71 | K15: 1857.15 | L15: 161.39 | M15: =K15-L15 -> 1695.76 | N15: =SUM(G15,H15,I15,M15) -> 9389.62
A16: Aug 11 - Aug 17 2025 | B16: 7673.65 | C16: =(B16*0.06)*1.13 -> 520.27347 | D16: =(B16*0.02)*1.13 -> 173.42449 | E16: 320 | F16: 7809.76 | G16: 6042.25 | I16: 217.4 | J16: 1550.11 | K16: 1568.7 | L16: 154.7 | M16: =K16-L16 -> 1414 | N16: =SUM(G16,H16,I16,M16) -> 7673.65
A17: Aug 18 - Aug 24 2025 | B17: 7636.43 | C17: =(B17*0.06)*1.13 -> 517.74995 | D17: =(B17*0.02)*1.13 -> 172.58332 | E17: 327 | F17: 7730.38 | G17: 5813.68 | I17: 111.05 | J17: 1805.65 | K17: 1849.11 | L17: 137.41 | M17: =K17-L17 -> 1711.7 | N17: =SUM(G17,H17,I17,M17) -> 7636.43
A18: Aug 25 - Aug 31 2025 | B18: 9006.58 | C18: =(B18*0.06)*1.13 -> 610.64612 | D18: =(B18*0.02)*1.13 -> 203.54871 | E18: 355 | F18: 9233.72 | G18: 7099.5 | I18: 242.59 | J18: 1891.63 | K18: 1814.57 | L18: 150.08 | M18: =K18-L18 -> 1664.49 | N18: =SUM(G18,H18,I18,M18) -> 9006.58
A19: Sep 01 - Sep 07 2025 | B19: 8431.4 | C19: =(B19*0.06)*1.13 -> 571.64892 | D19: =(B19*0.02)*1.13 -> 190.54964 | E19: 334 | F19: 8531.43 | G19: 6374 | I19: 115.78 | J19: 2041.65 | K19: 2023.36 | L19: 81.74 | M19: =K19-L19 -> 1941.62 | N19: =SUM(G19,H19,I19,M19) -> 8431.4
A20: Sep 08 - Sep 14 2025 | B20: 7397.47 | C20: =(B20*0.06)*1.13 -> 501.54847 | D20: =(B20*0.02)*1.13 -> 167.18282 | E20: 311 | F20: 7386.62 | G20: 5610.51 | I20: 72.9 | J20: 1703.21 | K20: 1798.56 | L20: 84.5 | M20: =K20-L20 -> 1714.06 | N20: =SUM(G20,H20,I20,M20) -> 7397.47
A21: Sep 15 - Sep 21 2025 | B21: 7398.78 | C21: =(B21*0.06)*1.13 -> 501.63728 | D21: =(B21*0.02)*1.13 -> 167.21243 | E21: 323 | F21: 7513.93 | G21: 5237.2 | I21: 217.16 | J21: 2059.57 | K21: 2026.84 | L21: 82.42 | M21: =K21-L21 -> 1944.42 | N21: =SUM(G21,H21,I21,M21) -> 7398.78
A22: Sep 22 - Sep 28 2025 | B22: 7341.94 | C22: =(B22*0.06)*1.13 -> 497.78353 | D22: =(B22*0.02)*1.13 -> 165.92784 | E22: 293 | F22: 7334.35 | G22: 5453.04 | I22: 293.34 | J22: 1587.97 | K22: 1680.62 | L22: 85.06 | M22: =K22-L22 -> 1595.56 | N22: =SUM(G22,H22,I22,M22) -> 7341.94
A23: Sep 29 - Oct 05 2025 | B23: 9463.4 | C23: =(B23*0.06)*1.13 -> 641.61852 | D23: =(B23*0.02)*1.13 -> 213.87284 | E23: 358 | F23: 9546.61 | G23: 6246.2 | I23: 494.71 | J23: 2805.7 | K23: 2804.51 | L23: 82.02 | M23: =K23-L23 -> 2722.49 | N23: =SUM(G23,H23,I23,M23) -> 9463.4
A24: Oct 6 - Oct 12 2025 | B24: 8229.9 | C24: =(B24*0.06)*1.13 -> 557.98722 | D24: =(B24*0.02)*1.13 -> 185.99574 | E24: 340 | F24: 8237.23 | G24: 5767.37 | I24: 739.57 | J24: 1730.29 | K24: 1807.58 | L24: 84.62 | M24: =K24-L24 -> 1722.96 | N24: =SUM(G24,H24,I24,M24) -> 8229.9
A25: Oct 13 - Oct 19 2025 | B25: 7408.42 | C25: =(B25*0.06)*1.13 -> 502.29088 | D25: =(B25*0.02)*1.13 -> 167.43029 | F25: 7456.76 | G25: 4598.46 | H25: 0 | I25: 454.67 | J25: 2403.63 | K25: 2457.81 | L25: 102.52 | M25: =K25-L25 -> 2355.29 | N25: =SUM(G25,H25,I25,M25) -> 7408.42
A26: Oct 20 - Oct 26 2025 | B26: 9439.54 | C26: =(B26*0.06)*1.13 -> 640.00081 | D26: =(B26*0.02)*1.13 -> 213.3336 | E26: 376 | F26: 9422.55 | G26: 5553.79 | H26: 0 | I26: 210.9 | J26: 3657.86 | K26: 3782.69 | L26: 107.84 | M26: =K26-L26 -> 3674.85 | N26: =SUM(G26,H26,I26,M26) -> 9439.54
A27: Oct 27 - Nov 02 2025 | B27: 9180.19 | C27: =(B27*0.06)*1.13 -> 622.41688 | D27: =(B27*0.02)*1.13 -> 207.47229 | E27: 346 | F27: 8082.91 | G27: 6768.21 | H27: 0 | I27: 70.76 | J27: 1243.94 | K27: 2629.83 | L27: 288.61 | M27: =K27-L27 -> 2341.22 | N27: =SUM(G27,H27,I27,M27) -> 9180.19
A28: Nov 03 - Nov 09 2025 | B28: 9148.1 | C28: =(B28*0.06)*1.13 -> 620.24118 | D28: =(B28*0.02)*1.13 -> 206.74706 | E28: 346 | F28: 8885.45 | G28: 5311.78 | H28: 0 | I28: 242.31 | J28: 3331.36 | K28: 3914.5 | L28: 320.49 | M28: =K28-L28 -> 3594.01 | N28: =SUM(G28,H28,I28,M28) -> 9148.1
A29: Nov 10 - Nov 16 2025 | B29: 7638.78 | C29: =(B29*0.06)*1.13 -> 517.90928 | D29: =(B29*0.02)*1.13 -> 172.63643 | E29: 315 | F29: 7967.12 | G29: 3847.95 | H29: 0 | I29: 294.03 | J29: 3825.14 | K29: 3827.23 | L29: 330.43 | M29: =K29-L29 -> 3496.8 | N29: =SUM(G29,H29,I29,M29) -> 7638.78
A30: Nov 17 - Nov 23 2025 | B30: 6968.05 | C30: =(B30*0.06)*1.13 -> 472.43379 | D30: =(B30*0.02)*1.13 -> 157.47793 | E30: 305 | F30: 7318.71 | G30: 4338.26 | H30: 0 | I30: 177.36 | J30: 2803.09 | K30: 2787.59 | L30: 335.16 | M30: =K30-L30 -> 2452.43 | N30: =SUM(G30,H30,I30,M30) -> 6968.05
A31: Nov 24 - Nov 30 2025 | B31: 8782.19 | C31: =(B31*0.06)*1.13 -> 595.43248 | D31: =(B31*0.02)*1.13 -> 198.47749 | E31: 335 | F31: 8999.43 | G31: 4761.98 | H31: 0 | I31: 306.06 | J31: 3931.39 | K31: 3939.5 | L31: 225.35 | M31: =K31-L31 -> 3714.15 | N31: =SUM(G31,H31,I31,M31) -> 8782.19
A32: Dec 01 - Dec 07 2025 | B32: 7210.28 | C32: =(B32*0.06)*1.13 -> 488.85698 | D32: =(B32*0.02)*1.13 -> 162.95233 | E32: 282 | F32: 7372.1 | G32: 4225.44 | H32: 0 | I32: 117.42 | J32: 3029.24 | K32: 3049.33 | L32: 181.91 | M32: =K32-L32 -> 2867.42 | N32: =SUM(G32,H32,I32,M32) -> 7210.28
A33: Dec 08 - Dec 14 2025 | B33: 6637.35 | C33: =(B33*0.06)*1.13 -> 450.01233 | D33: =(B33*0.02)*1.13 -> 150.00411 | E33: 273 | F33: 6771.76 | G33: 3568.66 | H33: 0 | I33: 310.62 | J33: 2892.48 | K33: 2944.47 | L33: 186.4 | M33: =K33-L33 -> 2758.07 | N33: =SUM(G33,H33,I33,M33) -> 6637.35
A34: Dec 15 - Dec 21 2025 | B34: 7902.12 | C34: =(B34*0.06)*1.13 -> 535.76374 | D34: =(B34*0.02)*1.13 -> 178.58791 | E34: 343 | F34: 8311.76 | G34: 4860.79 | H34: 0 | I34: 198.22 | J34: 3252.75 | K34: 3264.29 | L34: 421.18 | M34: =K34-L34 -> 2843.11 | N34: =SUM(G34,H34,I34,M34) -> 7902.12
A35: Dec 22 - Dec 28 2025 | B35: 8908.59 | C35: =(B35*0.06)*1.13 -> 604.0024 | D35: =(B35*0.02)*1.13 -> 201.33413 | E35: 305 | F35: 9493.53 | G35: 5368.84 | H35: 0 | I35: 765.87 | J35: 3358.82 | K35: 3446.18 | L35: 672.3 | M35: =K35-L35 -> 2773.88 | N35: =SUM(G35,H35,I35,M35) -> 8908.59
A36: Dec 29 - Jan 04 2026 | B36: 7851.46 | C36: =(B36*0.06)*1.13 -> 532.32899 | D36: =(B36*0.02)*1.13 -> 177.443 | E36: 310 | F36: 8472.26 | G36: 4894.42 | H36: 0 | I36: 508.39 | J36: 3069.45 | K36: 3053.95 | L36: 605.3 | M36: =K36-L36 -> 2448.65 | N36: =SUM(G36,H36,I36,M36) -> 7851.46
A37: Jan 05 - Jan 11 2026 | B37: 7141.27 | C37: =(B37*0.06)*1.13 -> 484.17811 | D37: =(B37*0.02)*1.13 -> 161.3927 | E37: 308 | F37: 7857.99 | G37: 3981.81 | H37: 0 | I37: 253.79 | J37: 3622.39 | K37: 3568.23 | L37: 662.56 | M37: =K37-L37 -> 2905.67 | N37: =SUM(G37,H37,I37,M37) -> 7141.27
A38: Jan 12 - Jan 18 2026 | B38: 5922.81 | C38: =(B38*0.06)*1.13 -> 401.56652 | D38: =(B38*0.02)*1.13 -> 133.85551 | E38: 250 | F38: 6428.8 | G38: 3249.17 | H38: 0 | I38: 364.72 | J38: 2814.91 | K38: 2904.47 | L38: 595.55 | M38: =K38-L38 -> 2308.92 | N38: =SUM(G38,H38,I38,M38) -> 5922.81
A39: Jan 19 - Jan 25 2026 | B39: 6472.16 | C39: =(B39*0.06)*1.13 -> 438.81245 | D39: =(B39*0.02)*1.13 -> 146.27082 | E39: 279 | F39: 7110.51 | G39: 3635.23 | H39: 0 | I39: 226.12 | J39: 3249.16 | K39: 3249.16 | L39: 638.35 | M39: =K39-L39 -> 2610.81 | N39: =SUM(G39,H39,I39,M39) -> 6472.16
A40: Jan 26 - Feb 01 2026 | B40: 6003.96 | C40: =(B40*0.06)*1.13 -> 407.06849 | D40: =(B40*0.02)*1.13 -> 135.6895 | E40: 253 | F40: 6460.23 | G40: 3315.16 | H40: 0 | I40: 350.28 | J40: 2794.79 | K40: 2793.89 | L40: 455.37 | M40: =K40-L40 -> 2338.52 | N40: =SUM(G40,H40,I40,M40) -> 6003.96
...

Sheet Lebovic
A1: Lebovic
A2: Statement For Selected Period | B2: Total Revenue (Net Sales) | C2: Royalties (6%) +HST | D2: Marketing (2%) +HST | E2: Bill Count | F2: POS Total | G2: In-Store | H2: Skip | I2: DD | J2: Uber (TB) | K2: PK Uber (Rev) | L2: PK Uber (Marketing) | M2: Chickentarian Uber (Rev) | N2: Chickentarian Uber (Marketing) | O2: Final Uber | P2: Total
A3: Mar 07 - Mar 09 2025 | B3: 1358.01 | C3: =(B3*0.06)*1.13 -> 92.073078 | D3: =(B3*0.02)*1.13 -> 30.691026 | G3: 1358.01 | K3: 138.56 | L3: 18.1 | M3: 0 | N3: 0 | O3: =K3-L3 -> 120.46
A4: Mar 10 - Mar 16 2025 | B4: 6551.2 | C4: =(B4*0.06)*1.13 -> 444.17136 | D4: =(B4*0.02)*1.13 -> 148.05712 | K4: 1147.55 | L4: 174.79 | O4: =K4-L4 -> 972.76
A5: Mar 17 - Mar 23 2025 | B5: 6541.54 | C5: =(B5*0.06)*1.13 -> 443.51641 | D5: =(B5*0.02)*1.13 -> 147.8388 | G5: 5648.64 | H5: 0 | I5: 378.89 | J5: 611.14 | K5: 613.95 | L5: 99.94 | O5: =K5-L5 -> 514.01 | P5: =SUM(G5,H5,I5,O5) -> 6541.54
A6: Mar 24 - Mar 30 2025 | B6: 11256.19 | C6: =(B6*0.06)*1.13 -> 763.16968 | D6: =(B6*0.02)*1.13 -> 254.38989 | G6: 9146.42 | H6: 45.58 | I6: 643.8 | J6: 1507.24 | K6: 1428.04 | L6: 7.65 | O6: =K6-L6 -> 1420.39 | P6: =SUM(G6,H6,I6,O6) -> 11256.19
A7: Mar 31 - Apr 6 2025 | B7: 12830.78 | C7: =(B7*0.06)*1.13 -> 869.92688 | D7: =(B7*0.02)*1.13 -> 289.97563 | G7: 10209.73 | H7: 57.89 | I7: 678.18 | J7: 1871.77 | K7: 1884.98 | L7: 0 | O7: =K7-L7 -> 1884.98 | P7: =SUM(G7,H7,I7,O7) -> 12830.78
A8: Apr 7 - Apr 13 2025 | B8: 11068.59 | C8: =(B8*0.06)*1.13 -> 750.4504 | D8: =(B8*0.02)*1.13 -> 250.15013 | G8: 8238.21 | H8: 147.88 | I8: 550.39 | J8: 2079.43 | K8: 2311.9 | L8: 179.79 | O8: =K8-L8 -> 2132.11 | P8: =SUM(G8,H8,I8,O8) -> 11068.59
A9: Apr 14 - Apr 20 2025 | B9: 12721.55 | C9: =(B9*0.06)*1.13 -> 862.52109 | D9: =(B9*0.02)*1.13 -> 287.50703 | G9: 10280.08 | H9: 189.09 | I9: 341.64 | J9: 2100.59 | K9: 2061 | L9: 150.26 | O9: =K9-L9 -> 1910.74 | P9: =SUM(G9,H9,I9,O9) -> 12721.55
A10: Apr 21 - Apr 27 2025 | B10: 12290.19 | C10: =(B10*0.06)*1.13 -> 833.27488 | D10: =(B10*0.02)*1.13 -> 277.75829 | G10: 9891.12 | H10: 275.94 | I10: 356.63 | J10: 1881.72 | K10: 1921.31 | L10: 154.81 | O10: =K10-L10 -> 1766.5 | P10: =SUM(G10,H10,I10,O10) -> 12290.19
A11: Apr 28 - May 04 2025 | B11: 11476.5 | C11: =(B11*0.06)*1.13 -> 778.1067 | D11: =(B11*0.02)*1.13 -> 259.3689 | G11: 9723.35 | H11: 0 | I11: 429 | J11: 1464.57 | K11: 1414.63 | L11: 90.48 | M11: 0 | N11: 0 | O11: =K11-L11 -> 1324.15 | P11: =SUM(G11,H11,I11,O11) -> 11476.5
A12: May 05 - May 11 2025 | B12: 11751.38 | C12: =(B12*0.06)*1.13 -> 796.74356 | D12: =(B12*0.02)*1.13 -> 265.58119 | F12: 11836.23 | G12: 9769.66 | H12: 142.18 | I12: 508.31 | J12: 1416.08 | K12: 1417.03 | L12: 85.8 | M12: 0 | N12: 0 | O12: =K12-L12 -> 1331.23 | P12: =SUM(G12,H12,I12,O12) -> 11751.38
A13: May 12 - May 18 2025 | B13: 10854.11 | C13: =(B13*0.06)*1.13 -> 735.90866 | D13: =(B13*0.02)*1.13 -> 245.30289 | F13: 11010.2 | G13: 8491.04 | H13: 121.8 | I13: 523.69 | J13: 1873.67 | K13: 1851.46 | L13: 133.88 | M13: 0 | N13: 0 | O13: =K13-L13 -> 1717.58 | P13: =SUM(G13,H13,I13,O13) -> 10854.11
A14: May 19 - May 25 2025 | B14: 13336.76 | C14: =(B14*0.06)*1.13 -> 904.23233 | D14: =(B14*0.02)*1.13 -> 301.41078 | F14: 13507.97 | G14: 9697.44 | H14: 217.18 | I14: 712.54 | J14: 2880.81 | K14: 2884.87 | L14: 192.05 | M14: 16.78 | N14: 0 | O14: =(K14-L14)+(M14-N14) -> 2709.6 | P14: =SUM(G14,H14,I14,O14) -> 13336.76
A15: May 26 - June 01 2025 | B15: 11398.24 | C15: =(B15*0.06)*1.13 -> 772.80067 | D15: =(B15*0.02)*1.13 -> 257.60022 | F15: 11545.8 | G15: 8647.53 | H15: 141.7 | I15: 466.14 | J15: 2290.43 | K15: 2310.57 | L15: 183.9 | M15: 16.2 | N15: 0 | O15: =(K15-L15)+(M15-N15) -> 2142.87 | P15: =SUM(G15,H15,I15,O15) -> 11398.24
A16: June 02 - June 08 2025 | B16: 12039.09 | C16: =(B16*0.06)*1.13 -> 816.2503 | D16: =(B16*0.02)*1.13 -> 272.08343 | F16: 12047.67 | G16: 9433.31 | H16: 158.94 | I16: 590.33 | J16: 1865.09 | K16: 1978.48 | L16: 138.17 | M16: 16.2 | N16: 0 | O16: =(K16-L16)+(M16-N16) -> 1856.51 | P16: =SUM(G16,H16,I16,O16) -> 12039.09
A17: June 09 - June 15 2025 | B17: 13055.04 | C17: =(B17*0.06)*1.13 -> 885.13171 | D17: =(B17*0.02)*1.13 -> 295.0439 | F17: 13288.84 | G17: 9385.52 | H17: 185.69 | I17: 549.69 | J17: 3167.94 | K17: 3141.24 | L17: 237.08 | M17: 29.98 | N17: 0 | O17: =(K17-L17)+(M17-N17) -> 2934.14 | P17: =SUM(G17,H17,I17,O17) -> 13055.04
A18: June 16 - June 22 2025 | B18: 12983.72 | C18: =(B18*0.06)*1.13 -> 880.29622 | D18: =(B18*0.02)*1.13 -> 293.43207 | F18: 13103.48 | G18: 10064.45 | H18: 65.2 | I18: 625.54 | J18: 2348.29 | K18: 2347.39 | L18: 168.32 | M18: 49.46 | N18: 0 | O18: =(K18-L18)+(M18-N18) -> 2228.53 | P18: =SUM(G18,H18,I18,O18) -> 12983.72
A19: June 23 - June 29 2025 | B19: 13364.94 | C19: =(B19*0.06)*1.13 -> 906.14293 | D19: =(B19*0.02)*1.13 -> 302.04764 | F19: 13603.33 | G19: 10254.47 | H19: 167.99 | I19: 515.75 | J19: 2665.12 | K19: 2541.82 | L19: 133.99 | M19: 18.9 | N19: 0 | O19: =(K19-L19)+(M19-N19) -> 2426.73 | P19: =SUM(G19,H19,I19,O19) -> 13364.94
A20: June 30 - July 06 2025 | B20: 14314.06 | C20: =(B20*0.06)*1.13 -> 970.49327 | D20: =(B20*0.02)*1.13 -> 323.49776 | F20: 14252.5 | G20: 11199.44 | H20: 135.29 | I20: 839.42 | J20: 2078.35 | K20: 2147.79 | L20: 44.14 | M20: 36.26 | N20: 0 | O20: =(K20-L20)+(M20-N20) -> 2139.91 | P20: =SUM(G20,H20,I20,O20) -> 14314.06
A21: July 07 - July 13 2025 | B21: 11942.82 | C21: =(B21*0.06)*1.13 -> 809.7232 | D21: =(B21*0.02)*1.13 -> 269.90773 | F21: 11966.52 | G21: 9037.18 | H21: 148.95 | I21: 490.59 | J21: 2289.8 | K21: 2371.26 | L21: 105.16 | M21: 0 | N21: 0 | O21: =(K21-L21)+(M21-N21) -> 2266.1 | P21: =SUM(G21,H21,I21,O21) -> 11942.82
