Workbook

Sheet checker
A1: Jul 13 - Jul 19
B3: Items | C3: markham | D3: percentage | E3: ajax | F3: percentage | G3: lebovic | H3: percentage | I3: wonderland | J3: percentage | K3: downtown | L3: percentage | M3: highway | N3: percentage | O3: heartland | P3: percentage | Q3: eglinton | R3: percentage | S3: oshawa | T3: percentage | U3: milton | V3: percentage | W3: food court | X3: percentage | Y3: kabab wala | Z3: percentage | AA3: kababwala Q St | AB3: percentage
A4: Pizza K Deals | B4: Wing Wednesday - 10 | C4: =IFERROR(SUMIF('Markham Rd'!$A:$A, B4, 'Markham Rd'!$F:$F), 0) | E4: =IFERROR(SUMIF(Ajax!$A:$A, B4, Ajax!$F:$F), 0) | G4: =IFERROR(SUMIF(Lebovic!$A:$A, B4, Lebovic!$F:$F), 0) | I4: =IFERROR(SUMIF(Wonderland!$A:$A, B4, Wonderland!$F:$F), 0) | K4: =IFERROR(SUMIF('Pizza Karachi Downtown TO'!$A:$A, B4, 'Pizza Karachi Downtown TO'!$F:$F), 0) | M4: =IFERROR(SUMIF('Highway Karahi'!$A:$A, B4, 'Highway Karahi'!$F:$F), 0) | O4: =IFERROR(SUMIF(Heartland!$A:$A, B4, Heartland!$F:$F), 0) | Q4: =IFERROR(SUMIF(Eglinton!$A:$A, B4, Eglinton!$F:$F), 0) | S4: =IFERROR(SUMIF(Oshawa!$A:$A, B4, Oshawa!$F:$F), 0) | U4: =IFERROR(SUMIF(Milton!$A:$A, B4, Milton!$F:$F), 0) | W4: - | Y4: -
B5: Personal Pizza Lunch Deal | C5: =IFERROR(SUMIF('Markham Rd'!$A:$A, B5, 'Markham Rd'!$F:$F), 0) | E5: =IFERROR(SUMIF(Ajax!$A:$A, B5, Ajax!$F:$F), 0) | G5: =IFERROR(SUMIF(Lebovic!$A:$A, B5, Lebovic!$F:$F), 0) | I5: =IFERROR(SUMIF(Wonderland!$A:$A, B5, Wonderland!$F:$F), 0) | K5: =IFERROR(SUMIF('Pizza Karachi Downtown TO'!$A:$A, B5, 'Pizza Karachi Downtown TO'!$F:$F), 0) | M5: =IFERROR(SUMIF('Highway Karahi'!$A:$A, B5, 'Highway Karahi'!$F:$F), 0) | O5: =IFERROR(SUMIF(Heartland!$A:$A, B5, Heartland!$F:$F), 0) | Q5: =IFERROR(SUMIF(Eglinton!$A:$A, B5, Eglinton!$F:$F), 0) | S5: =IFERROR(SUMIF(Oshawa!$A:$A, B5, Oshawa!$F:$F), 0) | U5: =IFERROR(SUMIF(Milton!$A:$A, B5, Milton!$F:$F), 0) | W5: - | Y5: -
B6: Personal Pizza Lunch Deal - OO | C6: =IFERROR(SUMIF('Markham Rd'!$A:$A, B6, 'Markham Rd'!$F:$F), 0) | E6: =IFERROR(SUMIF(Ajax!$A:$A, B6, Ajax!$F:$F), 0) | G6: =IFERROR(SUMIF(Lebovic!$A:$A, B6, Lebovic!$F:$F), 0) | I6: =IFERROR(SUMIF(Wonderland!$A:$A, B6, Wonderland!$F:$F), 0) | K6: =IFERROR(SUMIF('Pizza Karachi Downtown TO'!$A:$A, B6, 'Pizza Karachi Downtown TO'!$F:$F), 0) | M6: =IFERROR(SUMIF('Highway Karahi'!$A:$A, B6, 'Highway Karahi'!$F:$F), 0) | O6: =IFERROR(SUMIF(Heartland!$A:$A, B6, Heartland!$F:$F), 0) | Q6: =IFERROR(SUMIF(Eglinton!$A:$A, B6, Eglinton!$F:$F), 0) | S6: =IFERROR(SUMIF(Oshawa!$A:$A, B6, Oshawa!$F:$F), 0) | U6: =IFERROR(SUMIF(Milton!$A:$A, B6, Milton!$F:$F), 0) | W6: - | Y6: -
B7: Wings Lunch Deal - OO | C7: =IFERROR(SUMIF('Markham Rd'!$A:$A, B7, 'Markham Rd'!$F:$F), 0) | E7: =IFERROR(SUMIF(Ajax!$A:$A, B7, Ajax!$F:$F), 0) | G7: =IFERROR(SUMIF(Lebovic!$A:$A, B7, Lebovic!$F:$F), 0) | I7: =IFERROR(SUMIF(Wonderland!$A:$A, B7, Wonderland!$F:$F), 0) | K7: =IFERROR(SUMIF('Pizza Karachi Downtown TO'!$A:$A, B7, 'Pizza Karachi Downtown TO'!$F:$F), 0) | M7: =IFERROR(SUMIF('Highway Karahi'!$A:$A, B7, 'Highway Karahi'!$F:$F), 0) | O7: =IFERROR(SUMIF(Heartland!$A:$A, B7, Heartland!$F:$F), 0) | Q7: =IFERROR(SUMIF(Eglinton!$A:$A, B7, Eglinton!$F:$F), 0) | S7: =IFERROR(SUMIF(Oshawa!$A:$A, B7, Oshawa!$F:$F), 0) | U7: =IFERROR(SUMIF(Milton!$A:$A, B7, Milton!$F:$F), 0) | W7: - | Y7: -
B8: Wings Lunch Deal | C8: =IFERROR(SUMIF('Markham Rd'!$A:$A, B8, 'Markham Rd'!$F:$F), 0) | E8: =IFERROR(SUMIF(Ajax!$A:$A, B8, Ajax!$F:$F), 0) | G8: =IFERROR(SUMIF(Lebovic!$A:$A, B8, Lebovic!$F:$F), 0) | I8: =IFERROR(SUMIF(Wonderland!$A:$A, B8, Wonderland!$F:$F), 0) | K8: =IFERROR(SUMIF('Pizza Karachi Downtown TO'!$A:$A, B8, 'Pizza Karachi Downtown TO'!$F:$F), 0) | M8: =IFERROR(SUMIF('Highway Karahi'!$A:$A, B8, 'Highway Karahi'!$F:$F), 0) | O8: =IFERROR(SUMIF(Heartland!$A:$A, B8, Heartland!$F:$F), 0) | Q8: =IFERROR(SUMIF(Eglinton!$A:$A, B8, Eglinton!$F:$F), 0) | S8: =IFERROR(SUMIF(Oshawa!$A:$A, B8, Oshawa!$F:$F), 0) | U8: =IFERROR(SUMIF(Milton!$A:$A, B8, Milton!$F:$F), 0) | W8: - | Y8: -
B9: Late Night Deal (2 Med $34.99) | C9: =IFERROR(SUMIF('Markham Rd'!$A:$A, B9, 'Markham Rd'!$F:$F), 0) | E9: =IFERROR(SUMIF(Ajax!$A:$A, B9, Ajax!$F:$F), 0) | G9: =IFERROR(SUMIF(Lebovic!$A:$A, B9, Lebovic!$F:$F), 0) | I9: =IFERROR(SUMIF(Wonderland!$A:$A, B9, Wonderland!$F:$F), 0) | K9: =IFERROR(SUMIF('Pizza Karachi Downtown TO'!$A:$A, B9, 'Pizza Karachi Downtown TO'!$F:$F), 0) | M9: =IFERROR(SUMIF('Highway Karahi'!$A:$A, B9, 'Highway Karahi'!$F:$F), 0) | O9: =IFERROR(SUMIF(Heartland!$A:$A, B9, Heartland!$F:$F), 0) | Q9: =IFERROR(SUMIF(Eglinton!$A:$A, B9, Eglinton!$F:$F), 0) | S9: =IFERROR(SUMIF(Oshawa!$A:$A, B9, Oshawa!$F:$F), 0) | U9: =IFERROR(SUMIF(Milton!$A:$A, B9, Milton!$F:$F), 0)
B10: Late Night Deal (2 Large $44.99) | C10: =IFERROR(SUMIF('Markham Rd'!$A:$A, B10, 'Markham Rd'!$F:$F), 0) | E10: =IFERROR(SUMIF(Ajax!$A:$A, B10, Ajax!$F:$F), 0) | G10: =IFERROR(SUMIF(Lebovic!$A:$A, B10, Lebovic!$F:$F), 0) | I10: =IFERROR(SUMIF(Wonderland!$A:$A, B10, Wonderland!$F:$F), 0) | K10: =IFERROR(SUMIF('Pizza Karachi Downtown TO'!$A:$A, B10, 'Pizza Karachi Downtown TO'!$F:$F), 0) | M10: =IFERROR(SUMIF('Highway Karahi'!$A:$A, B10, 'Highway Karahi'!$F:$F), 0) | O10: =IFERROR(SUMIF(Heartland!$A:$A, B10, Heartland!$F:$F), 0) | Q10: =IFERROR(SUMIF(Eglinton!$A:$A, B10, Eglinton!$F:$F), 0) | S10: =IFERROR(SUMIF(Oshawa!$A:$A, B10, Oshawa!$F:$F), 0) | U10: =IFERROR(SUMIF(Milton!$A:$A, B10, Milton!$F:$F), 0)
B11: Sidekick Combo - 12 | C11: =IFERROR(SUMIF('Markham Rd'!$A:$A, B11, 'Markham Rd'!$F:$F), 0) | E11: =IFERROR(SUMIF(Ajax!$A:$A, B11, Ajax!$F:$F), 0) | G11: =IFERROR(SUMIF(Lebovic!$A:$A, B11, Lebovic!$F:$F), 0) | I11: =IFERROR(SUMIF(Wonderland!$A:$A, B11, Wonderland!$F:$F), 0) | K11: =IFERROR(SUMIF('Pizza Karachi Downtown TO'!$A:$A, B11, 'Pizza Karachi Downtown TO'!$F:$F), 0) | M11: =IFERROR(SUMIF('Highway Karahi'!$A:$A, B11, 'Highway Karahi'!$F:$F), 0) | O11: =IFERROR(SUMIF(Heartland!$A:$A, B11, Heartland!$F:$F), 0) | Q11: =IFERROR(SUMIF(Eglinton!$A:$A, B11, Eglinton!$F:$F), 0) | S11: =IFERROR(SUMIF(Oshawa!$A:$A, B11, Oshawa!$F:$F), 0) | U11: =IFERROR(SUMIF(Milton!$A:$A, B11, Milton!$F:$F), 0)
B12: Sidekick Combo - 12 - OO | C12: =IFERROR(SUMIF('Markham Rd'!$A:$A, B12, 'Markham Rd'!$F:$F), 0) | E12: =IFERROR(SUMIF(Ajax!$A:$A, B12, Ajax!$F:$F), 0) | G12: =IFERROR(SUMIF(Lebovic!$A:$A, B12, Lebovic!$F:$F), 0) | I12: =IFERROR(SUMIF(Wonderland!$A:$A, B12, Wonderland!$F:$F), 0) | K12: =IFERROR(SUMIF('Pizza Karachi Downtown TO'!$A:$A, B12, 'Pizza Karachi Downtown TO'!$F:$F), 0) | M12: =IFERROR(SUMIF('Highway Karahi'!$A:$A, B12, 'Highway Karahi'!$F:$F), 0) | O12: =IFERROR(SUMIF(Heartland!$A:$A, B12, Heartland!$F:$F), 0) | Q12: =IFERROR(SUMIF(Eglinton!$A:$A, B12, Eglinton!$F:$F), 0) | S12: =IFERROR(SUMIF(Oshawa!$A:$A, B12, Oshawa!$F:$F), 0) | U12: =IFERROR(SUMIF(Milton!$A:$A, B12, Milton!$F:$F), 0)
B13: Sidekick Combo - 14 | C13: =IFERROR(SUMIF('Markham Rd'!$A:$A, B13, 'Markham Rd'!$F:$F), 0) | E13: =IFERROR(SUMIF(Ajax!$A:$A, B13, Ajax!$F:$F), 0) | G13: =IFERROR(SUMIF(Lebovic!$A:$A, B13, Lebovic!$F:$F), 0) | I13: =IFERROR(SUMIF(Wonderland!$A:$A, B13, Wonderland!$F:$F), 0) | K13: =IFERROR(SUMIF('Pizza Karachi Downtown TO'!$A:$A, B13, 'Pizza Karachi Downtown TO'!$F:$F), 0) | M13: =IFERROR(SUMIF('Highway Karahi'!$A:$A, B13, 'Highway Karahi'!$F:$F), 0) | O13: =IFERROR(SUMIF(Heartland!$A:$A, B13, Heartland!$F:$F), 0) | Q13: =IFERROR(SUMIF(Eglinton!$A:$A, B13, Eglinton!$F:$F), 0) | S13: =IFERROR(SUMIF(Oshawa!$A:$A, B13, Oshawa!$F:$F), 0) | U13: =IFERROR(SUMIF(Milton!$A:$A, B13, Milton!$F:$F), 0)
B14: Sidekick Combo - 14 - OO | C14: =IFERROR(SUMIF('Markham Rd'!$A:$A, B14, 'Markham Rd'!$F:$F), 0) | E14: =IFERROR(SUMIF(Ajax!$A:$A, B14, Ajax!$F:$F), 0) | G14: =IFERROR(SUMIF(Lebovic!$A:$A, B14, Lebovic!$F:$F), 0) | I14: =IFERROR(SUMIF(Wonderland!$A:$A, B14, Wonderland!$F:$F), 0) | K14: =IFERROR(SUMIF('Pizza Karachi Downtown TO'!$A:$A, B14, 'Pizza Karachi Downtown TO'!$F:$F), 0) | M14: =IFERROR(SUMIF('Highway Karahi'!$A:$A, B14, 'Highway Karahi'!$F:$F), 0) | O14: =IFERROR(SUMIF(Heartland!$A:$A, B14, Heartland!$F:$F), 0) | Q14: =IFERROR(SUMIF(Eglinton!$A:$A, B14, Eglinton!$F:$F), 0) | S14: =IFERROR(SUMIF(Oshawa!$A:$A, B14, Oshawa!$F:$F), 0) | U14: =IFERROR(SUMIF(Milton!$A:$A, B14, Milton!$F:$F), 0)
B15: Wingman Combo - 12 | C15: =IFERROR(SUMIF('Markham Rd'!$A:$A, B15, 'Markham Rd'!$F:$F), 0) | E15: =IFERROR(SUMIF(Ajax!$A:$A, B15, Ajax!$F:$F), 0) | G15: =IFERROR(SUMIF(Lebovic!$A:$A, B15, Lebovic!$F:$F), 0) | I15: =IFERROR(SUMIF(Wonderland!$A:$A, B15, Wonderland!$F:$F), 0) | K15: =IFERROR(SUMIF('Pizza Karachi Downtown TO'!$A:$A, B15, 'Pizza Karachi Downtown TO'!$F:$F), 0) | M15: =IFERROR(SUMIF('Highway Karahi'!$A:$A, B15, 'Highway Karahi'!$F:$F), 0) | O15: =IFERROR(SUMIF(Heartland!$A:$A, B15, Heartland!$F:$F), 0) | Q15: =IFERROR(SUMIF(Eglinton!$A:$A, B15, Eglinton!$F:$F), 0) | S15: =IFERROR(SUMIF(Oshawa!$A:$A, B15, Oshawa!$F:$F), 0) | U15: =IFERROR(SUMIF(Milton!$A:$A, B15, Milton!$F:$F), 0)
B16: Wingman Combo - 12 - OO | C16: =IFERROR(SUMIF('Markham Rd'!$A:$A, B16, 'Markham Rd'!$F:$F), 0) | E16: =IFERROR(SUMIF(Ajax!$A:$A, B16, Ajax!$F:$F), 0) | G16: =IFERROR(SUMIF(Lebovic!$A:$A, B16, Lebovic!$F:$F), 0) | I16: =IFERROR(SUMIF(Wonderland!$A:$A, B16, Wonderland!$F:$F), 0) | K16: =IFERROR(SUMIF('Pizza Karachi Downtown TO'!$A:$A, B16, 'Pizza Karachi Downtown TO'!$F:$F), 0) | M16: =IFERROR(SUMIF('Highway Karahi'!$A:$A, B16, 'Highway Karahi'!$F:$F), 0) | O16: =IFERROR(SUMIF(Heartland!$A:$A, B16, Heartland!$F:$F), 0) | Q16: =IFERROR(SUMIF(Eglinton!$A:$A, B16, Eglinton!$F:$F), 0) | S16: =IFERROR(SUMIF(Oshawa!$A:$A, B16, Oshawa!$F:$F), 0) | U16: =IFERROR(SUMIF(Milton!$A:$A, B16, Milton!$F:$F), 0)
B17: Wingman Combo - 14 | C17: =IFERROR(SUMIF('Markham Rd'!$A:$A, B17, 'Markham Rd'!$F:$F), 0) | E17: =IFERROR(SUMIF(Ajax!$A:$A, B17, Ajax!$F:$F), 0) | G17: =IFERROR(SUMIF(Lebovic!$A:$A, B17, Lebovic!$F:$F), 0) | I17: =IFERROR(SUMIF(Wonderland!$A:$A, B17, Wonderland!$F:$F), 0) | K17: =IFERROR(SUMIF('Pizza Karachi Downtown TO'!$A:$A, B17, 'Pizza Karachi Downtown TO'!$F:$F), 0) | M17: =IFERROR(SUMIF('Highway Karahi'!$A:$A, B17, 'Highway Karahi'!$F:$F), 0) | O17: =IFERROR(SUMIF(Heartland!$A:$A, B17, Heartland!$F:$F), 0) | Q17: =IFERROR(SUMIF(Eglinton!$A:$A, B17, Eglinton!$F:$F), 0) | S17: =IFERROR(SUMIF(Oshawa!$A:$A, B17, Oshawa!$F:$F), 0) | U17: =IFERROR(SUMIF(Milton!$A:$A, B17, Milton!$F:$F), 0)
B18: Wingman Combo - 14 - OO | C18: =IFERROR(SUMIF('Markham Rd'!$A:$A, B18, 'Markham Rd'!$F:$F), 0) | E18: =IFERROR(SUMIF(Ajax!$A:$A, B18, Ajax!$F:$F), 0) | G18: =IFERROR(SUMIF(Lebovic!$A:$A, B18, Lebovic!$F:$F), 0) | I18: =IFERROR(SUMIF(Wonderland!$A:$A, B18, Wonderland!$F:$F), 0) | K18: =IFERROR(SUMIF('Pizza Karachi Downtown TO'!$A:$A, B18, 'Pizza Karachi Downtown TO'!$F:$F), 0) | M18: =IFERROR(SUMIF('Highway Karahi'!$A:$A, B18, 'Highway Karahi'!$F:$F), 0) | O18: =IFERROR(SUMIF(Heartland!$A:$A, B18, Heartland!$F:$F), 0) | Q18: =IFERROR(SUMIF(Eglinton!$A:$A, B18, Eglinton!$F:$F), 0) | S18: =IFERROR(SUMIF(Oshawa!$A:$A, B18, Oshawa!$F:$F), 0) | U18: =IFERROR(SUMIF(Milton!$A:$A, B18, Milton!$F:$F), 0)
B19: Family Feast 12 | C19: =IFERROR(SUMIF('Markham Rd'!$A:$A, B19, 'Markham Rd'!$F:$F), 0) | E19: =IFERROR(SUMIF(Ajax!$A:$A, B19, Ajax!$F:$F), 0) | G19: =IFERROR(SUMIF(Lebovic!$A:$A, B19, Lebovic!$F:$F), 0) | I19: =IFERROR(SUMIF(Wonderland!$A:$A, B19, Wonderland!$F:$F), 0) | K19: =IFERROR(SUMIF('Pizza Karachi Downtown TO'!$A:$A, B19, 'Pizza Karachi Downtown TO'!$F:$F), 0) | M19: =IFERROR(SUMIF('Highway Karahi'!$A:$A, B19, 'Highway Karahi'!$F:$F), 0) | O19: =IFERROR(SUMIF(Heartland!$A:$A, B19, Heartland!$F:$F), 0) | Q19: =IFERROR(SUMIF(Eglinton!$A:$A, B19, Eglinton!$F:$F), 0) | S19: =IFERROR(SUMIF(Oshawa!$A:$A, B19, Oshawa!$F:$F), 0) | U19: =IFERROR(SUMIF(Milton!$A:$A, B19, Milton!$F:$F), 0)
B20: Family Feast - 12 - OO | C20: =IFERROR(SUMIF('Markham Rd'!$A:$A, B20, 'Markham Rd'!$F:$F), 0) | E20: =IFERROR(SUMIF(Ajax!$A:$A, B20, Ajax!$F:$F), 0) | G20: =IFERROR(SUMIF(Lebovic!$A:$A, B20, Lebovic!$F:$F), 0) | I20: =IFERROR(SUMIF(Wonderland!$A:$A, B20, Wonderland!$F:$F), 0) | K20: =IFERROR(SUMIF('Pizza Karachi Downtown TO'!$A:$A, B20, 'Pizza Karachi Downtown TO'!$F:$F), 0) | M20: =IFERROR(SUMIF('Highway Karahi'!$A:$A, B20, 'Highway Karahi'!$F:$F), 0) | O20: =IFERROR(SUMIF(Heartland!$A:$A, B20, Heartland!$F:$F), 0) | Q20: =IFERROR(SUMIF(Eglinton!$A:$A, B20, Eglinton!$F:$F), 0) | S20: =IFERROR(SUMIF(Oshawa!$A:$A, B20, Oshawa!$F:$F), 0) | U20: =IFERROR(SUMIF(Milton!$A:$A, B20, Milton!$F:$F), 0)
... B45: Friday 10” Classic sweet heat Qeema | C45: =IFERROR(SUMIF('Markham Rd'!$A:$A, B45, 'Markham Rd'!$F:$F), 0) | E45: =IFERROR(SUMIF(Ajax!$A:$A, B45, Ajax!$F:$F), 0) | G45: =IFERROR(SUMIF(Lebovic!$A:$A, B45, Lebovic!$F:$F), 0) | I45: =IFERROR(SUMIF(Wonderland!$A:$A, B45, Wonderland!$F:$F), 0) | K45: =IFERROR(SUMIF('Pizza Karachi Downtown TO'!$A:$A, B45, 'Pizza Karachi Downtown TO'!$F:$F), 0) | M45: =IFERROR(SUMIF('Highway Karahi'!$A:$A, B45, 'Highway Karahi'!$F:$F), 0) | O45: =IFERROR(SUMIF(Heartland!$A:$A, B45, Heartland!$F:$F), 0) | Q45: =IFERROR(SUMIF(Eglinton!$A:$A, B45, Eglinton!$F:$F), 0) | S45: =IFERROR(SUMIF(Oshawa!$A:$A, B45, Oshawa!$F:$F), 0) | U45: =IFERROR(SUMIF(Milton!$A:$A, B45, Milton!$F:$F), 0)
A46: Stuffed Crust | B46: Cheese Stuffed Crust - 10 | C46: =IFERROR(SUMIF('Markham Rd'!$A:$A, B46, 'Markham Rd'!$F:$F), 0) | E46: =IFERROR(SUMIF(Ajax!$A:$A, B46, Ajax!$F:$F), 0) | G46: =IFERROR(SUMIF(Lebovic!$A:$A, B46, Lebovic!$F:$F), 0) | I46: =IFERROR(SUMIF(Wonderland!$A:$A, B46, Wonderland!$F:$F), 0) | K46: =IFERROR(SUMIF('Pizza Karachi Downtown TO'!$A:$A, B46, 'Pizza Karachi Downtown TO'!$F:$F), 0) | M46: =IFERROR(SUMIF('Highway Karahi'!$A:$A, B46, 'Highway Karahi'!$F:$F), 0) | O46: =IFERROR(SUMIF(Heartland!$A:$A, B46, Heartland!$F:$F), 0) | Q46: =IFERROR(SUMIF(Eglinton!$A:$A, B46, Eglinton!$F:$F), 0) | S46: =IFERROR(SUMIF(Oshawa!$A:$A, B46, Oshawa!$F:$F), 0) | U46: =IFERROR(SUMIF(Milton!$A:$A, B46, Milton!$F:$F), 0) | W46: - | Y46: -
B47: P2 Cheese Stuffed Crust - 12 | C47: =IFERROR(SUMIF('Markham Rd'!$A:$A, B47, 'Markham Rd'!$F:$F), 0) | E47: =IFERROR(SUMIF(Ajax!$A:$A, B47, Ajax!$F:$F), 0) | G47: =IFERROR(SUMIF(Lebovic!$A:$A, B47, Lebovic!$F:$F), 0) | I47: =IFERROR(SUMIF(Wonderland!$A:$A, B47, Wonderland!$F:$F), 0) | K47: =IFERROR(SUMIF('Pizza Karachi Downtown TO'!$A:$A, B47, 'Pizza Karachi Downtown TO'!$F:$F), 0) | M47: =IFERROR(SUMIF('Highway Karahi'!$A:$A, B47, 'Highway Karahi'!$F:$F), 0) | O47: =IFERROR(SUMIF(Heartland!$A:$A, B47, Heartland!$F:$F), 0) | Q47: =IFERROR(SUMIF(Eglinton!$A:$A, B47, Eglinton!$F:$F), 0) | S47: =IFERROR(SUMIF(Oshawa!$A:$A, B47, Oshawa!$F:$F), 0) | U47: =IFERROR(SUMIF(Milton!$A:$A, B47, Milton!$F:$F), 0) | W47: - | Y47: -
B48: P1 Cheese Stuffed Crust - 12 | C48: =IFERROR(SUMIF('Markham Rd'!$A:$A, B48, 'Markham Rd'!$F:$F), 0) | E48: =IFERROR(SUMIF(Ajax!$A:$A, B48, Ajax!$F:$F), 0) | G48: =IFERROR(SUMIF(Lebovic!$A:$A, B48, Lebovic!$F:$F), 0) | I48: =IFERROR(SUMIF(Wonderland!$A:$A, B48, Wonderland!$F:$F), 0) | K48: =IFERROR(SUMIF('Pizza Karachi Downtown TO'!$A:$A, B48, 'Pizza Karachi Downtown TO'!$F:$F), 0) | M48: =IFERROR(SUMIF('Highway Karahi'!$A:$A, B48, 'Highway Karahi'!$F:$F), 0) | O48: =IFERROR(SUMIF(Heartland!$A:$A, B48, Heartland!$F:$F), 0) | Q48: =IFERROR(SUMIF(Eglinton!$A:$A, B48, Eglinton!$F:$F), 0) | S48: =IFERROR(SUMIF(Oshawa!$A:$A, B48, Oshawa!$F:$F), 0) | U48: =IFERROR(SUMIF(Milton!$A:$A, B48, Milton!$F:$F), 0) | W48: - | Y48: -
B49: Cheese Stuffed Crust - 12 | C49: =IFERROR(SUMIF('Markham Rd'!$A:$A, B49, 'Markham Rd'!$F:$F), 0) | E49: =IFERROR(SUMIF(Ajax!$A:$A, B49, Ajax!$F:$F), 0) | G49: =IFERROR(SUMIF(Lebovic!$A:$A, B49, Lebovic!$F:$F), 0) | I49: =IFERROR(SUMIF(Wonderland!$A:$A, B49, Wonderland!$F:$F), 0) | K49: =IFERROR(SUMIF('Pizza Karachi Downtown TO'!$A:$A, B49, 'Pizza Karachi Downtown TO'!$F:$F), 0) | M49: =IFERROR(SUMIF('Highway Karahi'!$A:$A, B49, 'Highway Karahi'!$F:$F), 0) | O49: =IFERROR(SUMIF(Heartland!$A:$A, B49, Heartland!$F:$F), 0) | Q49: =IFERROR(SUMIF(Eglinton!$A:$A, B49, Eglinton!$F:$F), 0) | S49: =IFERROR(SUMIF(Oshawa!$A:$A, B49, Oshawa!$F:$F), 0) | U49: =IFERROR(SUMIF(Milton!$A:$A, B49, Milton!$F:$F), 0) | W49: - | Y49: -
B50: Chicken Stuffed Kabab - 10 | C50: =IFERROR(SUMIF('Markham Rd'!$A:$A, B50, 'Markham Rd'!$F:$F), 0) | E50: =IFERROR(SUMIF(Ajax!$A:$A, B50, Ajax!$F:$F), 0) | G50: =IFERROR(SUMIF(Lebovic!$A:$A, B50, Lebovic!$F:$F), 0) | I50: =IFERROR(SUMIF(Wonderland!$A:$A, B50, Wonderland!$F:$F), 0) | K50: =IFERROR(SUMIF('Pizza Karachi Downtown TO'!$A:$A, B50, 'Pizza Karachi Downtown TO'!$F:$F), 0) | M50: =IFERROR(SUMIF('Highway Karahi'!$A:$A, B50, 'Highway Karahi'!$F:$F), 0) | O50: =IFERROR(SUMIF(Heartland!$A:$A, B50, Heartland!$F:$F), 0) | Q50: =IFERROR(SUMIF(Eglinton!$A:$A, B50, Eglinton!$F:$F), 0) | S50: =IFERROR(SUMIF(Oshawa!$A:$A, B50, Oshawa!$F:$F), 0) | U50: =IFERROR(SUMIF(Milton!$A:$A, B50, Milton!$F:$F), 0) | W50: - | Y50: -
B51: Chicken Stuffed Kabab - 12 | C51: =IFERROR(SUMIF('Markham Rd'!$A:$A, B51, 'Markham Rd'!$F:$F), 0) | E51: =IFERROR(SUMIF(Ajax!$A:$A, B51, Ajax!$F:$F), 0) | G51: =IFERROR(SUMIF(Lebovic!$A:$A, B51, Lebovic!$F:$F), 0) | I51: =IFERROR(SUMIF(Wonderland!$A:$A, B51, Wonderland!$F:$F), 0) | K51: =IFERROR(SUMIF('Pizza Karachi Downtown TO'!$A:$A, B51, 'Pizza Karachi Downtown TO'!$F:$F), 0) | M51: =IFERROR(SUMIF('Highway Karahi'!$A:$A, B51, 'Highway Karahi'!$F:$F), 0) | O51: =IFERROR(SUMIF(Heartland!$A:$A, B51, Heartland!$F:$F), 0) | Q51: =IFERROR(SUMIF(Eglinton!$A:$A, B51, Eglinton!$F:$F), 0) | S51: =IFERROR(SUMIF(Oshawa!$A:$A, B51, Oshawa!$F:$F), 0) | U51: =IFERROR(SUMIF(Milton!$A:$A, B51, Milton!$F:$F), 0) | W51: - | Y51: -
B52: P1 Chicken Stuffed Kabab - 12 | C52: =IFERROR(SUMIF('Markham Rd'!$A:$A, B52, 'Markham Rd'!$F:$F), 0) | E52: =IFERROR(SUMIF(Ajax!$A:$A, B52, Ajax!$F:$F), 0) | G52: =IFERROR(SUMIF(Lebovic!$A:$A, B52, Lebovic!$F:$F), 0) | I52: =IFERROR(SUMIF(Wonderland!$A:$A, B52, Wonderland!$F:$F), 0) | K52: =IFERROR(SUMIF('Pizza Karachi Downtown TO'!$A:$A, B52, 'Pizza Karachi Downtown TO'!$F:$F), 0) | M52: =IFERROR(SUMIF('Highway Karahi'!$A:$A, B52, 'Highway Karahi'!$F:$F), 0) | O52: =IFERROR(SUMIF(Heartland!$A:$A, B52, Heartland!$F:$F), 0) | Q52: =IFERROR(SUMIF(Eglinton!$A:$A, B52, Eglinton!$F:$F), 0) | S52: =IFERROR(SUMIF(Oshawa!$A:$A, B52, Oshawa!$F:$F), 0) | U52: =IFERROR(SUMIF(Milton!$A:$A, B52, Milton!$F:$F), 0) | W52: - | Y52: -
B53: P2 Chicken Stuffed Kabab - 12 | C53: =IFERROR(SUMIF('Markham Rd'!$A:$A, B53, 'Markham Rd'!$F:$F), 0) | E53: =IFERROR(SUMIF(Ajax!$A:$A, B53, Ajax!$F:$F), 0) | G53: =IFERROR(SUMIF(Lebovic!$A:$A, B53, Lebovic!$F:$F), 0) | I53: =IFERROR(SUMIF(Wonderland!$A:$A, B53, Wonderland!$F:$F), 0) | K53: =IFERROR(SUMIF('Pizza Karachi Downtown TO'!$A:$A, B53, 'Pizza Karachi Downtown TO'!$F:$F), 0) | M53: =IFERROR(SUMIF('Highway Karahi'!$A:$A, B53, 'Highway Karahi'!$F:$F), 0) | O53: =IFERROR(SUMIF(Heartland!$A:$A, B53, Heartland!$F:$F), 0) | Q53: =IFERROR(SUMIF(Eglinton!$A:$A, B53, Eglinton!$F:$F), 0) | S53: =IFERROR(SUMIF(Oshawa!$A:$A, B53, Oshawa!$F:$F), 0) | U53: =IFERROR(SUMIF(Milton!$A:$A, B53, Milton!$F:$F), 0) | W53: - | Y53: -
B54: Beef Stuffed Kabab - 12 | C54: =IFERROR(SUMIF('Markham Rd'!$A:$A, B54, 'Markham Rd'!$F:$F), 0) | E54: =IFERROR(SUMIF(Ajax!$A:$A, B54, Ajax!$F:$F), 0) | G54: =IFERROR(SUMIF(Lebovic!$A:$A, B54, Lebovic!$F:$F), 0) | I54: =IFERROR(SUMIF(Wonderland!$A:$A, B54, Wonderland!$F:$F), 0) | K54: =IFERROR(SUMIF('Pizza Karachi Downtown TO'!$A:$A, B54, 'Pizza Karachi Downtown TO'!$F:$F), 0) | M54: =IFERROR(SUMIF('Highway Karahi'!$A:$A, B54, 'Highway Karahi'!$F:$F), 0) | O54: =IFERROR(SUMIF(Heartland!$A:$A, B54, Heartland!$F:$F), 0) | Q54: =IFERROR(SUMIF(Eglinton!$A:$A, B54, Eglinton!$F:$F), 0) | S54: =IFERROR(SUMIF(Oshawa!$A:$A, B54, Oshawa!$F:$F), 0) | U54: =IFERROR(SUMIF(Milton!$A:$A, B54, Milton!$F:$F), 0) | W54: - | Y54: -
B55: P1 Beef Stuffed Kabab - 12 | C55: =IFERROR(SUMIF('Markham Rd'!$A:$A, B55, 'Markham Rd'!$F:$F), 0) | E55: =IFERROR(SUMIF(Ajax!$A:$A, B55, Ajax!$F:$F), 0) | G55: =IFERROR(SUMIF(Lebovic!$A:$A, B55, Lebovic!$F:$F), 0) | I55: =IFERROR(SUMIF(Wonderland!$A:$A, B55, Wonderland!$F:$F), 0) | K55: =IFERROR(SUMIF('Pizza Karachi Downtown TO'!$A:$A, B55, 'Pizza Karachi Downtown TO'!$F:$F), 0) | M55: =IFERROR(SUMIF('Highway Karahi'!$A:$A, B55, 'Highway Karahi'!$F:$F), 0) | O55: =IFERROR(SUMIF(Heartland!$A:$A, B55, Heartland!$F:$F), 0) | Q55: =IFERROR(SUMIF(Eglinton!$A:$A, B55, Eglinton!$F:$F), 0) | S55: =IFERROR(SUMIF(Oshawa!$A:$A, B55, Oshawa!$F:$F), 0) | U55: =IFERROR(SUMIF(Milton!$A:$A, B55, Milton!$F:$F), 0) | W55: - | Y55: -
B56: P2 Beef Stuffed Kabab - 12 | C56: =IFERROR(SUMIF('Markham Rd'!$A:$A, B56, 'Markham Rd'!$F:$F), 0) | E56: =IFERROR(SUMIF(Ajax!$A:$A, B56, Ajax!$F:$F), 0) | G56: =IFERROR(SUMIF(Lebovic!$A:$A, B56, Lebovic!$F:$F), 0) | I56: =IFERROR(SUMIF(Wonderland!$A:$A, B56, Wonderland!$F:$F), 0) | K56: =IFERROR(SUMIF('Pizza Karachi Downtown TO'!$A:$A, B56, 'Pizza Karachi Downtown TO'!$F:$F), 0) | M56: =IFERROR(SUMIF('Highway Karahi'!$A:$A, B56, 'Highway Karahi'!$F:$F), 0) | O56: =IFERROR(SUMIF(Heartland!$A:$A, B56, Heartland!$F:$F), 0) | Q56: =IFERROR(SUMIF(Eglinton!$A:$A, B56, Eglinton!$F:$F), 0) | S56: =IFERROR(SUMIF(Oshawa!$A:$A, B56, Oshawa!$F:$F), 0) | U56: =IFERROR(SUMIF(Milton!$A:$A, B56, Milton!$F:$F), 0) | W56: - | Y56: -
B57: Beef Stuffed Kabab - 10 | C57: =IFERROR(SUMIF('Markham Rd'!$A:$A, B57, 'Markham Rd'!$F:$F), 0) | E57: =IFERROR(SUMIF(Ajax!$A:$A, B57, Ajax!$F:$F), 0) | G57: =IFERROR(SUMIF(Lebovic!$A:$A, B57, Lebovic!$F:$F), 0) | I57: =IFERROR(SUMIF(Wonderland!$A:$A, B57, Wonderland!$F:$F), 0) | K57: =IFERROR(SUMIF('Pizza Karachi Downtown TO'!$A:$A, B57, 'Pizza Karachi Downtown TO'!$F:$F), 0) | M57: =IFERROR(SUMIF('Highway Karahi'!$A:$A, B57, 'Highway Karahi'!$F:$F), 0) | O57: =IFERROR(SUMIF(Heartland!$A:$A, B57, Heartland!$F:$F), 0) | Q57: =IFERROR(SUMIF(Eglinton!$A:$A, B57, Eglinton!$F:$F), 0) | S57: =IFERROR(SUMIF(Oshawa!$A:$A, B57, Oshawa!$F:$F), 0) | U57: =IFERROR(SUMIF(Milton!$A:$A, B57, Milton!$F:$F), 0) | W57: - | Y57: -
B58: Total Stuffed Crust | C58: =SUM(C46:C57) | E58: =SUM(E46:E57) | G58: =SUM(G46:G57) | I58: =SUM(I46:I57) | K58: =SUM(K46:K57) | M58: =SUM(M46:M57) | O58: =SUM(O46:O57) | Q58: =SUM(Q46:Q57) | S58: =SUM(S46:S57) | U58: =SUM(U46:U57)
A59: Karachi Kabab Wala and Food Court | B59: Frozen Haleem | C59: - | E59: - | G59: - | I59: - | K59: - | M59: - | O59: - | Q59: - | S59: - | U59: - | W59: =IFERROR(SUMIF('Karachi Food Court'!$A:$A, B59, 'Karachi Food Court'!$F:$F), 0) | Y59: =IFERROR(SUMIF('Karachi Kabab Wala'!$A:$A, B59, 'Karachi Kabab Wala'!$F:$F), 0)
B60: Frozen Hari Mirch Chicken Qeema | C60: - | E60: - | G60: - | I60: - | K60: - | M60: - | O60: - | Q60: - | S60: - | U60: - | W60: =IFERROR(SUMIF('Karachi Food Court'!$A:$A, B60, 'Karachi Food Court'!$F:$F), 0) | Y60: =IFERROR(SUMIF('Karachi Kabab Wala'!$A:$A, B60, 'Karachi Kabab Wala'!$F:$F), 0)
B61: Beef Lover Platter | C61: - | E61: - | G61: - | I61: - | K61: - | M61: - | O61: - | Q61: - | S61: - | U61: - | W61: =IFERROR(SUMIF('Karachi Food Court'!$A:$A, B61, 'Karachi Food Court'!$F:$F), 0) | Y61: =IFERROR(SUMIF('Karachi Kabab Wala'!$A:$A, B61, 'Karachi Kabab Wala'!$F:$F), 0) | AA61: =IFERROR(SUMIF('Karachi Kabab Wala - Queen'!$A:$A, B61, 'Karachi Kabab Wala - Queen'!$F:$F), 0)
B62: Chicken Lover Platter | C62: - | E62: - | G62: - | I62: - | K62: - | M62: - | O62: - | Q62: - | S62: - | U62: - | W62: =IFERROR(SUMIF('Karachi Food Court'!$A:$A, B62, 'Karachi Food Court'!$F:$F), 0) | Y62: =IFERROR(SUMIF('Karachi Kabab Wala'!$A:$A, B62, 'Karachi Kabab Wala'!$F:$F), 0) | AA62: =IFERROR(SUMIF('Karachi Kabab Wala - Queen'!$A:$A, B62, 'Karachi Kabab Wala - Queen'!$F:$F), 0)
B63: Mix Platter | C63: - | E63: - | G63: - | I63: - | K63: - | M63: - | O63: - | Q63: - | S63: - | U63: - | W63: =IFERROR(SUMIF('Karachi Food Court'!$A:$A, B63, 'Karachi Food Court'!$F:$F), 0) | Y63: =IFERROR(SUMIF('Karachi Kabab Wala'!$A:$A, B63, 'Karachi Kabab Wala'!$F:$F), 0) | AA63: =IFERROR(SUMIF('Karachi Kabab Wala - Queen'!$A:$A, B63, 'Karachi Kabab Wala - Queen'!$F:$F), 0)
B64: Premium Platter (KKW) | C64: - | E64: - | G64: - | I64: - | K64: - | M64: - | O64: - | Q64: - | S64: - | U64: - | W64: =IFERROR(SUMIF('Karachi Food Court'!$A:$A, B64, 'Karachi Food Court'!$F:$F), 0) | Y64: =IFERROR(SUMIF('Karachi Kabab Wala'!$A:$A, B64, 'Karachi Kabab Wala'!$F:$F), 0) | AA64: =IFERROR(SUMIF('Karachi Kabab Wala - Queen'!$A:$A, B64, 'Karachi Kabab Wala - Queen'!$F:$F), 0)
B65: Lunch Deal (KKW) | C65: - | E65: - | G65: - | I65: - | K65: - | M65: - | O65: - | Q65: - | S65: - | U65: - | W65: =IFERROR(SUMIF('Karachi Food Court'!$A:$A, B65, 'Karachi Food Court'!$F:$F), 0) | Y65: =IFERROR(SUMIF('Karachi Kabab Wala'!$A:$A, B65, 'Karachi Kabab Wala'!$F:$F), 0) | AA65: =IFERROR(SUMIF('Karachi Kabab Wala - Queen'!$A:$A, B65, 'Karachi Kabab Wala - Queen'!$F:$F), 0)
...
