Workbook

Sheet Karachi Kabab Wala - Queen
A1: Karachi Kabab Wala - Queen Street - Sales By Menu Item - 2026-02-16/2026-03-22
A2: "Menu Item" | B2: "Sales Category" | C2: "Menu Group" | D2: "Menu Item Void Quantity" | E2: "Voids" | F2: "Menu Item Quantity" | G2: "Gross Sales" | H2: "Item Discounts" | I2: "Bill Discounts" | J2: "Net Sales" | K2: "Menu Item Quantity (Refunds)" | L2: "Refund Amount (Net Sales)" | M2: "Sales Percentage" | N2: "Tax 1" | O2: "Tax 2" | P2: "Tax 3"
A3: 10 Klassic Wings | B3: Food | C3: Wings | D3: 0 | E3: 0 | F3: 1 | G3: 15 | H3: 0 | I3: 0 | J3: 15 | K3: 0 | L3: 0 | M3: 0.0003 | N3: 1.95 | O3: 0 | P3: 0.00
A4: 2 Can Dine - D | B4: Kabab Wala | C4: DEALS - KKW - OO | D4: 0 | E4: 0 | F4: 5 | G4: 199.95 | H4: 0 | I4: 0 | J4: 199.95 | K4: 0 | L4: 0 | M4: 0.0043 | N4: 25.99 | O4: 0 | P4: 0.00
A5: 2 Can Dine for $29.99 | B5: Kabab Wala | C5: Chef Special and Deals (KKW) | D5: 1 | E5: 29.99 | F5: 30 | G5: 899.7 | H5: 0 | I5: 0 | J5: 899.7 | K5: 0 | L5: 0 | M5: 0.0192 | N5: 116.96 | O5: 0 | P5: 0.00
A6: 2 for $10 Lassi | B6: Kabab Wala | C6: Chef Special and Deals (KKW) | D6: 1 | E6: 10 | F6: 4 | G6: 40 | H6: 0 | I6: 0 | J6: 40 | K6: 0 | L6: 0 | M6: 0.0009 | N6: 5.2 | O6: 0 | P6: 0.00
A7: 2Reshmi Kabab - Deal | B7: Kabab Wala | C7: BBQ | D7: 2 | E7: 11 | F7: 10 | G7: 0 | H7: 0 | I7: 0 | J7: 0 | K7: 0 | L7: 0 | M7: 0 | N7: 0 | O7: 0 | P7: 0.00
A8: 2Reshmi Kabab - Deal | B8: Kabab Wala | C8: Chef Special and Deals (KKW) | D8: 0 | E8: 0 | F8: 1 | G8: 0 | H8: 0 | I8: 0 | J8: 0 | K8: 0 | L8: 0 | M8: 0 | N8: 0 | O8: 0 | P8: 0.00
A9: 2Seekh Kabab - Deal | B9: Kabab Wala | C9: BBQ | D9: 1 | E9: 0 | F9: 7 | G9: 0 | H9: 0 | I9: 0 | J9: 0 | K9: 0 | L9: 0 | M9: 0 | N9: 0 | O9: 0 | P9: 0.00
A10: 2Seekh Kabab - Deal | B10: Kabab Wala | C10: Chef Special and Deals (KKW) | D10: 0 | E10: 0 | F10: 2 | G10: 0 | H10: 0 | I10: 0 | J10: 0 | K10: 0 | L10: 0 | M10: 0 | N10: 0 | O10: 0 | P10: 0.00
A11: 7up - OO | B11: Food Court | C11: Drinks (FC) - OO | D11: 0 | E11: 0 | F11: 1 | G11: 3.59 | H11: 0 | I11: 0 | J11: 3.59 | K11: 0 | L11: 0 | M11: 0.0001 | N11: 0.47 | O11: 0 | P11: 0.00
A12: 7up Bottle | B12: Kabab Wala | C12: Drinks (FC) | D12: 0 | E12: 0 | F12: 1 | G12: 3.25 | H12: 0 | I12: 0 | J12: 3.25 | K12: 0 | L12: 0 | M12: 0.0001 | N12: 0.42 | O12: 0 | P12: 0.00
A13: Add Add Cheese - D | B13: Food | C13: *Food Hidden Modifiers - D | D13: 0 | E13: 0 | F13: 1 | G13: 0 | H13: 0 | I13: 0 | J13: 0 | K13: 0 | L13: 0 | M13: 0 | N13: 0 | O13: 0 | P13: 0.00
A14: Add Cheese | B14: Food Court | C14: *Hidden Food Mod | D14: 0 | E14: 0 | F14: 1 | G14: 1.5 | H14: 0 | I14: 0 | J14: 1.5 | K14: 0 | L14: 0 | M14: 0 | N14: 0.2 | O14: 0 | P14: 0.00
... A278: w/ Spicy Honey Garlic | B278: Food | C278: Wings | D278: 0 | E278: 0 | F278: 1 | G278: 0 | H278: 0 | I278: 0 | J278: 0 | K278: 0 | L278: 0 | M278: 0 | N278: 0 | O278: 0 | P278: 0.00
A279: REPORT SUMMARY (276 entries) | D279: 73 | E279: 485.91 | F279: 5661 | G279: 46894.84 | H279: 0 | I279: 0 | J279: 46894.84 | K279: 0 | L279: 0 | M279: 0.9999 | N279: 6011.48 | O279: 0 | P279: 0.00

Sheet Eglinton
A1: Pizza Karachi- Eglinton - Sales By Menu Item - 2026-02-16/2026-03-22
A2: "Menu Item" | B2: "Sales Category" | C2: "Menu Group" | D2: "Menu Item Void Quantity" | E2: "Voids" | F2: "Menu Item Quantity" | G2: "Gross Sales" | H2: "Item Discounts" | I2: "Bill Discounts" | J2: "Net Sales" | K2: "Menu Item Quantity (Refunds)" | L2: "Refund Amount (Net Sales)" | M2: "Sales Percentage" | N2: "Tax 1" | O2: "Tax 2" | P2: "Tax 3"
A3: 1 Topp - 10 | B3: Food | C3: Klassic Pizza | D3: 0 | E3: 0 | F3: 3 | G3: 39 | H3: 0 | I3: 0 | J3: 39 | K3: 0 | L3: 0 | M3: 0.0002 | N3: 5.07 | O3: 0 | P3: 0.00
A4: 1 Topp - 12 | B4: Food | C4: Klassic Pizza | D4: 0 | E4: 0 | F4: 17 | G4: 255 | H4: 0 | I4: 0 | J4: 255 | K4: 0 | L4: 0 | M4: 0.0014 | N4: 33.15 | O4: 0 | P4: 0.00
A5: 1 Topp - 12 (New Crust) | B5: Food | C5: Signature Classic Crust Pizza | D5: 0 | E5: 0 | F5: 1 | G5: 13.99 | H5: 0 | I5: 0 | J5: 13.99 | K5: 0 | L5: 0 | M5: 0.0001 | N5: 1.82 | O5: 0 | P5: 0.00
A6: 1 Topp - 8 | B6: Food | C6: Klassic Pizza | D6: 0 | E6: 0 | F6: 3 | G6: 33 | H6: 0 | I6: 0 | J6: 33 | K6: 0 | L6: 0 | M6: 0.0002 | N6: 4.29 | O6: 0 | P6: 0.00
A7: 10 Baked Wings | B7: Food | C7: Wings | D7: 0 | E7: 0 | F7: 3 | G7: 45 | H7: 0 | I7: 0 | J7: 45 | K7: 0 | L7: 0 | M7: 0.0002 | N7: 5.85 | O7: 0 | P7: 0.00
A8: 10 Chargha Wings | B8: Food | C8: Wings | D8: 0 | E8: 0 | F8: 33 | G8: 495 | H8: 0 | I8: 0 | J8: 495 | K8: 0 | L8: 0 | M8: 0.0026 | N8: 64.35 | O8: 0 | P8: 0.00
A9: 10 Chargha Wings - OO | B9: Food | C9: Wings - OO | D9: 0 | E9: 0 | F9: 9 | G9: 162 | H9: 0 | I9: 0 | J9: 162 | K9: 0 | L9: 0 | M9: 0.0009 | N9: 21.06 | O9: 0 | P9: 0.00
A10: 10 Klassic Wings | B10: Food | C10: Wings | D10: 0 | E10: 0 | F10: 24 | G10: 360 | H10: 0 | I10: 0 | J10: 360 | K10: 0 | L10: 0 | M10: 0.0019 | N10: 46.8 | O10: 0 | P10: 0.00
A11: 10 Klassic Wings - OO | B11: Food | C11: Wings - OO | D11: 0 | E11: 0 | F11: 22 | G11: 396 | H11: 0 | I11: 0 | J11: 396 | K11: 0 | L11: 0 | M11: 0.0021 | N11: 51.48 | O11: 0 | P11: 0.00
A12: 10 Koated Wings | B12: Food | C12: Wings | D12: 0 | E12: 0 | F12: 48 | G12: 720 | H12: 0 | I12: 0 | J12: 720 | K12: 0 | L12: 0 | M12: 0.0038 | N12: 93.6 | O12: 0 | P12: 0.00
A13: 10 Koated Wings - OO | B13: Food | C13: Wings - OO | D13: 0 | E13: 0 | F13: 4 | G13: 72 | H13: 0 | I13: 0 | J13: 72 | K13: 0 | L13: 0 | M13: 0.0004 | N13: 9.36 | O13: 0 | P13: 0.00
A14: 20 Baked Wings | B14: Food | C14: Wings | D14: 0 | E14: 0 | F14: 1 | G14: 23.49 | H14: 0 | I14: 0 | J14: 23.49 | K14: 0 | L14: 0 | M14: 0.0001 | N14: 3.05 | O14: 0 | P14: 0.00
... A859: w/ Tzatziki Sauce - D | B859: Food | C859: *Food Hidden Modifiers - D | D859: 0 | E859: 0 | F859: 158 | G859: 0 | H859: 0 | I859: 0 | J859: 0 | K859: 0 | L859: 0 | M859: 0 | N859: 0 | O859: 0 | P859: 0.00
A860: REPORT SUMMARY (857 entries) | D860: 0 | E860: 0 | F860: 34561 | G860: 188044.11 | H860: 19.5 | I860: 0 | J860: 188024.61 | K860: 0 | L860: 0 | M860: 0.9997 | N860: 24441.23 | O860: 0 | P860: 0.00

Sheet Heartland
A1: Pizza Karachi -Heartland - Sales By Menu Item - 2026-02-16/2026-03-22
A2: "Menu Item" | B2: "Sales Category" | C2: "Menu Group" | D2: "Menu Item Void Quantity" | E2: "Voids" | F2: "Menu Item Quantity" | G2: "Gross Sales" | H2: "Item Discounts" | I2: "Bill Discounts" | J2: "Net Sales" | K2: "Menu Item Quantity (Refunds)" | L2: "Refund Amount (Net Sales)" | M2: "Sales Percentage" | N2: "Tax 1" | O2: "Tax 2" | P2: "Tax 3"
A3: 1 Topp - 12 | B3: Food | C3: Klassic Pizza | D3: 0 | E3: 0 | F3: 7 | G3: 105 | H3: 0 | I3: 0 | J3: 105 | K3: 0 | L3: 0 | M3: 0.0011 | N3: 13.65 | O3: 0 | P3: 0.00
A4: 1 Topp - 8 | B4: Food | C4: Klassic Pizza | D4: 0 | E4: 0 | F4: 2 | G4: 22 | H4: 0 | I4: 0 | J4: 22 | K4: 0 | L4: 0 | M4: 0.0002 | N4: 2.86 | O4: 0 | P4: 0.00
A5: 10 Baked Wings | B5: Food | C5: Wings | D5: 0 | E5: 0 | F5: 1 | G5: 15 | H5: 0 | I5: 0 | J5: 15 | K5: 0 | L5: 0 | M5: 0.0002 | N5: 1.95 | O5: 0 | P5: 0.00
A6: 10 Chargha Wings | B6: Food | C6: Wings | D6: 4 | E6: 60 | F6: 14 | G6: 210 | H6: 0 | I6: 0 | J6: 210 | K6: 0 | L6: 0 | M6: 0.0022 | N6: 27.3 | O6: 0 | P6: 0.00
A7: 10 Chargha Wings - OO | B7: Food | C7: Wings - OO | D7: 0 | E7: 0 | F7: 8 | G7: 144 | H7: 0 | I7: 0 | J7: 144 | K7: 0 | L7: 0 | M7: 0.0015 | N7: 18.72 | O7: 0 | P7: 0.00
A8: 10 Klassic Wings | B8: Food | C8: Wings | D8: 1 | E8: 15 | F8: 15 | G8: 225 | H8: 0 | I8: 0 | J8: 225 | K8: 0 | L8: 0 | M8: 0.0024 | N8: 29.25 | O8: 0 | P8: 0.00
A9: 10 Klassic Wings - OO | B9: Food | C9: Wings - OO | D9: 0 | E9: 0 | F9: 5 | G9: 90 | H9: 0 | I9: 0 | J9: 90 | K9: 0 | L9: 0 | M9: 0.0009 | N9: 11.7 | O9: 0 | P9: 0.00
A10: 10 Koated Wings | B10: Food | C10: Wings | D10: 2 | E10: 30 | F10: 6 | G10: 90 | H10: 0 | I10: 0 | J10: 90 | K10: 0 | L10: 0 | M10: 0.0009 | N10: 11.7 | O10: 0 | P10: 0.00
A11: 10 Koated Wings - OO | B11: Food | C11: Wings - OO | D11: 0 | E11: 0 | F11: 6 | G11: 108 | H11: 0 | I11: 0 | J11: 108 | K11: 0 | L11: 0 | M11: 0.0011 | N11: 14.04 | O11: 0 | P11: 0.00
A12: 2 Hot Drinks - $6 | B12: KT Icecream | C12: Klassic Flavors | D12: 1 | E12: 6 | F12: 21 | G12: 126 | H12: 0 | I12: 0 | J12: 126 | K12: 0 | L12: 0 | M12: 0.0013 | N12: 16.38 | O12: 0 | P12: 0.00
A13: 2 Zinger Burger Meal - D | B13: Chickentarian | C13: Deals Chickentarian - OO | D13: 0 | E13: 0 | F13: 1 | G13: 24.99 | H13: 0 | I13: 0 | J13: 24.99 | K13: 0 | L13: 0 | M13: 0.0003 | N13: 3.25 | O13: 0 | P13: 0.00
A14: 2 Zinger Meal (Double Sawari) | B14: Chickentarian | C14: Deals Chickentarian | D14: 0 | E14: 0 | F14: 14 | G14: 279.86 | H14: 0 | I14: 0 | J14: 279.86 | K14: 0 | L14: 0 | M14: 0.0029 | N14: 36.38 | O14: 0 | P14: 0.00
... A773: w/ Tzatziki Sauce - D | B773: Food | C773: *Food Hidden Modifiers - D | D773: 0 | E773: 0 | F773: 94 | G773: 0 | H773: 0 | I773: 0 | J773: 0 | K773: 0 | L773: 0 | M773: 0 | N773: 0 | O773: 0 | P773: 0.00
A774: REPORT SUMMARY (771 entries) | D774: 543 | E774: 2782.83 | F774: 16678 | G774: 94921.99 | H774: 0 | I774: 0 | J774: 94921.99 | K774: 0 | L774: 0 | M774: 0.9998 | N774: 12334.85 | O774: 0 | P774: 0.00

Sheet Karachi Kabab Wala
A1: Karachi Kabab Wala - Sales By Menu Item - 2026-02-16/2026-03-22
A2: "Menu Item" | B2: "Sales Category" | C2: "Menu Group" | D2: "Menu Item Void Quantity" | E2: "Voids" | F2: "Menu Item Quantity" | G2: "Gross Sales" | H2: "Item Discounts" | I2: "Bill Discounts" | J2: "Net Sales" | K2: "Menu Item Quantity (Refunds)" | L2: "Refund Amount (Net Sales)" | M2: "Sales Percentage" | N2: "Tax 1" | O2: "Tax 2" | P2: "Tax 3"
A3: 2 Can Dine - D | B3: Kabab Wala | C3: Deals (KKWnew) - OO | D3: 0 | E3: 0 | F3: 2 | G3: 79.98 | H3: 0 | I3: 0 | J3: 79.98 | K3: 0 | L3: 0 | M3: 0.001 | N3: 10.4 | O3: 0 | P3: 0.00
A4: 2 Can Dine for $29.99 | B4: Kabab Wala | C4: Chef Special and Deals (KKW) | D4: 0 | E4: 0 | F4: 11 | G4: 329.89 | H4: 0 | I4: 0 | J4: 329.89 | K4: 0 | L4: 0 | M4: 0.0042 | N4: 42.89 | O4: 0 | P4: 0.00
A5: 2 for $10 Lassi | B5: Kabab Wala | C5: Chef Special and Deals (KKW) | D5: 0 | E5: 0 | F5: 1 | G5: 10 | H5: 0 | I5: 0 | J5: 10 | K5: 0 | L5: 0 | M5: 0.0001 | N5: 1.3 | O5: 0 | P5: 0.00
A6: 2Reshmi Kabab - Deal | B6: Kabab Wala | C6: Chef Special and Deals (KKW) | D6: 0 | E6: 0 | F6: 1 | G6: 0 | H6: 0 | I6: 0 | J6: 0 | K6: 0 | L6: 0 | M6: 0 | N6: 0 | O6: 0 | P6: 0.00
A7: 2Reshmi Kabab - Deal | B7: Kabab Wala | C7: BBQ | D7: 0 | E7: 0 | F7: 1 | G7: 0 | H7: 0 | I7: 0 | J7: 0 | K7: 0 | L7: 0 | M7: 0 | N7: 0 | O7: 0 | P7: 0.00
A8: 2Seekh Kabab - Deal | B8: Kabab Wala | C8: BBQ | D8: 2 | E8: 24 | F8: 16 | G8: 180 | H8: 0 | I8: 0 | J8: 180 | K8: 0 | L8: 0 | M8: 0.0023 | N8: 23.4 | O8: 0 | P8: 0.00
A9: 2Seekh Kabab - Deal | B9: Kabab Wala | C9: Chef Special and Deals (KKW) | D9: 0 | E9: 0 | F9: 2 | G9: 0 | H9: 0 | I9: 0 | J9: 0 | K9: 0 | L9: 0 | M9: 0 | N9: 0 | O9: 0 | P9: 0.00
A10: Add Add Cheese - D | B10: Food | C10: *Food Hidden Modifiers - D | D10: 0 | E10: 0 | F10: 3 | G10: 5.4 | H10: 0 | I10: 0 | J10: 5.4 | K10: 0 | L10: 0 | M10: 0.0001 | N10: 0.7 | O10: 0 | P10: 0.00
A11: Add Cheese | B11: Food Court | C11: *Hidden Food Mod | D11: 0 | E11: 0 | F11: 1 | G11: 1.5 | H11: 0 | I11: 0 | J11: 1.5 | K11: 0 | L11: 0 | M11: 0 | N11: 0.2 | O11: 0 | P11: 0.00
A12: Add Cheese - D | B12: Food | C12: *Food Hidden Modifiers - D | D12: 0 | E12: 0 | F12: 1 | G12: 1.8 | H12: 0 | I12: 0 | J12: 1.8 | K12: 0 | L12: 0 | M12: 0 | N12: 0.23 | O12: 0 | P12: 0.00
A13: Add Chutney - D | B13: Food | C13: *Food Hidden Modifiers - D | D13: 0 | E13: 0 | F13: 16 | G13: 19.2 | H13: 0 | I13: 0 | J13: 19.2 | K13: 0 | L13: 0 | M13: 0.0002 | N13: 1.56 | O13: 0 | P13: 0.00
A14: Add Coleslaw - D | B14: Food | C14: *Food Hidden Modifiers - D | D14: 0 | E14: 0 | F14: 3 | G14: 0 | H14: 0 | I14: 0 | J14: 0 | K14: 0 | L14: 0 | M14: 0 | N14: 0 | O14: 0 | P14: 0.00
... A211: w/ Pepsi Can - D - KKW | B211: Kabab Wala | C211: *Food Hidden Modifiers - D | D211: 0 | E211: 0 | F211: 5 | G211: 0 | H211: 0 | I211: 0 | J211: 0 | K211: 0 | L211: 0 | M211: 0 | N211: 0 | O211: 0 | P211: 0.00
A212: REPORT SUMMARY (209 entries) | D212: 316 | E212: 2636.5 | F212: 8738 | G212: 79327.07 | H212: 0 | I212: 0 | J212: 79327.07 | K212: 0 | L212: 0 | M212: 0.9999 | N212: 9446.29 | O212: 0 | P212: 0.00

Sheet Karachi Food Court
A1: Karachi Food Court - Sales By Menu Item - 2026-02-16/2026-03-22
A2: "Menu Item" | B2: "Sales Category" | C2: "Menu Group" | D2: "Menu Item Void Quantity" | E2: "Voids" | F2: "Menu Item Quantity" | G2: "Gross Sales" | H2: "Item Discounts" | I2: "Bill Discounts" | J2: "Net Sales" | K2: "Menu Item Quantity (Refunds)" | L2: "Refund Amount (Net Sales)" | M2: "Sales Percentage" | N2: "Tax 1" | O2: "Tax 2" | P2: "Tax 3"
A3: 2 Fried Eggs | B3: Food Court | C3: Breakfast | D3: 1 | E3: 6.99 | F3: 5 | G3: 34.95 | H3: 0 | I3: 0 | J3: 34.95 | K3: 0 | L3: 0 | M3: 0.0001 | N3: 4.54 | O3: 0 | P3: 0.00
A4: 2pc Karachi Broast (ONLY) | B4: Chickentarian | C4: Broast | D4: 1 | E4: 7.99 | F4: 15 | G4: 95.93 | H4: 0 | I4: 0 | J4: 95.93 | K4: 0 | L4: 0 | M4: 0.0004 | N4: 12.47 | O4: 0 | P4: 0.00
A5: 2pc Karachi Broast (ONLY) - OO | B5: Chickentarian | C5: Broast - OO | D5: 0 | E5: 0 | F5: 11 | G5: 105.49 | H5: 0 | I5: 0 | J5: 105.49 | K5: 0 | L5: 0 | M5: 0.0004 | N5: 13.71 | O5: 0 | P5: 0.00
A6: 2pc Karachi Broast (With Fries and Cole) | B6: Chickentarian | C6: Broast | D6: 0 | E6: 0 | F6: 20 | G6: 209.8 | H6: 0 | I6: 0 | J6: 209.8 | K6: 0 | L6: 0 | M6: 0.0008 | N6: 27.27 | O6: 0 | P6: 0.00
A7: 2pc Karachi Broast (With Fries and Cole) - OO | B7: Chickentarian | C7: Broast - OO | D7: 0 | E7: 0 | F7: 5 | G7: 62.95 | H7: 0 | I7: 0 | J7: 62.95 | K7: 0 | L7: 0 | M7: 0.0002 | N7: 8.18 | O7: 0 | P7: 0.00
A8: 3pc Karachi Broast (ONLY) | B8: Chickentarian | C8: Broast | D8: 2 | E8: 21.98 | F8: 76 | G8: 835.24 | H8: 0 | I8: 0 | J8: 835.24 | K8: 0 | L8: 0 | M8: 0.003 | N8: 108.58 | O8: 0 | P8: 0.00
A9: 3pc Karachi Broast (ONLY) - OO | B9: Chickentarian | C9: Broast - OO | D9: 0 | E9: 0 | F9: 6 | G9: 79.14 | H9: 0 | I9: 0 | J9: 79.14 | K9: 0 | L9: 0 | M9: 0.0003 | N9: 10.29 | O9: 0 | P9: 0.00
A10: 3pc Karachi Broast (With Fries and Cole) | B10: Chickentarian | C10: Broast | D10: 3 | E10: 40.47 | F10: 133 | G10: 1794.17 | H10: 0 | I10: 0 | J10: 1794.17 | K10: 0 | L10: 0 | M10: 0.0065 | N10: 233.24 | O10: 0 | P10: 0.00
A11: 3pc Karachi Broast (With Fries and Cole) - OO | B11: Chickentarian | C11: Broast - OO | D11: 0 | E11: 0 | F11: 28 | G11: 453.32 | H11: 0 | I11: 0 | J11: 453.32 | K11: 0 | L11: 0 | M11: 0.0017 | N11: 58.93 | O11: 0 | P11: 0.00
A12: 7up Bottle | B12: Kabab Wala | C12: Drinks (FC) | D12: 0 | E12: 0 | F12: 1 | G12: 3.25 | H12: 0 | I12: 0 | J12: 3.25 | K12: 0 | L12: 0 | M12: 0 | N12: 0.42 | O12: 0 | P12: 0.00
A13: 9pc Karachi Broast (ONLY) | B13: Chickentarian | C13: Broast | D13: 1 | E13: 26.99 | F13: 15 | G13: 404.85 | H13: 0 | I13: 0 | J13: 404.85 | K13: 0 | L13: 0 | M13: 0.0015 | N13: 52.63 | O13: 0 | P13: 0.00
A14: 9pc Karachi Broast (ONLY) - OO | B14: Chickentarian | C14: Broast - OO | D14: 0 | E14: 0 | F14: 3 | G14: 97.17 | H14: 0 | I14: 0 | J14: 97.17 | K14: 0 | L14: 0 | M14: 0.0004 | N14: 12.63 | O14: 0 | P14: 0.00
... A426: w/ Diet Pepsi Can - D | B426: Food | C426: *Food Hidden Modifiers - D | D426: 0 | E426: 0 | F426: 1 | G426: 0 | H426: 0 | I426: 0 | J426: 0 | K426: 0 | L426: 0 | M426: 0 | N426: 0 | O426: 0 | P426: 0.00
A427: REPORT SUMMARY (424 entries) | D427: 718 | E427: 6609.51 | F427: 32287 | G427: 274071.52 | H427: 0 | I427: 0 | J427: 274071.52 | K427: 0 | L427: 0 | M427: 0.9998 | N427: 35046.5 | O427: 0 | P427: 0.00

Sheet Pizza Karachi Downtown TO
A1: Pizza Karachi Downtown TO - Sales By Menu Item - 2026-02-16/2026-03-22
A2: "Menu Item" | B2: "Sales Category" | C2: "Menu Group" | D2: "Menu Item Void Quantity" | E2: "Voids" | F2: "Menu Item Quantity" | G2: "Gross Sales" | H2: "Item Discounts" | I2: "Bill Discounts" | J2: "Net Sales" | K2: "Menu Item Quantity (Refunds)" | L2: "Refund Amount (Net Sales)" | M2: "Sales Percentage" | N2: "Tax 1" | O2: "Tax 2" | P2: "Tax 3"
A3: 10 Chargha Wings - OO | B3: Food | C3: Wings - OO | D3: 0 | E3: 0 | F3: 6 | G3: 108 | H3: 0 | I3: 0 | J3: 108 | K3: 0 | L3: 0 | M3: 0.0014 | N3: 14.04 | O3: 0 | P3: 0.00
A4: 10 Klassic Wings | B4: Food | C4: Wings | D4: 0 | E4: 0 | F4: 6 | G4: 90 | H4: 0 | I4: 0 | J4: 90 | K4: 0 | L4: 0 | M4: 0.0012 | N4: 11.7 | O4: 0 | P4: 0.00
A5: 10 Klassic Wings - OO | B5: Food | C5: Wings - OO | D5: 0 | E5: 0 | F5: 11 | G5: 198 | H5: 0 | I5: 0 | J5: 198 | K5: 0 | L5: 0 | M5: 0.0025 | N5: 25.74 | O5: 0 | P5: 0.00
A6: 10 Koated Wings | B6: Food | C6: Wings | D6: 0 | E6: 0 | F6: 2 | G6: 30 | H6: 0 | I6: 0 | J6: 30 | K6: 0 | L6: 0 | M6: 0.0004 | N6: 3.9 | O6: 0 | P6: 0.00
A7: 10 Koated Wings - OO | B7: Food | C7: Wings - OO | D7: 0 | E7: 0 | F7: 1 | G7: 18 | H7: 0 | I7: 0 | J7: 18 | K7: 0 | L7: 0 | M7: 0.0002 | N7: 2.34 | O7: 0 | P7: 0.00
A8: 100% off 12 Pizza - With Coupon | B8: Food | C8: Deals | D8: 0 | E8: 0 | F8: 1 | G8: 0 | H8: 0 | I8: 0 | J8: 0 | K8: 0 | L8: 0 | M8: 0 | N8: 0 | O8: 0 | P8: 0.00
A9: 2 Zinger Burger Meal - D | B9: Chickentarian | C9: Deals Chickentarian - OO | D9: 2 | E9: 49.98 | F9: 2 | G9: 49.98 | H9: 0 | I9: 0 | J9: 49.98 | K9: 0 | L9: 0 | M9: 0.0006 | N9: 6.5 | O9: 0 | P9: 0.00
A10: 2 Zinger Meal (Double Sawari) | B10: Chickentarian | C10: Deals Chickentarian | D10: 0 | E10: 0 | F10: 4 | G10: 79.96 | H10: 0 | I10: 0 | J10: 79.96 | K10: 0 | L10: 0 | M10: 0.001 | N10: 10.39 | O10: 0 | P10: 0.00
A11: 20 Chargha Wings | B11: Food | C11: Wings | D11: 0 | E11: 0 | F11: 1 | G11: 23.49 | H11: 0 | I11: 0 | J11: 23.49 | K11: 0 | L11: 0 | M11: 0.0003 | N11: 3.05 | O11: 0 | P11: 0.00
A12: 20 Chargha Wings - OO | B12: Food | C12: Wings - OO | D12: 0 | E12: 0 | F12: 7 | G12: 197.33 | H12: 0 | I12: 0 | J12: 197.33 | K12: 0 | L12: 0 | M12: 0.0025 | N12: 25.65 | O12: 0 | P12: 0.00
A13: 20 Klassic Wings | B13: Food | C13: Wings | D13: 0 | E13: 0 | F13: 1 | G13: 23.49 | H13: 0 | I13: 0 | J13: 23.49 | K13: 0 | L13: 0 | M13: 0.0003 | N13: 3.05 | O13: 0 | P13: 0.00
A14: 20 Klassic Wings - OO | B14: Food | C14: Wings - OO | D14: 0 | E14: 0 | F14: 2 | G14: 56.38 | H14: 0 | I14: 0 | J14: 56.38 | K14: 0 | L14: 0 | M14: 0.0007 | N14: 7.33 | O14: 0 | P14: 0.00
... A818: w/ Tzatziki Sauce - D | B818: Food | C818: *Food Hidden Modifiers - D | D818: 0 | E818: 0 | F818: 114 | G818: 0 | H818: 0 | I818: 0 | J818: 0 | K818: 0 | L818: 0 | M818: 0 | N818: 0 | O818: 0 | P818: 0.00
A819: REPORT SUMMARY (816 entries) | D819: 168 | E819: 773.72 | F819: 13401 | G819: 78145.16 | H819: 60.12 | I819: 0 | J819: 78085.04 | K819: -9 | L819: -41.49 | M819: 0.9998 | N819: 10149.76 | O819: 0 | P819: 0.00

Sheet Highway Karahi
A1: Pizza Karachi- Highway Karahi - Sales By Menu Item - 2026-02-16/2026-03-22
A2: "Menu Item" | B2: "Sales Category" | C2: "Menu Group" | D2: "Menu Item Void Quantity" | E2: "Voids" | F2: "Menu Item Quantity" | G2: "Gross Sales" | H2: "Item Discounts" | I2: "Bill Discounts" | J2: "Net Sales" | K2: "Menu Item Quantity (Refunds)" | L2: "Refund Amount (Net Sales)" | M2: "Sales Percentage" | N2: "Tax 1" | O2: "Tax 2" | P2: "Tax 3"
A3: $13 Lunch Deal (KHK) | B3: Food Highway | C3: Takeout / Deals (HW) | D3: 1 | E3: 13 | F3: 40 | G3: 520 | H3: 0 | I3: 0 | J3: 520 | K3: 0 | L3: 0 | M3: 0.0059 | N3: 67.6 | O3: 0 | P3: 0.00
A4: 10 Chargha Wings | B4: Food | C4: Wings | D4: 1 | E4: 15 | F4: 3 | G4: 45 | H4: 0 | I4: 0 | J4: 45 | K4: 0 | L4: 0 | M4: 0.0005 | N4: 5.85 | O4: 0 | P4: 0.00
A5: 10 Chargha Wings - OO | B5: Food | C5: Wings - OO | D5: 0 | E5: 0 | F5: 3 | G5: 54 | H5: 0 | I5: 0 | J5: 54 | K5: 0 | L5: 0 | M5: 0.0006 | N5: 7.02 | O5: 0 | P5: 0.00
A6: 10 Klassic Wings | B6: Food | C6: Wings | D6: 0 | E6: 0 | F6: 5 | G6: 75 | H6: 0 | I6: 0 | J6: 75 | K6: 0 | L6: 0 | M6: 0.0008 | N6: 9.75 | O6: 0 | P6: 0.00
A7: 10 Klassic Wings - OO | B7: Food | C7: Wings - OO | D7: 0 | E7: 0 | F7: 2 | G7: 36 | H7: 0 | I7: 0 | J7: 36 | K7: 0 | L7: 0 | M7: 0.0004 | N7: 4.68 | O7: 0 | P7: 0.00
A8: 10 Koated Wings | B8: Food | C8: Wings | D8: 0 | E8: 0 | F8: 6 | G8: 90 | H8: 0 | I8: 0 | J8: 90 | K8: 0 | L8: 0 | M8: 0.001 | N8: 11.7 | O8: 0 | P8: 0.00
A9: 10 Koated Wings - OO | B9: Food | C9: Wings - OO | D9: 0 | E9: 0 | F9: 1 | G9: 18 | H9: 0 | I9: 0 | J9: 18 | K9: 0 | L9: 0 | M9: 0.0002 | N9: 2.34 | O9: 0 | P9: 0.00
A10: 20 Chargha Wings | B10: Food | C10: Wings | D10: 0 | E10: 0 | F10: 5 | G10: 117.45 | H10: 0 | I10: 0 | J10: 117.45 | K10: 0 | L10: 0 | M10: 0.0013 | N10: 15.27 | O10: 0 | P10: 0.00
A11: 20 Klassic Wings | B11: Food | C11: Wings | D11: 0 | E11: 0 | F11: 1 | G11: 23.49 | H11: 0 | I11: 0 | J11: 23.49 | K11: 0 | L11: 0 | M11: 0.0003 | N11: 3.05 | O11: 0 | P11: 0.00
A12: 20 Koated Wings | B12: Food | C12: Wings | D12: 0 | E12: 0 | F12: 2 | G12: 46.98 | H12: 0 | I12: 0 | J12: 46.98 | K12: 0 | L12: 0 | M12: 0.0005 | N12: 6.11 | O12: 0 | P12: 0.00
A13: 3 Topp - 12 | B13: Food | C13: Klassic Pizza | D13: 0 | E13: 0 | F13: 1 | G13: 18 | H13: 0 | I13: 0 | J13: 18 | K13: 0 | L13: 0 | M13: 0.0002 | N13: 2.34 | O13: 0 | P13: 0.00
A14: 5 Chargha Wings | B14: Food | C14: Wings | D14: 0 | E14: 0 | F14: 4 | G14: 32 | H14: 0 | I14: 0 | J14: 32 | K14: 0 | L14: 0 | M14: 0.0004 | N14: 4.16 | O14: 0 | P14: 0.00
... A514: w/ Tzatziki Sauce - D | B514: Food | C514: *Food Hidden Modifiers - D | D514: 0 | E514: 0 | F514: 17 | G514: 0 | H514: 0 | I514: 0 | J514: 0 | K514: 0 | L514: 0 | M514: 0 | N514: 0 | O514: 0 | P514: 0.00
A515: REPORT SUMMARY (512 entries) | D515: 467 | E515: 5491.59 | F515: 8733 | G515: 89142.4 | H515: 306.7 | I515: 0 | J515: 88835.7 | K515: 0 | L515: 0 | M515: 0.9998 | N515: 11543.95 | O515: 0 | P515: 0.00

Sheet Wonderland
A1: Pizza Karachi - Wonderland - Sales By Menu Item - 2026-02-16/2026-03-22
A2: "Menu Item" | B2: "Sales Category" | C2: "Menu Group" | D2: "Menu Item Void Quantity" | E2: "Voids" | F2: "Menu Item Quantity" | G2: "Gross Sales" | H2: "Item Discounts" | I2: "Bill Discounts" | J2: "Net Sales" | K2: "Menu Item Quantity (Refunds)" | L2: "Refund Amount (Net Sales)" | M2: "Sales Percentage" | N2: "Tax 1" | O2: "Tax 2" | P2: "Tax 3"
A3: 1 Topp - 10 | B3: Food | C3: Klassic Pizza | D3: 0 | E3: 0 | F3: 1 | G3: 13 | H3: 0 | I3: 0 | J3: 13 | K3: 0 | L3: 0 | M3: 0.0003 | N3: 1.69 | O3: 0 | P3: 0.00
A4: 1 Topp - 12 | B4: Food | C4: Klassic Pizza | D4: 0 | E4: 0 | F4: 2 | G4: 30 | H4: 0 | I4: 0 | J4: 30 | K4: 0 | L4: 0 | M4: 0.0006 | N4: 3.9 | O4: 0 | P4: 0.00
A5: 1 Topp - 12 (New Crust) | B5: Food | C5: Signature Classic Crust Pizza | D5: 1 | E5: 13.99 | F5: 0 | G5: 0 | H5: 0 | I5: 0 | J5: 0 | K5: 0 | L5: 0 | M5: 0 | N5: 0 | O5: 0 | P5: 0.00
A6: 1 Topp - 8 | B6: Food | C6: Klassic Pizza | D6: 0 | E6: 0 | F6: 1 | G6: 11 | H6: 0 | I6: 0 | J6: 11 | K6: 0 | L6: 0 | M6: 0.0002 | N6: 1.43 | O6: 0 | P6: 0.00
A7: 10 Chargha Wings | B7: Food | C7: Wings | D7: 0 | E7: 0 | F7: 17 | G7: 255 | H7: 0 | I7: 0 | J7: 255 | K7: 0 | L7: 0 | M7: 0.0052 | N7: 33.15 | O7: 0 | P7: 0.00
A8: 10 Chargha Wings - OO | B8: Food | C8: Wings - OO | D8: 0 | E8: 0 | F8: 11 | G8: 198 | H8: 0 | I8: 0 | J8: 198 | K8: 0 | L8: 0 | M8: 0.004 | N8: 25.74 | O8: 0 | P8: 0.00
A9: 10 Klassic Wings | B9: Food | C9: Wings | D9: 0 | E9: 0 | F9: 21 | G9: 315 | H9: 0 | I9: 0 | J9: 315 | K9: 0 | L9: 0 | M9: 0.0064 | N9: 40.95 | O9: 0 | P9: 0.00
A10: 10 Klassic Wings - OO | B10: Food | C10: Wings - OO | D10: 0 | E10: 0 | F10: 5 | G10: 90 | H10: 0 | I10: 0 | J10: 90 | K10: 0 | L10: 0 | M10: 0.0018 | N10: 11.7 | O10: 0 | P10: 0.00
A11: 10 Koated Wings | B11: Food | C11: Wings | D11: 1 | E11: 15 | F11: 6 | G11: 90 | H11: 0 | I11: 0 | J11: 90 | K11: 0 | L11: 0 | M11: 0.0018 | N11: 11.7 | O11: 0 | P11: 0.00
A12: 10 Koated Wings - OO | B12: Food | C12: Wings - OO | D12: 0 | E12: 0 | F12: 6 | G12: 108 | H12: 0 | I12: 0 | J12: 108 | K12: 0 | L12: 0 | M12: 0.0022 | N12: 14.04 | O12: 0 | P12: 0.00
A13: 20 Chargha Wings | B13: Food | C13: Wings | D13: 0 | E13: 0 | F13: 11 | G13: 258.39 | H13: 0 | I13: 0 | J13: 258.39 | K13: 0 | L13: 0 | M13: 0.0053 | N13: 33.59 | O13: 0 | P13: 0.00
A14: 20 Chargha Wings - OO | B14: Food | C14: Wings - OO | D14: 0 | E14: 0 | F14: 2 | G14: 56.38 | H14: 0 | I14: 0 | J14: 56.38 | K14: 0 | L14: 0 | M14: 0.0011 | N14: 7.33 | O14: 0 | P14: 0.00
... A684: w/ Tzatziki Sauce - D | B684: Food | C684: *Food Hidden Modifiers - D | D684: 0 | E684: 0 | F684: 25 | G684: 0 | H684: 0 | I684: 0 | J684: 0 | K684: 0 | L684: 0 | M684: 0 | N684: 0 | O684: 0 | P684: 0.00
A685: REPORT SUMMARY (682 entries) | D685: 162 | E685: 824.02 | F685: 9220 | G685: 49195.88 | H685: 43.9 | I685: 0 | J685: 49151.98 | K685: -23 | L685: -122.33 | M685: 0.9998 | N685: 6383.03 | O685: 0 | P685: 0.00

Sheet Lebovic
A1: Pizza Karachi - Lebovic - Sales By Menu Item - 2026-02-16/2026-03-22
A2: "Menu Item" | B2: "Sales Category" | C2: "Menu Group" | D2: "Menu Item Void Quantity" | E2: "Voids" | F2: "Menu Item Quantity" | G2: "Gross Sales" | H2: "Item Discounts" | I2: "Bill Discounts" | J2: "Net Sales" | K2: "Menu Item Quantity (Refunds)" | L2: "Refund Amount (Net Sales)" | M2: "Sales Percentage" | N2: "Tax 1" | O2: "Tax 2" | P2: "Tax 3"
A3: 1 Topp - 10 | B3: Food | C3: Klassic Pizza | D3: 0 | E3: 0 | F3: 1 | G3: 13 | H3: 0 | I3: 0 | J3: 13 | K3: 0 | L3: 0 | M3: 0.0003 | N3: 1.69 | O3: 0 | P3: 0.00
A4: 1 Topp - 12 | B4: Food | C4: Klassic Pizza | D4: 0 | E4: 0 | F4: 1 | G4: 15 | H4: 0 | I4: 0 | J4: 15 | K4: 0 | L4: 0 | M4: 0.0003 | N4: 1.95 | O4: 0 | P4: 0.00
A5: 10 Chargha Wings | B5: Food | C5: Wings | D5: 0 | E5: 0 | F5: 12 | G5: 180 | H5: 1.5 | I5: 0 | J5: 178.5 | K5: 0 | L5: 0 | M5: 0.0035 | N5: 23.21 | O5: 0 | P5: 0.00
A6: 10 Chargha Wings - OO | B6: Food | C6: Wings - OO | D6: 0 | E6: 0 | F6: 4 | G6: 72 | H6: 0 | I6: 0 | J6: 72 | K6: 0 | L6: 0 | M6: 0.0014 | N6: 9.36 | O6: 0 | P6: 0.00
A7: 10 Klassic Wings | B7: Food | C7: Wings | D7: 0 | E7: 0 | F7: 12 | G7: 180 | H7: 0 | I7: 0 | J7: 180 | K7: 0 | L7: 0 | M7: 0.0036 | N7: 23.4 | O7: 0 | P7: 0.00
A8: 10 Klassic Wings - OO | B8: Food | C8: Wings - OO | D8: 0 | E8: 0 | F8: 4 | G8: 72 | H8: 0 | I8: 0 | J8: 72 | K8: 0 | L8: 0 | M8: 0.0014 | N8: 9.36 | O8: 0 | P8: 0.00
A9: 10 Koated Wings | B9: Food | C9: Wings | D9: 0 | E9: 0 | F9: 9 | G9: 135 | H9: 1.5 | I9: 0 | J9: 133.5 | K9: 0 | L9: 0 | M9: 0.0027 | N9: 17.36 | O9: 0 | P9: 0.00
A10: 2 Zinger Meal | B10: Chickentarian | C10: Deals Chickentarian | D10: 0 | E10: 0 | F10: 1 | G10: 19.99 | H10: 0 | I10: 0 | J10: 19.99 | K10: 0 | L10: 0 | M10: 0.0004 | N10: 2.6 | O10: 0 | P10: 0.00
A11: 2 Zinger Meal (Double Sawari) | B11: Chickentarian | C11: Deals Chickentarian | D11: 1 | E11: 19.99 | F11: 17 | G11: 339.83 | H11: 0 | I11: 0 | J11: 339.83 | K11: 0 | L11: 0 | M11: 0.0067 | N11: 44.18 | O11: 0 | P11: 0.00
A12: 20 Chargha Wings | B12: Food | C12: Wings | D12: 0 | E12: 0 | F12: 4 | G12: 93.96 | H12: 0 | I12: 0 | J12: 93.96 | K12: 0 | L12: 0 | M12: 0.0019 | N12: 12.21 | O12: 0 | P12: 0.00
A13: 20 Chargha Wings - OO | B13: Food | C13: Wings - OO | D13: 0 | E13: 0 | F13: 1 | G13: 28.19 | H13: 0 | I13: 0 | J13: 28.19 | K13: 0 | L13: 0 | M13: 0.0006 | N13: 3.66 | O13: 0 | P13: 0.00
A14: 20 Klassic Wings | B14: Food | C14: Wings | D14: 1 | E14: 23.49 | F14: 5 | G14: 117.45 | H14: 0 | I14: 0 | J14: 117.45 | K14: 0 | L14: 0 | M14: 0.0023 | N14: 15.27 | O14: 0 | P14: 0.00
... A758: w/ Tzatziki Sauce - D | B758: Food | C758: *Food Hidden Modifiers - D | D758: 0 | E758: 0 | F758: 40 | G758: 0 | H758: 0 | I758: 0 | J758: 0 | K758: 0 | L758: 0 | M758: 0 | N758: 0 | O758: 0 | P758: 0.00
A759: REPORT SUMMARY (756 entries) | D759: 235.2 | E759: 1250.37 | F759: 10121.1 | G759: 50487.77 | H759: 120.89 | I759: 0 | J759: 50366.88 | K759: -9 | L759: -62.48 | M759: 0.9998 | N759: 6558.02 | O759: 0 | P759: 0.00

Sheet Ajax
A1: Pizza Karachi - Ajax - Sales By Menu Item - 2026-02-16/2026-03-22
A2: "Menu Item" | B2: "Sales Category" | C2: "Menu Group" | D2: "Menu Item Void Quantity" | E2: "Voids" | F2: "Menu Item Quantity" | G2: "Gross Sales" | H2: "Item Discounts" | I2: "Bill Discounts" | J2: "Net Sales" | K2: "Menu Item Quantity (Refunds)" | L2: "Refund Amount (Net Sales)" | M2: "Sales Percentage" | N2: "Tax 1" | O2: "Tax 2" | P2: "Tax 3"
A3: 10 Chargha Wings | B3: Food | C3: Wings | D3: 1 | E3: 15 | F3: 8 | G3: 120 | H3: 0 | I3: 0 | J3: 120 | K3: 0 | L3: 0 | M3: 0.0025 | N3: 15.6 | O3: 0 | P3: 0.00
A4: 10 Chargha Wings - OO | B4: Food | C4: Wings - OO | D4: 0 | E4: 0 | F4: 2 | G4: 36 | H4: 0 | I4: 0 | J4: 36 | K4: 0 | L4: 0 | M4: 0.0008 | N4: 4.68 | O4: 0 | P4: 0.00
A5: 10 Klassic Wings | B5: Food | C5: Wings | D5: 6 | E5: 90 | F5: 13 | G5: 195 | H5: 0 | I5: 0 | J5: 195 | K5: 0 | L5: 0 | M5: 0.0041 | N5: 25.35 | O5: 0 | P5: 0.00
A6: 10 Klassic Wings - OO | B6: Food | C6: Wings - OO | D6: 0 | E6: 0 | F6: 12 | G6: 216 | H6: 0 | I6: 0 | J6: 216 | K6: 0 | L6: 0 | M6: 0.0046 | N6: 28.08 | O6: 0 | P6: 0.00
A7: 10 Koated Wings | B7: Food | C7: Wings | D7: 2 | E7: 30 | F7: 8 | G7: 120 | H7: 0 | I7: 0 | J7: 120 | K7: 0 | L7: 0 | M7: 0.0025 | N7: 15.6 | O7: 0 | P7: 0.00
A8: 100% off 12 Pizza - With Coupon | B8: Food | C8: Deals | D8: 1 | E8: 0 | F8: 0 | G8: 0 | H8: 0 | I8: 0 | J8: 0 | K8: 0 | L8: 0 | M8: 0 | N8: 0 | O8: 0 | P8: 0.00
A9: 2 Zinger Burger Meal - D | B9: Chickentarian | C9: Deals Chickentarian - OO | D9: 0 | E9: 0 | F9: 3 | G9: 74.97 | H9: 0 | I9: 0 | J9: 74.97 | K9: 0 | L9: 0 | M9: 0.0016 | N9: 9.75 | O9: 0 | P9: 0.00
A10: 2 Zinger Meal (Double Sawari) | B10: Chickentarian | C10: Deals Chickentarian | D10: 0 | E10: 0 | F10: 2 | G10: 39.98 | H10: 0 | I10: 0 | J10: 39.98 | K10: 0 | L10: 0 | M10: 0.0008 | N10: 5.2 | O10: 0 | P10: 0.00
A11: 20 Chargha Wings | B11: Food | C11: Wings | D11: 1 | E11: 23.49 | F11: 6 | G11: 140.94 | H11: 0 | I11: 0 | J11: 140.94 | K11: 0 | L11: 0 | M11: 0.003 | N11: 18.32 | O11: 0 | P11: 0.00
A12: 20 Klassic Wings | B12: Food | C12: Wings | D12: 0.5 | E12: 11.75 | F12: 14.5 | G12: 340.61 | H12: 0 | I12: 0 | J12: 340.61 | K12: 0 | L12: 0 | M12: 0.0072 | N12: 44.28 | O12: 0 | P12: 0.00
A13: 20 Klassic Wings - OO | B13: Food | C13: Wings - OO | D13: 0 | E13: 0 | F13: 1 | G13: 28.19 | H13: 0 | I13: 0 | J13: 28.19 | K13: 0 | L13: 0 | M13: 0.0006 | N13: 3.66 | O13: 0 | P13: 0.00
A14: 20 Koated Wings | B14: Food | C14: Wings | D14: 2 | E14: 46.98 | F14: 4 | G14: 93.96 | H14: 0 | I14: 0 | J14: 93.96 | K14: 0 | L14: 0 | M14: 0.002 | N14: 12.21 | O14: 0 | P14: 0.00
... A629: w/ Tzatziki Sauce - D | B629: Food | C629: *Food Hidden Modifiers - D | D629: 0 | E629: 0 | F629: 27 | G629: 0 | H629: 0 | I629: 0 | J629: 0 | K629: 0 | L629: 0 | M629: 0 | N629: 0 | O629: 0 | P629: 0.00
A630: REPORT SUMMARY (627 entries) | D630: 1460.5 | E630: 6720.18 | F630: 8665.5 | G630: 47504.7 | H630: 97.27 | I630: 0 | J630: 47407.43 | K630: 0 | L630: 0 | M630: 0.9998 | N630: 6162.19 | O630: 0 | P630: 0.00

Sheet Markham Rd
A1: Pizza Karachi - Markham Rd - Sales By Menu Item - 2026-02-16/2026-03-22
A2: "Menu Item" | B2: "Sales Category" | C2: "Menu Group" | D2: "Menu Item Void Quantity" | E2: "Voids" | F2: "Menu Item Quantity" | G2: "Gross Sales" | H2: "Item Discounts" | I2: "Bill Discounts" | J2: "Net Sales" | K2: "Menu Item Quantity (Refunds)" | L2: "Refund Amount (Net Sales)" | M2: "Sales Percentage" | N2: "Tax 1" | O2: "Tax 2" | P2: "Tax 3"
A3: 10 Baked Wings | B3: Food | C3: Wings | D3: 0 | E3: 0 | F3: 1 | G3: 15 | H3: 2.85 | I3: 0 | J3: 12.15 | K3: 0 | L3: 0 | M3: 0.0003 | N3: 1.58 | O3: 0 | P3: 0.00
A4: 10 Chargha Wings | B4: Food | C4: Wings | D4: 0 | E4: 0 | F4: 15 | G4: 225 | H4: 0 | I4: 0 | J4: 225 | K4: 0 | L4: 0 | M4: 0.005 | N4: 29.25 | O4: 0 | P4: 0.00
A5: 10 Chargha Wings - OO | B5: Food | C5: Wings - OO | D5: 0 | E5: 0 | F5: 3 | G5: 54 | H5: 0 | I5: 0 | J5: 54 | K5: 0 | L5: 0 | M5: 0.0012 | N5: 7.02 | O5: 0 | P5: 0.00
A6: 10 Klassic Wings | B6: Food | C6: Wings | D6: 0 | E6: 0 | F6: 8 | G6: 120 | H6: 0 | I6: 0 | J6: 120 | K6: 0 | L6: 0 | M6: 0.0027 | N6: 15.6 | O6: 0 | P6: 0.00
A7: 10 Klassic Wings - OO | B7: Food | C7: Wings - OO | D7: 0 | E7: 0 | F7: 14 | G7: 252 | H7: 0 | I7: 0 | J7: 252 | K7: 0 | L7: 0 | M7: 0.0056 | N7: 32.76 | O7: 0 | P7: 0.00
A8: 10 Koated Wings | B8: Food | C8: Wings | D8: 0 | E8: 0 | F8: 9 | G8: 135 | H8: 0 | I8: 0 | J8: 135 | K8: 0 | L8: 0 | M8: 0.003 | N8: 17.55 | O8: 0 | P8: 0.00
A9: 10 Koated Wings - OO | B9: Food | C9: Wings - OO | D9: 0 | E9: 0 | F9: 7 | G9: 126 | H9: 0 | I9: 0 | J9: 126 | K9: 0 | L9: 0 | M9: 0.0028 | N9: 16.38 | O9: 0 | P9: 0.00
A10: 20 Baked Wings | B10: Food | C10: Wings | D10: 0 | E10: 0 | F10: 1 | G10: 23.49 | H10: 4.46 | I10: 0 | J10: 19.03 | K10: 0 | L10: 0 | M10: 0.0004 | N10: 2.47 | O10: 0 | P10: 0.00
A11: 20 Chargha Wings | B11: Food | C11: Wings | D11: 0 | E11: 0 | F11: 7 | G11: 164.43 | H11: 0 | I11: 0 | J11: 164.43 | K11: 0 | L11: 0 | M11: 0.0036 | N11: 21.38 | O11: 0 | P11: 0.00
A12: 20 Chargha Wings - OO | B12: Food | C12: Wings - OO | D12: 0 | E12: 0 | F12: 1 | G12: 28.19 | H12: 0 | I12: 0 | J12: 28.19 | K12: 0 | L12: 0 | M12: 0.0006 | N12: 3.66 | O12: 0 | P12: 0.00
A13: 20 Klassic Wings | B13: Food | C13: Wings | D13: 0 | E13: 0 | F13: 2 | G13: 46.98 | H13: 0 | I13: 0 | J13: 46.98 | K13: 0 | L13: 0 | M13: 0.001 | N13: 6.11 | O13: 0 | P13: 0.00
A14: 20 Klassic Wings - OO | B14: Food | C14: Wings - OO | D14: 0 | E14: 0 | F14: 3 | G14: 84.57 | H14: 0 | I14: 0 | J14: 84.57 | K14: 0 | L14: 0 | M14: 0.0019 | N14: 10.99 | O14: 0 | P14: 0.00
... A593: w/ Tzatziki Sauce - D | B593: Food | C593: *Food Hidden Modifiers - D | D593: 0 | E593: 0 | F593: 39 | G593: 0 | H593: 0 | I593: 0 | J593: 0 | K593: 0 | L593: 0 | M593: 0 | N593: 0 | O593: 0 | P593: 0.00
A594: REPORT SUMMARY (591 entries) | D594: 190 | E594: 1047.8 | F594: 7915 | G594: 45409.05 | H594: 141.1 | I594: 0 | J594: 45267.95 | K594: 0 | L594: 0 | M594: 0.9998 | N594: 5885.27 | O594: 0 | P594: 0.00

Sheet checker
A1: Mar 16 - Mar 22
B3: Items | C3: markham | D3: percentage | E3: ajax | F3: percentage | G3: lebovic | H3: percentage | I3: wonderland | J3: percentage | K3: downtown | L3: percentage | M3: highway | N3: percentage | O3: heartland | P3: percentage | Q3: eglinton | R3: percentage | S3: food court | T3: percentage | U3: kabab wala | V3: percentage | W3: kababwala Q St | X3: percentage
A4: Pizza K Deals | B4: Wing Wednesday - 10 | C4: =IFERROR(SUMIF('Markham Rd'!$A:$A, B4, 'Markham Rd'!$F:$F), 0) -> 9 | E4: =IFERROR(SUMIF(Ajax!$A:$A, B4, Ajax!$F:$F), 0) -> 8 | G4: =IFERROR(SUMIF(Lebovic!$A:$A, B4, Lebovic!$F:$F), 0) -> 3 | I4: =IFERROR(SUMIF(Wonderland!$A:$A, B4, Wonderland!$F:$F), 0) -> 31 | K4: =IFERROR(SUMIF('Pizza Karachi Downtown TO'!$A:$A, B4, 'Pizza Karachi Downtown TO'!$F:$F), 0) -> 7 | M4: =IFERROR(SUMIF('Highway Karahi'!$A:$A, B4, 'Highway Karahi'!$F:$F), 0) -> 0 | O4: =IFERROR(SUMIF(Heartland!$A:$A, B4, Heartland!$F:$F), 0) -> 15 | Q4: =IFERROR(SUMIF(Eglinton!$A:$A, B4, Eglinton!$F:$F), 0) -> 23 | S4: - | U4: -
B5: Family Deal | C5: =IFERROR(SUMIF('Markham Rd'!$A:$A, B5, 'Markham Rd'!$F:$F), 0) -> 64 | E5: =IFERROR(SUMIF(Ajax!$A:$A, B5, Ajax!$F:$F), 0) -> 60 | G5: =IFERROR(SUMIF(Lebovic!$A:$A, B5, Lebovic!$F:$F), 0) -> 88 | I5: =IFERROR(SUMIF(Wonderland!$A:$A, B5, Wonderland!$F:$F), 0) -> 60 | K5: =IFERROR(SUMIF('Pizza Karachi Downtown TO'!$A:$A, B5, 'Pizza Karachi Downtown TO'!$F:$F), 0) -> 18 | M5: =IFERROR(SUMIF('Highway Karahi'!$A:$A, B5, 'Highway Karahi'!$F:$F), 0) -> 32 | O5: =IFERROR(SUMIF(Heartland!$A:$A, B5, Heartland!$F:$F), 0) -> 121 | Q5: =IFERROR(SUMIF(Eglinton!$A:$A, B5, Eglinton!$F:$F), 0) -> 246 | S5: - | U5: -
B6: Personal Pizza Lunch Deal | C6: =IFERROR(SUMIF('Markham Rd'!$A:$A, B6, 'Markham Rd'!$F:$F), 0) -> 6 | E6: =IFERROR(SUMIF(Ajax!$A:$A, B6, Ajax!$F:$F), 0) -> 16 | G6: =IFERROR(SUMIF(Lebovic!$A:$A, B6, Lebovic!$F:$F), 0) -> 19 | I6: =IFERROR(SUMIF(Wonderland!$A:$A, B6, Wonderland!$F:$F), 0) -> 13 | K6: =IFERROR(SUMIF('Pizza Karachi Downtown TO'!$A:$A, B6, 'Pizza Karachi Downtown TO'!$F:$F), 0) -> 64 | M6: =IFERROR(SUMIF('Highway Karahi'!$A:$A, B6, 'Highway Karahi'!$F:$F), 0) -> 0 | O6: =IFERROR(SUMIF(Heartland!$A:$A, B6, Heartland!$F:$F), 0) -> 32 | Q6: =IFERROR(SUMIF(Eglinton!$A:$A, B6, Eglinton!$F:$F), 0) -> 19 | S6: - | U6: -
B7: Personal Pizza Lunch Deal - OO | C7: =IFERROR(SUMIF('Markham Rd'!$A:$A, B7, 'Markham Rd'!$F:$F), 0) -> 27 | E7: =IFERROR(SUMIF(Ajax!$A:$A, B7, Ajax!$F:$F), 0) -> 26 | G7: =IFERROR(SUMIF(Lebovic!$A:$A, B7, Lebovic!$F:$F), 0) -> 18 | I7: =IFERROR(SUMIF(Wonderland!$A:$A, B7, Wonderland!$F:$F), 0) -> 24 | K7: =IFERROR(SUMIF('Pizza Karachi Downtown TO'!$A:$A, B7, 'Pizza Karachi Downtown TO'!$F:$F), 0) -> 135 | M7: =IFERROR(SUMIF('Highway Karahi'!$A:$A, B7, 'Highway Karahi'!$F:$F), 0) -> 5 | O7: =IFERROR(SUMIF(Heartland!$A:$A, B7, Heartland!$F:$F), 0) -> 45 | Q7: =IFERROR(SUMIF(Eglinton!$A:$A, B7, Eglinton!$F:$F), 0) -> 65 | S7: - | U7: -
B8: Wings Lunch Deal - OO | C8: =IFERROR(SUMIF('Markham Rd'!$A:$A, B8, 'Markham Rd'!$F:$F), 0) -> 2 | E8: =IFERROR(SUMIF(Ajax!$A:$A, B8, Ajax!$F:$F), 0) -> 1 | G8: =IFERROR(SUMIF(Lebovic!$A:$A, B8, Lebovic!$F:$F), 0) -> 5 | I8: =IFERROR(SUMIF(Wonderland!$A:$A, B8, Wonderland!$F:$F), 0) -> 10 | K8: =IFERROR(SUMIF('Pizza Karachi Downtown TO'!$A:$A, B8, 'Pizza Karachi Downtown TO'!$F:$F), 0) -> 10 | M8: =IFERROR(SUMIF('Highway Karahi'!$A:$A, B8, 'Highway Karahi'!$F:$F), 0) -> 0 | O8: =IFERROR(SUMIF(Heartland!$A:$A, B8, Heartland!$F:$F), 0) -> 10 | Q8: =IFERROR(SUMIF(Eglinton!$A:$A, B8, Eglinton!$F:$F), 0) -> 11 | S8: - | U8: -
B9: Wings Lunch Deal | C9: =IFERROR(SUMIF('Markham Rd'!$A:$A, B9, 'Markham Rd'!$F:$F), 0) -> 0 | E9: =IFERROR(SUMIF(Ajax!$A:$A, B9, Ajax!$F:$F), 0) -> 0 | G9: =IFERROR(SUMIF(Lebovic!$A:$A, B9, Lebovic!$F:$F), 0) -> 0 | I9: =IFERROR(SUMIF(Wonderland!$A:$A, B9, Wonderland!$F:$F), 0) -> 1 | K9: =IFERROR(SUMIF('Pizza Karachi Downtown TO'!$A:$A, B9, 'Pizza Karachi Downtown TO'!$F:$F), 0) -> 0 | M9: =IFERROR(SUMIF('Highway Karahi'!$A:$A, B9, 'Highway Karahi'!$F:$F), 0) -> 0 | O9: =IFERROR(SUMIF(Heartland!$A:$A, B9, Heartland!$F:$F), 0) -> 0 | Q9: =IFERROR(SUMIF(Eglinton!$A:$A, B9, Eglinton!$F:$F), 0) -> 0 | S9: - | U9: -
B10: Monday Deal | C10: =IFERROR(SUMIF('Markham Rd'!$A:$A, B10, 'Markham Rd'!$F:$F), 0) -> 0 | E10: =IFERROR(SUMIF(Ajax!$A:$A, B10, Ajax!$F:$F), 0) -> 1 | G10: =IFERROR(SUMIF(Lebovic!$A:$A, B10, Lebovic!$F:$F), 0) -> 2 | I10: =IFERROR(SUMIF(Wonderland!$A:$A, B10, Wonderland!$F:$F), 0) -> 0 | K10: =IFERROR(SUMIF('Pizza Karachi Downtown TO'!$A:$A, B10, 'Pizza Karachi Downtown TO'!$F:$F), 0) -> 1 | M10: =IFERROR(SUMIF('Highway Karahi'!$A:$A, B10, 'Highway Karahi'!$F:$F), 0) -> 0 | O10: =IFERROR(SUMIF(Heartland!$A:$A, B10, Heartland!$F:$F), 0) -> 2 | Q10: =IFERROR(SUMIF(Eglinton!$A:$A, B10, Eglinton!$F:$F), 0) -> 3
B11: Tuesday Deal | C11: =IFERROR(SUMIF('Markham Rd'!$A:$A, B11, 'Markham Rd'!$F:$F), 0) -> 1 | E11: =IFERROR(SUMIF(Ajax!$A:$A, B11, Ajax!$F:$F), 0) -> 3 | G11: =IFERROR(SUMIF(Lebovic!$A:$A, B11, Lebovic!$F:$F), 0) -> 0 | I11: =IFERROR(SUMIF(Wonderland!$A:$A, B11, Wonderland!$F:$F), 0) -> 0 | K11: =IFERROR(SUMIF('Pizza Karachi Downtown TO'!$A:$A, B11, 'Pizza Karachi Downtown TO'!$F:$F), 0) -> 1 | M11: =IFERROR(SUMIF('Highway Karahi'!$A:$A, B11, 'Highway Karahi'!$F:$F), 0) -> 0 | O11: =IFERROR(SUMIF(Heartland!$A:$A, B11, Heartland!$F:$F), 0) -> 1 | Q11: =IFERROR(SUMIF(Eglinton!$A:$A, B11, Eglinton!$F:$F), 0) -> 2
B12: Thursday Deal | C12: =IFERROR(SUMIF('Markham Rd'!$A:$A, B12, 'Markham Rd'!$F:$F), 0) -> 2 | E12: =IFERROR(SUMIF(Ajax!$A:$A, B12, Ajax!$F:$F), 0) -> 1 | G12: =IFERROR(SUMIF(Lebovic!$A:$A, B12, Lebovic!$F:$F), 0) -> 1 | I12: =IFERROR(SUMIF(Wonderland!$A:$A, B12, Wonderland!$F:$F), 0) -> 0 | K12: =IFERROR(SUMIF('Pizza Karachi Downtown TO'!$A:$A, B12, 'Pizza Karachi Downtown TO'!$F:$F), 0) -> 2 | M12: =IFERROR(SUMIF('Highway Karahi'!$A:$A, B12, 'Highway Karahi'!$F:$F), 0) -> 0 | O12: =IFERROR(SUMIF(Heartland!$A:$A, B12, Heartland!$F:$F), 0) -> 0 | Q12: =IFERROR(SUMIF(Eglinton!$A:$A, B12, Eglinton!$F:$F), 0) -> 0
B13: Friday Deal | C13: =IFERROR(SUMIF('Markham Rd'!$A:$A, B13, 'Markham Rd'!$F:$F), 0) -> 0 | E13: =IFERROR(SUMIF(Ajax!$A:$A, B13, Ajax!$F:$F), 0) -> 2 | G13: =IFERROR(SUMIF(Lebovic!$A:$A, B13, Lebovic!$F:$F), 0) -> 0 | I13: =IFERROR(SUMIF(Wonderland!$A:$A, B13, Wonderland!$F:$F), 0) -> 0 | K13: =IFERROR(SUMIF('Pizza Karachi Downtown TO'!$A:$A, B13, 'Pizza Karachi Downtown TO'!$F:$F), 0) -> 0 | M13: =IFERROR(SUMIF('Highway Karahi'!$A:$A, B13, 'Highway Karahi'!$F:$F), 0) -> 0 | O13: =IFERROR(SUMIF(Heartland!$A:$A, B13, Heartland!$F:$F), 0) -> 3 | Q13: =IFERROR(SUMIF(Eglinton!$A:$A, B13, Eglinton!$F:$F), 0) -> 3
B14: Late Night Deal (2 Med $34.99) | C14: =IFERROR(SUMIF('Markham Rd'!$A:$A, B14, 'Markham Rd'!$F:$F), 0) -> 36 | E14: =IFERROR(SUMIF(Ajax!$A:$A, B14, Ajax!$F:$F), 0) -> 32 | G14: =IFERROR(SUMIF(Lebovic!$A:$A, B14, Lebovic!$F:$F), 0) -> 13 | I14: =IFERROR(SUMIF(Wonderland!$A:$A, B14, Wonderland!$F:$F), 0) -> 17 | K14: =IFERROR(SUMIF('Pizza Karachi Downtown TO'!$A:$A, B14, 'Pizza Karachi Downtown TO'!$F:$F), 0) -> 11 | M14: =IFERROR(SUMIF('Highway Karahi'!$A:$A, B14, 'Highway Karahi'!$F:$F), 0) -> 13 | O14: =IFERROR(SUMIF(Heartland!$A:$A, B14, Heartland!$F:$F), 0) -> 68 | Q14: =IFERROR(SUMIF(Eglinton!$A:$A, B14, Eglinton!$F:$F), 0) -> 231
A15: Stuffed Crust | B15: Cheese Stuffed Crust - 10 | C15: =IFERROR(SUMIF('Markham Rd'!$A:$A, B15, 'Markham Rd'!$F:$F), 0) -> 12 | E15: =IFERROR(SUMIF(Ajax!$A:$A, B15, Ajax!$F:$F), 0) -> 8 | G15: =IFERROR(SUMIF(Lebovic!$A:$A, B15, Lebovic!$F:$F), 0) -> 24 | I15: =IFERROR(SUMIF(Wonderland!$A:$A, B15, Wonderland!$F:$F), 0) -> 5 | K15: =IFERROR(SUMIF('Pizza Karachi Downtown TO'!$A:$A, B15, 'Pizza Karachi Downtown TO'!$F:$F), 0) -> 10 | M15: =IFERROR(SUMIF('Highway Karahi'!$A:$A, B15, 'Highway Karahi'!$F:$F), 0) -> 2 | O15: =IFERROR(SUMIF(Heartland!$A:$A, B15, Heartland!$F:$F), 0) -> 6 | Q15: =IFERROR(SUMIF(Eglinton!$A:$A, B15, Eglinton!$F:$F), 0) -> 23 | S15: - | U15: -
B16: P2 Cheese Stuffed Crust - 12 | C16: =IFERROR(SUMIF('Markham Rd'!$A:$A, B16, 'Markham Rd'!$F:$F), 0) -> 4 | E16: =IFERROR(SUMIF(Ajax!$A:$A, B16, Ajax!$F:$F), 0) -> 0 | G16: =IFERROR(SUMIF(Lebovic!$A:$A, B16, Lebovic!$F:$F), 0) -> 3 | I16: =IFERROR(SUMIF(Wonderland!$A:$A, B16, Wonderland!$F:$F), 0) -> 2 | K16: =IFERROR(SUMIF('Pizza Karachi Downtown TO'!$A:$A, B16, 'Pizza Karachi Downtown TO'!$F:$F), 0) -> 3 | M16: =IFERROR(SUMIF('Highway Karahi'!$A:$A, B16, 'Highway Karahi'!$F:$F), 0) -> 2 | O16: =IFERROR(SUMIF(Heartland!$A:$A, B16, Heartland!$F:$F), 0) -> 5 | Q16: =IFERROR(SUMIF(Eglinton!$A:$A, B16, Eglinton!$F:$F), 0) -> 7 | S16: - | U16: -
B17: P1 Cheese Stuffed Crust - 12 | C17: =IFERROR(SUMIF('Markham Rd'!$A:$A, B17, 'Markham Rd'!$F:$F), 0) -> 3 | E17: =IFERROR(SUMIF(Ajax!$A:$A, B17, Ajax!$F:$F), 0) -> 1 | G17: =IFERROR(SUMIF(Lebovic!$A:$A, B17, Lebovic!$F:$F), 0) -> 9 | I17: =IFERROR(SUMIF(Wonderland!$A:$A, B17, Wonderland!$F:$F), 0) -> 3 | K17: =IFERROR(SUMIF('Pizza Karachi Downtown TO'!$A:$A, B17, 'Pizza Karachi Downtown TO'!$F:$F), 0) -> 3 | M17: =IFERROR(SUMIF('Highway Karahi'!$A:$A, B17, 'Highway Karahi'!$F:$F), 0) -> 0 | O17: =IFERROR(SUMIF(Heartland!$A:$A, B17, Heartland!$F:$F), 0) -> 3 | Q17: =IFERROR(SUMIF(Eglinton!$A:$A, B17, Eglinton!$F:$F), 0) -> 6 | S17: - | U17: -
B18: Cheese Stuffed Crust - 12 | C18: =IFERROR(SUMIF('Markham Rd'!$A:$A, B18, 'Markham Rd'!$F:$F), 0) -> 0 | E18: =IFERROR(SUMIF(Ajax!$A:$A, B18, Ajax!$F:$F), 0) -> 0 | G18: =IFERROR(SUMIF(Lebovic!$A:$A, B18, Lebovic!$F:$F), 0) -> 0 | I18: =IFERROR(SUMIF(Wonderland!$A:$A, B18, Wonderland!$F:$F), 0) -> 0 | K18: =IFERROR(SUMIF('Pizza Karachi Downtown TO'!$A:$A, B18, 'Pizza Karachi Downtown TO'!$F:$F), 0) -> 0 | M18: =IFERROR(SUMIF('Highway Karahi'!$A:$A, B18, 'Highway Karahi'!$F:$F), 0) -> 0 | O18: =IFERROR(SUMIF(Heartland!$A:$A, B18, Heartland!$F:$F), 0) -> 0 | Q18: =IFERROR(SUMIF(Eglinton!$A:$A, B18, Eglinton!$F:$F), 0) -> 0 | S18: - | U18: -
B19: Chicken Stuffed Kabab - 10 | C19: =IFERROR(SUMIF('Markham Rd'!$A:$A, B19, 'Markham Rd'!$F:$F), 0) -> 2 | E19: =IFERROR(SUMIF(Ajax!$A:$A, B19, Ajax!$F:$F), 0) -> 2 | G19: =IFERROR(SUMIF(Lebovic!$A:$A, B19, Lebovic!$F:$F), 0) -> 5 | I19: =IFERROR(SUMIF(Wonderland!$A:$A, B19, Wonderland!$F:$F), 0) -> 2 | K19: =IFERROR(SUMIF('Pizza Karachi Downtown TO'!$A:$A, B19, 'Pizza Karachi Downtown TO'!$F:$F), 0) -> 4 | M19: =IFERROR(SUMIF('Highway Karahi'!$A:$A, B19, 'Highway Karahi'!$F:$F), 0) -> 1 | O19: =IFERROR(SUMIF(Heartland!$A:$A, B19, Heartland!$F:$F), 0) -> 5 | Q19: =IFERROR(SUMIF(Eglinton!$A:$A, B19, Eglinton!$F:$F), 0) -> 5 | S19: - | U19: -
B20: Chicken Stuffed Kabab - 12 | C20: =IFERROR(SUMIF('Markham Rd'!$A:$A, B20, 'Markham Rd'!$F:$F), 0) -> 0 | E20: =IFERROR(SUMIF(Ajax!$A:$A, B20, Ajax!$F:$F), 0) -> 0 | G20: =IFERROR(SUMIF(Lebovic!$A:$A, B20, Lebovic!$F:$F), 0) -> 0 | I20: =IFERROR(SUMIF(Wonderland!$A:$A, B20, Wonderland!$F:$F), 0) -> 0 | K20: =IFERROR(SUMIF('Pizza Karachi Downtown TO'!$A:$A, B20, 'Pizza Karachi Downtown TO'!$F:$F), 0) -> 0 | M20: =IFERROR(SUMIF('Highway Karahi'!$A:$A, B20, 'Highway Karahi'!$F:$F), 0) -> 0 | O20: =IFERROR(SUMIF(Heartland!$A:$A, B20, Heartland!$F:$F), 0) -> 0 | Q20: =IFERROR(SUMIF(Eglinton!$A:$A, B20, Eglinton!$F:$F), 0) -> 0 | S20: - | U20: -
B21: P1 Chicken Stuffed Kabab - 12 | C21: =IFERROR(SUMIF('Markham Rd'!$A:$A, B21, 'Markham Rd'!$F:$F), 0) -> 4 | E21: =IFERROR(SUMIF(Ajax!$A:$A, B21, Ajax!$F:$F), 0) -> 1 | G21: =IFERROR(SUMIF(Lebovic!$A:$A, B21, Lebovic!$F:$F), 0) -> 3 | I21: =IFERROR(SUMIF(Wonderland!$A:$A, B21, Wonderland!$F:$F), 0) -> 2 | K21: =IFERROR(SUMIF('Pizza Karachi Downtown TO'!$A:$A, B21, 'Pizza Karachi Downtown TO'!$F:$F), 0) -> 1 | M21: =IFERROR(SUMIF('Highway Karahi'!$A:$A, B21, 'Highway Karahi'!$F:$F), 0) -> 0 | O21: =IFERROR(SUMIF(Heartland!$A:$A, B21, Heartland!$F:$F), 0) -> 2 | Q21: =IFERROR(SUMIF(Eglinton!$A:$A, B21, Eglinton!$F:$F), 0) -> 1 | S21: - | U21: -
B22: P2 Chicken Stuffed Kabab - 12 | C22: =IFERROR(SUMIF('Markham Rd'!$A:$A, B22, 'Markham Rd'!$F:$F), 0) -> 2 | E22: =IFERROR(SUMIF(Ajax!$A:$A, B22, Ajax!$F:$F), 0) -> 1 | G22: =IFERROR(SUMIF(Lebovic!$A:$A, B22, Lebovic!$F:$F), 0) -> 1 | I22: =IFERROR(SUMIF(Wonderland!$A:$A, B22, Wonderland!$F:$F), 0) -> 3 | K22: =IFERROR(SUMIF('Pizza Karachi Downtown TO'!$A:$A, B22, 'Pizza Karachi Downtown TO'!$F:$F), 0) -> 1 | M22: =IFERROR(SUMIF('Highway Karahi'!$A:$A, B22, 'Highway Karahi'!$F:$F), 0) -> 0 | O22: =IFERROR(SUMIF(Heartland!$A:$A, B22, Heartland!$F:$F), 0) -> 2 | Q22: =IFERROR(SUMIF(Eglinton!$A:$A, B22, Eglinton!$F:$F), 0) -> 2 | S22: - | U22: -
B23: Beef Stuffed Kabab - 12 | C23: =IFERROR(SUMIF('Markham Rd'!$A:$A, B23, 'Markham Rd'!$F:$F), 0) -> 0 | E23: =IFERROR(SUMIF(Ajax!$A:$A, B23, Ajax!$F:$F), 0) -> 0 | G23: =IFERROR(SUMIF(Lebovic!$A:$A, B23, Lebovic!$F:$F), 0) -> 0 | I23: =IFERROR(SUMIF(Wonderland!$A:$A, B23, Wonderland!$F:$F), 0) -> 0 | K23: =IFERROR(SUMIF('Pizza Karachi Downtown TO'!$A:$A, B23, 'Pizza Karachi Downtown TO'!$F:$F), 0) -> 0 | M23: =IFERROR(SUMIF('Highway Karahi'!$A:$A, B23, 'Highway Karahi'!$F:$F), 0) -> 0 | O23: =IFERROR(SUMIF(Heartland!$A:$A, B23, Heartland!$F:$F), 0) -> 0 | Q23: =IFERROR(SUMIF(Eglinton!$A:$A, B23, Eglinton!$F:$F), 0) -> 0 | S23: - | U23: -
B24: P1 Beef Stuffed Kabab - 12 | C24: =IFERROR(SUMIF('Markham Rd'!$A:$A, B24, 'Markham Rd'!$F:$F), 0) -> 1 | E24: =IFERROR(SUMIF(Ajax!$A:$A, B24, Ajax!$F:$F), 0) -> 0 | G24: =IFERROR(SUMIF(Lebovic!$A:$A, B24, Lebovic!$F:$F), 0) -> 2 | I24: =IFERROR(SUMIF(Wonderland!$A:$A, B24, Wonderland!$F:$F), 0) -> 2 | K24: =IFERROR(SUMIF('Pizza Karachi Downtown TO'!$A:$A, B24, 'Pizza Karachi Downtown TO'!$F:$F), 0) -> 1 | M24: =IFERROR(SUMIF('Highway Karahi'!$A:$A, B24, 'Highway Karahi'!$F:$F), 0) -> 0 | O24: =IFERROR(SUMIF(Heartland!$A:$A, B24, Heartland!$F:$F), 0) -> 1 | Q24: =IFERROR(SUMIF(Eglinton!$A:$A, B24, Eglinton!$F:$F), 0) -> 5 | S24: - | U24: -
B25: P2 Beef Stuffed Kabab - 12 | C25: =IFERROR(SUMIF('Markham Rd'!$A:$A, B25, 'Markham Rd'!$F:$F), 0) -> 1 | E25: =IFERROR(SUMIF(Ajax!$A:$A, B25, Ajax!$F:$F), 0) -> 0 | G25: =IFERROR(SUMIF(Lebovic!$A:$A, B25, Lebovic!$F:$F), 0) -> 2 | I25: =IFERROR(SUMIF(Wonderland!$A:$A, B25, Wonderland!$F:$F), 0) -> 1 | K25: =IFERROR(SUMIF('Pizza Karachi Downtown TO'!$A:$A, B25, 'Pizza Karachi Downtown TO'!$F:$F), 0) -> 1 | M25: =IFERROR(SUMIF('Highway Karahi'!$A:$A, B25, 'Highway Karahi'!$F:$F), 0) -> 0 | O25: =IFERROR(SUMIF(Heartland!$A:$A, B25, Heartland!$F:$F), 0) -> 0 | Q25: =IFERROR(SUMIF(Eglinton!$A:$A, B25, Eglinton!$F:$F), 0) -> 1 | S25: - | U25: -
B26: Beef Stuffed Kabab - 10 | C26: =IFERROR(SUMIF('Markham Rd'!$A:$A, B26, 'Markham Rd'!$F:$F), 0) -> 3 | E26: =IFERROR(SUMIF(Ajax!$A:$A, B26, Ajax!$F:$F), 0) -> 0 | G26: =IFERROR(SUMIF(Lebovic!$A:$A, B26, Lebovic!$F:$F), 0) -> 3 | I26: =IFERROR(SUMIF(Wonderland!$A:$A, B26, Wonderland!$F:$F), 0) -> 0 | K26: =IFERROR(SUMIF('Pizza Karachi Downtown TO'!$A:$A, B26, 'Pizza Karachi Downtown TO'!$F:$F), 0) -> 1 | M26: =IFERROR(SUMIF('Highway Karahi'!$A:$A, B26, 'Highway Karahi'!$F:$F), 0) -> 2 | O26: =IFERROR(SUMIF(Heartland!$A:$A, B26, Heartland!$F:$F), 0) -> 2 | Q26: =IFERROR(SUMIF(Eglinton!$A:$A, B26, Eglinton!$F:$F), 0) -> 6 | S26: - | U26: -
B27: Total Stuffed Crust | C27: =IFERROR(SUMIF('Markham Rd'!$A:$A, B27, 'Markham Rd'!$F:$F), 0) -> 0 | E27: =IFERROR(SUMIF(Ajax!$A:$A, B27, Ajax!$F:$F), 0) -> 0 | G27: =IFERROR(SUMIF(Lebovic!$A:$A, B27, Lebovic!$F:$F), 0) -> 0 | I27: =IFERROR(SUMIF(Wonderland!$A:$A, B27, Wonderland!$F:$F), 0) -> 0 | K27: =IFERROR(SUMIF('Pizza Karachi Downtown TO'!$A:$A, B27, 'Pizza Karachi Downtown TO'!$F:$F), 0) -> 0 | M27: =IFERROR(SUMIF('Highway Karahi'!$A:$A, B27, 'Highway Karahi'!$F:$F), 0) -> 0 | O27: =IFERROR(SUMIF(Heartland!$A:$A, B27, Heartland!$F:$F), 0) -> 0 | Q27: =IFERROR(SUMIF(Eglinton!$A:$A, B27, Eglinton!$F:$F), 0) -> 0
A28: Karachi Kabab Wala and Food Court | B28: Beef Lover Platter | C28: - | E28: - | G28: - | I28: - | K28: - | M28: - | O28: - | Q28: - | S28: =IFERROR(SUMIF('Karachi Food Court'!$A:$A, B28, 'Karachi Food Court'!$F:$F), 0) -> 103 | U28: =IFERROR(SUMIF('Karachi Kabab Wala'!$A:$A, B28, 'Karachi Kabab Wala'!$F:$F), 0) -> 48 | W28: =IFERROR(SUMIF('Karachi Kabab Wala - Queen'!$A:$A, B28, 'Karachi Kabab Wala - Queen'!$F:$F), 0) -> 8
B29: Chicken Lover Platter | C29: - | E29: - | G29: - | I29: - | K29: - | M29: - | O29: - | Q29: - | S29: =IFERROR(SUMIF('Karachi Food Court'!$A:$A, B29, 'Karachi Food Court'!$F:$F), 0) -> 160 | U29: =IFERROR(SUMIF('Karachi Kabab Wala'!$A:$A, B29, 'Karachi Kabab Wala'!$F:$F), 0) -> 25 | W29: =IFERROR(SUMIF('Karachi Kabab Wala - Queen'!$A:$A, B29, 'Karachi Kabab Wala - Queen'!$F:$F), 0) -> 5
B30: Mix Platter | C30: - | E30: - | G30: - | I30: - | K30: - | M30: - | O30: - | Q30: - | S30: =IFERROR(SUMIF('Karachi Food Court'!$A:$A, B30, 'Karachi Food Court'!$F:$F), 0) -> 306 | U30: =IFERROR(SUMIF('Karachi Kabab Wala'!$A:$A, B30, 'Karachi Kabab Wala'!$F:$F), 0) -> 62 | W30: =IFERROR(SUMIF('Karachi Kabab Wala - Queen'!$A:$A, B30, 'Karachi Kabab Wala - Queen'!$F:$F), 0) -> 14
B31: Premium Platter (KKW) | C31: - | E31: - | G31: - | I31: - | K31: - | M31: - | O31: - | Q31: - | S31: =IFERROR(SUMIF('Karachi Food Court'!$A:$A, B31, 'Karachi Food Court'!$F:$F), 0) -> 0 | U31: =IFERROR(SUMIF('Karachi Kabab Wala'!$A:$A, B31, 'Karachi Kabab Wala'!$F:$F), 0) -> 0 | W31: =IFERROR(SUMIF('Karachi Kabab Wala - Queen'!$A:$A, B31, 'Karachi Kabab Wala - Queen'!$F:$F), 0) -> 0
B32: Lunch Deal (KKW) | C32: - | E32: - | G32: - | I32: - | K32: - | M32: - | O32: - | Q32: - | S32: =IFERROR(SUMIF('Karachi Food Court'!$A:$A, B32, 'Karachi Food Court'!$F:$F), 0) -> 0 | U32: =IFERROR(SUMIF('Karachi Kabab Wala'!$A:$A, B32, 'Karachi Kabab Wala'!$F:$F), 0) -> 0 | W32: =IFERROR(SUMIF('Karachi Kabab Wala - Queen'!$A:$A, B32, 'Karachi Kabab Wala - Queen'!$F:$F), 0) -> 0
B33: Shami Kabab (Beef) (12) | C33: - | E33: - | G33: - | I33: - | K33: - | M33: - | O33: - | Q33: - | S33: =IFERROR(SUMIF('Karachi Food Court'!$A:$A, B33, 'Karachi Food Court'!$F:$F), 0) -> 0 | U33: =IFERROR(SUMIF('Karachi Kabab Wala'!$A:$A, B33, 'Karachi Kabab Wala'!$F:$F), 0) -> 108 | W33: =IFERROR(SUMIF('Karachi Kabab Wala - Queen'!$A:$A, B33, 'Karachi Kabab Wala - Queen'!$F:$F), 0) -> 4
B34: Shami Kabab (Beef (6) | C34: - | E34: - | G34: - | I34: - | K34: - | M34: - | O34: - | Q34: - | S34: =IFERROR(SUMIF('Karachi Food Court'!$A:$A, B34, 'Karachi Food Court'!$F:$F), 0) -> 156 | U34: =IFERROR(SUMIF('Karachi Kabab Wala'!$A:$A, B34, 'Karachi Kabab Wala'!$F:$F), 0) -> 9 | W34: =IFERROR(SUMIF('Karachi Kabab Wala - Queen'!$A:$A, B34, 'Karachi Kabab Wala - Queen'!$F:$F), 0) -> 2
B35: Shami Kabab (Chicken) (12) | C35: - | E35: - | G35: - | I35: - | K35: - | M35: - | O35: - | Q35: - | S35: =IFERROR(SUMIF('Karachi Food Court'!$A:$A, B35, 'Karachi Food Court'!$F:$F), 0) -> 0 | U35: =IFERROR(SUMIF('Karachi Kabab Wala'!$A:$A, B35, 'Karachi Kabab Wala'!$F:$F), 0) -> 79 | W35: =IFERROR(SUMIF('Karachi Kabab Wala - Queen'!$A:$A, B35, 'Karachi Kabab Wala - Queen'!$F:$F), 0) -> 5
B36: Shami Kabab (Chicken) (6) | C36: - | E36: - | G36: - | I36: - | K36: - | M36: - | O36: - | Q36: - | S36: =IFERROR(SUMIF('Karachi Food Court'!$A:$A, B36, 'Karachi Food Court'!$F:$F), 0) -> 85 | U36: =IFERROR(SUMIF('Karachi Kabab Wala'!$A:$A, B36, 'Karachi Kabab Wala'!$F:$F), 0) -> 12 | W36: =IFERROR(SUMIF('Karachi Kabab Wala - Queen'!$A:$A, B36, 'Karachi Kabab Wala - Queen'!$F:$F), 0) -> 2
B37: Shami Kabab (Beef) (12) - OO | C37: - | E37: - | G37: - | I37: - | K37: - | M37: - | O37: - | Q37: - | S37: =IFERROR(SUMIF('Karachi Food Court'!$A:$A, B37, 'Karachi Food Court'!$F:$F), 0) -> 0 | U37: =IFERROR(SUMIF('Karachi Kabab Wala'!$A:$A, B37, 'Karachi Kabab Wala'!$F:$F), 0) -> 6 | W37: =IFERROR(SUMIF('Karachi Kabab Wala - Queen'!$A:$A, B37, 'Karachi Kabab Wala - Queen'!$F:$F), 0) -> 12
B38: Shami Kabab (Beef (6) - OO | C38: - | E38: - | G38: - | I38: - | K38: - | M38: - | O38: - | Q38: - | S38: =IFERROR(SUMIF('Karachi Food Court'!$A:$A, B38, 'Karachi Food Court'!$F:$F), 0) -> 3 | U38: =IFERROR(SUMIF('Karachi Kabab Wala'!$A:$A, B38, 'Karachi Kabab Wala'!$F:$F), 0) -> 0 | W38: =IFERROR(SUMIF('Karachi Kabab Wala - Queen'!$A:$A, B38, 'Karachi Kabab Wala - Queen'!$F:$F), 0) -> 1
B39: Shami Kabab (Chicken) (12) - OO | C39: - | E39: - | G39: - | I39: - | K39: - | M39: - | O39: - | Q39: - | S39: =IFERROR(SUMIF('Karachi Food Court'!$A:$A, B39, 'Karachi Food Court'!$F:$F), 0) -> 0 | U39: =IFERROR(SUMIF('Karachi Kabab Wala'!$A:$A, B39, 'Karachi Kabab Wala'!$F:$F), 0) -> 9 | W39: =IFERROR(SUMIF('Karachi Kabab Wala - Queen'!$A:$A, B39, 'Karachi Kabab Wala - Queen'!$F:$F), 0) -> 5
B40: 2 Can Dine for $29.99 | M40: - | Q40: - | S40: - | U40: =IFERROR(SUMIF('Karachi Kabab Wala'!$A:$A, B40, 'Karachi Kabab Wala'!$F:$F), 0) -> 11 | W40: =IFERROR(SUMIF('Karachi Kabab Wala - Queen'!$A:$A, B40, 'Karachi Kabab Wala - Queen'!$F:$F), 0) -> 30
B41: Lunch Deal with Biryani (KKW) | M41: - | Q41: - | S41: - | U41: =IFERROR(SUMIF('Karachi Kabab Wala'!$A:$A, B41, 'Karachi Kabab Wala'!$F:$F), 0) -> 0 | W41: =IFERROR(SUMIF('Karachi Kabab Wala - Queen'!$A:$A, B41, 'Karachi Kabab Wala - Queen'!$F:$F), 0) -> 13
...
