Workbook

Sheet Karachi Kabab Wala - Queen
A1: Karachi Kabab Wala - Queen Street - Sales By Menu Item - 2026-03-16/2026-03-22
A2: "Menu Item" | B2: "Sales Category" | C2: "Menu Group" | D2: "Menu Item Void Quantity" | E2: "Voids" | F2: "Menu Item Quantity" | G2: "Gross Sales" | H2: "Item Discounts" | I2: "Bill Discounts" | J2: "Net Sales" | K2: "Menu Item Quantity (Refunds)" | L2: "Refund Amount (Net Sales)" | M2: "Sales Percentage" | N2: "Tax 1" | O2: "Tax 2" | P2: "Tax 3"
A3: 2 Can Dine - D | B3: Kabab Wala | C3: DEALS - KKW - OO | D3: 0 | E3: 0 | F3: 1 | G3: 39.99 | H3: 0 | I3: 0 | J3: 39.99 | K3: 0 | L3: 0 | M3: 0.0036 | N3: 5.2 | O3: 0 | P3: 0.00
A4: 2 Can Dine for $29.99 | B4: Kabab Wala | C4: Chef Special and Deals (KKW) | D4: 1 | E4: 29.99 | F4: 5 | G4: 149.95 | H4: 0 | I4: 0 | J4: 149.95 | K4: 0 | L4: 0 | M4: 0.0135 | N4: 19.49 | O4: 0 | P4: 0.00
A5: 2 for $10 Lassi | B5: Kabab Wala | C5: Chef Special and Deals (KKW) | D5: 1 | E5: 10 | F5: 2 | G5: 20 | H5: 0 | I5: 0 | J5: 20 | K5: 0 | L5: 0 | M5: 0.0018 | N5: 2.6 | O5: 0 | P5: 0.00
A6: 2Reshmi Kabab - Deal | B6: Kabab Wala | C6: BBQ | D6: 1 | E6: 0 | F6: 8 | G6: 0 | H6: 0 | I6: 0 | J6: 0 | K6: 0 | L6: 0 | M6: 0 | N6: 0 | O6: 0 | P6: 0.00
A7: 2Seekh Kabab - Deal | B7: Kabab Wala | C7: BBQ | D7: 1 | E7: 0 | F7: 6 | G7: 0 | H7: 0 | I7: 0 | J7: 0 | K7: 0 | L7: 0 | M7: 0 | N7: 0 | O7: 0 | P7: 0.00
A8: 7up Bottle | B8: Kabab Wala | C8: Drinks (FC) | D8: 0 | E8: 0 | F8: 1 | G8: 3.25 | H8: 0 | I8: 0 | J8: 3.25 | K8: 0 | L8: 0 | M8: 0.0003 | N8: 0.42 | O8: 0 | P8: 0.00
A9: Add Cheese - D | B9: Food | C9: *Food Hidden Modifiers - D | D9: 0 | E9: 0 | F9: 1 | G9: 1.8 | H9: 0 | I9: 0 | J9: 1.8 | K9: 0 | L9: 0 | M9: 0.0002 | N9: 0.23 | O9: 0 | P9: 0.00
A10: Add Chutney - D | B10: Food | C10: *Food Hidden Modifiers - D | D10: 0 | E10: 0 | F10: 5 | G10: 6 | H10: 0 | I10: 0 | J10: 6 | K10: 0 | L10: 0 | M10: 0.0005 | N10: 0.31 | O10: 0 | P10: 0.00
A11: Add Garlic Mayo | B11: Food Court | C11: *Hidden Food Mod | D11: 0 | E11: 0 | F11: 3 | G11: 3 | H11: 0 | I11: 0 | J11: 3 | K11: 0 | L11: 0 | M11: 0.0003 | N11: 0.26 | O11: 0 | P11: 0.00
A12: Add Garlic Mayo - D | B12: Food | C12: *Food Hidden Modifiers - D | D12: 0 | E12: 0 | F12: 1 | G12: 1.2 | H12: 0 | I12: 0 | J12: 1.2 | K12: 0 | L12: 0 | M12: 0.0001 | N12: 0.16 | O12: 0 | P12: 0.00
A13: Add Onions | B13: Food Court | C13: *Hidden Food Mod | D13: 0 | E13: 0 | F13: 1 | G13: 1 | H13: 0 | I13: 0 | J13: 1 | K13: 0 | L13: 0 | M13: 0.0001 | N13: 0.13 | O13: 0 | P13: 0.00
A14: Add Onions - D | B14: Food | C14: *Food Hidden Modifiers - D | D14: 0 | E14: 0 | F14: 3 | G14: 3.6 | H14: 0 | I14: 0 | J14: 3.6 | K14: 0 | L14: 0 | M14: 0.0003 | N14: 0.47 | O14: 0 | P14: 0.00
... A186: w/ Pepsi Can | B186: Drinks | C186: * Drinks Hidden Modifiers | D186: 0 | E186: 0 | F186: 2 | G186: 0 | H186: 0 | I186: 0 | J186: 0 | K186: 0 | L186: 0 | M186: 0 | N186: 0 | O186: 0 | P186: 0.00
A187: REPORT SUMMARY (184 entries) | D187: 33 | E187: 219.65 | F187: 1318 | G187: 11116.48 | H187: 0 | I187: 0 | J187: 11116.48 | K187: 0 | L187: 0 | M187: 0.9999 | N187: 1435.54 | O187: 0 | P187: 0.00

Sheet Eglinton
A1: Pizza Karachi- Eglinton - Sales By Menu Item - 2026-03-16/2026-03-22
A2: "Menu Item" | B2: "Sales Category" | C2: "Menu Group" | D2: "Menu Item Void Quantity" | E2: "Voids" | F2: "Menu Item Quantity" | G2: "Gross Sales" | H2: "Item Discounts" | I2: "Bill Discounts" | J2: "Net Sales" | K2: "Menu Item Quantity (Refunds)" | L2: "Refund Amount (Net Sales)" | M2: "Sales Percentage" | N2: "Tax 1" | O2: "Tax 2" | P2: "Tax 3"
A3: 1 Topp - 10 | B3: Food | C3: Klassic Pizza | D3: 0 | E3: 0 | F3: 1 | G3: 13 | H3: 0 | I3: 0 | J3: 13 | K3: 0 | L3: 0 | M3: 0.0002 | N3: 1.69 | O3: 0 | P3: 0.00
A4: 1 Topp - 12 | B4: Food | C4: Klassic Pizza | D4: 0 | E4: 0 | F4: 2 | G4: 30 | H4: 0 | I4: 0 | J4: 30 | K4: 0 | L4: 0 | M4: 0.0006 | N4: 3.9 | O4: 0 | P4: 0.00
A5: 1 Topp - 8 | B5: Food | C5: Klassic Pizza | D5: 0 | E5: 0 | F5: 1 | G5: 11 | H5: 0 | I5: 0 | J5: 11 | K5: 0 | L5: 0 | M5: 0.0002 | N5: 1.43 | O5: 0 | P5: 0.00
A6: 10 Chargha Wings | B6: Food | C6: Wings | D6: 0 | E6: 0 | F6: 11 | G6: 165 | H6: 0 | I6: 0 | J6: 165 | K6: 0 | L6: 0 | M6: 0.003 | N6: 21.45 | O6: 0 | P6: 0.00
A7: 10 Chargha Wings - OO | B7: Food | C7: Wings - OO | D7: 0 | E7: 0 | F7: 1 | G7: 18 | H7: 0 | I7: 0 | J7: 18 | K7: 0 | L7: 0 | M7: 0.0003 | N7: 2.34 | O7: 0 | P7: 0.00
A8: 10 Klassic Wings | B8: Food | C8: Wings | D8: 0 | E8: 0 | F8: 9 | G8: 135 | H8: 0 | I8: 0 | J8: 135 | K8: 0 | L8: 0 | M8: 0.0025 | N8: 17.55 | O8: 0 | P8: 0.00
A9: 10 Klassic Wings - OO | B9: Food | C9: Wings - OO | D9: 0 | E9: 0 | F9: 5 | G9: 90 | H9: 0 | I9: 0 | J9: 90 | K9: 0 | L9: 0 | M9: 0.0017 | N9: 11.7 | O9: 0 | P9: 0.00
A10: 10 Koated Wings | B10: Food | C10: Wings | D10: 0 | E10: 0 | F10: 18 | G10: 270 | H10: 0 | I10: 0 | J10: 270 | K10: 0 | L10: 0 | M10: 0.005 | N10: 35.1 | O10: 0 | P10: 0.00
A11: 10 Koated Wings - OO | B11: Food | C11: Wings - OO | D11: 0 | E11: 0 | F11: 1 | G11: 18 | H11: 0 | I11: 0 | J11: 18 | K11: 0 | L11: 0 | M11: 0.0003 | N11: 2.34 | O11: 0 | P11: 0.00
A12: 20 Baked Wings | B12: Food | C12: Wings | D12: 0 | E12: 0 | F12: 1 | G12: 23.49 | H12: 0 | I12: 0 | J12: 23.49 | K12: 0 | L12: 0 | M12: 0.0004 | N12: 3.05 | O12: 0 | P12: 0.00
A13: 20 Chargha Wings | B13: Food | C13: Wings | D13: 0 | E13: 0 | F13: 4 | G13: 93.96 | H13: 0 | I13: 0 | J13: 93.96 | K13: 0 | L13: 0 | M13: 0.0017 | N13: 12.21 | O13: 0 | P13: 0.00
A14: 20 Chargha Wings - OO | B14: Food | C14: Wings - OO | D14: 0 | E14: 0 | F14: 1 | G14: 28.19 | H14: 0 | I14: 0 | J14: 28.19 | K14: 0 | L14: 0 | M14: 0.0005 | N14: 3.66 | O14: 0 | P14: 0.00
... A534: w/ Tzatziki Sauce - D | B534: Food | C534: *Food Hidden Modifiers - D | D534: 0 | E534: 0 | F534: 43 | G534: 0 | H534: 0 | I534: 0 | J534: 0 | K534: 0 | L534: 0 | M534: 0 | N534: 0 | O534: 0 | P534: 0.00
A535: REPORT SUMMARY (532 entries) | D535: 0 | E535: 0 | F535: 10056 | G535: 54292.11 | H535: 0 | I535: 0 | J535: 54292.11 | K535: 0 | L535: 0 | M535: 0.9998 | N535: 7056.48 | O535: 0 | P535: 0.00

Sheet Heartland
A1: Pizza Karachi -Heartland - Sales By Menu Item - 2026-03-16/2026-03-22
A2: "Menu Item" | B2: "Sales Category" | C2: "Menu Group" | D2: "Menu Item Void Quantity" | E2: "Voids" | F2: "Menu Item Quantity" | G2: "Gross Sales" | H2: "Item Discounts" | I2: "Bill Discounts" | J2: "Net Sales" | K2: "Menu Item Quantity (Refunds)" | L2: "Refund Amount (Net Sales)" | M2: "Sales Percentage" | N2: "Tax 1" | O2: "Tax 2" | P2: "Tax 3"
A3: 1 Topp - 12 | B3: Food | C3: Klassic Pizza | D3: 0 | E3: 0 | F3: 3 | G3: 45 | H3: 0 | I3: 0 | J3: 45 | K3: 0 | L3: 0 | M3: 0.0017 | N3: 5.85 | O3: 0 | P3: 0.00
A4: 1 Topp - 8 | B4: Food | C4: Klassic Pizza | D4: 0 | E4: 0 | F4: 1 | G4: 11 | H4: 0 | I4: 0 | J4: 11 | K4: 0 | L4: 0 | M4: 0.0004 | N4: 1.43 | O4: 0 | P4: 0.00
A5: 10 Chargha Wings | B5: Food | C5: Wings | D5: 0 | E5: 0 | F5: 4 | G5: 60 | H5: 0 | I5: 0 | J5: 60 | K5: 0 | L5: 0 | M5: 0.0023 | N5: 7.8 | O5: 0 | P5: 0.00
A6: 10 Chargha Wings - OO | B6: Food | C6: Wings - OO | D6: 0 | E6: 0 | F6: 2 | G6: 36 | H6: 0 | I6: 0 | J6: 36 | K6: 0 | L6: 0 | M6: 0.0014 | N6: 4.68 | O6: 0 | P6: 0.00
A7: 10 Klassic Wings | B7: Food | C7: Wings | D7: 0 | E7: 0 | F7: 3 | G7: 45 | H7: 0 | I7: 0 | J7: 45 | K7: 0 | L7: 0 | M7: 0.0017 | N7: 5.85 | O7: 0 | P7: 0.00
A8: 10 Klassic Wings - OO | B8: Food | C8: Wings - OO | D8: 0 | E8: 0 | F8: 1 | G8: 18 | H8: 0 | I8: 0 | J8: 18 | K8: 0 | L8: 0 | M8: 0.0007 | N8: 2.34 | O8: 0 | P8: 0.00
A9: 10 Koated Wings | B9: Food | C9: Wings | D9: 1 | E9: 15 | F9: 0 | G9: 0 | H9: 0 | I9: 0 | J9: 0 | K9: 0 | L9: 0 | M9: 0 | N9: 0 | O9: 0 | P9: 0.00
A10: 10 Koated Wings - OO | B10: Food | C10: Wings - OO | D10: 0 | E10: 0 | F10: 3 | G10: 54 | H10: 0 | I10: 0 | J10: 54 | K10: 0 | L10: 0 | M10: 0.002 | N10: 7.02 | O10: 0 | P10: 0.00
A11: 2 Hot Drinks - $6 | B11: KT Icecream | C11: Klassic Flavors | D11: 0 | E11: 0 | F11: 4 | G11: 24 | H11: 0 | I11: 0 | J11: 24 | K11: 0 | L11: 0 | M11: 0.0009 | N11: 3.12 | O11: 0 | P11: 0.00
A12: 2 Zinger Meal (Double Sawari) | B12: Chickentarian | C12: Deals Chickentarian | D12: 0 | E12: 0 | F12: 1 | G12: 19.99 | H12: 0 | I12: 0 | J12: 19.99 | K12: 0 | L12: 0 | M12: 0.0008 | N12: 2.6 | O12: 0 | P12: 0.00
A13: 20 Chargha Wings | B13: Food | C13: Wings | D13: 0 | E13: 0 | F13: 2 | G13: 46.98 | H13: 0 | I13: 0 | J13: 46.98 | K13: 0 | L13: 0 | M13: 0.0018 | N13: 6.11 | O13: 0 | P13: 0.00
A14: 20 Klassic Wings | B14: Food | C14: Wings | D14: 0 | E14: 0 | F14: 2 | G14: 46.98 | H14: 0 | I14: 0 | J14: 46.98 | K14: 0 | L14: 0 | M14: 0.0018 | N14: 6.11 | O14: 0 | P14: 0.00
... A440: w/ Tzatziki Sauce - D | B440: Food | C440: *Food Hidden Modifiers - D | D440: 0 | E440: 0 | F440: 29 | G440: 0 | H440: 0 | I440: 0 | J440: 0 | K440: 0 | L440: 0 | M440: 0 | N440: 0 | O440: 0 | P440: 0.00
A441: REPORT SUMMARY (438 entries) | D441: 129 | E441: 690.74 | F441: 4631 | G441: 26371.2 | H441: 0 | I441: 0 | J441: 26371.2 | K441: 0 | L441: 0 | M441: 0.9999 | N441: 3426.76 | O441: 0 | P441: 0.00

Sheet Karachi Kabab Wala
A1: Karachi Kabab Wala - Sales By Menu Item - 2026-03-16/2026-03-22
A2: "Menu Item" | B2: "Sales Category" | C2: "Menu Group" | D2: "Menu Item Void Quantity" | E2: "Voids" | F2: "Menu Item Quantity" | G2: "Gross Sales" | H2: "Item Discounts" | I2: "Bill Discounts" | J2: "Net Sales" | K2: "Menu Item Quantity (Refunds)" | L2: "Refund Amount (Net Sales)" | M2: "Sales Percentage" | N2: "Tax 1" | O2: "Tax 2" | P2: "Tax 3"
A3: 2 Can Dine for $29.99 | B3: Kabab Wala | C3: Chef Special and Deals (KKW) | D3: 0 | E3: 0 | F3: 1 | G3: 29.99 | H3: 0 | I3: 0 | J3: 29.99 | K3: 0 | L3: 0 | M3: 0.0012 | N3: 3.9 | O3: 0 | P3: 0.00
A4: 2 for $10 Lassi | B4: Kabab Wala | C4: Chef Special and Deals (KKW) | D4: 0 | E4: 0 | F4: 1 | G4: 10 | H4: 0 | I4: 0 | J4: 10 | K4: 0 | L4: 0 | M4: 0.0004 | N4: 1.3 | O4: 0 | P4: 0.00
A5: Add Cheese | B5: Food Court | C5: *Hidden Food Mod | D5: 0 | E5: 0 | F5: 1 | G5: 1.5 | H5: 0 | I5: 0 | J5: 1.5 | K5: 0 | L5: 0 | M5: 0.0001 | N5: 0.2 | O5: 0 | P5: 0.00
A6: Add Chutney - D | B6: Food | C6: *Food Hidden Modifiers - D | D6: 0 | E6: 0 | F6: 5 | G6: 6 | H6: 0 | I6: 0 | J6: 6 | K6: 0 | L6: 0 | M6: 0.0002 | N6: 0.78 | O6: 0 | P6: 0.00
A7: Add Egg | B7: Smash Ox Burger | C7: *Hidden Food Mod | D7: 0 | E7: 0 | F7: 3 | G7: 4.5 | H7: 0 | I7: 0 | J7: 4.5 | K7: 0 | L7: 0 | M7: 0.0002 | N7: 0.39 | O7: 0 | P7: 0.00
A8: Add Garlic Mayo | B8: Food Court | C8: *Hidden Food Mod | D8: 0 | E8: 0 | F8: 4 | G8: 4 | H8: 0 | I8: 0 | J8: 4 | K8: 0 | L8: 0 | M8: 0.0002 | N8: 0.52 | O8: 0 | P8: 0.00
A9: Add Garlic Mayo - D | B9: Food | C9: *Food Hidden Modifiers - D | D9: 0 | E9: 0 | F9: 2 | G9: 2.4 | H9: 0 | I9: 0 | J9: 2.4 | K9: 0 | L9: 0 | M9: 0.0001 | N9: 0.31 | O9: 0 | P9: 0.00
A10: Add Onions - D | B10: Food | C10: *Food Hidden Modifiers - D | D10: 0 | E10: 0 | F10: 6 | G10: 7.2 | H10: 0 | I10: 0 | J10: 7.2 | K10: 0 | L10: 0 | M10: 0.0003 | N10: 0.94 | O10: 0 | P10: 0.00
A11: Add Raita - D | B11: Food | C11: *Food Hidden Modifiers - D | D11: 0 | E11: 0 | F11: 1 | G11: 1.2 | H11: 0 | I11: 0 | J11: 1.2 | K11: 0 | L11: 0 | M11: 0 | N11: 0.16 | O11: 0 | P11: 0.00
A12: Add Special House Chutney - D | B12: Food | C12: *Food Hidden Modifiers - D | D12: 0 | E12: 0 | F12: 1 | G12: 1.2 | H12: 0 | I12: 0 | J12: 1.2 | K12: 0 | L12: 0 | M12: 0 | N12: 0.16 | O12: 0 | P12: 0.00
A13: B - Fries - D | B13: Food | C13: *Food Hidden Modifiers - D | D13: 0 | E13: 0 | F13: 1 | G13: 4 | H13: 0 | I13: 0 | J13: 4 | K13: 0 | L13: 0 | M13: 0.0002 | N13: 0.52 | O13: 0 | P13: 0.00
A14: B - Karachi Parantha | B14: Food Court | C14: *Hidden Food Mod | D14: 6 | E14: 0 | F14: 198 | G14: 0 | H14: 0 | I14: 0 | J14: 0 | K14: 0 | L14: 0 | M14: 0 | N14: 0 | O14: 0 | P14: 0.00
... A137: w/ Pepsi Can - D - KKW | B137: Kabab Wala | C137: *Food Hidden Modifiers - D | D137: 0 | E137: 0 | F137: 2 | G137: 0 | H137: 0 | I137: 0 | J137: 0 | K137: 0 | L137: 0 | M137: 0 | N137: 0 | O137: 0 | P137: 0.00
A138: REPORT SUMMARY (135 entries) | D138: 137 | E138: 1279.05 | F138: 2560 | G138: 24836.08 | H138: 0 | I138: 0 | J138: 24836.08 | K138: 0 | L138: 0 | M138: 0.9999 | N138: 3133 | O138: 0 | P138: 0.00

Sheet Karachi Food Court
A1: Karachi Food Court - Sales By Menu Item - 2026-03-16/2026-03-22
A2: "Menu Item" | B2: "Sales Category" | C2: "Menu Group" | D2: "Menu Item Void Quantity" | E2: "Voids" | F2: "Menu Item Quantity" | G2: "Gross Sales" | H2: "Item Discounts" | I2: "Bill Discounts" | J2: "Net Sales" | K2: "Menu Item Quantity (Refunds)" | L2: "Refund Amount (Net Sales)" | M2: "Sales Percentage" | N2: "Tax 1" | O2: "Tax 2" | P2: "Tax 3"
A3: 2pc Karachi Broast (ONLY) | B3: Chickentarian | C3: Broast | D3: 0 | E3: 0 | F3: 3 | G3: 15 | H3: 0 | I3: 0 | J3: 15 | K3: 0 | L3: 0 | M3: 0.0002 | N3: 1.95 | O3: 0 | P3: 0.00
A4: 2pc Karachi Broast (ONLY) - OO | B4: Chickentarian | C4: Broast - OO | D4: 0 | E4: 0 | F4: 3 | G4: 28.77 | H4: 0 | I4: 0 | J4: 28.77 | K4: 0 | L4: 0 | M4: 0.0003 | N4: 3.74 | O4: 0 | P4: 0.00
A5: 2pc Karachi Broast (With Fries and Cole) | B5: Chickentarian | C5: Broast | D5: 0 | E5: 0 | F5: 6 | G5: 62.94 | H5: 0 | I5: 0 | J5: 62.94 | K5: 0 | L5: 0 | M5: 0.0007 | N5: 8.18 | O5: 0 | P5: 0.00
A6: 2pc Karachi Broast (With Fries and Cole) - OO | B6: Chickentarian | C6: Broast - OO | D6: 0 | E6: 0 | F6: 2 | G6: 25.18 | H6: 0 | I6: 0 | J6: 25.18 | K6: 0 | L6: 0 | M6: 0.0003 | N6: 3.27 | O6: 0 | P6: 0.00
A7: 3pc Karachi Broast (ONLY) | B7: Chickentarian | C7: Broast | D7: 0 | E7: 0 | F7: 23 | G7: 252.77 | H7: 0 | I7: 0 | J7: 252.77 | K7: 0 | L7: 0 | M7: 0.0029 | N7: 32.86 | O7: 0 | P7: 0.00
A8: 3pc Karachi Broast (With Fries and Cole) | B8: Chickentarian | C8: Broast | D8: 0 | E8: 0 | F8: 49 | G8: 661.01 | H8: 0 | I8: 0 | J8: 661.01 | K8: 0 | L8: 0 | M8: 0.0076 | N8: 85.93 | O8: 0 | P8: 0.00
A9: 3pc Karachi Broast (With Fries and Cole) - OO | B9: Chickentarian | C9: Broast - OO | D9: 0 | E9: 0 | F9: 5 | G9: 80.95 | H9: 0 | I9: 0 | J9: 80.95 | K9: 0 | L9: 0 | M9: 0.0009 | N9: 10.52 | O9: 0 | P9: 0.00
A10: 9pc Karachi Broast (ONLY) | B10: Chickentarian | C10: Broast | D10: 0 | E10: 0 | F10: 5 | G10: 134.95 | H10: 0 | I10: 0 | J10: 134.95 | K10: 0 | L10: 0 | M10: 0.0016 | N10: 17.54 | O10: 0 | P10: 0.00
A11: 9pc Karachi Broast (ONLY) - OO | B11: Chickentarian | C11: Broast - OO | D11: 0 | E11: 0 | F11: 1 | G11: 32.39 | H11: 0 | I11: 0 | J11: 32.39 | K11: 0 | L11: 0 | M11: 0.0004 | N11: 4.21 | O11: 0 | P11: 0.00
A12: 9pc Karachi Broast (With Fries and Cole) | B12: Chickentarian | C12: Broast | D12: 0 | E12: 0 | F12: 15 | G12: 479.85 | H12: 0 | I12: 0 | J12: 479.85 | K12: 0 | L12: 0 | M12: 0.0055 | N12: 62.38 | O12: 0 | P12: 0.00
A13: ABC Juice (L) | B13: Food Court | C13: Juices | D13: 0 | E13: 0 | F13: 2 | G13: 20 | H13: 0 | I13: 0 | J13: 20 | K13: 0 | L13: 0 | M13: 0.0002 | N13: 2.6 | O13: 0 | P13: 0.00
A14: ABC Juice (M) | B14: Food Court | C14: Juices | D14: 0 | E14: 0 | F14: 6 | G14: 42 | H14: 0 | I14: 0 | J14: 42 | K14: 0 | L14: 0 | M14: 0.0005 | N14: 5.46 | O14: 0 | P14: 0.00
... A289: Zinger Burger - OO | B289: Chickentarian | C289: Wings N Things - OO | D289: 0 | E289: 0 | F289: 12 | G289: 201.48 | H289: 0 | I289: 0 | J289: 201.48 | K289: 0 | L289: 0 | M289: 0.0023 | N289: 26.19 | O289: 0 | P289: 0.00
A290: REPORT SUMMARY (287 entries) | D290: 32 | E290: 314.53 | F290: 10179 | G290: 86979.6 | H290: 0 | I290: 0 | J290: 86979.6 | K290: 0 | L290: 0 | M290: 0.9999 | N290: 11172.37 | O290: 0 | P290: 0.00

Sheet Wonderland
A1: Pizza Karachi - Wonderland - Sales By Menu Item - 2026-03-16/2026-03-22
A2: "Menu Item" | B2: "Sales Category" | C2: "Menu Group" | D2: "Menu Item Void Quantity" | E2: "Voids" | F2: "Menu Item Quantity" | G2: "Gross Sales" | H2: "Item Discounts" | I2: "Bill Discounts" | J2: "Net Sales" | K2: "Menu Item Quantity (Refunds)" | L2: "Refund Amount (Net Sales)" | M2: "Sales Percentage" | N2: "Tax 1" | O2: "Tax 2" | P2: "Tax 3"
A3: 10 Chargha Wings | B3: Food | C3: Wings | D3: 0 | E3: 0 | F3: 6 | G3: 90 | H3: 0 | I3: 0 | J3: 90 | K3: 0 | L3: 0 | M3: 0.0077 | N3: 11.7 | O3: 0 | P3: 0.00
A4: 10 Klassic Wings | B4: Food | C4: Wings | D4: 0 | E4: 0 | F4: 3 | G4: 45 | H4: 0 | I4: 0 | J4: 45 | K4: 0 | L4: 0 | M4: 0.0039 | N4: 5.85 | O4: 0 | P4: 0.00
A5: 10 Klassic Wings - OO | B5: Food | C5: Wings - OO | D5: 0 | E5: 0 | F5: 2 | G5: 36 | H5: 0 | I5: 0 | J5: 36 | K5: 0 | L5: 0 | M5: 0.0031 | N5: 4.68 | O5: 0 | P5: 0.00
A6: 10 Koated Wings | B6: Food | C6: Wings | D6: 0 | E6: 0 | F6: 1 | G6: 15 | H6: 0 | I6: 0 | J6: 15 | K6: 0 | L6: 0 | M6: 0.0013 | N6: 1.95 | O6: 0 | P6: 0.00
A7: 10 Koated Wings - OO | B7: Food | C7: Wings - OO | D7: 0 | E7: 0 | F7: 3 | G7: 54 | H7: 0 | I7: 0 | J7: 54 | K7: 0 | L7: 0 | M7: 0.0046 | N7: 7.02 | O7: 0 | P7: 0.00
A8: 20 Chargha Wings | B8: Food | C8: Wings | D8: 0 | E8: 0 | F8: 2 | G8: 46.98 | H8: 0 | I8: 0 | J8: 46.98 | K8: 0 | L8: 0 | M8: 0.004 | N8: 6.11 | O8: 0 | P8: 0.00
A9: 20 Klassic Wings | B9: Food | C9: Wings | D9: 0 | E9: 0 | F9: 2 | G9: 46.98 | H9: 0 | I9: 0 | J9: 46.98 | K9: 0 | L9: 0 | M9: 0.004 | N9: 6.11 | O9: 0 | P9: 0.00
A10: 20 Koated Wings - OO | B10: Food | C10: Wings - OO | D10: 0 | E10: 0 | F10: 1 | G10: 28.19 | H10: 0 | I10: 0 | J10: 28.19 | K10: 0 | L10: 0 | M10: 0.0024 | N10: 3.66 | O10: 0 | P10: 0.00
A11: 3 Topp - 12 | B11: Food | C11: Klassic Pizza | D11: 0 | E11: 0 | F11: 3 | G11: 54 | H11: 0 | I11: 0 | J11: 54 | K11: 0 | L11: 0 | M11: 0.0046 | N11: 7.02 | O11: 0 | P11: 0.00
A12: 5 Chargha Wings | B12: Food | C12: Wings | D12: 0 | E12: 0 | F12: 3 | G12: 24 | H12: 0 | I12: 0 | J12: 24 | K12: -1 | L12: -8 | M12: 0.0021 | N12: 3.12 | O12: 0 | P12: 0.00
A13: 5 Chargha Wings - OO | B13: Food | C13: Wings - OO | D13: 0 | E13: 0 | F13: 1 | G13: 9.6 | H13: 0 | I13: 0 | J13: 9.6 | K13: 0 | L13: 0 | M13: 0.0008 | N13: 1.25 | O13: 0 | P13: 0.00
A14: 5 Klassic Wings | B14: Food | C14: Wings | D14: 0 | E14: 0 | F14: 2 | G14: 16 | H14: 0 | I14: 0 | J14: 16 | K14: 0 | L14: 0 | M14: 0.0014 | N14: 2.08 | O14: 0 | P14: 0.00
... A359: w/ Tzatziki Sauce - D | B359: Food | C359: *Food Hidden Modifiers - D | D359: 0 | E359: 0 | F359: 3 | G359: 0 | H359: 0 | I359: 0 | J359: 0 | K359: 0 | L359: 0 | M359: 0 | N359: 0 | O359: 0 | P359: 0.00
A360: REPORT SUMMARY (357 entries) | D360: 34 | E360: 179.93 | F360: 2218 | G360: 11664.95 | H360: 0 | I360: 0 | J360: 11664.95 | K360: -6 | L360: -44.46 | M360: 0.9999 | N360: 1513.77 | O360: 0 | P360: 0.00

Sheet Pizza Karachi Downtown TO
A1: Pizza Karachi Downtown TO - Sales By Menu Item - 2026-03-16/2026-03-22
A2: "Menu Item" | B2: "Sales Category" | C2: "Menu Group" | D2: "Menu Item Void Quantity" | E2: "Voids" | F2: "Menu Item Quantity" | G2: "Gross Sales" | H2: "Item Discounts" | I2: "Bill Discounts" | J2: "Net Sales" | K2: "Menu Item Quantity (Refunds)" | L2: "Refund Amount (Net Sales)" | M2: "Sales Percentage" | N2: "Tax 1" | O2: "Tax 2" | P2: "Tax 3"
A3: 10 Chargha Wings - OO | B3: Food | C3: Wings - OO | D3: 0 | E3: 0 | F3: 1 | G3: 18 | H3: 0 | I3: 0 | J3: 18 | K3: 0 | L3: 0 | M3: 0.0011 | N3: 2.34 | O3: 0 | P3: 0.00
A4: 10 Klassic Wings - OO | B4: Food | C4: Wings - OO | D4: 0 | E4: 0 | F4: 1 | G4: 18 | H4: 0 | I4: 0 | J4: 18 | K4: 0 | L4: 0 | M4: 0.0011 | N4: 2.34 | O4: 0 | P4: 0.00
A5: 100% off 12 Pizza - With Coupon | B5: Food | C5: Deals | D5: 0 | E5: 0 | F5: 1 | G5: 0 | H5: 0 | I5: 0 | J5: 0 | K5: 0 | L5: 0 | M5: 0 | N5: 0 | O5: 0 | P5: 0.00
A6: 2 Zinger Meal (Double Sawari) | B6: Chickentarian | C6: Deals Chickentarian | D6: 0 | E6: 0 | F6: 1 | G6: 19.99 | H6: 0 | I6: 0 | J6: 19.99 | K6: 0 | L6: 0 | M6: 0.0012 | N6: 2.6 | O6: 0 | P6: 0.00
A7: 20 Chargha Wings - OO | B7: Food | C7: Wings - OO | D7: 0 | E7: 0 | F7: 2 | G7: 56.38 | H7: 0 | I7: 0 | J7: 56.38 | K7: 0 | L7: 0 | M7: 0.0034 | N7: 7.33 | O7: 0 | P7: 0.00
A8: 20 Klassic Wings | B8: Food | C8: Wings | D8: 0 | E8: 0 | F8: 1 | G8: 23.49 | H8: 0 | I8: 0 | J8: 23.49 | K8: 0 | L8: 0 | M8: 0.0014 | N8: 3.05 | O8: 0 | P8: 0.00
A9: 2pc Karachi Broast (ONLY) | B9: Chickentarian | C9: Broast | D9: 0 | E9: 0 | F9: 1 | G9: 5 | H9: 0 | I9: 0 | J9: 5 | K9: 0 | L9: 0 | M9: 0.0003 | N9: 0.65 | O9: 0 | P9: 0.00
A10: 3pc Karachi Broast (With Fries and Cole) - OO | B10: Chickentarian | C10: Broast - OO | D10: 0 | E10: 0 | F10: 1 | G10: 16.19 | H10: 0 | I10: 0 | J10: 16.19 | K10: 0 | L10: 0 | M10: 0.001 | N10: 2.1 | O10: 0 | P10: 0.00
A11: 5 Chargha Wings | B11: Food | C11: Wings | D11: 0 | E11: 0 | F11: 1 | G11: 8 | H11: 0 | I11: 0 | J11: 8 | K11: 0 | L11: 0 | M11: 0.0005 | N11: 1.04 | O11: 0 | P11: 0.00
A12: 5 Chargha Wings - OO | B12: Food | C12: Wings - OO | D12: 0 | E12: 0 | F12: 2 | G12: 19.2 | H12: 0 | I12: 0 | J12: 19.2 | K12: 0 | L12: 0 | M12: 0.0012 | N12: 2.5 | O12: 0 | P12: 0.00
A13: 5 Klassic Wings | B13: Food | C13: Wings | D13: 0 | E13: 0 | F13: 1 | G13: 8 | H13: 0 | I13: 0 | J13: 8 | K13: 0 | L13: 0 | M13: 0.0005 | N13: 1.04 | O13: 0 | P13: 0.00
A14: 5 Klassic Wings - OO | B14: Food | C14: Wings - OO | D14: 0 | E14: 0 | F14: 4 | G14: 38.4 | H14: 0 | I14: 0 | J14: 38.4 | K14: 0 | L14: 0 | M14: 0.0023 | N14: 4.99 | O14: 0 | P14: 0.00
... A438: w/ Tzatziki Sauce - D | B438: Food | C438: *Food Hidden Modifiers - D | D438: 0 | E438: 0 | F438: 29 | G438: 0 | H438: 0 | I438: 0 | J438: 0 | K438: 0 | L438: 0 | M438: 0 | N438: 0 | O438: 0 | P438: 0.00
A439: REPORT SUMMARY (436 entries) | D439: 14 | E439: 64.75 | F439: 2752 | G439: 16675.07 | H439: 0 | I439: 0 | J439: 16675.07 | K439: 0 | L439: 0 | M439: 0.9998 | N439: 2167.07 | O439: 0 | P439: 0.00

Sheet Highway Karahi
A1: Pizza Karachi- Highway Karahi - Sales By Menu Item - 2026-03-16/2026-03-22
A2: "Menu Item" | B2: "Sales Category" | C2: "Menu Group" | D2: "Menu Item Void Quantity" | E2: "Voids" | F2: "Menu Item Quantity" | G2: "Gross Sales" | H2: "Item Discounts" | I2: "Bill Discounts" | J2: "Net Sales" | K2: "Menu Item Quantity (Refunds)" | L2: "Refund Amount (Net Sales)" | M2: "Sales Percentage" | N2: "Tax 1" | O2: "Tax 2" | P2: "Tax 3"
A3: $13 Lunch Deal (KHK) | B3: Food Highway | C3: Takeout / Deals (HW) | D3: 1 | E3: 13 | F3: 8 | G3: 104 | H3: 0 | I3: 0 | J3: 104 | K3: 0 | L3: 0 | M3: 0.0042 | N3: 13.52 | O3: 0 | P3: 0.00
A4: 10 Chargha Wings | B4: Food | C4: Wings | D4: 0 | E4: 0 | F4: 1 | G4: 15 | H4: 0 | I4: 0 | J4: 15 | K4: 0 | L4: 0 | M4: 0.0006 | N4: 1.95 | O4: 0 | P4: 0.00
A5: 10 Chargha Wings - OO | B5: Food | C5: Wings - OO | D5: 0 | E5: 0 | F5: 1 | G5: 18 | H5: 0 | I5: 0 | J5: 18 | K5: 0 | L5: 0 | M5: 0.0007 | N5: 2.34 | O5: 0 | P5: 0.00
A6: 10 Klassic Wings | B6: Food | C6: Wings | D6: 0 | E6: 0 | F6: 3 | G6: 45 | H6: 0 | I6: 0 | J6: 45 | K6: 0 | L6: 0 | M6: 0.0018 | N6: 5.85 | O6: 0 | P6: 0.00
A7: 10 Koated Wings | B7: Food | C7: Wings | D7: 0 | E7: 0 | F7: 2 | G7: 30 | H7: 0 | I7: 0 | J7: 30 | K7: 0 | L7: 0 | M7: 0.0012 | N7: 3.9 | O7: 0 | P7: 0.00
A8: 20 Chargha Wings | B8: Food | C8: Wings | D8: 0 | E8: 0 | F8: 4 | G8: 93.96 | H8: 0 | I8: 0 | J8: 93.96 | K8: 0 | L8: 0 | M8: 0.0038 | N8: 12.21 | O8: 0 | P8: 0.00
A9: 20 Klassic Wings | B9: Food | C9: Wings | D9: 0 | E9: 0 | F9: 1 | G9: 23.49 | H9: 0 | I9: 0 | J9: 23.49 | K9: 0 | L9: 0 | M9: 0.0009 | N9: 3.05 | O9: 0 | P9: 0.00
A10: 3 Topp - 12 | B10: Food | C10: Klassic Pizza | D10: 0 | E10: 0 | F10: 1 | G10: 18 | H10: 0 | I10: 0 | J10: 18 | K10: 0 | L10: 0 | M10: 0.0007 | N10: 2.34 | O10: 0 | P10: 0.00
A11: 5 Chargha Wings | B11: Food | C11: Wings | D11: 0 | E11: 0 | F11: 3 | G11: 24 | H11: 0 | I11: 0 | J11: 24 | K11: 0 | L11: 0 | M11: 0.001 | N11: 3.12 | O11: 0 | P11: 0.00
A12: 5 Koated Wings | B12: Food | C12: Wings | D12: 0 | E12: 0 | F12: 2 | G12: 16 | H12: 0 | I12: 0 | J12: 16 | K12: 0 | L12: 0 | M12: 0.0006 | N12: 2.08 | O12: 0 | P12: 0.00
A13: 7Up Bottle (Plastic) - OO | B13: Drinks | C13: Drinks (PK) - OO | D13: 0 | E13: 0 | F13: 1 | G13: 3.9 | H13: 0 | I13: 0 | J13: 3.9 | K13: 0 | L13: 0 | M13: 0.0002 | N13: 0.51 | O13: 0 | P13: 0.00
A14: 7Up Can | B14: Drinks | C14: Drinks (PK) | D14: 0 | E14: 0 | F14: 6 | G14: 13.5 | H14: 0.9 | I14: 0 | J14: 12.6 | K14: 0 | L14: 0 | M14: 0.0005 | N14: 1.64 | O14: 0 | P14: 0.00
... A312: w/ Tzatziki Sauce - D | B312: Food | C312: *Food Hidden Modifiers - D | D312: 0 | E312: 0 | F312: 3 | G312: 0 | H312: 0 | I312: 0 | J312: 0 | K312: 0 | L312: 0 | M312: 0 | N312: 0 | O312: 0 | P312: 0.00
A313: REPORT SUMMARY (310 entries) | D313: 154 | E313: 1538.61 | F313: 2967 | G313: 25127.18 | H313: 306.7 | I313: 0 | J313: 24820.48 | K313: 0 | L313: 0 | M313: 0.9999 | N313: 3225.78 | O313: 0 | P313: 0.00

Sheet Lebovic
A1: Pizza Karachi - Lebovic - Sales By Menu Item - 2026-03-16/2026-03-22
A2: "Menu Item" | B2: "Sales Category" | C2: "Menu Group" | D2: "Menu Item Void Quantity" | E2: "Voids" | F2: "Menu Item Quantity" | G2: "Gross Sales" | H2: "Item Discounts" | I2: "Bill Discounts" | J2: "Net Sales" | K2: "Menu Item Quantity (Refunds)" | L2: "Refund Amount (Net Sales)" | M2: "Sales Percentage" | N2: "Tax 1" | O2: "Tax 2" | P2: "Tax 3"
A3: 10 Chargha Wings | B3: Food | C3: Wings | D3: 0 | E3: 0 | F3: 2 | G3: 30 | H3: 0 | I3: 0 | J3: 30 | K3: 0 | L3: 0 | M3: 0.0021 | N3: 3.9 | O3: 0 | P3: 0.00
A4: 10 Chargha Wings - OO | B4: Food | C4: Wings - OO | D4: 0 | E4: 0 | F4: 2 | G4: 36 | H4: 0 | I4: 0 | J4: 36 | K4: 0 | L4: 0 | M4: 0.0025 | N4: 4.68 | O4: 0 | P4: 0.00
A5: 10 Klassic Wings | B5: Food | C5: Wings | D5: 0 | E5: 0 | F5: 1 | G5: 15 | H5: 0 | I5: 0 | J5: 15 | K5: 0 | L5: 0 | M5: 0.001 | N5: 1.95 | O5: 0 | P5: 0.00
A6: 10 Koated Wings | B6: Food | C6: Wings | D6: 0 | E6: 0 | F6: 4 | G6: 60 | H6: 1.5 | I6: 0 | J6: 58.5 | K6: 0 | L6: 0 | M6: 0.004 | N6: 7.61 | O6: 0 | P6: 0.00
A7: 2 Zinger Meal (Double Sawari) | B7: Chickentarian | C7: Deals Chickentarian | D7: 1 | E7: 19.99 | F7: 2 | G7: 39.98 | H7: 0 | I7: 0 | J7: 39.98 | K7: 0 | L7: 0 | M7: 0.0027 | N7: 5.2 | O7: 0 | P7: 0.00
A8: 20 Chargha Wings | B8: Food | C8: Wings | D8: 0 | E8: 0 | F8: 1 | G8: 23.49 | H8: 0 | I8: 0 | J8: 23.49 | K8: 0 | L8: 0 | M8: 0.0016 | N8: 3.05 | O8: 0 | P8: 0.00
A9: 20 Klassic Wings | B9: Food | C9: Wings | D9: 1 | E9: 23.49 | F9: 3 | G9: 70.47 | H9: 0 | I9: 0 | J9: 70.47 | K9: 0 | L9: 0 | M9: 0.0048 | N9: 9.16 | O9: 0 | P9: 0.00
A10: 20 Klassic Wings - OO | B10: Food | C10: Wings - OO | D10: 0 | E10: 0 | F10: 1 | G10: 28.19 | H10: 0 | I10: 0 | J10: 28.19 | K10: 0 | L10: 0 | M10: 0.0019 | N10: 3.66 | O10: 0 | P10: 0.00
A11: 20 Koated Wings | B11: Food | C11: Wings | D11: 0 | E11: 0 | F11: 2 | G11: 46.98 | H11: 0 | I11: 0 | J11: 46.98 | K11: 0 | L11: 0 | M11: 0.0032 | N11: 6.11 | O11: 0 | P11: 0.00
A12: 2nd Falooda $2 | B12: KT Icecream | C12: Others | D12: 1 | E12: 2 | F12: 1 | G12: 2 | H12: 0 | I12: 0 | J12: 2 | K12: -1 | L12: -2 | M12: 0.0001 | N12: 0.26 | O12: 0 | P12: 0.00
A13: 2pc Karachi Broast (ONLY) | B13: Chickentarian | C13: Broast | D13: 0 | E13: 0 | F13: 10 | G13: 50 | H13: 0 | I13: 0 | J13: 50 | K13: 0 | L13: 0 | M13: 0.0034 | N13: 6.5 | O13: 0 | P13: 0.00
A14: 2pc Karachi Broast (ONLY) - OO | B14: Chickentarian | C14: Broast - OO | D14: 0 | E14: 0 | F14: 1 | G14: 9.59 | H14: 0 | I14: 0 | J14: 9.59 | K14: 0 | L14: 0 | M14: 0.0007 | N14: 1.25 | O14: 0 | P14: 0.00
... A408: w/ Tzatziki Sauce - D | B408: Food | C408: *Food Hidden Modifiers - D | D408: 0 | E408: 0 | F408: 14 | G408: 0 | H408: 0 | I408: 0 | J408: 0 | K408: 0 | L408: 0 | M408: 0 | N408: 0 | O408: 0 | P408: 0.00
A409: REPORT SUMMARY (406 entries) | D409: 96 | E409: 477.95 | F409: 2917 | G409: 14589.52 | H409: 8.95 | I409: 0 | J409: 14580.57 | K409: -3 | L409: -24.48 | M409: 0.9999 | N409: 1903.61 | O409: 0 | P409: 0.00

Sheet Ajax
A1: Pizza Karachi - Ajax - Sales By Menu Item - 2026-03-16/2026-03-22
A2: "Menu Item" | B2: "Sales Category" | C2: "Menu Group" | D2: "Menu Item Void Quantity" | E2: "Voids" | F2: "Menu Item Quantity" | G2: "Gross Sales" | H2: "Item Discounts" | I2: "Bill Discounts" | J2: "Net Sales" | K2: "Menu Item Quantity (Refunds)" | L2: "Refund Amount (Net Sales)" | M2: "Sales Percentage" | N2: "Tax 1" | O2: "Tax 2" | P2: "Tax 3"
A3: 10 Chargha Wings | B3: Food | C3: Wings | D3: 0 | E3: 0 | F3: 2 | G3: 30 | H3: 0 | I3: 0 | J3: 30 | K3: 0 | L3: 0 | M3: 0.0026 | N3: 3.9 | O3: 0 | P3: 0.00
A4: 10 Klassic Wings | B4: Food | C4: Wings | D4: 1 | E4: 15 | F4: 2 | G4: 30 | H4: 0 | I4: 0 | J4: 30 | K4: 0 | L4: 0 | M4: 0.0026 | N4: 3.9 | O4: 0 | P4: 0.00
A5: 10 Klassic Wings - OO | B5: Food | C5: Wings - OO | D5: 0 | E5: 0 | F5: 4 | G5: 72 | H5: 0 | I5: 0 | J5: 72 | K5: 0 | L5: 0 | M5: 0.0063 | N5: 9.36 | O5: 0 | P5: 0.00
A6: 2 Zinger Burger Meal - D | B6: Chickentarian | C6: Deals Chickentarian - OO | D6: 0 | E6: 0 | F6: 2 | G6: 49.98 | H6: 0 | I6: 0 | J6: 49.98 | K6: 0 | L6: 0 | M6: 0.0044 | N6: 6.5 | O6: 0 | P6: 0.00
A7: 20 Chargha Wings | B7: Food | C7: Wings | D7: 0 | E7: 0 | F7: 3 | G7: 70.47 | H7: 0 | I7: 0 | J7: 70.47 | K7: 0 | L7: 0 | M7: 0.0062 | N7: 9.16 | O7: 0 | P7: 0.00
A8: 20 Klassic Wings | B8: Food | C8: Wings | D8: 0 | E8: 0 | F8: 4 | G8: 93.96 | H8: 0 | I8: 0 | J8: 93.96 | K8: 0 | L8: 0 | M8: 0.0083 | N8: 12.21 | O8: 0 | P8: 0.00
A9: 20 Koated Wings | B9: Food | C9: Wings | D9: 1 | E9: 23.49 | F9: 0 | G9: 0 | H9: 0 | I9: 0 | J9: 0 | K9: 0 | L9: 0 | M9: 0 | N9: 0 | O9: 0 | P9: 0.00
A10: 3pc Karachi Broast (ONLY) - OO | B10: Chickentarian | C10: Broast - OO | D10: 0 | E10: 0 | F10: 1 | G10: 13.19 | H10: 0 | I10: 0 | J10: 13.19 | K10: 0 | L10: 0 | M10: 0.0012 | N10: 1.71 | O10: 0 | P10: 0.00
A11: 5 Chargha Wings | B11: Food | C11: Wings | D11: 0 | E11: 0 | F11: 1 | G11: 8 | H11: 0 | I11: 0 | J11: 8 | K11: 0 | L11: 0 | M11: 0.0007 | N11: 1.04 | O11: 0 | P11: 0.00
A12: 5 Chargha Wings - OO | B12: Food | C12: Wings - OO | D12: 0 | E12: 0 | F12: 1 | G12: 9.6 | H12: 0 | I12: 0 | J12: 9.6 | K12: 0 | L12: 0 | M12: 0.0008 | N12: 1.25 | O12: 0 | P12: 0.00
A13: 5 Klassic Wings | B13: Food | C13: Wings | D13: 1 | E13: 8 | F13: 4 | G13: 32 | H13: 0 | I13: 0 | J13: 32 | K13: 0 | L13: 0 | M13: 0.0028 | N13: 4.16 | O13: 0 | P13: 0.00
A14: 5 Klassic Wings - OO | B14: Food | C14: Wings - OO | D14: 0 | E14: 0 | F14: 1 | G14: 9.6 | H14: 0 | I14: 0 | J14: 9.6 | K14: 0 | L14: 0 | M14: 0.0008 | N14: 1.25 | O14: 0 | P14: 0.00
... A299: w/ Tzatziki Sauce - D | B299: Food | C299: *Food Hidden Modifiers - D | D299: 0 | E299: 0 | F299: 9 | G299: 0 | H299: 0 | I299: 0 | J299: 0 | K299: 0 | L299: 0 | M299: 0 | N299: 0 | O299: 0 | P299: 0.00
A300: REPORT SUMMARY (297 entries) | D300: 298 | E300: 1404.93 | F300: 2080 | G300: 11404.81 | H300: 53.41 | I300: 0 | J300: 11351.4 | K300: 0 | L300: 0 | M300: 0.9999 | N300: 1475.28 | O300: 0 | P300: 0.00

Sheet Markham Rd
A1: Pizza Karachi - Markham Rd - Sales By Menu Item - 2026-03-16/2026-03-22
A2: "Menu Item" | B2: "Sales Category" | C2: "Menu Group" | D2: "Menu Item Void Quantity" | E2: "Voids" | F2: "Menu Item Quantity" | G2: "Gross Sales" | H2: "Item Discounts" | I2: "Bill Discounts" | J2: "Net Sales" | K2: "Menu Item Quantity (Refunds)" | L2: "Refund Amount (Net Sales)" | M2: "Sales Percentage" | N2: "Tax 1" | O2: "Tax 2" | P2: "Tax 3"
A3: 10 Chargha Wings | B3: Food | C3: Wings | D3: 0 | E3: 0 | F3: 3 | G3: 45 | H3: 0 | I3: 0 | J3: 45 | K3: 0 | L3: 0 | M3: 0.0043 | N3: 5.85 | O3: 0 | P3: 0.00
A4: 10 Klassic Wings | B4: Food | C4: Wings | D4: 0 | E4: 0 | F4: 2 | G4: 30 | H4: 0 | I4: 0 | J4: 30 | K4: 0 | L4: 0 | M4: 0.0028 | N4: 3.9 | O4: 0 | P4: 0.00
A5: 10 Klassic Wings - OO | B5: Food | C5: Wings - OO | D5: 0 | E5: 0 | F5: 3 | G5: 54 | H5: 0 | I5: 0 | J5: 54 | K5: 0 | L5: 0 | M5: 0.0051 | N5: 7.02 | O5: 0 | P5: 0.00
A6: 10 Koated Wings - OO | B6: Food | C6: Wings - OO | D6: 0 | E6: 0 | F6: 1 | G6: 18 | H6: 0 | I6: 0 | J6: 18 | K6: 0 | L6: 0 | M6: 0.0017 | N6: 2.34 | O6: 0 | P6: 0.00
A7: 20 Chargha Wings | B7: Food | C7: Wings | D7: 0 | E7: 0 | F7: 1 | G7: 23.49 | H7: 0 | I7: 0 | J7: 23.49 | K7: 0 | L7: 0 | M7: 0.0022 | N7: 3.05 | O7: 0 | P7: 0.00
A8: 20 Klassic Wings | B8: Food | C8: Wings | D8: 0 | E8: 0 | F8: 2 | G8: 46.98 | H8: 0 | I8: 0 | J8: 46.98 | K8: 0 | L8: 0 | M8: 0.0044 | N8: 6.11 | O8: 0 | P8: 0.00
A9: 3 Topp - 8 | B9: Food | C9: Klassic Pizza | D9: 0 | E9: 0 | F9: 1 | G9: 12 | H9: 0 | I9: 0 | J9: 12 | K9: 0 | L9: 0 | M9: 0.0011 | N9: 1.56 | O9: 0 | P9: 0.00
A10: 5 Chargha Wings | B10: Food | C10: Wings | D10: 0 | E10: 0 | F10: 2 | G10: 16 | H10: 0 | I10: 0 | J10: 16 | K10: 0 | L10: 0 | M10: 0.0015 | N10: 2.08 | O10: 0 | P10: 0.00
A11: 5 Klassic Wings | B11: Food | C11: Wings | D11: 0 | E11: 0 | F11: 1 | G11: 8 | H11: 0 | I11: 0 | J11: 8 | K11: 0 | L11: 0 | M11: 0.0008 | N11: 1.04 | O11: 0 | P11: 0.00
A12: 5 Klassic Wings - OO | B12: Food | C12: Wings - OO | D12: 0 | E12: 0 | F12: 2 | G12: 19.2 | H12: 0 | I12: 0 | J12: 19.2 | K12: 0 | L12: 0 | M12: 0.0018 | N12: 2.5 | O12: 0 | P12: 0.00
A13: 5 Koated Wings - OO | B13: Food | C13: Wings - OO | D13: 0 | E13: 0 | F13: 1 | G13: 9.6 | H13: 0 | I13: 0 | J13: 9.6 | K13: 0 | L13: 0 | M13: 0.0009 | N13: 1.25 | O13: 0 | P13: 0.00
A14: 50 Chargha Wings | B14: Food | C14: Wings | D14: 0 | E14: 0 | F14: 1 | G14: 55.49 | H14: 0 | I14: 0 | J14: 55.49 | K14: 0 | L14: 0 | M14: 0.0052 | N14: 7.21 | O14: 0 | P14: 0.00
... A300: w/ Tzatziki Sauce - D | B300: Food | C300: *Food Hidden Modifiers - D | D300: 0 | E300: 0 | F300: 6 | G300: 0 | H300: 0 | I300: 0 | J300: 0 | K300: 0 | L300: 0 | M300: 0 | N300: 0 | O300: 0 | P300: 0.00
A301: REPORT SUMMARY (298 entries) | D301: 70 | E301: 360.46 | F301: 1867 | G301: 10582.2 | H301: 0 | I301: 0 | J301: 10582.2 | K301: 0 | L301: 0 | M301: 0.9999 | N301: 1375.73 | O301: 0 | P301: 0.00

Sheet checker
A1: Mar 16 - Mar 22
B3: Items | C3: markham | D3: percentage | E3: ajax | F3: percentage | G3: lebovic | H3: percentage | I3: wonderland | J3: percentage | K3: downtown | L3: percentage | M3: highway | N3: percentage | O3: heartland | P3: percentage | Q3: eglinton | R3: percentage | S3: food court | T3: percentage | U3: kabab wala | V3: percentage | W3: kababwala Q St | X3: percentage
A4: Pizza K Deals | B4: Wing Wednesday - 10 | C4: =IFERROR(SUMIF('Markham Rd'!$A:$A, B4, 'Markham Rd'!$F:$F), 0) -> 3 | E4: =IFERROR(SUMIF(Ajax!$A:$A, B4, Ajax!$F:$F), 0) -> 2 | G4: =IFERROR(SUMIF(Lebovic!$A:$A, B4, Lebovic!$F:$F), 0) -> 0 | I4: =IFERROR(SUMIF(Wonderland!$A:$A, B4, Wonderland!$F:$F), 0) -> 10 | K4: =IFERROR(SUMIF('Pizza Karachi Downtown TO'!$A:$A, B4, 'Pizza Karachi Downtown TO'!$F:$F), 0) -> 1 | M4: =IFERROR(SUMIF('Highway Karahi'!$A:$A, B4, 'Highway Karahi'!$F:$F), 0) -> 0 | O4: =IFERROR(SUMIF(Heartland!$A:$A, B4, Heartland!$F:$F), 0) -> 2 | Q4: =IFERROR(SUMIF(Eglinton!$A:$A, B4, Eglinton!$F:$F), 0) -> 12 | S4: - | U4: -
B5: Family Deal | C5: =IFERROR(SUMIF('Markham Rd'!$A:$A, B5, 'Markham Rd'!$F:$F), 0) -> 24 | E5: =IFERROR(SUMIF(Ajax!$A:$A, B5, Ajax!$F:$F), 0) -> 20 | G5: =IFERROR(SUMIF(Lebovic!$A:$A, B5, Lebovic!$F:$F), 0) -> 34 | I5: =IFERROR(SUMIF(Wonderland!$A:$A, B5, Wonderland!$F:$F), 0) -> 27 | K5: =IFERROR(SUMIF('Pizza Karachi Downtown TO'!$A:$A, B5, 'Pizza Karachi Downtown TO'!$F:$F), 0) -> 5 | M5: =IFERROR(SUMIF('Highway Karahi'!$A:$A, B5, 'Highway Karahi'!$F:$F), 0) -> 4 | O5: =IFERROR(SUMIF(Heartland!$A:$A, B5, Heartland!$F:$F), 0) -> 49 | Q5: =IFERROR(SUMIF(Eglinton!$A:$A, B5, Eglinton!$F:$F), 0) -> 73 | S5: - | U5: -
B6: Personal Pizza Lunch Deal | C6: =IFERROR(SUMIF('Markham Rd'!$A:$A, B6, 'Markham Rd'!$F:$F), 0) -> 0 | E6: =IFERROR(SUMIF(Ajax!$A:$A, B6, Ajax!$F:$F), 0) -> 6 | G6: =IFERROR(SUMIF(Lebovic!$A:$A, B6, Lebovic!$F:$F), 0) -> 2 | I6: =IFERROR(SUMIF(Wonderland!$A:$A, B6, Wonderland!$F:$F), 0) -> 3 | K6: =IFERROR(SUMIF('Pizza Karachi Downtown TO'!$A:$A, B6, 'Pizza Karachi Downtown TO'!$F:$F), 0) -> 16 | M6: =IFERROR(SUMIF('Highway Karahi'!$A:$A, B6, 'Highway Karahi'!$F:$F), 0) -> 0 | O6: =IFERROR(SUMIF(Heartland!$A:$A, B6, Heartland!$F:$F), 0) -> 11 | Q6: =IFERROR(SUMIF(Eglinton!$A:$A, B6, Eglinton!$F:$F), 0) -> 3 | S6: - | U6: -
B7: Personal Pizza Lunch Deal - OO | C7: =IFERROR(SUMIF('Markham Rd'!$A:$A, B7, 'Markham Rd'!$F:$F), 0) -> 4 | E7: =IFERROR(SUMIF(Ajax!$A:$A, B7, Ajax!$F:$F), 0) -> 5 | G7: =IFERROR(SUMIF(Lebovic!$A:$A, B7, Lebovic!$F:$F), 0) -> 5 | I7: =IFERROR(SUMIF(Wonderland!$A:$A, B7, Wonderland!$F:$F), 0) -> 5 | K7: =IFERROR(SUMIF('Pizza Karachi Downtown TO'!$A:$A, B7, 'Pizza Karachi Downtown TO'!$F:$F), 0) -> 28 | M7: =IFERROR(SUMIF('Highway Karahi'!$A:$A, B7, 'Highway Karahi'!$F:$F), 0) -> 3 | O7: =IFERROR(SUMIF(Heartland!$A:$A, B7, Heartland!$F:$F), 0) -> 9 | Q7: =IFERROR(SUMIF(Eglinton!$A:$A, B7, Eglinton!$F:$F), 0) -> 20 | S7: - | U7: -
B8: Wings Lunch Deal - OO | C8: =IFERROR(SUMIF('Markham Rd'!$A:$A, B8, 'Markham Rd'!$F:$F), 0) -> 0 | E8: =IFERROR(SUMIF(Ajax!$A:$A, B8, Ajax!$F:$F), 0) -> 0 | G8: =IFERROR(SUMIF(Lebovic!$A:$A, B8, Lebovic!$F:$F), 0) -> 0 | I8: =IFERROR(SUMIF(Wonderland!$A:$A, B8, Wonderland!$F:$F), 0) -> 2 | K8: =IFERROR(SUMIF('Pizza Karachi Downtown TO'!$A:$A, B8, 'Pizza Karachi Downtown TO'!$F:$F), 0) -> 4 | M8: =IFERROR(SUMIF('Highway Karahi'!$A:$A, B8, 'Highway Karahi'!$F:$F), 0) -> 0 | O8: =IFERROR(SUMIF(Heartland!$A:$A, B8, Heartland!$F:$F), 0) -> 2 | Q8: =IFERROR(SUMIF(Eglinton!$A:$A, B8, Eglinton!$F:$F), 0) -> 4 | S8: - | U8: -
B9: Wings Lunch Deal | C9: =IFERROR(SUMIF('Markham Rd'!$A:$A, B9, 'Markham Rd'!$F:$F), 0) -> 0 | E9: =IFERROR(SUMIF(Ajax!$A:$A, B9, Ajax!$F:$F), 0) -> 0 | G9: =IFERROR(SUMIF(Lebovic!$A:$A, B9, Lebovic!$F:$F), 0) -> 0 | I9: =IFERROR(SUMIF(Wonderland!$A:$A, B9, Wonderland!$F:$F), 0) -> 0 | K9: =IFERROR(SUMIF('Pizza Karachi Downtown TO'!$A:$A, B9, 'Pizza Karachi Downtown TO'!$F:$F), 0) -> 0 | M9: =IFERROR(SUMIF('Highway Karahi'!$A:$A, B9, 'Highway Karahi'!$F:$F), 0) -> 0 | O9: =IFERROR(SUMIF(Heartland!$A:$A, B9, Heartland!$F:$F), 0) -> 0 | Q9: =IFERROR(SUMIF(Eglinton!$A:$A, B9, Eglinton!$F:$F), 0) -> 0 | S9: - | U9: -
B10: Monday Deal | C10: =IFERROR(SUMIF('Markham Rd'!$A:$A, B10, 'Markham Rd'!$F:$F), 0) -> 0 | E10: =IFERROR(SUMIF(Ajax!$A:$A, B10, Ajax!$F:$F), 0) -> 0 | G10: =IFERROR(SUMIF(Lebovic!$A:$A, B10, Lebovic!$F:$F), 0) -> 0 | I10: =IFERROR(SUMIF(Wonderland!$A:$A, B10, Wonderland!$F:$F), 0) -> 0 | K10: =IFERROR(SUMIF('Pizza Karachi Downtown TO'!$A:$A, B10, 'Pizza Karachi Downtown TO'!$F:$F), 0) -> 0 | M10: =IFERROR(SUMIF('Highway Karahi'!$A:$A, B10, 'Highway Karahi'!$F:$F), 0) -> 0 | O10: =IFERROR(SUMIF(Heartland!$A:$A, B10, Heartland!$F:$F), 0) -> 1 | Q10: =IFERROR(SUMIF(Eglinton!$A:$A, B10, Eglinton!$F:$F), 0) -> 3
B11: Tuesday Deal | C11: =IFERROR(SUMIF('Markham Rd'!$A:$A, B11, 'Markham Rd'!$F:$F), 0) -> 0 | E11: =IFERROR(SUMIF(Ajax!$A:$A, B11, Ajax!$F:$F), 0) -> 0 | G11: =IFERROR(SUMIF(Lebovic!$A:$A, B11, Lebovic!$F:$F), 0) -> 0 | I11: =IFERROR(SUMIF(Wonderland!$A:$A, B11, Wonderland!$F:$F), 0) -> 0 | K11: =IFERROR(SUMIF('Pizza Karachi Downtown TO'!$A:$A, B11, 'Pizza Karachi Downtown TO'!$F:$F), 0) -> 0 | M11: =IFERROR(SUMIF('Highway Karahi'!$A:$A, B11, 'Highway Karahi'!$F:$F), 0) -> 0 | O11: =IFERROR(SUMIF(Heartland!$A:$A, B11, Heartland!$F:$F), 0) -> 1 | Q11: =IFERROR(SUMIF(Eglinton!$A:$A, B11, Eglinton!$F:$F), 0) -> 0
B12: Thursday Deal | C12: =IFERROR(SUMIF('Markham Rd'!$A:$A, B12, 'Markham Rd'!$F:$F), 0) -> 0 | E12: =IFERROR(SUMIF(Ajax!$A:$A, B12, Ajax!$F:$F), 0) -> 0 | G12: =IFERROR(SUMIF(Lebovic!$A:$A, B12, Lebovic!$F:$F), 0) -> 0 | I12: =IFERROR(SUMIF(Wonderland!$A:$A, B12, Wonderland!$F:$F), 0) -> 0 | K12: =IFERROR(SUMIF('Pizza Karachi Downtown TO'!$A:$A, B12, 'Pizza Karachi Downtown TO'!$F:$F), 0) -> 1 | M12: =IFERROR(SUMIF('Highway Karahi'!$A:$A, B12, 'Highway Karahi'!$F:$F), 0) -> 0 | O12: =IFERROR(SUMIF(Heartland!$A:$A, B12, Heartland!$F:$F), 0) -> 0 | Q12: =IFERROR(SUMIF(Eglinton!$A:$A, B12, Eglinton!$F:$F), 0) -> 0
B13: Friday Deal | C13: =IFERROR(SUMIF('Markham Rd'!$A:$A, B13, 'Markham Rd'!$F:$F), 0) -> 0 | E13: =IFERROR(SUMIF(Ajax!$A:$A, B13, Ajax!$F:$F), 0) -> 0 | G13: =IFERROR(SUMIF(Lebovic!$A:$A, B13, Lebovic!$F:$F), 0) -> 0 | I13: =IFERROR(SUMIF(Wonderland!$A:$A, B13, Wonderland!$F:$F), 0) -> 0 | K13: =IFERROR(SUMIF('Pizza Karachi Downtown TO'!$A:$A, B13, 'Pizza Karachi Downtown TO'!$F:$F), 0) -> 0 | M13: =IFERROR(SUMIF('Highway Karahi'!$A:$A, B13, 'Highway Karahi'!$F:$F), 0) -> 0 | O13: =IFERROR(SUMIF(Heartland!$A:$A, B13, Heartland!$F:$F), 0) -> 0 | Q13: =IFERROR(SUMIF(Eglinton!$A:$A, B13, Eglinton!$F:$F), 0) -> 2
B14: Late Night Deal (2 Med $34.99) | C14: =IFERROR(SUMIF('Markham Rd'!$A:$A, B14, 'Markham Rd'!$F:$F), 0) -> 9 | E14: =IFERROR(SUMIF(Ajax!$A:$A, B14, Ajax!$F:$F), 0) -> 4 | G14: =IFERROR(SUMIF(Lebovic!$A:$A, B14, Lebovic!$F:$F), 0) -> 4 | I14: =IFERROR(SUMIF(Wonderland!$A:$A, B14, Wonderland!$F:$F), 0) -> 2 | K14: =IFERROR(SUMIF('Pizza Karachi Downtown TO'!$A:$A, B14, 'Pizza Karachi Downtown TO'!$F:$F), 0) -> 4 | M14: =IFERROR(SUMIF('Highway Karahi'!$A:$A, B14, 'Highway Karahi'!$F:$F), 0) -> 3 | O14: =IFERROR(SUMIF(Heartland!$A:$A, B14, Heartland!$F:$F), 0) -> 25 | Q14: =IFERROR(SUMIF(Eglinton!$A:$A, B14, Eglinton!$F:$F), 0) -> 69
A15: Stuffed Crust | B15: Cheese Stuffed Crust - 10 | C15: =IFERROR(SUMIF('Markham Rd'!$A:$A, B15, 'Markham Rd'!$F:$F), 0) -> 4 | E15: =IFERROR(SUMIF(Ajax!$A:$A, B15, Ajax!$F:$F), 0) -> 0 | G15: =IFERROR(SUMIF(Lebovic!$A:$A, B15, Lebovic!$F:$F), 0) -> 4 | I15: =IFERROR(SUMIF(Wonderland!$A:$A, B15, Wonderland!$F:$F), 0) -> 1 | K15: =IFERROR(SUMIF('Pizza Karachi Downtown TO'!$A:$A, B15, 'Pizza Karachi Downtown TO'!$F:$F), 0) -> 2 | M15: =IFERROR(SUMIF('Highway Karahi'!$A:$A, B15, 'Highway Karahi'!$F:$F), 0) -> 0 | O15: =IFERROR(SUMIF(Heartland!$A:$A, B15, Heartland!$F:$F), 0) -> 3 | Q15: =IFERROR(SUMIF(Eglinton!$A:$A, B15, Eglinton!$F:$F), 0) -> 8 | S15: - | U15: -
B16: P2 Cheese Stuffed Crust - 12 | C16: =IFERROR(SUMIF('Markham Rd'!$A:$A, B16, 'Markham Rd'!$F:$F), 0) -> 2 | E16: =IFERROR(SUMIF(Ajax!$A:$A, B16, Ajax!$F:$F), 0) -> 0 | G16: =IFERROR(SUMIF(Lebovic!$A:$A, B16, Lebovic!$F:$F), 0) -> 1 | I16: =IFERROR(SUMIF(Wonderland!$A:$A, B16, Wonderland!$F:$F), 0) -> 1 | K16: =IFERROR(SUMIF('Pizza Karachi Downtown TO'!$A:$A, B16, 'Pizza Karachi Downtown TO'!$F:$F), 0) -> 1 | M16: =IFERROR(SUMIF('Highway Karahi'!$A:$A, B16, 'Highway Karahi'!$F:$F), 0) -> 2 | O16: =IFERROR(SUMIF(Heartland!$A:$A, B16, Heartland!$F:$F), 0) -> 2 | Q16: =IFERROR(SUMIF(Eglinton!$A:$A, B16, Eglinton!$F:$F), 0) -> 2 | S16: - | U16: -
B17: P1 Cheese Stuffed Crust - 12 | C17: =IFERROR(SUMIF('Markham Rd'!$A:$A, B17, 'Markham Rd'!$F:$F), 0) -> 1 | E17: =IFERROR(SUMIF(Ajax!$A:$A, B17, Ajax!$F:$F), 0) -> 1 | G17: =IFERROR(SUMIF(Lebovic!$A:$A, B17, Lebovic!$F:$F), 0) -> 2 | I17: =IFERROR(SUMIF(Wonderland!$A:$A, B17, Wonderland!$F:$F), 0) -> 1 | K17: =IFERROR(SUMIF('Pizza Karachi Downtown TO'!$A:$A, B17, 'Pizza Karachi Downtown TO'!$F:$F), 0) -> 1 | M17: =IFERROR(SUMIF('Highway Karahi'!$A:$A, B17, 'Highway Karahi'!$F:$F), 0) -> 0 | O17: =IFERROR(SUMIF(Heartland!$A:$A, B17, Heartland!$F:$F), 0) -> 1 | Q17: =IFERROR(SUMIF(Eglinton!$A:$A, B17, Eglinton!$F:$F), 0) -> 2 | S17: - | U17: -
B18: Cheese Stuffed Crust - 12 | C18: =IFERROR(SUMIF('Markham Rd'!$A:$A, B18, 'Markham Rd'!$F:$F), 0) -> 0 | E18: =IFERROR(SUMIF(Ajax!$A:$A, B18, Ajax!$F:$F), 0) -> 0 | G18: =IFERROR(SUMIF(Lebovic!$A:$A, B18, Lebovic!$F:$F), 0) -> 0 | I18: =IFERROR(SUMIF(Wonderland!$A:$A, B18, Wonderland!$F:$F), 0) -> 0 | K18: =IFERROR(SUMIF('Pizza Karachi Downtown TO'!$A:$A, B18, 'Pizza Karachi Downtown TO'!$F:$F), 0) -> 0 | M18: =IFERROR(SUMIF('Highway Karahi'!$A:$A, B18, 'Highway Karahi'!$F:$F), 0) -> 0 | O18: =IFERROR(SUMIF(Heartland!$A:$A, B18, Heartland!$F:$F), 0) -> 0 | Q18: =IFERROR(SUMIF(Eglinton!$A:$A, B18, Eglinton!$F:$F), 0) -> 0 | S18: - | U18: -
B19: Chicken Stuffed Kabab - 10 | C19: =IFERROR(SUMIF('Markham Rd'!$A:$A, B19, 'Markham Rd'!$F:$F), 0) -> 0 | E19: =IFERROR(SUMIF(Ajax!$A:$A, B19, Ajax!$F:$F), 0) -> 0 | G19: =IFERROR(SUMIF(Lebovic!$A:$A, B19, Lebovic!$F:$F), 0) -> 1 | I19: =IFERROR(SUMIF(Wonderland!$A:$A, B19, Wonderland!$F:$F), 0) -> 1 | K19: =IFERROR(SUMIF('Pizza Karachi Downtown TO'!$A:$A, B19, 'Pizza Karachi Downtown TO'!$F:$F), 0) -> 1 | M19: =IFERROR(SUMIF('Highway Karahi'!$A:$A, B19, 'Highway Karahi'!$F:$F), 0) -> 0 | O19: =IFERROR(SUMIF(Heartland!$A:$A, B19, Heartland!$F:$F), 0) -> 1 | Q19: =IFERROR(SUMIF(Eglinton!$A:$A, B19, Eglinton!$F:$F), 0) -> 0 | S19: - | U19: -
B20: Chicken Stuffed Kabab - 12 | C20: =IFERROR(SUMIF('Markham Rd'!$A:$A, B20, 'Markham Rd'!$F:$F), 0) -> 0 | E20: =IFERROR(SUMIF(Ajax!$A:$A, B20, Ajax!$F:$F), 0) -> 0 | G20: =IFERROR(SUMIF(Lebovic!$A:$A, B20, Lebovic!$F:$F), 0) -> 0 | I20: =IFERROR(SUMIF(Wonderland!$A:$A, B20, Wonderland!$F:$F), 0) -> 0 | K20: =IFERROR(SUMIF('Pizza Karachi Downtown TO'!$A:$A, B20, 'Pizza Karachi Downtown TO'!$F:$F), 0) -> 0 | M20: =IFERROR(SUMIF('Highway Karahi'!$A:$A, B20, 'Highway Karahi'!$F:$F), 0) -> 0 | O20: =IFERROR(SUMIF(Heartland!$A:$A, B20, Heartland!$F:$F), 0) -> 0 | Q20: =IFERROR(SUMIF(Eglinton!$A:$A, B20, Eglinton!$F:$F), 0) -> 0 | S20: - | U20: -
B21: P1 Chicken Stuffed Kabab - 12 | C21: =IFERROR(SUMIF('Markham Rd'!$A:$A, B21, 'Markham Rd'!$F:$F), 0) -> 1 | E21: =IFERROR(SUMIF(Ajax!$A:$A, B21, Ajax!$F:$F), 0) -> 0 | G21: =IFERROR(SUMIF(Lebovic!$A:$A, B21, Lebovic!$F:$F), 0) -> 1 | I21: =IFERROR(SUMIF(Wonderland!$A:$A, B21, Wonderland!$F:$F), 0) -> 1 | K21: =IFERROR(SUMIF('Pizza Karachi Downtown TO'!$A:$A, B21, 'Pizza Karachi Downtown TO'!$F:$F), 0) -> 0 | M21: =IFERROR(SUMIF('Highway Karahi'!$A:$A, B21, 'Highway Karahi'!$F:$F), 0) -> 0 | O21: =IFERROR(SUMIF(Heartland!$A:$A, B21, Heartland!$F:$F), 0) -> 2 | Q21: =IFERROR(SUMIF(Eglinton!$A:$A, B21, Eglinton!$F:$F), 0) -> 1 | S21: - | U21: -
B22: P2 Chicken Stuffed Kabab - 12 | C22: =IFERROR(SUMIF('Markham Rd'!$A:$A, B22, 'Markham Rd'!$F:$F), 0) -> 1 | E22: =IFERROR(SUMIF(Ajax!$A:$A, B22, Ajax!$F:$F), 0) -> 0 | G22: =IFERROR(SUMIF(Lebovic!$A:$A, B22, Lebovic!$F:$F), 0) -> 0 | I22: =IFERROR(SUMIF(Wonderland!$A:$A, B22, Wonderland!$F:$F), 0) -> 1 | K22: =IFERROR(SUMIF('Pizza Karachi Downtown TO'!$A:$A, B22, 'Pizza Karachi Downtown TO'!$F:$F), 0) -> 0 | M22: =IFERROR(SUMIF('Highway Karahi'!$A:$A, B22, 'Highway Karahi'!$F:$F), 0) -> 0 | O22: =IFERROR(SUMIF(Heartland!$A:$A, B22, Heartland!$F:$F), 0) -> 2 | Q22: =IFERROR(SUMIF(Eglinton!$A:$A, B22, Eglinton!$F:$F), 0) -> 1 | S22: - | U22: -
B23: Beef Stuffed Kabab - 12 | C23: =IFERROR(SUMIF('Markham Rd'!$A:$A, B23, 'Markham Rd'!$F:$F), 0) -> 0 | E23: =IFERROR(SUMIF(Ajax!$A:$A, B23, Ajax!$F:$F), 0) -> 0 | G23: =IFERROR(SUMIF(Lebovic!$A:$A, B23, Lebovic!$F:$F), 0) -> 0 | I23: =IFERROR(SUMIF(Wonderland!$A:$A, B23, Wonderland!$F:$F), 0) -> 0 | K23: =IFERROR(SUMIF('Pizza Karachi Downtown TO'!$A:$A, B23, 'Pizza Karachi Downtown TO'!$F:$F), 0) -> 0 | M23: =IFERROR(SUMIF('Highway Karahi'!$A:$A, B23, 'Highway Karahi'!$F:$F), 0) -> 0 | O23: =IFERROR(SUMIF(Heartland!$A:$A, B23, Heartland!$F:$F), 0) -> 0 | Q23: =IFERROR(SUMIF(Eglinton!$A:$A, B23, Eglinton!$F:$F), 0) -> 0 | S23: - | U23: -
B24: P1 Beef Stuffed Kabab - 12 | C24: =IFERROR(SUMIF('Markham Rd'!$A:$A, B24, 'Markham Rd'!$F:$F), 0) -> 0 | E24: =IFERROR(SUMIF(Ajax!$A:$A, B24, Ajax!$F:$F), 0) -> 0 | G24: =IFERROR(SUMIF(Lebovic!$A:$A, B24, Lebovic!$F:$F), 0) -> 0 | I24: =IFERROR(SUMIF(Wonderland!$A:$A, B24, Wonderland!$F:$F), 0) -> 0 | K24: =IFERROR(SUMIF('Pizza Karachi Downtown TO'!$A:$A, B24, 'Pizza Karachi Downtown TO'!$F:$F), 0) -> 0 | M24: =IFERROR(SUMIF('Highway Karahi'!$A:$A, B24, 'Highway Karahi'!$F:$F), 0) -> 0 | O24: =IFERROR(SUMIF(Heartland!$A:$A, B24, Heartland!$F:$F), 0) -> 1 | Q24: =IFERROR(SUMIF(Eglinton!$A:$A, B24, Eglinton!$F:$F), 0) -> 3 | S24: - | U24: -
B25: P2 Beef Stuffed Kabab - 12 | C25: =IFERROR(SUMIF('Markham Rd'!$A:$A, B25, 'Markham Rd'!$F:$F), 0) -> 0 | E25: =IFERROR(SUMIF(Ajax!$A:$A, B25, Ajax!$F:$F), 0) -> 0 | G25: =IFERROR(SUMIF(Lebovic!$A:$A, B25, Lebovic!$F:$F), 0) -> 0 | I25: =IFERROR(SUMIF(Wonderland!$A:$A, B25, Wonderland!$F:$F), 0) -> 0 | K25: =IFERROR(SUMIF('Pizza Karachi Downtown TO'!$A:$A, B25, 'Pizza Karachi Downtown TO'!$F:$F), 0) -> 0 | M25: =IFERROR(SUMIF('Highway Karahi'!$A:$A, B25, 'Highway Karahi'!$F:$F), 0) -> 0 | O25: =IFERROR(SUMIF(Heartland!$A:$A, B25, Heartland!$F:$F), 0) -> 0 | Q25: =IFERROR(SUMIF(Eglinton!$A:$A, B25, Eglinton!$F:$F), 0) -> 1 | S25: - | U25: -
B26: Beef Stuffed Kabab - 10 | C26: =IFERROR(SUMIF('Markham Rd'!$A:$A, B26, 'Markham Rd'!$F:$F), 0) -> 0 | E26: =IFERROR(SUMIF(Ajax!$A:$A, B26, Ajax!$F:$F), 0) -> 0 | G26: =IFERROR(SUMIF(Lebovic!$A:$A, B26, Lebovic!$F:$F), 0) -> 0 | I26: =IFERROR(SUMIF(Wonderland!$A:$A, B26, Wonderland!$F:$F), 0) -> 0 | K26: =IFERROR(SUMIF('Pizza Karachi Downtown TO'!$A:$A, B26, 'Pizza Karachi Downtown TO'!$F:$F), 0) -> 0 | M26: =IFERROR(SUMIF('Highway Karahi'!$A:$A, B26, 'Highway Karahi'!$F:$F), 0) -> 2 | O26: =IFERROR(SUMIF(Heartland!$A:$A, B26, Heartland!$F:$F), 0) -> 0 | Q26: =IFERROR(SUMIF(Eglinton!$A:$A, B26, Eglinton!$F:$F), 0) -> 1 | S26: - | U26: -
B27: Total Stuffed Crust | C27: =IFERROR(SUMIF('Markham Rd'!$A:$A, B27, 'Markham Rd'!$F:$F), 0) -> 0 | E27: =IFERROR(SUMIF(Ajax!$A:$A, B27, Ajax!$F:$F), 0) -> 0 | G27: =IFERROR(SUMIF(Lebovic!$A:$A, B27, Lebovic!$F:$F), 0) -> 0 | I27: =IFERROR(SUMIF(Wonderland!$A:$A, B27, Wonderland!$F:$F), 0) -> 0 | K27: =IFERROR(SUMIF('Pizza Karachi Downtown TO'!$A:$A, B27, 'Pizza Karachi Downtown TO'!$F:$F), 0) -> 0 | M27: =IFERROR(SUMIF('Highway Karahi'!$A:$A, B27, 'Highway Karahi'!$F:$F), 0) -> 0 | O27: =IFERROR(SUMIF(Heartland!$A:$A, B27, Heartland!$F:$F), 0) -> 0 | Q27: =IFERROR(SUMIF(Eglinton!$A:$A, B27, Eglinton!$F:$F), 0) -> 0
A28: Karachi Kabab Wala and Food Court | B28: Beef Lover Platter | C28: - | E28: - | G28: - | I28: - | K28: - | M28: - | O28: - | Q28: - | S28: =IFERROR(SUMIF('Karachi Food Court'!$A:$A, B28, 'Karachi Food Court'!$F:$F), 0) -> 31 | U28: =IFERROR(SUMIF('Karachi Kabab Wala'!$A:$A, B28, 'Karachi Kabab Wala'!$F:$F), 0) -> 20 | W28: =IFERROR(SUMIF('Karachi Kabab Wala - Queen'!$A:$A, B28, 'Karachi Kabab Wala - Queen'!$F:$F), 0) -> 2
B29: Chicken Lover Platter | C29: - | E29: - | G29: - | I29: - | K29: - | M29: - | O29: - | Q29: - | S29: =IFERROR(SUMIF('Karachi Food Court'!$A:$A, B29, 'Karachi Food Court'!$F:$F), 0) -> 49 | U29: =IFERROR(SUMIF('Karachi Kabab Wala'!$A:$A, B29, 'Karachi Kabab Wala'!$F:$F), 0) -> 9 | W29: =IFERROR(SUMIF('Karachi Kabab Wala - Queen'!$A:$A, B29, 'Karachi Kabab Wala - Queen'!$F:$F), 0) -> 3
B30: Mix Platter | C30: - | E30: - | G30: - | I30: - | K30: - | M30: - | O30: - | Q30: - | S30: =IFERROR(SUMIF('Karachi Food Court'!$A:$A, B30, 'Karachi Food Court'!$F:$F), 0) -> 109 | U30: =IFERROR(SUMIF('Karachi Kabab Wala'!$A:$A, B30, 'Karachi Kabab Wala'!$F:$F), 0) -> 21 | W30: =IFERROR(SUMIF('Karachi Kabab Wala - Queen'!$A:$A, B30, 'Karachi Kabab Wala - Queen'!$F:$F), 0) -> 4
B31: Premium Platter (KKW) | C31: - | E31: - | G31: - | I31: - | K31: - | M31: - | O31: - | Q31: - | S31: =IFERROR(SUMIF('Karachi Food Court'!$A:$A, B31, 'Karachi Food Court'!$F:$F), 0) -> 0 | U31: =IFERROR(SUMIF('Karachi Kabab Wala'!$A:$A, B31, 'Karachi Kabab Wala'!$F:$F), 0) -> 0 | W31: =IFERROR(SUMIF('Karachi Kabab Wala - Queen'!$A:$A, B31, 'Karachi Kabab Wala - Queen'!$F:$F), 0) -> 0
B32: Lunch Deal (KKW) | C32: - | E32: - | G32: - | I32: - | K32: - | M32: - | O32: - | Q32: - | S32: =IFERROR(SUMIF('Karachi Food Court'!$A:$A, B32, 'Karachi Food Court'!$F:$F), 0) -> 0 | U32: =IFERROR(SUMIF('Karachi Kabab Wala'!$A:$A, B32, 'Karachi Kabab Wala'!$F:$F), 0) -> 0 | W32: =IFERROR(SUMIF('Karachi Kabab Wala - Queen'!$A:$A, B32, 'Karachi Kabab Wala - Queen'!$F:$F), 0) -> 0
B33: Shami Kabab (Beef) (12) | C33: - | E33: - | G33: - | I33: - | K33: - | M33: - | O33: - | Q33: - | S33: =IFERROR(SUMIF('Karachi Food Court'!$A:$A, B33, 'Karachi Food Court'!$F:$F), 0) -> 0 | U33: =IFERROR(SUMIF('Karachi Kabab Wala'!$A:$A, B33, 'Karachi Kabab Wala'!$F:$F), 0) -> 12 | W33: =IFERROR(SUMIF('Karachi Kabab Wala - Queen'!$A:$A, B33, 'Karachi Kabab Wala - Queen'!$F:$F), 0) -> 0
B34: Shami Kabab (Beef (6) | C34: - | E34: - | G34: - | I34: - | K34: - | M34: - | O34: - | Q34: - | S34: =IFERROR(SUMIF('Karachi Food Court'!$A:$A, B34, 'Karachi Food Court'!$F:$F), 0) -> 41 | U34: =IFERROR(SUMIF('Karachi Kabab Wala'!$A:$A, B34, 'Karachi Kabab Wala'!$F:$F), 0) -> 2 | W34: =IFERROR(SUMIF('Karachi Kabab Wala - Queen'!$A:$A, B34, 'Karachi Kabab Wala - Queen'!$F:$F), 0) -> 0
B35: Shami Kabab (Chicken) (12) | C35: - | E35: - | G35: - | I35: - | K35: - | M35: - | O35: - | Q35: - | S35: =IFERROR(SUMIF('Karachi Food Court'!$A:$A, B35, 'Karachi Food Court'!$F:$F), 0) -> 0 | U35: =IFERROR(SUMIF('Karachi Kabab Wala'!$A:$A, B35, 'Karachi Kabab Wala'!$F:$F), 0) -> 21 | W35: =IFERROR(SUMIF('Karachi Kabab Wala - Queen'!$A:$A, B35, 'Karachi Kabab Wala - Queen'!$F:$F), 0) -> 0
B36: Shami Kabab (Chicken) (6) | C36: - | E36: - | G36: - | I36: - | K36: - | M36: - | O36: - | Q36: - | S36: =IFERROR(SUMIF('Karachi Food Court'!$A:$A, B36, 'Karachi Food Court'!$F:$F), 0) -> 36 | U36: =IFERROR(SUMIF('Karachi Kabab Wala'!$A:$A, B36, 'Karachi Kabab Wala'!$F:$F), 0) -> 2 | W36: =IFERROR(SUMIF('Karachi Kabab Wala - Queen'!$A:$A, B36, 'Karachi Kabab Wala - Queen'!$F:$F), 0) -> 0
B37: Shami Kabab (Beef) (12) - OO | C37: - | E37: - | G37: - | I37: - | K37: - | M37: - | O37: - | Q37: - | S37: =IFERROR(SUMIF('Karachi Food Court'!$A:$A, B37, 'Karachi Food Court'!$F:$F), 0) -> 0 | U37: =IFERROR(SUMIF('Karachi Kabab Wala'!$A:$A, B37, 'Karachi Kabab Wala'!$F:$F), 0) -> 0 | W37: =IFERROR(SUMIF('Karachi Kabab Wala - Queen'!$A:$A, B37, 'Karachi Kabab Wala - Queen'!$F:$F), 0) -> 2
B38: Shami Kabab (Beef (6) - OO | C38: - | E38: - | G38: - | I38: - | K38: - | M38: - | O38: - | Q38: - | S38: =IFERROR(SUMIF('Karachi Food Court'!$A:$A, B38, 'Karachi Food Court'!$F:$F), 0) -> 1 | U38: =IFERROR(SUMIF('Karachi Kabab Wala'!$A:$A, B38, 'Karachi Kabab Wala'!$F:$F), 0) -> 0 | W38: =IFERROR(SUMIF('Karachi Kabab Wala - Queen'!$A:$A, B38, 'Karachi Kabab Wala - Queen'!$F:$F), 0) -> 1
B39: Shami Kabab (Chicken) (12) - OO | C39: - | E39: - | G39: - | I39: - | K39: - | M39: - | O39: - | Q39: - | S39: =IFERROR(SUMIF('Karachi Food Court'!$A:$A, B39, 'Karachi Food Court'!$F:$F), 0) -> 0 | U39: =IFERROR(SUMIF('Karachi Kabab Wala'!$A:$A, B39, 'Karachi Kabab Wala'!$F:$F), 0) -> 4 | W39: =IFERROR(SUMIF('Karachi Kabab Wala - Queen'!$A:$A, B39, 'Karachi Kabab Wala - Queen'!$F:$F), 0) -> 0
B40: 2 Can Dine for $29.99 | M40: - | Q40: - | S40: - | U40: =IFERROR(SUMIF('Karachi Kabab Wala'!$A:$A, B40, 'Karachi Kabab Wala'!$F:$F), 0) -> 1 | W40: =IFERROR(SUMIF('Karachi Kabab Wala - Queen'!$A:$A, B40, 'Karachi Kabab Wala - Queen'!$F:$F), 0) -> 5
B41: Lunch Deal with Biryani (KKW) | M41: - | Q41: - | S41: - | U41: =IFERROR(SUMIF('Karachi Kabab Wala'!$A:$A, B41, 'Karachi Kabab Wala'!$F:$F), 0) -> 0 | W41: =IFERROR(SUMIF('Karachi Kabab Wala - Queen'!$A:$A, B41, 'Karachi Kabab Wala - Queen'!$F:$F), 0) -> 2
...
